Workbook

Sheet Смета по ТСН-2001(с доп.43
A1: =Source!B1 -> Smeta.RU (495) 974-1589
J2: Форма № 4б
A3: 02-01-01 Строительство КЛ - 10 кВ траншея
A4: (наименование стройки и/или объекта)
A6: =CONCATENATE( "ЛОКАЛЬНАЯ СМЕТА № ",IF(Source!F12<>"Новый объект", Source!F12, "")) -> ЛОКАЛЬНАЯ СМЕТА № 02-01-01 КЛ - 10 кВ траншея
A8: Строительство КЛ - 10 кВ траншея
A9: (наименование работ и затрат)
A11: =CONCATENATE( "Основание: чертежи № ", Source!J12) -> Основание: чертежи №
I13: В базисном уровне цен | J13: В текущем уровне цен
E14: Сметная стоимость | I14: =I15+I16+I17+I18 -> 34.55 | J14: =J15+J16+J17+J18 -> 359.12 | K14: тыс.руб.
E15: Строительные работы | I15: =ROUND(SUM(X1:X400)/1000, 2) -> 6.77 | J15: =ROUND((Source!P501)/1000, 2) -> 99.86 | K15: тыс.руб.
E16: Работы по монтажу оборудования | I16: =ROUND(SUM(Y1:Y400)/1000, 2) -> 27.78 | J16: =ROUND((Source!P502)/1000, 2) -> 259.26 | K16: тыс.руб.
E17: Оборудование | I17: =ROUND(SUM(Z1:Z400)/1000, 2) -> 0 | J17: =ROUND((Source!P493)/1000, 2) -> 0 | K17: тыс.руб.
E18: Прочие работы и затраты | I18: =ROUND(SUM(AA1:AA400)/1000, 2) -> 0 | J18: =ROUND((Source!P503+Source!P504)/1000, 2) -> 0 | K18: тыс.руб.
E19: Средства на оплату труда | I19: =ROUND(SUM(W1:W400)/1000, 2) -> 1.14 | J19: =((Source!P499 + Source!P498)/1000) -> 39.43562 | K19: тыс.руб.
E20: Затраты труда | I20: =SUM(AB1:AB400) -> 87.630626 | K20: чел.-ч.
E21: Кроме того:
E22: Возврат материалов | I22: =ROUND(SUM(AE1:AE400)/1000, 2) -> 0 | J22: =SUM(AF1:AF400)/1000 -> 0 | K22: тыс.руб.
A24: Составлен(а) по ТСН-2001 с учетом Дополнения №: 73
A25: № и период сборника коэффициентов (индексов) пересчета: Коэффициенты к ТСН-2001 МГЭ №212 III квартал 2024 года | AP25: № и период сборника коэффициентов (индексов) пересчета: Коэффициенты к ТСН-2001 МГЭ №212 III квартал 2024 года
A26: № п/п | B26: Шифр расценки и коды ресурсов | C26: Наименование работ и затрат | D26: Ед. изм. | E26: Кол-во единиц | F26: Цена на ед. изм., руб. | G26: Попра- вочные коэффи- циенты | H26: Коэффи- циенты зимних удорожа- ний | I26: Всего затрат в базисном уровне цен, руб. | J26: Коэффи- циенты (индек- сы) пере- счета, нормы НР и СП | K26: ВСЕГО затрат в текущем уровне цен, руб.
A27: 1 | B27: 2 | C27: 3 | D27: 4 | E27: 5 | F27: 6 | G27: 7 | H27: 8 | I27: 9 | J27: 10 | K27: 11
A29: =CONCATENATE("Раздел: ",IF(Source!G24<>"Новый раздел", Source!G24, "")) -> Раздел: Земляные работы
A30: 1 | B30: 3.1-51-1 Поправка: О.П. п.3.4.30.г | C30: Разработка грунта вручную в траншеях глубиной до 2 м без креплений с откосами группа грунтов 1-3 | D30: =Source!DW29 -> 100 м3 грунта | E30: =Source!I29 -> 0.03672 | Q30: =ROUND((Source!DN29/100)*ROUND((ROUND((Source!AF29*Source!AV29*Source!I29),2)),2), 2) -> 103.2 | R30: =Source!X29 -> 2951.03 | S30: =ROUND((Source!DO29/100)*ROUND((ROUND((Source!AF29*Source!AV29*Source!I29),2)),2), 2) -> 75.68 | T30: =Source!Y29 -> 1390.72 | U30: =ROUND((175/100)*ROUND((ROUND((Source!AE29*Source!AV29*Source!I29),2)),2), 2) -> 0 | V30: =ROUND((160/100)*ROUND(ROUND((ROUND((Source!AE29*Source!AV29*Source!I29),2)*Source!BS29),2), 2), 2) -> 0 | AI30: 0
C31: ="Объем: "&Source!I29&"=12,24*"&"0,3/"&"100" -> Объем: 0,03672=12,24*0,3/100
C32: ЗП | F32: =Source!AO29 -> 2042.62 | G32: =Source!DG29 -> *1,05 | H32: =Source!AV29 -> 1.248 | I32: =ROUND((ROUND((Source!AF29*Source!AV29*Source!I29),2)),2) -> 98.29 | J32: =IF(Source!BA29<> 0, Source!BA29, 1) -> 34.51 | K32: =Source!S29 -> 3391.99 | W32: =I32 -> 98.29
C33: НР от ЗП | D33: % | E33: =Source!DN29 -> 105 | I33: =SUM(Q30:Q32) -> 103.2 | J33: =Source!BZ29 -> 87 | K33: =SUM(R30:R32) -> 2951.03
C34: СП от ЗП | D34: % | E34: =Source!DO29 -> 77 | I34: =SUM(S30:S33) -> 75.68 | J34: =Source!CA29 -> 41 | K34: =SUM(T30:T33) -> 1390.72
C35: ЗТР | D35: чел-ч | E35: =Source!AQ29 -> 192.7 | G35: =Source!DI29 -> *1,05 | H35: =Source!AV29 -> 1.248 | I35: =Source!U29 -> 9.272317 | AB35: =I35 -> 9.272317
C36: Всего по позиции: | H36: =I32+I33+I34+0 -> 277.17 | J36: =K32+K33+K34+0 -> 7733.74 | O36: =I32+I33+I34+0 -> 277.17 | P36: =K32+K33+K34+0 -> 7733.74 | X36: =IF(Source!BI29<=1,I32+I33+I34-0, 0) -> 277.17 | Y36: =IF(Source!BI29=2,I32+I33+I34-0, 0) -> 0 | Z36: =IF(Source!BI29=3,I32+I33+I34-0, 0) -> 0 | AA36: =IF(Source!BI29=4,I32+I33+I34,0) -> 0
A38: 2 | B38: 3.1-7-2 Поправка: О.П. п.3.4.30.г | C38: Разработка грунта с погрузкой на автомобили-самосвалы экскаваторами с ковшом вместимостью 0,25 м3 группа грунтов 1-3 | D38: =Source!DW31 -> 100 м3 грунта | E38: =Source!I31 -> 0.0481 | Q38: =ROUND((Source!DN31/100)*ROUND((ROUND((Source!AF31*Source!AV31*Source!I31),2)),2), 2) -> 1.78 | R38: =Source!X31 -> 59.04 | S38: =ROUND((Source!DO31/100)*ROUND((ROUND((Source!AF31*Source!AV31*Source!I31),2)),2), 2) -> 1.4 | T38: =Source!Y31 -> 32.03 | U38: =ROUND((175/100)*ROUND((ROUND((Source!AE31*Source!AV31*Source!I31),2)),2), 2) -> 13.97 | V38: =ROUND((160/100)*ROUND(ROUND((ROUND((Source!AE31*Source!AV31*Source!I31),2)*Source!BS31),2), 2), 2) -> 440.62 | AI38: 0
C39: ="Объем: "&Source!I31&"=4,81/"&"100" -> Объем: 0,0481=4,81/100
C40: ЗП | F40: =Source!AO31 -> 30.15 | G40: =Source!DG31 -> *1,05 | H40: =Source!AV31 -> 1.192 | I40: =ROUND((ROUND((Source!AF31*Source!AV31*Source!I31),2)),2) -> 1.82 | J40: =IF(Source!BA31<> 0, Source!BA31, 1) -> 34.51 | K40: =Source!S31 -> 62.81 | W40: =I40 -> 1.82
C41: ЭМ | F41: =Source!AM31 -> 1340.63 | G41: =Source!DE31 -> *1,05 | H41: =Source!AV31 -> 1.192 | I41: =(ROUND((ROUND((((Source!ET31*1.05))*Source!AV31*Source!I31),2)),2)+ROUND((ROUND(((Source!AE31-((Source!EU31*1.05)))*Source!AV31*Source!I31),2)),2)) -> 80.71 | J41: =IF(Source!BB31<> 0, Source!BB31, 1) -> 12.15 | K41: =Source!Q31 -> 980.63
C42: в т.ч. ЗПМ | F42: =Source!AN31 -> 132.48 | G42: =Source!DF31 -> *1,05 | H42: =Source!AV31 -> 1.192 | I42: =ROUND((ROUND((Source!AE31*Source!AV31*Source!I31),2)),2) -> 7.98 | J42: =IF(Source!BS31<> 0, Source!BS31, 1) -> 34.51 | K42: =Source!R31 -> 275.39 | W42: =I42 -> 7.98
C43: НР от ЗП | D43: % | E43: =Source!DN31 -> 98 | I43: =SUM(Q38:Q42) -> 1.78 | J43: =Source!BZ31 -> 94 | K43: =SUM(R38:R42) -> 59.04
C44: СП от ЗП | D44: % | E44: =Source!DO31 -> 77 | I44: =SUM(S38:S43) -> 1.4 | J44: =Source!CA31 -> 51 | K44: =SUM(T38:T43) -> 32.03
C45: НР и СП от ЗПМ | D45: % | E45: =175 -> 175 | I45: =SUM(U38:U44) -> 13.97 | J45: =160 -> 160 | K45: =SUM(V38:V44) -> 440.62
C46: ЗТР | D46: чел-ч | E46: =Source!AQ31 -> 2.95 | G46: =Source!DI31 -> *1,05 | H46: =Source!AV31 -> 1.192 | I46: =Source!U31 -> 0.17759578 | AB46: =I46 -> 0.17759578
C47: Всего по позиции: | H47: =I40+I41+I43+I44+I45+0 -> 99.68 | J47: =K40+K41+K43+K44+K45+0 -> 1575.13 | O47: =I40+I41+I43+I44+I45+0 -> 99.68 | P47: =K40+K41+K43+K44+K45+0 -> 1575.13 | X47: =IF(Source!BI31<=1,I40+I41+I43+I44+I45-0, 0) -> 99.68 | Y47: =IF(Source!BI31=2,I40+I41+I43+I44+I45-0, 0) -> 0 | Z47: =IF(Source!BI31=3,I40+I41+I43+I44+I45-0, 0) -> 0 | AA47: =IF(Source!BI31=4,I40+I41+I43+I44+I45,0) -> 0
...

Sheet Source
A1: 0 | B1: Smeta.RU (495) 974-1589 | D1: _PS_ | F1: 0 | G1: 0 | H1: 0 | I1: Smeta.RU | K1: 1 | L1: 75112 | M1: 10 | N1: 11 | O1: 15 | P1: 0 | Q1: 1
A12: 1 | B12: 519 | C12: 1 | D12: =ROW(A484) -> 484 | E12: 0 | F12: 02-01-01 КЛ - 10 кВ траншея | G12: 02-01-01 | I12: 0 | K12: 0 | L12: 0 | M12: 4098 | O12: 0 | P12: 0 | Q12: 0 | R12: 175 | S12: 160 | T12: 1 | V12: 0 | BB12: 0 | BH12: Сметные нормы списания | BI12: Коды ОКП для ТСН-2001 МГЭ (История развития) | BJ12: 1 | BK12: 1 | BL12: 0 | BM12: 0 | BN12: 1 | BO12: 0 | BP12: 6 | BQ12: 2 | BR12: 1 | BS12: 1 | BT12: 0 | BU12: 0 | BV12: 0 | BW12: 0 | BX12: 0 | BZ12: Типовой расчет для ТСН-2001 МГЭ, Новая методика с выпуска доп. 43 (Строительство), Доп 73 | CA12: История развития для ТСН-2001 (МГЭ) 73 доп от 17.07.2024 | CB12: История развития для ТСН-2001 (МГЭ) 73 доп от 17.07.2024 | CC12: История развития для ТСН-2001 (МГЭ) 73 доп от 17.07.2024 | CD12: История развития для ТСН-2001 (МГЭ) 73 доп от 17.07.2024 | CE12: Поправки для ТСН-2001 от 16.04.2024 г. доп.72 | CF12: 0 | CG12: 0 | CH12: 8 | CK12: 79 | CQ12: Территориальные сметные нормативы для Москвы (ТСН-2001) | CR12: ТЕР | CS12: 41660 | CT12: 1 | CU12: 73 | CY12: 0 | EC12: 0
A15: 15 | B15: 1
A18: 52 | B18: =B484 -> 519 | C18: =C484 -> 1 | D18: =D484 -> 12 | E18: =E484 -> 0 | F18: =F484 -> 02-01-01 КЛ - 10 кВ траншея | G18: =G484 -> 02-01-01 | O18: =O484 -> 32252.82 | P18: =P484 -> 30165.58 | Q18: =Q484 -> 1076.15 | R18: =R484 -> 131.64 | S18: =S484 -> 1011.09 | T18: =T484 -> 0 | U18: =U484 -> 87.630626 | V18: =V484 -> 0 | ... GX18: =GX484 -> 0
A20: 3 | B20: 1 | D20: =ROW(A454) -> 454 | F20: Новая локальная смета | G20: Строительство КЛ 10 кВ | I20: 0 | K20: -1 | L20: Новая локальная смета | S20: 0 | T20: 0 | V20: 0 | BX20: 0 | CF20: 0 | CG20: 0
A22: 52 | B22: =B454 -> 1 | C22: =C454 -> 3 | D22: =D454 -> 20 | E22: =E454 -> 0 | F22: =F454 -> Новая локальная смета | G22: =G454 -> Строительство КЛ 10 кВ | O22: =O454 -> 32252.82 | P22: =P454 -> 30165.58 | Q22: =Q454 -> 1076.15 | R22: =R454 -> 131.64 | S22: =S454 -> 1011.09 | T22: =T454 -> 0 | U22: =U454 -> 87.630626 | V22: =V454 -> 0 | ... GX22: =GX454 -> 0
A24: 4 | B24: 1 | D24: =ROW(A59) -> 59 | F24: Новый раздел | G24: Земляные работы | I24: 0 | K24: 0 | S24: 0 | T24: 0 | V24: 0 | BX24: 0 | CJ24: 0
A26: 52 | B26: =B59 -> 1 | C26: =C59 -> 4 | D26: =D59 -> 24 | E26: =E59 -> 0 | F26: =F59 -> Новый раздел | G26: =G59 -> Земляные работы | O26: =O59 -> 266.14 | P26: =P59 -> 0 | Q26: =Q59 -> 132.32 | R26: =R59 -> 13.08 | S26: =S59 -> 133.82 | T26: =T59 -> 0 | U26: =U59 -> 12.880666 | V26: =V59 -> 0 | ... GX26: =GX59 -> 0
A28: 17 | B28: 1 | D28: =ROW(EtalonRes!A1) -> 1 | E28: 1 | F28: 3.1-51-1 | G28: Разработка грунта вручную в траншеях глубиной до 2 м без креплений с откосами группа грунтов 1-3 | H28: 100 м3 грунта | I28: =ROUND(12.24*0.3/100,9) -> 0.03672 | J28: 0 | K28: =ROUND(12.24*0.3/100,9) -> 0.03672 | O28: =ROUND(CP28,2) -> 98.29 | P28: =ROUND((ROUND((AC28*AW28*I28),2)*BC28),2) -> 0 | Q28: =(ROUND((ROUND((((ET28*1.05))*AV28*I28),2)*BB28),2)+ROUND((ROUND(((AE28-((EU28*1.05)))*AV28*I28),2)*BS28),2)) -> 0 | R28: =ROUND((ROUND((AE28*AV28*I28),2)*BS28),2) -> 0 | S28: =ROUND((ROUND((AF28*AV28*I28),2)*BA28),2) -> 98.29 | T28: =ROUND(CU28*I28,2) -> 0 | U28: =CV28*I28 -> 9.272317 | V28: =CW28*I28 -> 0 | W28: =ROUND(CX28*I28,2) -> 0 | X28: =ROUND(CY28,2) -> 103.2 | Y28: =ROUND(CZ28,2) -> 75.68 | AA28: 56622490 | AB28: =ROUND((AC28+AD28+AF28),6) -> 2144.751 | AC28: =ROUND((ES28),6) -> 0 | AD28: =ROUND(((((ET28*1.05))-((EU28*1.05)))+AE28),6) -> 0 | AE28: =ROUND(((EU28*1.05)),6) -> 0 | AF28: =ROUND(((EV28*1.05)),6) -> 2144.751 | AG28: =ROUND((AP28),6) -> 0 | AH28: =((EW28*1.05)) -> 202.335 | AI28: =((EX28*1.05)) -> 0 | AJ28: =(AS28) -> 0 | AK28: 2042.62 | AL28: 0 | AM28: 0 | AN28: 0 | AO28: 2042.62 | AP28: 0 | AQ28: 192.7 | AR28: 0 | AS28: 0 | AT28: 105 | AU28: 77 | AV28: 1.248 | AW28: 1 | AZ28: 1 | BA28: 1 | BB28: 1 | BC28: 1 | BH28: 0 | BI28: 1 | BJ28: ТСН-2001.3. Доп. 1-42. Сб. 1, т. 51, поз. 1 | BM28: 16 | BN28: 0 | BP28: 0 | BQ28: 30 | BR28: 0 | BS28: 1 | BT28: 1 | BU28: 1 | BV28: 1 | BW28: 1 | BX28: 1 | BZ28: 105 | CA28: 77 | CE28: 30 | CF28: 0 | CG28: 0 | CM28: 0 | CN28: Поправка: О.П. п.3.4.30.г Наименование: В отношении объектов, реализуемых с привлечением средств бюджета города Москвы, затраты, учитывающие усложненные условия производства работ (стесненность, сложность складирования и транспортной логистики, наличие в зоне производства работ действующего технологического оборудования или движения технологического транспорта и т.п.), определяются заказчиком в задании на проектирование при составлении локальных сметных расчетов (смет): для объектов города Москвы, расположенных за пределами Московской кольцевой автомобильной дороги | CO28: 0 | CP28: =(P28+Q28+S28) -> 98.29 | CQ28: =ROUND((ROUND((AC28*AW28*1),2)*BC28),2) -> 0 | CR28: =(ROUND((ROUND((((ET28*1.05))*AV28*1),2)*BB28),2)+ROUND((ROUND(((AE28-((EU28*1.05)))*AV28*1),2)*BS28),2)) -> 0 | CS28: =ROUND((ROUND((AE28*AV28*1),2)*BS28),2) -> 0 | CT28: =ROUND((ROUND((AF28*AV28*1),2)*BA28),2) -> 2676.65 | CU28: =AG28 -> 0 | CV28: =(AH28*AV28) -> 252.51408 | CW28: =AI28 -> 0 | CX28: =AJ28 -> 0 | CY28: =((S28*BZ28)/100) -> 103.2045 | CZ28: =((S28*CA28)/100) -> 75.6833 | DB28: 1 | DE28: *1,05 | DF28: *1,05 | DG28: *1,05 | DI28: *1,05 | DJ28: *1,05 | DN28: 0 | DO28: 0 | DP28: 1 | DQ28: 1 | DU28: 1013 | DV28: 100 м3 грунта | DW28: 100 м3 грунта | DX28: 1 | EE28: 51696099 | EF28: 30 | EG28: Строительные работы | EH28: 0 | EJ28: 1 | EK28: 16 | EL28: ТСН-2001.3-1. 1-49...1-55 | EM28: ТСН-2001.3-1-15 | EO28: Поправка: О.П. п.3.4.30.г | EQ28: 131072 | ER28: 2042.62 | ES28: 0 | ET28: 0 | EU28: 0 | EV28: 2042.62 | EW28: 192.7 | EX28: 0 | EY28: 0 | FQ28: 0 | FR28: 0 | FS28: 0 | FX28: 105 | FY28: 77 | GD28: 0 | GF28: -2104602307 | GG28: 2 | GH28: 1 | GI28: -2 | GJ28: 0 | GK28: =ROUND(R28*(R12)/100,2) -> 0 | GL28: =ROUND(IF(AND(BH28=3,BI28=3,FS28<>0),P28,0),2) -> 0 | GM28: =ROUND(O28+X28+Y28+GK28,2)+GX28 -> 277.17 | GN28: =IF(OR(BI28=0,BI28=1),GM28-GX28,0) -> 277.17 | GO28: =IF(BI28=2,GM28-GX28,0) -> 0 | GP28: =IF(BI28=4,GM28-GX28,0) -> 0 | GR28: 0 | GS28: 0 | GT28: 0 | GV28: =ROUND((GT28),6) -> 0 | GW28: 1 | GX28: =ROUND(HC28*I28,2) -> 0 | HA28: 0 | HB28: 0 | HC28: =GV28*GW28 -> 0 | HS28: 0 | IK28: 0
A29: 17 | B29: 1 | D29: =ROW(EtalonRes!A2) -> 2 | E29: 1 | F29: 3.1-51-1 | G29: Разработка грунта вручную в траншеях глубиной до 2 м без креплений с откосами группа грунтов 1-3 | H29: 100 м3 грунта | I29: =ROUND(12.24*0.3/100,9) -> 0.03672 | J29: 0 | K29: =ROUND(12.24*0.3/100,9) -> 0.03672 | O29: =ROUND(CP29,2) -> 3391.99 | P29: =ROUND((ROUND((AC29*AW29*I29),2)*BC29),2) -> 0 | Q29: =(ROUND((ROUND((((ET29*1.05))*AV29*I29),2)*BB29),2)+ROUND((ROUND(((AE29-((EU29*1.05)))*AV29*I29),2)*BS29),2)) -> 0 | R29: =ROUND((ROUND((AE29*AV29*I29),2)*BS29),2) -> 0 | S29: =ROUND((ROUND((AF29*AV29*I29),2)*BA29),2) -> 3391.99 | T29: =ROUND(CU29*I29,2) -> 0 | U29: =CV29*I29 -> 9.272317 | V29: =CW29*I29 -> 0 | W29: =ROUND(CX29*I29,2) -> 0 | X29: =ROUND(CY29,2) -> 2951.03 | Y29: =ROUND(CZ29,2) -> 1390.72 | AA29: 56610029 | AB29: =ROUND((AC29+AD29+AF29),6) -> 2144.751 | AC29: =ROUND((ES29),6) -> 0 | AD29: =ROUND(((((ET29*1.05))-((EU29*1.05)))+AE29),6) -> 0 | AE29: =ROUND(((EU29*1.05)),6) -> 0 | AF29: =ROUND(((EV29*1.05)),6) -> 2144.751 | AG29: =ROUND((AP29),6) -> 0 | AH29: =((EW29*1.05)) -> 202.335 | AI29: =((EX29*1.05)) -> 0 | AJ29: =(AS29) -> 0 | AK29: 2042.62 | AL29: 0 | AM29: 0 | AN29: 0 | AO29: 2042.62 | AP29: 0 | AQ29: 192.7 | AR29: 0 | AS29: 0 | AT29: 87 | AU29: 41 | AV29: 1.248 | AW29: 1 | AZ29: 1 | BA29: 34.51 | BB29: 1 | BC29: 1 | BH29: 0 | BI29: 1 | BJ29: ТСН-2001.3. Доп. 1-42. Сб. 1, т. 51, поз. 1 | BM29: 16 | BN29: 0 | BO29: 3.1-51-1 | BP29: 1 | BQ29: 30 | BR29: 0 | BS29: 34.51 | BT29: 1 | BU29: 1 | BV29: 1 | BW29: 1 | BX29: 1 | BZ29: 87 | CA29: 41 | CE29: 30 | CF29: 0 | CG29: 0 | CM29: 0 | CN29: Поправка: О.П. п.3.4.30.г Наименование: В отношении объектов, реализуемых с привлечением средств бюджета города Москвы, затраты, учитывающие усложненные условия производства работ (стесненность, сложность складирования и транспортной логистики, наличие в зоне производства работ действующего технологического оборудования или движения технологического транспорта и т.п.), определяются заказчиком в задании на проектирование при составлении локальных сметных расчетов (смет): для объектов города Москвы, расположенных за пределами Московской кольцевой автомобильной дороги | CO29: 0 | CP29: =(P29+Q29+S29) -> 3391.99 | CQ29: =ROUND((ROUND((AC29*AW29*1),2)*BC29),2) -> 0 | CR29: =(ROUND((ROUND((((ET29*1.05))*AV29*1),2)*BB29),2)+ROUND((ROUND(((AE29-((EU29*1.05)))*AV29*1),2)*BS29),2)) -> 0 | CS29: =ROUND((ROUND((AE29*AV29*1),2)*BS29),2) -> 0 | CT29: =ROUND((ROUND((AF29*AV29*1),2)*BA29),2) -> 92371.19 | CU29: =AG29 -> 0 | CV29: =(AH29*AV29) -> 252.51408 | CW29: =AI29 -> 0 | CX29: =AJ29 -> 0 | CY29: =S29*(BZ29/100) -> 2951.0313 | CZ29: =S29*(CA29/100) -> 1390.7159 | DB29: 2 | DE29: *1,05 | DF29: *1,05 | DG29: *1,05 | DI29: *1,05 | DJ29: *1,05 | DN29: 105 | DO29: 77 | DP29: 1.248 | DQ29: 1 | DU29: 1013 | DV29: 100 м3 грунта | DW29: 100 м3 грунта | DX29: 1 | EE29: 51696099 | EF29: 30 | EG29: Строительные работы | EH29: 0 | EJ29: 1 | EK29: 16 | EL29: ТСН-2001.3-1. 1-49...1-55 | EM29: ТСН-2001.3-1-15 | EO29: Поправка: О.П. п.3.4.30.г | EQ29: 131072 | ER29: 2042.62 | ES29: 0 | ET29: 0 | EU29: 0 | EV29: 2042.62 | EW29: 192.7 | EX29: 0 | EY29: 0 | FQ29: 0 | FR29: 0 | FS29: 0 | FX29: 105 | FY29: 77 | GD29: 0 | GF29: -2104602307 | GG29: 2 | GH29: 1 | GI29: 2 | GJ29: 0 | GK29: =ROUND(R29*(S12)/100,2) -> 0 | GL29: =ROUND(IF(AND(BH29=3,BI29=3,FS29<>0),P29,0),2) -> 0 | GM29: =ROUND(O29+X29+Y29+GK29,2)+GX29 -> 7733.74 | GN29: =IF(OR(BI29=0,BI29=1),GM29-GX29,0) -> 7733.74 | GO29: =IF(BI29=2,GM29-GX29,0) -> 0 | GP29: =IF(BI29=4,GM29-GX29,0) -> 0 | GR29: 0 | GS29: 3 | GT29: 0 | GV29: =ROUND((GT29),6) -> 0 | GW29: 1 | GX29: =ROUND(HC29*I29,2) -> 0 | HA29: 0 | HB29: 0 | HC29: =GV29*GW29 -> 0 | HS29: 0 | IK29: 0
A30: 17 | B30: 1 | D30: =ROW(EtalonRes!A5) -> 5 | E30: 2 | F30: 3.1-7-2 | G30: Разработка грунта с погрузкой на автомобили-самосвалы экскаваторами с ковшом вместимостью 0,25 м3 группа грунтов 1-3 | H30: 100 м3 грунта | I30: =ROUND(4.81/100,9) -> 0.0481 | J30: 0 | K30: =ROUND(4.81/100,9) -> 0.0481 | O30: =ROUND(CP30,2) -> 82.53 | P30: =ROUND((ROUND((AC30*AW30*I30),2)*BC30),2) -> 0 | Q30: =(ROUND((ROUND((((ET30*1.05))*AV30*I30),2)*BB30),2)+ROUND((ROUND(((AE30-((EU30*1.05)))*AV30*I30),2)*BS30),2)) -> 80.71 | R30: =ROUND((ROUND((AE30*AV30*I30),2)*BS30),2) -> 7.98 | S30: =ROUND((ROUND((AF30*AV30*I30),2)*BA30),2) -> 1.82 | T30: =ROUND(CU30*I30,2) -> 0 | U30: =CV30*I30 -> 0.17759578 | V30: =CW30*I30 -> 0 | W30: =ROUND(CX30*I30,2) -> 0 | X30: =ROUND(CY30,2) -> 1.78 | Y30: =ROUND(CZ30,2) -> 1.4 | AA30: 56622490 | AB30: =ROUND((AC30+AD30+AF30),6) -> 1439.319 | AC30: =ROUND((ES30),6) -> 0 | AD30: =ROUND(((((ET30*1.05))-((EU30*1.05)))+AE30),6) -> 1407.6615 | AE30: =ROUND(((EU30*1.05)),6) -> 139.104 | AF30: =ROUND(((EV30*1.05)),6) -> 31.6575 | AG30: =ROUND((AP30),6) -> 0 | AH30: =((EW30*1.05)) -> 3.0975 | AI30: =((EX30*1.05)) -> 0 | AJ30: =(AS30) -> 0 | AK30: 1370.78 | AL30: 0 | AM30: 1340.63 | AN30: 132.48 | AO30: 30.15 | AP30: 0 | AQ30: 2.95 | AR30: 0 | AS30: 0 | AT30: 98 | AU30: 77 | AV30: 1.192 | AW30: 1 | AZ30: 1 | BA30: 1 | BB30: 1 | BC30: 1 | BH30: 0 | BI30: 1 | BJ30: ТСН-2001.3 Доп. 70, Сб. 1, т. 7, поз. 2 | BM30: 2 | BN30: 0 | BP30: 0 | BQ30: 30 | BR30: 0 | BS30: 1 | BT30: 1 | BU30: 1 | BV30: 1 | BW30: 1 | BX30: 1 | BZ30: 98 | CA30: 77 | CE30: 30 | CF30: 0 | CG30: 0 | CM30: 0 | CN30: Поправка: О.П. п.3.4.30.г Наименование: В отношении объектов, реализуемых с привлечением средств бюджета города Москвы, затраты, учитывающие усложненные условия производства работ (стесненность, сложность складирования и транспортной логистики, наличие в зоне производства работ действующего технологического оборудования или движения технологического транспорта и т.п.), определяются заказчиком в задании на проектирование при составлении локальных сметных расчетов (смет): для объектов города Москвы, расположенных за пределами Московской кольцевой автомобильной дороги | CO30: 0 | CP30: =(P30+Q30+S30) -> 82.53 | CQ30: =ROUND((ROUND((AC30*AW30*1),2)*BC30),2) -> 0 | CR30: =(ROUND((ROUND((((ET30*1.05))*AV30*1),2)*BB30),2)+ROUND((ROUND(((AE30-((EU30*1.05)))*AV30*1),2)*BS30),2)) -> 1677.93 | CS30: =ROUND((ROUND((AE30*AV30*1),2)*BS30),2) -> 165.81 | CT30: =ROUND((ROUND((AF30*AV30*1),2)*BA30),2) -> 37.74 | CU30: =AG30 -> 0 | CV30: =(AH30*AV30) -> 3.69222 | CW30: =AI30 -> 0 | CX30: =AJ30 -> 0 | CY30: =((S30*BZ30)/100) -> 1.7836 | CZ30: =((S30*CA30)/100) -> 1.4014 | DB30: 3 | DE30: *1,05 | DF30: *1,05 | DG30: *1,05 | DI30: *1,05 | DJ30: *1,05 | DN30: 0 | DO30: 0 | DP30: 1 | DQ30: 1 | DU30: 1013 | DV30: 100 м3 грунта | DW30: 100 м3 грунта | DX30: 1 | EE30: 51696085 | EF30: 30 | EG30: Строительные работы | EH30: 0 | EJ30: 1 | EK30: 2 | EL30: ТСН-2001.3-1. 1-1...1-7 | EM30: ТСН-2001.3-1-1 | EO30: Поправка: О.П. п.3.4.30.г | EQ30: 131072 | ER30: 1370.78 | ES30: 0 | ET30: 1340.63 | EU30: 132.48 | EV30: 30.15 | EW30: 2.95 | EX30: 0 | EY30: 0 | FQ30: 0 | FR30: 0 | FS30: 0 | FX30: 98 | FY30: 77 | GD30: 0 | GF30: -1260581983 | GG30: 2 | GH30: 1 | GI30: -2 | GJ30: 0 | GK30: =ROUND(R30*(R12)/100,2) -> 13.97 | GL30: =ROUND(IF(AND(BH30=3,BI30=3,FS30<>0),P30,0),2) -> 0 | GM30: =ROUND(O30+X30+Y30+GK30,2)+GX30 -> 99.68 | GN30: =IF(OR(BI30=0,BI30=1),GM30-GX30,0) -> 99.68 | GO30: =IF(BI30=2,GM30-GX30,0) -> 0 | GP30: =IF(BI30=4,GM30-GX30,0) -> 0 | GR30: 0 | GS30: 0 | GT30: 0 | GV30: =ROUND((GT30),6) -> 0 | GW30: 1 | GX30: =ROUND(HC30*I30,2) -> 0 | HA30: 0 | HB30: 0 | HC30: =GV30*GW30 -> 0 | HS30: 0 | IK30: 0
A31: 17 | B31: 1 | D31: =ROW(EtalonRes!A8) -> 8 | E31: 2 | F31: 3.1-7-2 | G31: Разработка грунта с погрузкой на автомобили-самосвалы экскаваторами с ковшом вместимостью 0,25 м3 группа грунтов 1-3 | H31: 100 м3 грунта | I31: =ROUND(4.81/100,9) -> 0.0481 | J31: 0 | K31: =ROUND(4.81/100,9) -> 0.0481 | O31: =ROUND(CP31,2) -> 1043.44 | P31: =ROUND((ROUND((AC31*AW31*I31),2)*BC31),2) -> 0 | Q31: =(ROUND((ROUND((((ET31*1.05))*AV31*I31),2)*BB31),2)+ROUND((ROUND(((AE31-((EU31*1.05)))*AV31*I31),2)*BS31),2)) -> 980.63 | R31: =ROUND((ROUND((AE31*AV31*I31),2)*BS31),2) -> 275.39 | S31: =ROUND((ROUND((AF31*AV31*I31),2)*BA31),2) -> 62.81 | T31: =ROUND(CU31*I31,2) -> 0 | U31: =CV31*I31 -> 0.17759578 | V31: =CW31*I31 -> 0 | W31: =ROUND(CX31*I31,2) -> 0 | X31: =ROUND(CY31,2) -> 59.04 | Y31: =ROUND(CZ31,2) -> 32.03 | AA31: 56610029 | AB31: =ROUND((AC31+AD31+AF31),6) -> 1439.319 | AC31: =ROUND((ES31),6) -> 0 | AD31: =ROUND(((((ET31*1.05))-((EU31*1.05)))+AE31),6) -> 1407.6615 | AE31: =ROUND(((EU31*1.05)),6) -> 139.104 | AF31: =ROUND(((EV31*1.05)),6) -> 31.6575 | AG31: =ROUND((AP31),6) -> 0 | AH31: =((EW31*1.05)) -> 3.0975 | AI31: =((EX31*1.05)) -> 0 | AJ31: =(AS31) -> 0 | AK31: 1370.78 | AL31: 0 | AM31: 1340.63 | AN31: 132.48 | AO31: 30.15 | AP31: 0 | AQ31: 2.95 | AR31: 0 | AS31: 0 | AT31: 94 | AU31: 51 | AV31: 1.192 | AW31: 1 | AZ31: 1 | BA31: 34.51 | BB31: 12.15 | BC31: 1 | BH31: 0 | BI31: 1 | BJ31: ТСН-2001.3 Доп. 70, Сб. 1, т. 7, поз. 2 | BM31: 2 | BN31: 0 | BO31: 3.1-7-2 | BP31: 1 | BQ31: 30 | BR31: 0 | BS31: 34.51 | BT31: 1 | BU31: 1 | BV31: 1 | BW31: 1 | BX31: 1 | BZ31: 94 | CA31: 51 | CE31: 30 | CF31: 0 | CG31: 0 | CM31: 0 | CN31: Поправка: О.П. п.3.4.30.г Наименование: В отношении объектов, реализуемых с привлечением средств бюджета города Москвы, затраты, учитывающие усложненные условия производства работ (стесненность, сложность складирования и транспортной логистики, наличие в зоне производства работ действующего технологического оборудования или движения технологического транспорта и т.п.), определяются заказчиком в задании на проектирование при составлении локальных сметных расчетов (смет): для объектов города Москвы, расположенных за пределами Московской кольцевой автомобильной дороги | CO31: 0 | CP31: =(P31+Q31+S31) -> 1043.44 | CQ31: =ROUND((ROUND((AC31*AW31*1),2)*BC31),2) -> 0 | CR31: =(ROUND((ROUND((((ET31*1.05))*AV31*1),2)*BB31),2)+ROUND((ROUND(((AE31-((EU31*1.05)))*AV31*1),2)*BS31),2)) -> 20386.85 | CS31: =ROUND((ROUND((AE31*AV31*1),2)*BS31),2) -> 5722.1 | CT31: =ROUND((ROUND((AF31*AV31*1),2)*BA31),2) -> 1302.41 | CU31: =AG31 -> 0 | CV31: =(AH31*AV31) -> 3.69222 | CW31: =AI31 -> 0 | CX31: =AJ31 -> 0 | CY31: =S31*(BZ31/100) -> 59.0414 | CZ31: =S31*(CA31/100) -> 32.0331 | DB31: 4 | DE31: *1,05 | DF31: *1,05 | DG31: *1,05 | DI31: *1,05 | DJ31: *1,05 | DN31: 98 | DO31: 77 | DP31: 1.192 | DQ31: 1 | DU31: 1013 | DV31: 100 м3 грунта | DW31: 100 м3 грунта | DX31: 1 | EE31: 51696085 | EF31: 30 | EG31: Строительные работы | EH31: 0 | EJ31: 1 | EK31: 2 | EL31: ТСН-2001.3-1. 1-1...1-7 | EM31: ТСН-2001.3-1-1 | EO31: Поправка: О.П. п.3.4.30.г | EQ31: 131072 | ER31: 1370.78 | ES31: 0 | ET31: 1340.63 | EU31: 132.48 | EV31: 30.15 | EW31: 2.95 | EX31: 0 | EY31: 0 | FQ31: 0 | FR31: 0 | FS31: 0 | FX31: 98 | FY31: 77 | GD31: 0 | GF31: -1260581983 | GG31: 2 | GH31: 1 | GI31: 2 | GJ31: 0 | GK31: =ROUND(R31*(S12)/100,2) -> 440.62 | GL31: =ROUND(IF(AND(BH31=3,BI31=3,FS31<>0),P31,0),2) -> 0 | GM31: =ROUND(O31+X31+Y31+GK31,2)+GX31 -> 1575.13 | GN31: =IF(OR(BI31=0,BI31=1),GM31-GX31,0) -> 1575.13 | GO31: =IF(BI31=2,GM31-GX31,0) -> 0 | GP31: =IF(BI31=4,GM31-GX31,0) -> 0 | GR31: 0 | GS31: 3 | GT31: 0 | GV31: =ROUND((GT31),6) -> 0 | GW31: 1 | GX31: =ROUND(HC31*I31,2) -> 0 | HA31: 0 | HB31: 0 | HC31: =GV31*GW31 -> 0 | HS31: 0 | IK31: 0
A32: 17 | B32: 1 | D32: =ROW(EtalonRes!A10) -> 10 | E32: 3 | F32: 3.1-3-2 | G32: Разработка грунта в отвал экскаваторами с ковшом вместимостью 0,25 м3 группа грунтов 1-3 | H32: 100 м3 грунта | I32: =ROUND(12.24/100-I28-I30,9) -> 0.03758 | J32: 0 | K32: =ROUND(12.24/100-I28-I30,9) -> 0.03758 | O32: =ROUND(CP32,2) -> 44.41 | P32: =ROUND((ROUND((AC32*AW32*I32),2)*BC32),2) -> 0 | Q32: =(ROUND((ROUND((((ET32*1.05))*AV32*I32),2)*BB32),2)+ROUND((ROUND(((AE32-((EU32*1.05)))*AV32*I32),2)*BS32),2)) -> 43.84 | R32: =ROUND((ROUND((AE32*AV32*I32),2)*BS32),2) -> 4.32 | S32: =ROUND((ROUND((AF32*AV32*I32),2)*BA32),2) -> 0.57 | T32: =ROUND(CU32*I32,2) -> 0 | U32: =CV32*I32 -> 0.055971802 | V32: =CW32*I32 -> 0 | W32: =ROUND(CX32*I32,2) -> 0 | X32: =ROUND(CY32,2) -> 0.56 | Y32: =ROUND(CZ32,2) -> 0.44 | AA32: 56622490 | AB32: =ROUND((AC32+AD32+AF32),6) -> 991.431 | AC32: =ROUND((ES32),6) -> 0 | AD32: =ROUND(((((ET32*1.05))-((EU32*1.05)))+AE32),6) -> 978.663 | AE32: =ROUND(((EU32*1.05)),6) -> 96.4845 | AF32: =ROUND(((EV32*1.05)),6) -> 12.768 | AG32: =ROUND((AP32),6) -> 0 | AH32: =((EW32*1.05)) -> 1.2495 | AI32: =((EX32*1.05)) -> 0 | AJ32: =(AS32) -> 0 | AK32: 944.22 | AL32: 0 | AM32: 932.06 | AN32: 91.89 | AO32: 12.16 | AP32: 0 | AQ32: 1.19 | AR32: 0 | AS32: 0 | AT32: 98 | AU32: 77 | AV32: 1.192 | AW32: 1 | AZ32: 1 | BA32: 1 | BB32: 1 | BC32: 1 | BH32: 0 | BI32: 1 | BJ32: ТСН-2001.3 Доп. 68, Сб. 1, т. 3, поз. 2 | BM32: 2 | BN32: 0 | BP32: 0 | BQ32: 30 | BR32: 0 | BS32: 1 | BT32: 1 | BU32: 1 | BV32: 1 | BW32: 1 | BX32: 1 | BZ32: 98 | CA32: 77 | CE32: 30 | CF32: 0 | CG32: 0 | CM32: 0 | CN32: Поправка: О.П. п.3.4.30.г Наименование: В отношении объектов, реализуемых с привлечением средств бюджета города Москвы, затраты, учитывающие усложненные условия производства работ (стесненность, сложность складирования и транспортной логистики, наличие в зоне производства работ действующего технологического оборудования или движения технологического транспорта и т.п.), определяются заказчиком в задании на проектирование при составлении локальных сметных расчетов (смет): для объектов города Москвы, расположенных за пределами Московской кольцевой автомобильной дороги | CO32: 0 | CP32: =(P32+Q32+S32) -> 44.41 | CQ32: =ROUND((ROUND((AC32*AW32*1),2)*BC32),2) -> 0 | CR32: =(ROUND((ROUND((((ET32*1.05))*AV32*1),2)*BB32),2)+ROUND((ROUND(((AE32-((EU32*1.05)))*AV32*1),2)*BS32),2)) -> 1166.57 | CS32: =ROUND((ROUND((AE32*AV32*1),2)*BS32),2) -> 115.01 | CT32: =ROUND((ROUND((AF32*AV32*1),2)*BA32),2) -> 15.22 | CU32: =AG32 -> 0 | CV32: =(AH32*AV32) -> 1.489404 | CW32: =AI32 -> 0 | CX32: =AJ32 -> 0 | CY32: =((S32*BZ32)/100) -> 0.5586 | CZ32: =((S32*CA32)/100) -> 0.4389 | DB32: 5 | DE32: *1,05 | DF32: *1,05 | DG32: *1,05 | DI32: *1,05 | DJ32: *1,05 | DN32: 0 | DO32: 0 | DP32: 1 | DQ32: 1 | DU32: 1013 | DV32: 100 м3 грунта | DW32: 100 м3 грунта | DX32: 1 | EE32: 51696085 | EF32: 30 | EG32: Строительные работы | EH32: 0 | EJ32: 1 | EK32: 2 | EL32: ТСН-2001.3-1. 1-1...1-7 | EM32: ТСН-2001.3-1-1 | EO32: Поправка: О.П. п.3.4.30.г | EQ32: 131072 | ER32: 944.22 | ES32: 0 | ET32: 932.06 | EU32: 91.89 | EV32: 12.16 | EW32: 1.19 | EX32: 0 | EY32: 0 | FQ32: 0 | FR32: 0 | FS32: 0 | FX32: 98 | FY32: 77 | GD32: 0 | GF32: 864155608 | GG32: 2 | GH32: 1 | GI32: -2 | GJ32: 0 | GK32: =ROUND(R32*(R12)/100,2) -> 7.56 | GL32: =ROUND(IF(AND(BH32=3,BI32=3,FS32<>0),P32,0),2) -> 0 | GM32: =ROUND(O32+X32+Y32+GK32,2)+GX32 -> 52.97 | GN32: =IF(OR(BI32=0,BI32=1),GM32-GX32,0) -> 52.97 | GO32: =IF(BI32=2,GM32-GX32,0) -> 0 | GP32: =IF(BI32=4,GM32-GX32,0) -> 0 | GR32: 0 | GS32: 0 | GT32: 0 | GV32: =ROUND((GT32),6) -> 0 | GW32: 1 | GX32: =ROUND(HC32*I32,2) -> 0 | HA32: 0 | HB32: 0 | HC32: =GV32*GW32 -> 0 | HS32: 0 | IK32: 0
A33: 17 | B33: 1 | D33: =ROW(EtalonRes!A12) -> 12 | E33: 3 | F33: 3.1-3-2 | G33: Разработка грунта в отвал экскаваторами с ковшом вместимостью 0,25 м3 группа грунтов 1-3 | H33: 100 м3 грунта | I33: =ROUND(12.24/100-I29-I31,9) -> 0.03758 | J33: 0 | K33: =ROUND(12.24/100-I29-I31,9) -> 0.03758 | O33: =ROUND(CP33,2) -> 553.2 | P33: =ROUND((ROUND((AC33*AW33*I33),2)*BC33),2) -> 0 | Q33: =(ROUND((ROUND((((ET33*1.05))*AV33*I33),2)*BB33),2)+ROUND((ROUND(((AE33-((EU33*1.05)))*AV33*I33),2)*BS33),2)) -> 533.53 | R33: =ROUND((ROUND((AE33*AV33*I33),2)*BS33),2) -> 149.08 | S33: =ROUND((ROUND((AF33*AV33*I33),2)*BA33),2) -> 19.67 | T33: =ROUND(CU33*I33,2) -> 0 | U33: =CV33*I33 -> 0.055971802 | V33: =CW33*I33 -> 0 | W33: =ROUND(CX33*I33,2) -> 0 | X33: =ROUND(CY33,2) -> 18.49 | Y33: =ROUND(CZ33,2) -> 10.03 | AA33: 56610029 | AB33: =ROUND((AC33+AD33+AF33),6) -> 991.431 | AC33: =ROUND((ES33),6) -> 0 | AD33: =ROUND(((((ET33*1.05))-((EU33*1.05)))+AE33),6) -> 978.663 | AE33: =ROUND(((EU33*1.05)),6) -> 96.4845 | AF33: =ROUND(((EV33*1.05)),6) -> 12.768 | AG33: =ROUND((AP33),6) -> 0 | AH33: =((EW33*1.05)) -> 1.2495 | AI33: =((EX33*1.05)) -> 0 | AJ33: =(AS33) -> 0 | AK33: 944.22 | AL33: 0 | AM33: 932.06 | AN33: 91.89 | AO33: 12.16 | AP33: 0 | AQ33: 1.19 | AR33: 0 | AS33: 0 | AT33: 94 | AU33: 51 | AV33: 1.192 | AW33: 1 | AZ33: 1 | BA33: 34.51 | BB33: 12.17 | BC33: 1 | BH33: 0 | BI33: 1 | BJ33: ТСН-2001.3 Доп. 68, Сб. 1, т. 3, поз. 2 | BM33: 2 | BN33: 0 | BO33: 3.1-3-2 | BP33: 1 | BQ33: 30 | BR33: 0 | BS33: 34.51 | BT33: 1 | BU33: 1 | BV33: 1 | BW33: 1 | BX33: 1 | BZ33: 94 | CA33: 51 | CE33: 30 | CF33: 0 | CG33: 0 | CM33: 0 | CN33: Поправка: О.П. п.3.4.30.г Наименование: В отношении объектов, реализуемых с привлечением средств бюджета города Москвы, затраты, учитывающие усложненные условия производства работ (стесненность, сложность складирования и транспортной логистики, наличие в зоне производства работ действующего технологического оборудования или движения технологического транспорта и т.п.), определяются заказчиком в задании на проектирование при составлении локальных сметных расчетов (смет): для объектов города Москвы, расположенных за пределами Московской кольцевой автомобильной дороги | CO33: 0 | CP33: =(P33+Q33+S33) -> 553.2 | CQ33: =ROUND((ROUND((AC33*AW33*1),2)*BC33),2) -> 0 | CR33: =(ROUND((ROUND((((ET33*1.05))*AV33*1),2)*BB33),2)+ROUND((ROUND(((AE33-((EU33*1.05)))*AV33*1),2)*BS33),2)) -> 14197.16 | CS33: =ROUND((ROUND((AE33*AV33*1),2)*BS33),2) -> 3969 | CT33: =ROUND((ROUND((AF33*AV33*1),2)*BA33),2) -> 525.24 | CU33: =AG33 -> 0 | CV33: =(AH33*AV33) -> 1.489404 | CW33: =AI33 -> 0 | CX33: =AJ33 -> 0 | CY33: =S33*(BZ33/100) -> 18.4898 | CZ33: =S33*(CA33/100) -> 10.0317 | DB33: 6 | DE33: *1,05 | DF33: *1,05 | DG33: *1,05 | DI33: *1,05 | DJ33: *1,05 | DN33: 98 | DO33: 77 | DP33: 1.192 | DQ33: 1 | DU33: 1013 | DV33: 100 м3 грунта | DW33: 100 м3 грунта | DX33: 1 | EE33: 51696085 | EF33: 30 | EG33: Строительные работы | EH33: 0 | EJ33: 1 | EK33: 2 | EL33: ТСН-2001.3-1. 1-1...1-7 | EM33: ТСН-2001.3-1-1 | EO33: Поправка: О.П. п.3.4.30.г | EQ33: 131072 | ER33: 944.22 | ES33: 0 | ET33: 932.06 | EU33: 91.89 | EV33: 12.16 | EW33: 1.19 | EX33: 0 | EY33: 0 | FQ33: 0 | FR33: 0 | FS33: 0 | FX33: 98 | FY33: 77 | GD33: 0 | GF33: 864155608 | GG33: 2 | GH33: 1 | GI33: 2 | GJ33: 0 | GK33: =ROUND(R33*(S12)/100,2) -> 238.53 | GL33: =ROUND(IF(AND(BH33=3,BI33=3,FS33<>0),P33,0),2) -> 0 | GM33: =ROUND(O33+X33+Y33+GK33,2)+GX33 -> 820.25 | GN33: =IF(OR(BI33=0,BI33=1),GM33-GX33,0) -> 820.25 | GO33: =IF(BI33=2,GM33-GX33,0) -> 0 | GP33: =IF(BI33=4,GM33-GX33,0) -> 0 | GR33: 0 | GS33: 3 | GT33: 0 | GV33: =ROUND((GT33),6) -> 0 | GW33: 1 | GX33: =ROUND(HC33*I33,2) -> 0 | HA33: 0 | HB33: 0 | HC33: =GV33*GW33 -> 0 | HS33: 0 | IK33: 0
A34: 17 | B34: 1 | D34: =ROW(EtalonRes!A13) -> 13 | E34: 4 | F34: 3.1-53-1 | G34: Засыпка вручную траншей, пазух котлованов и ям группа грунтов 1-3 | H34: 100 м3 грунта | I34: =ROUND(8.02*0.3/100,9) -> 0.02406 | J34: 0 | K34: =ROUND(8.02*0.3/100,9) -> 0.02406 | O34: =ROUND(CP34,2) -> 33.14 | P34: =ROUND((ROUND((AC34*AW34*I34),2)*BC34),2) -> 0 | Q34: =(ROUND((ROUND((((ET34*1.05))*AV34*I34),2)*BB34),2)+ROUND((ROUND(((AE34-((EU34*1.05)))*AV34*I34),2)*BS34),2)) -> 0 | R34: =ROUND((ROUND((AE34*AV34*I34),2)*BS34),2) -> 0 | S34: =ROUND((ROUND((AF34*AV34*I34),2)*BA34),2) -> 33.14 | T34: =ROUND(CU34*I34,2) -> 0 | U34: =CV34*I34 -> 3.3747811 | V34: =CW34*I34 -> 0 | W34: =ROUND(CX34*I34,2) -> 0 | X34: =ROUND(CY34,2) -> 34.8 | Y34: =ROUND(CZ34,2) -> 25.52 | AA34: 56622490 | AB34: =ROUND((AC34+AD34+AF34),6) -> 1103.6865 | AC34: =ROUND((ES34),6) -> 0 | AD34: =ROUND(((((ET34*1.05))-((EU34*1.05)))+AE34),6) -> 0 | AE34: =ROUND(((EU34*1.05)),6) -> 0 | AF34: =ROUND(((EV34*1.05)),6) -> 1103.6865 | AG34: =ROUND((AP34),6) -> 0 | AH34: =((EW34*1.05)) -> 112.392 | AI34: =((EX34*1.05)) -> 0 | AJ34: =(AS34) -> 0 | AK34: 1051.13 | AL34: 0 | AM34: 0 | AN34: 0 | AO34: 1051.13 | AP34: 0 | AQ34: 107.04 | AR34: 0 | AS34: 0 | AT34: 105 | AU34: 77 | AV34: 1.248 | AW34: 1 | AZ34: 1 | BA34: 1 | BB34: 1 | BC34: 1 | BH34: 0 | BI34: 1 | BJ34: ТСН-2001.3. Доп. 1-42. Сб. 1, т. 53, поз. 1 | BM34: 16 | BN34: 0 | BP34: 0 | BQ34: 30 | BR34: 0 | BS34: 1 | BT34: 1 | BU34: 1 | BV34: 1 | BW34: 1 | BX34: 1 | BZ34: 105 | CA34: 77 | CE34: 30 | CF34: 0 | CG34: 0 | CM34: 0 | CN34: Поправка: О.П. п.3.4.30.г Наименование: В отношении объектов, реализуемых с привлечением средств бюджета города Москвы, затраты, учитывающие усложненные условия производства работ (стесненность, сложность складирования и транспортной логистики, наличие в зоне производства работ действующего технологического оборудования или движения технологического транспорта и т.п.), определяются заказчиком в задании на проектирование при составлении локальных сметных расчетов (смет): для объектов города Москвы, расположенных за пределами Московской кольцевой автомобильной дороги | CO34: 0 | CP34: =(P34+Q34+S34) -> 33.14 | CQ34: =ROUND((ROUND((AC34*AW34*1),2)*BC34),2) -> 0 | CR34: =(ROUND((ROUND((((ET34*1.05))*AV34*1),2)*BB34),2)+ROUND((ROUND(((AE34-((EU34*1.05)))*AV34*1),2)*BS34),2)) -> 0 | CS34: =ROUND((ROUND((AE34*AV34*1),2)*BS34),2) -> 0 | CT34: =ROUND((ROUND((AF34*AV34*1),2)*BA34),2) -> 1377.4 | CU34: =AG34 -> 0 | CV34: =(AH34*AV34) -> 140.26522 | CW34: =AI34 -> 0 | CX34: =AJ34 -> 0 | CY34: =((S34*BZ34)/100) -> 34.797 | CZ34: =((S34*CA34)/100) -> 25.5178 | DB34: 7 | DE34: *1,05 | DF34: *1,05 | DG34: *1,05 | DI34: *1,05 | DJ34: *1,05 | DN34: 0 | DO34: 0 | DP34: 1 | DQ34: 1 | DU34: 1013 | DV34: 100 м3 грунта | DW34: 100 м3 грунта | DX34: 1 | EE34: 51696099 | EF34: 30 | EG34: Строительные работы | EH34: 0 | EJ34: 1 | EK34: 16 | EL34: ТСН-2001.3-1. 1-49...1-55 | EM34: ТСН-2001.3-1-15 | EO34: Поправка: О.П. п.3.4.30.г | EQ34: 131072 | ER34: 1051.13 | ES34: 0 | ET34: 0 | EU34: 0 | EV34: 1051.13 | EW34: 107.04 | EX34: 0 | EY34: 0 | FQ34: 0 | FR34: 0 | FS34: 0 | FX34: 105 | FY34: 77 | GD34: 0 | GF34: 1725378853 | GG34: 2 | GH34: 1 | GI34: -2 | GJ34: 0 | GK34: =ROUND(R34*(R12)/100,2) -> 0 | GL34: =ROUND(IF(AND(BH34=3,BI34=3,FS34<>0),P34,0),2) -> 0 | GM34: =ROUND(O34+X34+Y34+GK34,2)+GX34 -> 93.46 | GN34: =IF(OR(BI34=0,BI34=1),GM34-GX34,0) -> 93.46 | GO34: =IF(BI34=2,GM34-GX34,0) -> 0 | GP34: =IF(BI34=4,GM34-GX34,0) -> 0 | GR34: 0 | GS34: 0 | GT34: 0 | GV34: =ROUND((GT34),6) -> 0 | GW34: 1 | GX34: =ROUND(HC34*I34,2) -> 0 | HA34: 0 | HB34: 0 | HC34: =GV34*GW34 -> 0 | HS34: 0 | IK34: 0
A35: 17 | B35: 1 | D35: =ROW(EtalonRes!A14) -> 14 | E35: 4 | F35: 3.1-53-1 | G35: Засыпка вручную траншей, пазух котлованов и ям группа грунтов 1-3 | H35: 100 м3 грунта | I35: =ROUND(8.02*0.3/100,9) -> 0.02406 | J35: 0 | K35: =ROUND(8.02*0.3/100,9) -> 0.02406 | O35: =ROUND(CP35,2) -> 1143.66 | P35: =ROUND((ROUND((AC35*AW35*I35),2)*BC35),2) -> 0 | Q35: =(ROUND((ROUND((((ET35*1.05))*AV35*I35),2)*BB35),2)+ROUND((ROUND(((AE35-((EU35*1.05)))*AV35*I35),2)*BS35),2)) -> 0 | R35: =ROUND((ROUND((AE35*AV35*I35),2)*BS35),2) -> 0 | S35: =ROUND((ROUND((AF35*AV35*I35),2)*BA35),2) -> 1143.66 | T35: =ROUND(CU35*I35,2) -> 0 | U35: =CV35*I35 -> 3.3747811 | V35: =CW35*I35 -> 0 | W35: =ROUND(CX35*I35,2) -> 0 | X35: =ROUND(CY35,2) -> 994.98 | Y35: =ROUND(CZ35,2) -> 468.9 | AA35: 56610029 | AB35: =ROUND((AC35+AD35+AF35),6) -> 1103.6865 | AC35: =ROUND((ES35),6) -> 0 | AD35: =ROUND(((((ET35*1.05))-((EU35*1.05)))+AE35),6) -> 0 | AE35: =ROUND(((EU35*1.05)),6) -> 0 | AF35: =ROUND(((EV35*1.05)),6) -> 1103.6865 | AG35: =ROUND((AP35),6) -> 0 | AH35: =((EW35*1.05)) -> 112.392 | AI35: =((EX35*1.05)) -> 0 | AJ35: =(AS35) -> 0 | AK35: 1051.13 | AL35: 0 | AM35: 0 | AN35: 0 | AO35: 1051.13 | AP35: 0 | AQ35: 107.04 | AR35: 0 | AS35: 0 | AT35: 87 | AU35: 41 | AV35: 1.248 | AW35: 1 | AZ35: 1 | BA35: 34.51 | BB35: 1 | BC35: 1 | BH35: 0 | BI35: 1 | BJ35: ТСН-2001.3. Доп. 1-42. Сб. 1, т. 53, поз. 1 | BM35: 16 | BN35: 0 | BO35: 3.1-53-1 | BP35: 1 | BQ35: 30 | BR35: 0 | BS35: 34.51 | BT35: 1 | BU35: 1 | BV35: 1 | BW35: 1 | BX35: 1 | BZ35: 87 | CA35: 41 | CE35: 30 | CF35: 0 | CG35: 0 | CM35: 0 | CN35: Поправка: О.П. п.3.4.30.г Наименование: В отношении объектов, реализуемых с привлечением средств бюджета города Москвы, затраты, учитывающие усложненные условия производства работ (стесненность, сложность складирования и транспортной логистики, наличие в зоне производства работ действующего технологического оборудования или движения технологического транспорта и т.п.), определяются заказчиком в задании на проектирование при составлении локальных сметных расчетов (смет): для объектов города Москвы, расположенных за пределами Московской кольцевой автомобильной дороги | CO35: 0 | CP35: =(P35+Q35+S35) -> 1143.66 | CQ35: =ROUND((ROUND((AC35*AW35*1),2)*BC35),2) -> 0 | CR35: =(ROUND((ROUND((((ET35*1.05))*AV35*1),2)*BB35),2)+ROUND((ROUND(((AE35-((EU35*1.05)))*AV35*1),2)*BS35),2)) -> 0 | CS35: =ROUND((ROUND((AE35*AV35*1),2)*BS35),2) -> 0 | CT35: =ROUND((ROUND((AF35*AV35*1),2)*BA35),2) -> 47534.07 | CU35: =AG35 -> 0 | CV35: =(AH35*AV35) -> 140.26522 | CW35: =AI35 -> 0 | CX35: =AJ35 -> 0 | CY35: =S35*(BZ35/100) -> 994.9842 | CZ35: =S35*(CA35/100) -> 468.9006 | DB35: 8 | DE35: *1,05 | DF35: *1,05 | DG35: *1,05 | DI35: *1,05 | DJ35: *1,05 | DN35: 105 | DO35: 77 | DP35: 1.248 | DQ35: 1 | DU35: 1013 | DV35: 100 м3 грунта | DW35: 100 м3 грунта | DX35: 1 | EE35: 51696099 | EF35: 30 | EG35: Строительные работы | EH35: 0 | EJ35: 1 | EK35: 16 | EL35: ТСН-2001.3-1. 1-49...1-55 | EM35: ТСН-2001.3-1-15 | EO35: Поправка: О.П. п.3.4.30.г | EQ35: 131072 | ER35: 1051.13 | ES35: 0 | ET35: 0 | EU35: 0 | EV35: 1051.13 | EW35: 107.04 | EX35: 0 | EY35: 0 | FQ35: 0 | FR35: 0 | FS35: 0 | FX35: 105 | FY35: 77 | GD35: 0 | GF35: 1725378853 | GG35: 2 | GH35: 1 | GI35: 2 | GJ35: 0 | GK35: =ROUND(R35*(S12)/100,2) -> 0 | GL35: =ROUND(IF(AND(BH35=3,BI35=3,FS35<>0),P35,0),2) -> 0 | GM35: =ROUND(O35+X35+Y35+GK35,2)+GX35 -> 2607.54 | GN35: =IF(OR(BI35=0,BI35=1),GM35-GX35,0) -> 2607.54 | GO35: =IF(BI35=2,GM35-GX35,0) -> 0 | GP35: =IF(BI35=4,GM35-GX35,0) -> 0 | GR35: 0 | GS35: 3 | GT35: 0 | GV35: =ROUND((GT35),6) -> 0 | GW35: 1 | GX35: =ROUND(HC35*I35,2) -> 0 | HA35: 0 | HB35: 0 | HC35: =GV35*GW35 -> 0 | HS35: 0 | IK35: 0
A36: 17 | B36: 1 | D36: =ROW(EtalonRes!A15) -> 15 | E36: 5 | F36: 3.1-14-1 | G36: Засыпка траншей и котлованов бульдозерами мощностью 59 (80) кВт (л.с.) при перемещении грунта до 5 м группа грунтов 1-3 | H36: 100 м3 грунта | I36: =ROUND(8.02*0.7/100,9) -> 0.05614 | J36: 0 | K36: =ROUND(8.02*0.7/100,9) -> 0.05614 | O36: =ROUND(CP36,2) -> 7.77 | P36: =ROUND((ROUND((AC36*AW36*I36),2)*BC36),2) -> 0 | Q36: =(ROUND((ROUND((((ET36*1.05))*AV36*I36),2)*BB36),2)+ROUND((ROUND(((AE36-((EU36*1.05)))*AV36*I36),2)*BS36),2)) -> 7.77 | R36: =ROUND((ROUND((AE36*AV36*I36),2)*BS36),2) -> 0.78 | S36: =ROUND((ROUND((AF36*AV36*I36),2)*BA36),2) -> 0 | T36: =ROUND(CU36*I36,2) -> 0 | U36: =CV36*I36 -> 0 | V36: =CW36*I36 -> 0 | W36: =ROUND(CX36*I36,2) -> 0 | X36: =ROUND(CY36,2) -> 0 | Y36: =ROUND(CZ36,2) -> 0 | AA36: 56622490 | AB36: =ROUND((AC36+AD36+AF36),6) -> 136.5105 | AC36: =ROUND((ES36),6) -> 0 | AD36: =ROUND(((((ET36*1.05))-((EU36*1.05)))+AE36),6) -> 136.5105 | AE36: =ROUND(((EU36*1.05)),6) -> 13.629 | AF36: =ROUND(((EV36*1.05)),6) -> 0 | AG36: =ROUND((AP36),6) -> 0 | AH36: =((EW36*1.05)) -> 0 | AI36: =((EX36*1.05)) -> 0 | AJ36: =(AS36) -> 0 | AK36: 130.01 | AL36: 0 | AM36: 130.01 | AN36: 12.98 | AO36: 0 | AP36: 0 | AQ36: 0 | AR36: 0 | AS36: 0 | AT36: 98 | AU36: 77 | AV36: 1.014 | AW36: 1 | AZ36: 1 | BA36: 1 | BB36: 1 | BC36: 1 | BH36: 0 | BI36: 1 | BJ36: ТСН-2001.3 Доп. 68, Сб. 1, т. 14, поз. 1 | BM36: 5 | BN36: 0 | BP36: 0 | BQ36: 30 | BR36: 0 | BS36: 1 | BT36: 1 | BU36: 1 | BV36: 1 | BW36: 1 | BX36: 1 | BZ36: 98 | CA36: 77 | CE36: 30 | CF36: 0 | CG36: 0 | CM36: 0 | CN36: Поправка: О.П. п.3.4.30.г Наименование: В отношении объектов, реализуемых с привлечением средств бюджета города Москвы, затраты, учитывающие усложненные условия производства работ (стесненность, сложность складирования и транспортной логистики, наличие в зоне производства работ действующего технологического оборудования или движения технологического транспорта и т.п.), определяются заказчиком в задании на проектирование при составлении локальных сметных расчетов (смет): для объектов города Москвы, расположенных за пределами Московской кольцевой автомобильной дороги | CO36: 0 | CP36: =(P36+Q36+S36) -> 7.77 | CQ36: =ROUND((ROUND((AC36*AW36*1),2)*BC36),2) -> 0 | CR36: =(ROUND((ROUND((((ET36*1.05))*AV36*1),2)*BB36),2)+ROUND((ROUND(((AE36-((EU36*1.05)))*AV36*1),2)*BS36),2)) -> 138.42 | CS36: =ROUND((ROUND((AE36*AV36*1),2)*BS36),2) -> 13.82 | CT36: =ROUND((ROUND((AF36*AV36*1),2)*BA36),2) -> 0 | CU36: =AG36 -> 0 | CV36: =(AH36*AV36) -> 0 | CW36: =AI36 -> 0 | CX36: =AJ36 -> 0 | CY36: =((S36*BZ36)/100) -> 0 | CZ36: =((S36*CA36)/100) -> 0 | DB36: 9 | DE36: *1,05 | DF36: *1,05 | DG36: *1,05 | DI36: *1,05 | DJ36: *1,05 | DN36: 0 | DO36: 0 | DP36: 1 | DQ36: 1 | DU36: 1013 | DV36: 100 м3 грунта | DW36: 100 м3 грунта | DX36: 1 | EE36: 51696088 | EF36: 30 | EG36: Строительные работы | EH36: 0 | EJ36: 1 | EK36: 5 | EL36: ТСН-2001.3-1. 1-11...1-17 | EM36: ТСН-2001.3-1-4 | EO36: Поправка: О.П. п.3.4.30.г | EQ36: 131072 | ER36: 130.01 | ES36: 0 | ET36: 130.01 | EU36: 12.98 | EV36: 0 | EW36: 0 | EX36: 0 | EY36: 0 | FQ36: 0 | FR36: 0 | FS36: 0 | FX36: 98 | FY36: 77 | GD36: 0 | GF36: 1539452637 | GG36: 2 | GH36: 1 | GI36: -2 | GJ36: 0 | GK36: =ROUND(R36*(R12)/100,2) -> 1.37 | GL36: =ROUND(IF(AND(BH36=3,BI36=3,FS36<>0),P36,0),2) -> 0 | GM36: =ROUND(O36+X36+Y36+GK36,2)+GX36 -> 9.14 | GN36: =IF(OR(BI36=0,BI36=1),GM36-GX36,0) -> 9.14 | GO36: =IF(BI36=2,GM36-GX36,0) -> 0 | GP36: =IF(BI36=4,GM36-GX36,0) -> 0 | GR36: 0 | GS36: 0 | GT36: 0 | GV36: =ROUND((GT36),6) -> 0 | GW36: 1 | GX36: =ROUND(HC36*I36,2) -> 0 | HA36: 0 | HB36: 0 | HC36: =GV36*GW36 -> 0 | HS36: 0 | IK36: 0
A37: 17 | B37: 1 | D37: =ROW(EtalonRes!A16) -> 16 | E37: 5 | F37: 3.1-14-1 | G37: Засыпка траншей и котлованов бульдозерами мощностью 59 (80) кВт (л.с.) при перемещении грунта до 5 м группа грунтов 1-3 | H37: 100 м3 грунта | I37: =ROUND(8.02*0.7/100,9) -> 0.05614 | J37: 0 | K37: =ROUND(8.02*0.7/100,9) -> 0.05614 | O37: =ROUND(CP37,2) -> 93.86 | P37: =ROUND((ROUND((AC37*AW37*I37),2)*BC37),2) -> 0 | Q37: =(ROUND((ROUND((((ET37*1.05))*AV37*I37),2)*BB37),2)+ROUND((ROUND(((AE37-((EU37*1.05)))*AV37*I37),2)*BS37),2)) -> 93.86 | R37: =ROUND((ROUND((AE37*AV37*I37),2)*BS37),2) -> 26.92 | S37: =ROUND((ROUND((AF37*AV37*I37),2)*BA37),2) -> 0 | T37: =ROUND(CU37*I37,2) -> 0 | U37: =CV37*I37 -> 0 | V37: =CW37*I37 -> 0 | W37: =ROUND(CX37*I37,2) -> 0 | X37: =ROUND(CY37,2) -> 0 | Y37: =ROUND(CZ37,2) -> 0 | AA37: 56610029 | AB37: =ROUND((AC37+AD37+AF37),6) -> 136.5105 | AC37: =ROUND((ES37),6) -> 0 | AD37: =ROUND(((((ET37*1.05))-((EU37*1.05)))+AE37),6) -> 136.5105 | AE37: =ROUND(((EU37*1.05)),6) -> 13.629 | AF37: =ROUND(((EV37*1.05)),6) -> 0 | AG37: =ROUND((AP37),6) -> 0 | AH37: =((EW37*1.05)) -> 0 | AI37: =((EX37*1.05)) -> 0 | AJ37: =(AS37) -> 0 | AK37: 130.01 | AL37: 0 | AM37: 130.01 | AN37: 12.98 | AO37: 0 | AP37: 0 | AQ37: 0 | AR37: 0 | AS37: 0 | AT37: 94 | AU37: 51 | AV37: 1.014 | AW37: 1 | AZ37: 1 | BA37: 34.51 | BB37: 12.08 | BC37: 1 | BH37: 0 | BI37: 1 | BJ37: ТСН-2001.3 Доп. 68, Сб. 1, т. 14, поз. 1 | BM37: 5 | BN37: 0 | BO37: 3.1-14-1 | BP37: 1 | BQ37: 30 | BR37: 0 | BS37: 34.51 | BT37: 1 | BU37: 1 | BV37: 1 | BW37: 1 | BX37: 1 | BZ37: 94 | CA37: 51 | CE37: 30 | CF37: 0 | CG37: 0 | CM37: 0 | CN37: Поправка: О.П. п.3.4.30.г Наименование: В отношении объектов, реализуемых с привлечением средств бюджета города Москвы, затраты, учитывающие усложненные условия производства работ (стесненность, сложность складирования и транспортной логистики, наличие в зоне производства работ действующего технологического оборудования или движения технологического транспорта и т.п.), определяются заказчиком в задании на проектирование при составлении локальных сметных расчетов (смет): для объектов города Москвы, расположенных за пределами Московской кольцевой автомобильной дороги | CO37: 0 | CP37: =(P37+Q37+S37) -> 93.86 | CQ37: =ROUND((ROUND((AC37*AW37*1),2)*BC37),2) -> 0 | CR37: =(ROUND((ROUND((((ET37*1.05))*AV37*1),2)*BB37),2)+ROUND((ROUND(((AE37-((EU37*1.05)))*AV37*1),2)*BS37),2)) -> 1672.11 | CS37: =ROUND((ROUND((AE37*AV37*1),2)*BS37),2) -> 476.93 | CT37: =ROUND((ROUND((AF37*AV37*1),2)*BA37),2) -> 0 | CU37: =AG37 -> 0 | CV37: =(AH37*AV37) -> 0 | CW37: =AI37 -> 0 | CX37: =AJ37 -> 0 | CY37: =S37*(BZ37/100) -> 0 | CZ37: =S37*(CA37/100) -> 0 | DB37: 10 | DE37: *1,05 | DF37: *1,05 | DG37: *1,05 | DI37: *1,05 | DJ37: *1,05 | DN37: 98 | DO37: 77 | DP37: 1.014 | DQ37: 1 | DU37: 1013 | DV37: 100 м3 грунта | DW37: 100 м3 грунта | DX37: 1 | EE37: 51696088 | EF37: 30 | EG37: Строительные работы | EH37: 0 | EJ37: 1 | EK37: 5 | EL37: ТСН-2001.3-1. 1-11...1-17 | EM37: ТСН-2001.3-1-4 | EO37: Поправка: О.П. п.3.4.30.г | EQ37: 131072 | ER37: 130.01 | ES37: 0 | ET37: 130.01 | EU37: 12.98 | EV37: 0 | EW37: 0 | EX37: 0 | EY37: 0 | FQ37: 0 | FR37: 0 | FS37: 0 | FX37: 98 | FY37: 77 | GD37: 0 | GF37: 1539452637 | GG37: 2 | GH37: 1 | GI37: 2 | GJ37: 0 | GK37: =ROUND(R37*(S12)/100,2) -> 43.07 | GL37: =ROUND(IF(AND(BH37=3,BI37=3,FS37<>0),P37,0),2) -> 0 | GM37: =ROUND(O37+X37+Y37+GK37,2)+GX37 -> 136.93 | GN37: =IF(OR(BI37=0,BI37=1),GM37-GX37,0) -> 136.93 | GO37: =IF(BI37=2,GM37-GX37,0) -> 0 | GP37: =IF(BI37=4,GM37-GX37,0) -> 0 | GR37: 0 | GS37: 3 | GT37: 0 | GV37: =ROUND((GT37),6) -> 0 | GW37: 1 | GX37: =ROUND(HC37*I37,2) -> 0 | HA37: 0 | HB37: 0 | HC37: =GV37*GW37 -> 0 | HS37: 0 | IK37: 0
A38: 17 | B38: 1 | D38: =ROW(EtalonRes!A20) -> 20 | E38: 6 | F38: 3.34-17-4 | G38: Устройство трубопроводов из асбестоцементных труб с соединением манжетами полиэтиленовыми более 2-х отверстий | H38: 1 канало-километр трубопровода | I38: 0 | J38: 0 | K38: 0 | O38: =ROUND(CP38,2) -> 0 | P38: =ROUND((ROUND((AC38*AW38*I38),2)*BC38),2) -> 0 | Q38: =(ROUND((ROUND((((ET38*1.05))*AV38*I38),2)*BB38),2)+ROUND((ROUND(((AE38-((EU38*1.05)))*AV38*I38),2)*BS38),2)) -> 0 | R38: =ROUND((ROUND((AE38*AV38*I38),2)*BS38),2) -> 0 | S38: =ROUND((ROUND((AF38*AV38*I38),2)*BA38),2) -> 0 | T38: =ROUND(CU38*I38,2) -> 0 | U38: =CV38*I38 -> 0 | V38: =CW38*I38 -> 0 | W38: =ROUND(CX38*I38,2) -> 0 | X38: =ROUND(CY38,2) -> 0 | Y38: =ROUND(CZ38,2) -> 0 | AA38: 56622490 | AB38: =ROUND((AC38+AD38+AF38),6) -> 21174.122 | AC38: =ROUND((ES38),6) -> 19554.14 | AD38: =ROUND(((((ET38*1.05))-((EU38*1.05)))+AE38),6) -> 0 | AE38: =ROUND(((EU38*1.05)),6) -> 0 | AF38: =ROUND(((EV38*1.05)),6) -> 1619.982 | AG38: =ROUND((AP38),6) -> 0 | AH38: =((EW38*1.05)) -> 144.9 | AI38: =((EX38*1.05)) -> 0 | AJ38: =(AS38) -> 0 | AK38: 21096.98 | AL38: 19554.14 | AM38: 0 | AN38: 0 | AO38: 1542.84 | AP38: 0 | AQ38: 138 | AR38: 0 | AS38: 0 | AT38: 112 | AU38: 70 | AV38: 1.067 | AW38: 1.081 | AZ38: 1 | BA38: 1 | BB38: 1 | BC38: 1 | BH38: 0 | BI38: 1 | BJ38: ТСН-2001.3. Доп. 1-42. Сб. 34, т. 17, поз. 4 | BM38: 242 | BN38: 0 | BP38: 0 | BQ38: 30 | BR38: 0 | BS38: 1 | BT38: 1 | BU38: 1 | BV38: 1 | BW38: 1 | BX38: 1 | BZ38: 112 | CA38: 70 | CE38: 30 | CF38: 0 | CG38: 0 | CM38: 0 | CN38: Поправка: О.П. п.3.4.30.г Наименование: В отношении объектов, реализуемых с привлечением средств бюджета города Москвы, затраты, учитывающие усложненные условия производства работ (стесненность, сложность складирования и транспортной логистики, наличие в зоне производства работ действующего технологического оборудования или движения технологического транспорта и т.п.), определяются заказчиком в задании на проектирование при составлении локальных сметных расчетов (смет): для объектов города Москвы, расположенных за пределами Московской кольцевой автомобильной дороги | CO38: 0 | CP38: =(P38+Q38+S38) -> 0 | CQ38: =ROUND((ROUND((AC38*AW38*1),2)*BC38),2) -> 21138.03 | CR38: =(ROUND((ROUND((((ET38*1.05))*AV38*1),2)*BB38),2)+ROUND((ROUND(((AE38-((EU38*1.05)))*AV38*1),2)*BS38),2)) -> 0 | CS38: =ROUND((ROUND((AE38*AV38*1),2)*BS38),2) -> 0 | CT38: =ROUND((ROUND((AF38*AV38*1),2)*BA38),2) -> 1728.52 | CU38: =AG38 -> 0 | CV38: =(AH38*AV38) -> 154.6083 | CW38: =AI38 -> 0 | CX38: =AJ38 -> 0 | CY38: =((S38*BZ38)/100) -> 0 | CZ38: =((S38*CA38)/100) -> 0 | DB38: 11 | DE38: *1,05 | DF38: *1,05 | DG38: *1,05 | DI38: *1,05 | DJ38: *1,05 | DN38: 0 | DO38: 0 | DP38: 1 | DQ38: 1 | DU38: 1013 | DV38: 1 канало-километр трубопровода | DW38: 1 канало-километр трубопровода | DX38: 1 | EE38: 51696281 | EF38: 30 | EG38: Строительные работы | EH38: 0 | EJ38: 1 | EK38: 242 | EL38: ТСН-2001.3-34. 34-17...34-28 | EM38: ТСН-2001.3-34-6 | EO38: Поправка: О.П. п.3.4.30.г | EQ38: 131072 | ER38: 21096.98 | ES38: 19554.14 | ET38: 0 | EU38: 0 | EV38: 1542.84 | EW38: 138 | EX38: 0 | EY38: 0 | FQ38: 0 | FR38: 0 | FS38: 2 | FX38: 112 | FY38: 70 | GD38: 0 | GF38: -1466514599 | GG38: 2 | GH38: 1 | GI38: -2 | GJ38: 0 | GK38: =ROUND(R38*(R12)/100,2) -> 0 | GL38: =ROUND(IF(AND(BH38=3,BI38=3,FS38<>0),P38,0),2) -> 0 | GM38: =ROUND(O38+X38+Y38+GK38,2)+GX38 -> 0 | GN38: =IF(OR(BI38=0,BI38=1),GM38-GX38,0) -> 0 | GO38: =IF(BI38=2,GM38-GX38,0) -> 0 | GP38: =IF(BI38=4,GM38-GX38,0) -> 0 | GR38: 0 | GS38: 0 | GT38: 0 | GV38: =ROUND((GT38),6) -> 0 | GW38: 1 | GX38: =ROUND(HC38*I38,2) -> 0 | HA38: 0 | HB38: 0 | HC38: =GV38*GW38 -> 0 | HS38: 0 | IK38: 0
A39: 17 | B39: 1 | D39: =ROW(EtalonRes!A24) -> 24 | E39: 6 | F39: 3.34-17-4 | G39: Устройство трубопроводов из асбестоцементных труб с соединением манжетами полиэтиленовыми более 2-х отверстий | H39: 1 канало-километр трубопровода | I39: 0 | J39: 0 | K39: 0 | O39: =ROUND(CP39,2) -> 0 | P39: =ROUND((ROUND((AC39*AW39*I39),2)*BC39),2) -> 0 | Q39: =(ROUND((ROUND((((ET39*1.05))*AV39*I39),2)*BB39),2)+ROUND((ROUND(((AE39-((EU39*1.05)))*AV39*I39),2)*BS39),2)) -> 0 | R39: =ROUND((ROUND((AE39*AV39*I39),2)*BS39),2) -> 0 | S39: =ROUND((ROUND((AF39*AV39*I39),2)*BA39),2) -> 0 | T39: =ROUND(CU39*I39,2) -> 0 | U39: =CV39*I39 -> 0 | V39: =CW39*I39 -> 0 | W39: =ROUND(CX39*I39,2) -> 0 | X39: =ROUND(CY39,2) -> 0 | Y39: =ROUND(CZ39,2) -> 0 | AA39: 56610029 | AB39: =ROUND((AC39+AD39+AF39),6) -> 21174.122 | AC39: =ROUND((ES39),6) -> 19554.14 | AD39: =ROUND(((((ET39*1.05))-((EU39*1.05)))+AE39),6) -> 0 | AE39: =ROUND(((EU39*1.05)),6) -> 0 | AF39: =ROUND(((EV39*1.05)),6) -> 1619.982 | AG39: =ROUND((AP39),6) -> 0 | AH39: =((EW39*1.05)) -> 144.9 | AI39: =((EX39*1.05)) -> 0 | AJ39: =(AS39) -> 0 | AK39: 21096.98 | AL39: 19554.14 | AM39: 0 | AN39: 0 | AO39: 1542.84 | AP39: 0 | AQ39: 138 | AR39: 0 | AS39: 0 | AT39: 92 | AU39: 41 | AV39: 1.067 | AW39: 1.081 | AZ39: 1 | BA39: 34.51 | BB39: 1 | BC39: 7.65 | BH39: 0 | BI39: 1 | BJ39: ТСН-2001.3. Доп. 1-42. Сб. 34, т. 17, поз. 4 | BM39: 242 | BN39: 0 | BO39: 3.34-17-4 | BP39: 1 | BQ39: 30 | BR39: 0 | BS39: 34.51 | BT39: 1 | BU39: 1 | BV39: 1 | BW39: 1 | BX39: 1 | BZ39: 92 | CA39: 41 | CE39: 30 | CF39: 0 | CG39: 0 | CM39: 0 | CN39: Поправка: О.П. п.3.4.30.г Наименование: В отношении объектов, реализуемых с привлечением средств бюджета города Москвы, затраты, учитывающие усложненные условия производства работ (стесненность, сложность складирования и транспортной логистики, наличие в зоне производства работ действующего технологического оборудования или движения технологического транспорта и т.п.), определяются заказчиком в задании на проектирование при составлении локальных сметных расчетов (смет): для объектов города Москвы, расположенных за пределами Московской кольцевой автомобильной дороги | CO39: 0 | CP39: =(P39+Q39+S39) -> 0 | CQ39: =ROUND((ROUND((AC39*AW39*1),2)*BC39),2) -> 161705.93 | CR39: =(ROUND((ROUND((((ET39*1.05))*AV39*1),2)*BB39),2)+ROUND((ROUND(((AE39-((EU39*1.05)))*AV39*1),2)*BS39),2)) -> 0 | CS39: =ROUND((ROUND((AE39*AV39*1),2)*BS39),2) -> 0 | CT39: =ROUND((ROUND((AF39*AV39*1),2)*BA39),2) -> 59651.23 | CU39: =AG39 -> 0 | CV39: =(AH39*AV39) -> 154.6083 | CW39: =AI39 -> 0 | CX39: =AJ39 -> 0 | CY39: =S39*(BZ39/100) -> 0 | CZ39: =S39*(CA39/100) -> 0 | DB39: 12 | DE39: *1,05 | DF39: *1,05 | DG39: *1,05 | DI39: *1,05 | DJ39: *1,05 | DN39: 112 | DO39: 70 | DP39: 1.067 | DQ39: 1.081 | DU39: 1013 | DV39: 1 канало-километр трубопровода | DW39: 1 канало-километр трубопровода | DX39: 1 | EE39: 51696281 | EF39: 30 | EG39: Строительные работы | EH39: 0 | EJ39: 1 | EK39: 242 | EL39: ТСН-2001.3-34. 34-17...34-28 | EM39: ТСН-2001.3-34-6 | EO39: Поправка: О.П. п.3.4.30.г | EQ39: 131072 | ER39: 21096.98 | ES39: 19554.14 | ET39: 0 | EU39: 0 | EV39: 1542.84 | EW39: 138 | EX39: 0 | EY39: 0 | FQ39: 0 | FR39: 0 | FS39: 2 | FX39: 112 | FY39: 70 | GD39: 0 | GF39: -1466514599 | GG39: 2 | GH39: 1 | GI39: 2 | GJ39: 0 | GK39: =ROUND(R39*(S12)/100,2) -> 0 | GL39: =ROUND(IF(AND(BH39=3,BI39=3,FS39<>0),P39,0),2) -> 0 | GM39: =ROUND(O39+X39+Y39+GK39,2)+GX39 -> 0 | GN39: =IF(OR(BI39=0,BI39=1),GM39-GX39,0) -> 0 | GO39: =IF(BI39=2,GM39-GX39,0) -> 0 | GP39: =IF(BI39=4,GM39-GX39,0) -> 0 | GR39: 0 | GS39: 3 | GT39: 0 | GV39: =ROUND((GT39),6) -> 0 | GW39: 1 | GX39: =ROUND(HC39*I39,2) -> 0 | HA39: 0 | HB39: 0 | HC39: =GV39*GW39 -> 0 | HS39: 0 | IK39: 0
A40: 17 | B40: 1 | E40: 7 | F40: 1.12-3-25 | G40: Трубы хризотилцементные безнапорные, марка БНТ, диаметр условного прохода 100 мм, внутренний диаметр 100 мм | H40: м | I40: =ROUND(-(I38)*1000,9) -> 0 | J40: 0 | K40: =ROUND(-(I38)*1000,9) -> 0 | O40: =ROUND(CP40,2) -> 0 | P40: =ROUND((ROUND((AC40*AW40*I40),2)*BC40),2) -> 0 | Q40: =(ROUND((ROUND((((ET40*1.05))*AV40*I40),2)*BB40),2)+ROUND((ROUND(((AE40-((EU40*1.05)))*AV40*I40),2)*BS40),2)) -> 0 | R40: =ROUND((ROUND((AE40*AV40*I40),2)*BS40),2) -> 0 | S40: =ROUND((ROUND((AF40*AV40*I40),2)*BA40),2) -> 0 | T40: =ROUND(CU40*I40,2) -> 0 | U40: =CV40*I40 -> 0 | V40: =CW40*I40 -> 0 | W40: =ROUND(CX40*I40,2) -> 0 | X40: =ROUND(CY40,2) -> 0 | Y40: =ROUND(CZ40,2) -> 0 | AA40: 56622490 | AB40: =ROUND((AC40+AD40+AF40),6) -> 15.01 | AC40: =ROUND((ES40),6) -> 15.01 | AD40: =ROUND(((((ET40*1.05))-((EU40*1.05)))+AE40),6) -> 0 | AE40: =ROUND(((EU40*1.05)),6) -> 0 | AF40: =ROUND(((EV40*1.05)),6) -> 0 | AG40: =ROUND((AP40),6) -> 0 | AH40: =((EW40*1.05)) -> 0 | AI40: =((EX40*1.05)) -> 0 | AJ40: =(AS40) -> 0 | AK40: 15.01 | AL40: 15.01 | AM40: 0 | AN40: 0 | AO40: 0 | AP40: 0 | AQ40: 0 | AR40: 0 | AS40: 0 | AT40: 0 | AU40: 0 | AV40: 1 | AW40: 1 | AZ40: 1 | BA40: 1 | BB40: 1 | BC40: 1 | BH40: 3 | BI40: 1 | BJ40: ТСН-2001.1 Доп. 70, Р. 12, о. 3, поз. 25 | BM40: 1617 | BN40: 0 | BP40: 0 | BQ40: 200 | BR40: 0 | BS40: 1 | BT40: 1 | BU40: 1 | BV40: 1 | BW40: 1 | BX40: 1 | BZ40: 0 | CA40: 0 | CE40: 30 | CF40: 0 | CG40: 0 | CM40: 0 | CN40: Поправка: О.П. п.3.4.30.г Наименование: В отношении объектов, реализуемых с привлечением средств бюджета города Москвы, затраты, учитывающие усложненные условия производства работ (стесненность, сложность складирования и транспортной логистики, наличие в зоне производства работ действующего технологического оборудования или движения технологического транспорта и т.п.), определяются заказчиком в задании на проектирование при составлении локальных сметных расчетов (смет): для объектов города Москвы, расположенных за пределами Московской кольцевой автомобильной дороги | CO40: 0 | CP40: =(P40+Q40+S40) -> 0 | CQ40: =ROUND((ROUND((AC40*AW40*1),2)*BC40),2) -> 15.01 | CR40: =(ROUND((ROUND((((ET40*1.05))*AV40*1),2)*BB40),2)+ROUND((ROUND(((AE40-((EU40*1.05)))*AV40*1),2)*BS40),2)) -> 0 | CS40: =ROUND((ROUND((AE40*AV40*1),2)*BS40),2) -> 0 | CT40: =ROUND((ROUND((AF40*AV40*1),2)*BA40),2) -> 0 | CU40: =AG40 -> 0 | CV40: =(AH40*AV40) -> 0 | CW40: =AI40 -> 0 | CX40: =AJ40 -> 0 | CY40: =((S40*BZ40)/100) -> 0 | CZ40: =((S40*CA40)/100) -> 0 | DB40: 13 | DE40: *1,05 | DF40: *1,05 | DG40: *1,05 | DI40: *1,05 | DJ40: *1,05 | DN40: 0 | DO40: 0 | DP40: 1 | DQ40: 1 | DU40: 1003 | DV40: м | DW40: м | DX40: 1 | EE40: 51697656 | EF40: 200 | EG40: Материалы строительные | EH40: 0 | EJ40: 1 | EK40: 1617 | EL40: ТСН-2001.1 Материалы строительные | EM40: ТСН-2001.1-1 | EO40: Поправка: О.П. п.3.4.30.г | EQ40: 131072 | ER40: 15.01 | ES40: 15.01 | ET40: 0 | EU40: 0 | EV40: 0 | EW40: 0 | EX40: 0 | EY40: 0 | FQ40: 0 | FR40: 0 | FS40: 0 | FX40: 0 | FY40: 0 | GD40: 0 | GF40: 1181244062 | GG40: 2 | GH40: 1 | GI40: -2 | GJ40: 0 | GK40: =ROUND(R40*(R12)/100,2) -> 0 | GL40: =ROUND(IF(AND(BH40=3,BI40=3,FS40<>0),P40,0),2) -> 0 | GM40: =ROUND(O40+X40+Y40+GK40,2)+GX40 -> 0 | GN40: =IF(OR(BI40=0,BI40=1),GM40-GX40,0) -> 0 | GO40: =IF(BI40=2,GM40-GX40,0) -> 0 | GP40: =IF(BI40=4,GM40-GX40,0) -> 0 | GR40: 0 | GS40: 0 | GT40: 0 | GV40: =ROUND((GT40),6) -> 0 | GW40: 1 | GX40: =ROUND(HC40*I40,2) -> 0 | HA40: 0 | HB40: 0 | HC40: =GV40*GW40 -> 0 | HS40: 0 | IK40: 0
