Workbook

Sheet Смета по ТСН-2001(с доп.43
A1: =Source!B1 -> Smeta.RU (495) 974-1589
J2: Форма № 4б
A3: ПИР, СМР, ПНР, материалы, оборудование (за исключением замков, предоставляемых Заказчиком) по титулу: Строительство ТП-10/0,4кВ с тр-ми 2х400кВА, 4КЛ-10кВ от ТП-10/0,4кВ луч А,Б до КЛ-10кВ направлением ТП-10/0,4кВ № № 21782 - ТП-10/0,4кВ № 24478 луч А,Б, 8КЛ-0,4кВ от ТП-10/0,4кВ до ВРЩ-0,4кВ №1-3, в т.ч. ПИР: г.Москва, ул.Феодосийская, з/у 7 для нужд МКС – филиала ПАО «Россети Московский регион»
A4: (наименование стройки и/или объекта)
A6: ЛОКАЛЬНАЯ СМЕТА № 02-01-08
A8: Строительство закрытых переходов (2 этап)
A9: (наименование работ и затрат)
A11: =CONCATENATE( "Основание: чертежи № ", Source!J12) -> Основание: чертежи №
I13: В базисном уровне цен | J13: В текущем уровне цен
E14: Сметная стоимость | I14: =I15+I16+I17+I18 -> 973.4 | J14: =J15+J16+J17+J18 -> 8742.94 | K14: тыс.руб.
E15: Строительные работы | I15: =ROUND(SUM(X1:X155)/1000, 2) -> 852.04 | J15: =ROUND((Source!F191)/1000, 2) -> 7591.87 | K15: тыс.руб.
E16: Работы по монтажу оборудования | I16: =ROUND(SUM(Y1:Y155)/1000, 2) -> 121.36 | J16: =ROUND((Source!F192)/1000, 2) -> 1151.07 | K16: тыс.руб.
E17: Оборудование | I17: =ROUND(SUM(Z1:Z155)/1000, 2) -> 0 | J17: =ROUND((Source!F183)/1000, 2) -> 0 | K17: тыс.руб.
E18: Прочие работы и затраты | I18: =ROUND(SUM(AA1:AA155)/1000, 2) -> 0 | J18: =ROUND((Source!F193+Source!F194)/1000, 2) -> 0 | K18: тыс.руб.
E19: Средства на оплату труда | I19: =ROUND(SUM(W1:W155)/1000, 2) -> 21.84 | J19: =(Source!F189+ Source!F188)/1000 -> 753.82437 | K19: тыс.руб.
E20: Затраты труда | I20: =SUM(AB1:AB155) -> 748.80028 | K20: чел.-ч.
E21: Кроме того:
E22: Возврат материалов | I22: =ROUND(SUM(AE1:AE155)/1000, 2) -> 0 | J22: =SUM(AF1:AF155)/1000 -> 0 | K22: тыс.руб.
A24: Составлен(а) по ТСН-2001 с учетом Дополнения №: 73
A25: № и период сборника коэффициентов (индексов) пересчета: Коэффициенты к ТСН-2001 МГЭ №212 III квартал 2024 года | AP25: № и период сборника коэффициентов (индексов) пересчета: Коэффициенты к ТСН-2001 МГЭ №212 III квартал 2024 года
A26: № п/п | B26: Шифр расценки и коды ресурсов | C26: Наименование работ и затрат | D26: Ед. изм. | E26: Кол-во единиц | F26: Цена на ед. изм., руб. | G26: Попра- вочные коэффи- циенты | H26: Коэффи- циенты зимних удорожа- ний | I26: Всего затрат в базисном уровне цен, руб. | J26: Коэффи- циенты (индек- сы) пере- счета, нормы НР и СП | K26: ВСЕГО затрат в текущем уровне цен, руб.
A27: 1 | B27: 2 | C27: 3 | D27: 4 | E27: 5 | F27: 6 | G27: 7 | H27: 8 | I27: 9 | J27: 10 | K27: 11
A29: Раздел: Закрытый переход 2 сквх3тр (72,8м; 113,4м)
A31: =CONCATENATE("Подраздел: ",IF(Source!G28<>"Новый подраздел", Source!G28, "")) -> Подраздел: Строительные работы
A32: 1 | B32: 3.1-51-1 Поправка: О.П. п.3.4.30.г | C32: Разработка грунта вручную в траншеях глубиной до 2 м без креплений с откосами группа грунтов 1-3 | D32: =Source!DW32 -> 100 м3 грунта | E32: =Source!I32 -> 0.019155 | Q32: =ROUND((Source!DN32/100)*ROUND((ROUND((Source!AF32*Source!AV32*Source!I32),2)),2), 2) -> 53.83 | R32: =Source!X32 -> 1539.32 | S32: =ROUND((Source!DO32/100)*ROUND((ROUND((Source!AF32*Source!AV32*Source!I32),2)),2), 2) -> 39.48 | T32: =Source!Y32 -> 725.43 | U32: =ROUND((175/100)*ROUND((ROUND((Source!AE32*Source!AV32*Source!I32),2)),2), 2) -> 0 | V32: =ROUND((160/100)*ROUND(ROUND((ROUND((Source!AE32*Source!AV32*Source!I32),2)*Source!BS32),2), 2), 2) -> 0 | AI32: 0
C33: ЗП | F33: =Source!AO32 -> 2042.62 | G33: =Source!DG32 -> *1,05 | H33: =Source!AV32 -> 1.248 | I33: =ROUND((ROUND((Source!AF32*Source!AV32*Source!I32),2)),2) -> 51.27 | J33: =IF(Source!BA32<> 0, Source!BA32, 1) -> 34.51 | K33: =Source!S32 -> 1769.33 | W33: =I33 -> 51.27
C34: НР от ЗП | D34: % | E34: =Source!DN32 -> 105 | I34: =SUM(Q32:Q33) -> 53.83 | J34: =Source!BZ32 -> 87 | K34: =SUM(R32:R33) -> 1539.32
C35: СП от ЗП | D35: % | E35: =Source!DO32 -> 77 | I35: =SUM(S32:S34) -> 39.48 | J35: =Source!CA32 -> 41 | K35: =SUM(T32:T34) -> 725.43
C36: ЗТР | D36: чел-ч | E36: =Source!AQ32 -> 192.7 | G36: =Source!DI32 -> *1,05 | H36: =Source!AV32 -> 1.248 | I36: =Source!U32 -> 4.8369072 | AB36: =I36 -> 4.8369072
C37: Всего по позиции: | H37: =I33+I34+I35+0 -> 144.58 | J37: =K33+K34+K35+0 -> 4034.08 | O37: =I33+I34+I35+0 -> 144.58 | P37: =K33+K34+K35+0 -> 4034.08 | X37: =IF(Source!BI32<=1,I33+I34+I35-0, 0) -> 144.58 | Y37: =IF(Source!BI32=2,I33+I34+I35-0, 0) -> 0 | Z37: =IF(Source!BI32=3,I33+I34+I35-0, 0) -> 0 | AA37: =IF(Source!BI32=4,I33+I34+I35,0) -> 0
A39: 2 | B39: 3.1-53-1 Поправка: О.П. п.3.4.30.г | C39: Засыпка вручную траншей, пазух котлованов и ям группа грунтов 1-3 | D39: =Source!DW33 -> 100 м3 грунта | E39: =Source!I33 -> 0.04536 | Q39: =ROUND((Source!DN33/100)*ROUND((ROUND((Source!AF33*Source!AV33*Source!I33),2)),2), 2) -> 65.6 | R39: =Source!X33 -> 1875.88 | S39: =ROUND((Source!DO33/100)*ROUND((ROUND((Source!AF33*Source!AV33*Source!I33),2)),2), 2) -> 48.11 | T39: =Source!Y33 -> 884.03 | U39: =ROUND((175/100)*ROUND((ROUND((Source!AE33*Source!AV33*Source!I33),2)),2), 2) -> 0 | V39: =ROUND((160/100)*ROUND(ROUND((ROUND((Source!AE33*Source!AV33*Source!I33),2)*Source!BS33),2), 2), 2) -> 0 | AI39: 0
C40: ="Объем: "&Source!I33&"=4,536/"&"100" -> Объем: 0,04536=4,536/100
C41: ЗП | F41: =Source!AO33 -> 1051.13 | G41: =Source!DG33 -> *1,05 | H41: =Source!AV33 -> 1.248 | I41: =ROUND((ROUND((Source!AF33*Source!AV33*Source!I33),2)),2) -> 62.48 | J41: =IF(Source!BA33<> 0, Source!BA33, 1) -> 34.51 | K41: =Source!S33 -> 2156.18 | W41: =I41 -> 62.48
C42: НР от ЗП | D42: % | E42: =Source!DN33 -> 105 | I42: =SUM(Q39:Q41) -> 65.6 | J42: =Source!BZ33 -> 87 | K42: =SUM(R39:R41) -> 1875.88
C43: СП от ЗП | D43: % | E43: =Source!DO33 -> 77 | I43: =SUM(S39:S42) -> 48.11 | J43: =Source!CA33 -> 41 | K43: =SUM(T39:T42) -> 884.03
C44: ЗТР | D44: чел-ч | E44: =Source!AQ33 -> 107.04 | G44: =Source!DI33 -> *1,05 | H44: =Source!AV33 -> 1.248 | I44: =Source!U33 -> 6.3624302 | AB44: =I44 -> 6.3624302
C45: Всего по позиции: | H45: =I41+I42+I43+0 -> 176.19 | J45: =K41+K42+K43+0 -> 4916.09 | O45: =I41+I42+I43+0 -> 176.19 | P45: =K41+K42+K43+0 -> 4916.09 | X45: =IF(Source!BI33<=1,I41+I42+I43-0, 0) -> 176.19 | Y45: =IF(Source!BI33=2,I41+I42+I43-0, 0) -> 0 | Z45: =IF(Source!BI33=3,I41+I42+I43-0, 0) -> 0 | AA45: =IF(Source!BI33=4,I41+I42+I43,0) -> 0
A47: 3 | B47: 3.4-23-3 Поправка: О.П. п.3.4.30.г | C47: Устройство закрытого (подземного) перехода методом горизонтально направленного бурения с поэтапным расширением скважины для полиэтиленовых труб в грунтах I-III группы установками с тяговым усилием до 500 кН для труб Dy = 400 мм длиной до 400 м | D47: =Source!DW34 -> 1 М | E47: =Source!I34 -> 186.2 | Q47: =ROUND((Source!DN34/100)*ROUND((ROUND((Source!AF34*Source!AV34*Source!I34),2)),2), 2) -> 8857.25 | R47: =Source!X34 -> 244120.54 | S47: =ROUND((Source!DO34/100)*ROUND((ROUND((Source!AF34*Source!AV34*Source!I34),2)),2), 2) -> 9392.25 | T47: =Source!Y34 -> 114880.25 | U47: =ROUND((175/100)*ROUND((ROUND((Source!AE34*Source!AV34*Source!I34),2)),2), 2) -> 20526.19 | V47: =ROUND((160/100)*ROUND(ROUND((ROUND((Source!AE34*Source!AV34*Source!I34),2)*Source!BS34),2), 2), 2) -> 647642.27 | AI47: 0
C48: ="Объем: "&Source!I34&"=104,1+"&"113,4-"&"31,3" -> Объем: 186,2=104,1+113,4-31,3
C49: ЗП | F49: =Source!AO34 -> 29.04 | G49: =Source!DG34 -> *1,05 | H49: =Source!AV34 -> 1.047 | I49: =ROUND((ROUND((Source!AF34*Source!AV34*Source!I34),2)),2) -> 5944.46 | J49: =IF(Source!BA34<> 0, Source!BA34, 1) -> 34.51 | K49: =Source!S34 -> 205143.31 | W49: =I49 -> 5944.46
...

Sheet Source
A1: 0 | B1: Smeta.RU (495) 974-1589 | D1: _PS_ | F1: 0 | G1: 0 | H1: 0 | I1: Smeta.RU | K1: 1 | L1: 75112 | M1: 10 | N1: 11 | O1: 15 | P1: 0 | Q1: 1
A12: 1 | B12: 210 | C12: 1 | D12: =ROW(A174) -> 174 | E12: 0 | F12: 02-01-08 Закрытый переход_(2 этап) | G12: 02-01-08 Закрытый переход | I12: 0 | K12: 0 | L12: 0 | M12: 4098 | O12: 0 | P12: 0 | Q12: 0 | R12: 160 | T12: 1 | V12: 0 | BB12: 0 | BH12: Сметные нормы списания | BI12: Коды ОКП для ТСН-2001 МГЭ (История развития) | BJ12: 1 | BK12: 1 | BL12: 0 | BM12: 0 | BN12: 1 | BO12: 0 | BP12: 6 | BQ12: 2 | BR12: 1 | BS12: 1 | BT12: 0 | BU12: 0 | BV12: 0 | BW12: 0 | BX12: 0 | BZ12: Типовой расчет для ТСН-2001 МГЭ, Новая методика с выпуска доп. 43 (Строительство), Доп 73 | CA12: История развития для ТСН-2001 (МГЭ) 73 доп от 17.07.2024 | CB12: История развития для ТСН-2001 (МГЭ) 73 доп от 17.07.2024 | CC12: История развития для ТСН-2001 (МГЭ) 73 доп от 17.07.2024 | CD12: История развития для ТСН-2001 (МГЭ) 73 доп от 17.07.2024 | CE12: Поправки для ТСН-2001 от 16.04.2024 г. доп.72 | CF12: 0 | CG12: 0 | CH12: 8 | CK12: 79 | CQ12: Территориальные сметные нормативы для Москвы (ТСН-2001) | CR12: ТЕР | CS12: 41660 | CT12: 1 | CU12: 73 | CY12: 0 | EC12: 0
A15: 15 | B15: 1
A18: 52 | B18: =B174 -> 210 | C18: =C174 -> 1 | D18: =D174 -> 12 | E18: =E174 -> 0 | F18: =F174 -> 02-01-08 Закрытый переход_(2 этап) | G18: =G174 -> 02-01-08 Закрытый переход | O18: =O174 -> 7532850.3 | P18: =P174 -> 3626729 | Q18: =Q174 -> 3562517 | R18: =R174 -> 410220.03 | S18: =S174 -> 343604.34 | T18: =T174 -> 0 | U18: =U174 -> 748.80028 | V18: =V174 -> 0 | ... GX18: =GX174 -> 0
A20: 3 | B20: 1 | D20: =ROW(A144) -> 144 | F20: Новая локальная смета | G20: Закрытые переходы | I20: 0 | K20: -1 | L20: Новая локальная смета | S20: 0 | V20: 0 | BX20: 0 | CF20: 0 | CG20: 0
A22: 52 | B22: =B144 -> 1 | C22: =C144 -> 3 | D22: =D144 -> 20 | E22: =E144 -> 0 | F22: =F144 -> Новая локальная смета | G22: =G144 -> Закрытые переходы | O22: =O144 -> 7532850.3 | P22: =P144 -> 3626729 | Q22: =Q144 -> 3562517 | R22: =R144 -> 410220.03 | S22: =S144 -> 343604.34 | T22: =T144 -> 0 | U22: =U144 -> 748.80028 | V22: =V144 -> 0 | ... GX22: =GX144 -> 0
A24: 4 | B24: 1 | D24: =ROW(A114) -> 114 | F24: Новый раздел | G24: Закрытый переход 2 сквх3тр (104,1м; 113,4м) | I24: 0 | K24: -1 | S24: 0 | V24: 0 | BX24: 0 | CJ24: 0
A26: 52 | B26: =B114 -> 1 | C26: =C114 -> 4 | D26: =D114 -> 24 | E26: =E114 -> 0 | F26: =F114 -> Новый раздел | G26: =G114 -> Закрытый переход 2 сквх3тр (104,1м; 113,4м) | O26: =O114 -> 7532850.3 | P26: =P114 -> 3626729 | Q26: =Q114 -> 3562517 | R26: =R114 -> 410220.03 | S26: =S114 -> 343604.34 | T26: =T114 -> 0 | U26: =U114 -> 748.80028 | V26: =V114 -> 0 | ... GX26: =GX114 -> 0
A28: 5 | B28: 1 | D28: =ROW(A44) -> 44 | F28: Новый подраздел | G28: Строительные работы | I28: 0 | K28: 0 | S28: 0 | V28: 0 | BX28: 0 | CJ28: 0
A30: 52 | B30: =B44 -> 1 | C30: =C44 -> 5 | D30: =D44 -> 28 | E30: =E44 -> 0 | F30: =F44 -> Новый подраздел | G30: =G44 -> Строительные работы | O30: =O44 -> 6530938.2 | P30: =P44 -> 2740359.9 | Q30: =Q44 -> 3552687.1 | R30: =R44 -> 406750.74 | S30: =S44 -> 237891.23 | T30: =T44 -> 0 | U30: =U44 -> 501.77593 | V30: =V44 -> 0 | ... GX30: =GX44 -> 0
A32: 17 | B32: 1 | C32: =ROW(SmtRes!A1) -> 1 | D32: =ROW(EtalonRes!A1) -> 1 | E32: 1 | F32: 3.1-51-1 | G32: Разработка грунта вручную в траншеях глубиной до 2 м без креплений с откосами группа грунтов 1-3 | H32: 100 м3 грунта | I32: =ROUND(0.019155,9) -> 0.019155 | J32: 0 | K32: =ROUND(0.019155,9) -> 0.019155 | O32: =ROUND(CP32,2) -> 1769.33 | P32: =ROUND((ROUND((AC32*AW32*I32),2)*BC32),2) -> 0 | Q32: =(ROUND((ROUND((((ET32*1.05))*AV32*I32),2)*BB32),2)+ROUND((ROUND(((AE32-((EU32*1.05)))*AV32*I32),2)*BS32),2)) -> 0 | R32: =ROUND((ROUND((AE32*AV32*I32),2)*BS32),2) -> 0 | S32: =ROUND((ROUND((AF32*AV32*I32),2)*BA32),2) -> 1769.33 | T32: =ROUND(CU32*I32,2) -> 0 | U32: =CV32*I32 -> 4.8369072 | V32: =CW32*I32 -> 0 | W32: =ROUND(CX32*I32,2) -> 0 | X32: =ROUND(CY32,2) -> 1539.32 | Y32: =ROUND(CZ32,2) -> 725.43 | AA32: 57737055 | AB32: =ROUND((AC32+AD32+AF32),6) -> 2144.751 | AC32: =ROUND((ES32),6) -> 0 | AD32: =ROUND(((((ET32*1.05))-((EU32*1.05)))+AE32),6) -> 0 | AE32: =ROUND(((EU32*1.05)),6) -> 0 | AF32: =ROUND(((EV32*1.05)),6) -> 2144.751 | AG32: =ROUND((AP32),6) -> 0 | AH32: =((EW32*1.05)) -> 202.335 | AI32: =((EX32*1.05)) -> 0 | AJ32: =(AS32) -> 0 | AK32: 2042.62 | AL32: 0 | AM32: 0 | AN32: 0 | AO32: 2042.62 | AP32: 0 | AQ32: 192.7 | AR32: 0 | AS32: 0 | AT32: 87 | AU32: 41 | AV32: 1.248 | AW32: 1 | AZ32: 1 | BA32: 34.51 | BB32: 1 | BC32: 1 | BH32: 0 | BI32: 1 | BJ32: ТСН-2001.3. Доп. 1-42. Сб. 1, т. 51, поз. 1 | BM32: 16 | BN32: 0 | BO32: 3.1-51-1 | BP32: 1 | BQ32: 30 | BR32: 0 | BS32: 34.51 | BT32: 1 | BU32: 1 | BV32: 1 | BW32: 1 | BX32: 1 | BZ32: 87 | CA32: 41 | CE32: 30 | CF32: 0 | CG32: 0 | CM32: 0 | CN32: Поправка: О.П. п.3.4.30.г Наименование: В отношении объектов, реализуемых с привлечением средств бюджета города Москвы, затраты, учитывающие усложненные условия производства работ (стесненность, сложность складирования и транспортной логистики, наличие в зоне производства работ действующего технологического оборудования или движения технологического транспорта и т.п.), определяются заказчиком в задании на проектирование при составлении локальных сметных расчетов (смет): для объектов города Москвы, расположенных за пределами Московской кольцевой автомобильной дороги | CO32: 0 | CP32: =(P32+Q32+S32) -> 1769.33 | CQ32: =ROUND((ROUND((AC32*AW32*1),2)*BC32),2) -> 0 | CR32: =(ROUND((ROUND((((ET32*1.05))*AV32*1),2)*BB32),2)+ROUND((ROUND(((AE32-((EU32*1.05)))*AV32*1),2)*BS32),2)) -> 0 | CS32: =ROUND((ROUND((AE32*AV32*1),2)*BS32),2) -> 0 | CT32: =ROUND((ROUND((AF32*AV32*1),2)*BA32),2) -> 92371.19 | CU32: =AG32 -> 0 | CV32: =(AH32*AV32) -> 252.51408 | CW32: =AI32 -> 0 | CX32: =AJ32 -> 0 | CY32: =S32*(BZ32/100) -> 1539.3171 | CZ32: =S32*(CA32/100) -> 725.4253 | DB32: 1 | DE32: *1,05 | DF32: *1,05 | DG32: *1,05 | DI32: *1,05 | DJ32: *1,05 | DN32: 105 | DO32: 77 | DP32: 1.248 | DQ32: 1 | DU32: 1013 | DV32: 100 м3 грунта | DW32: 100 м3 грунта | DX32: 1 | EE32: 51696099 | EF32: 30 | EG32: Строительные работы | EH32: 0 | EJ32: 1 | EK32: 16 | EL32: ТСН-2001.3-1. 1-49...1-55 | EM32: ТСН-2001.3-1-15 | EO32: Поправка: О.П. п.3.4.30.г | EQ32: 131072 | ER32: 2042.62 | ES32: 0 | ET32: 0 | EU32: 0 | EV32: 2042.62 | EW32: 192.7 | EX32: 0 | EY32: 0 | FQ32: 0 | FR32: 0 | FS32: 0 | FX32: 105 | FY32: 77 | GD32: 0 | GF32: -2104602307 | GG32: 2 | GH32: 1 | GI32: 2 | GJ32: 0 | GK32: =ROUND(R32*(R12)/100,2) -> 0 | GL32: =ROUND(IF(AND(BH32=3,BI32=3,FS32<>0),P32,0),2) -> 0 | GM32: =ROUND(O32+X32+Y32+GK32,2)+GX32 -> 4034.08 | GN32: =IF(OR(BI32=0,BI32=1),GM32-GX32,0) -> 4034.08 | GO32: =IF(BI32=2,GM32-GX32,0) -> 0 | GP32: =IF(BI32=4,GM32-GX32,0) -> 0 | GR32: 0 | GS32: 3 | GT32: 0 | GV32: =ROUND((GT32),6) -> 0 | GW32: 1 | GX32: =ROUND(HC32*I32,2) -> 0 | HA32: 0 | HB32: 0 | HC32: =GV32*GW32 -> 0 | HS32: 0 | IK32: 0
A33: 17 | B33: 1 | C33: =ROW(SmtRes!A2) -> 2 | D33: =ROW(EtalonRes!A2) -> 2 | E33: 2 | F33: 3.1-53-1 | G33: Засыпка вручную траншей, пазух котлованов и ям группа грунтов 1-3 | H33: 100 м3 грунта | I33: =ROUND(4.536/100,9) -> 0.04536 | J33: 0 | K33: =ROUND(4.536/100,9) -> 0.04536 | O33: =ROUND(CP33,2) -> 2156.18 | P33: =ROUND((ROUND((AC33*AW33*I33),2)*BC33),2) -> 0 | Q33: =(ROUND((ROUND((((ET33*1.05))*AV33*I33),2)*BB33),2)+ROUND((ROUND(((AE33-((EU33*1.05)))*AV33*I33),2)*BS33),2)) -> 0 | R33: =ROUND((ROUND((AE33*AV33*I33),2)*BS33),2) -> 0 | S33: =ROUND((ROUND((AF33*AV33*I33),2)*BA33),2) -> 2156.18 | T33: =ROUND(CU33*I33,2) -> 0 | U33: =CV33*I33 -> 6.3624302 | V33: =CW33*I33 -> 0 | W33: =ROUND(CX33*I33,2) -> 0 | X33: =ROUND(CY33,2) -> 1875.88 | Y33: =ROUND(CZ33,2) -> 884.03 | AA33: 57737055 | AB33: =ROUND((AC33+AD33+AF33),6) -> 1103.6865 | AC33: =ROUND((ES33),6) -> 0 | AD33: =ROUND(((((ET33*1.05))-((EU33*1.05)))+AE33),6) -> 0 | AE33: =ROUND(((EU33*1.05)),6) -> 0 | AF33: =ROUND(((EV33*1.05)),6) -> 1103.6865 | AG33: =ROUND((AP33),6) -> 0 | AH33: =((EW33*1.05)) -> 112.392 | AI33: =((EX33*1.05)) -> 0 | AJ33: =(AS33) -> 0 | AK33: 1051.13 | AL33: 0 | AM33: 0 | AN33: 0 | AO33: 1051.13 | AP33: 0 | AQ33: 107.04 | AR33: 0 | AS33: 0 | AT33: 87 | AU33: 41 | AV33: 1.248 | AW33: 1 | AZ33: 1 | BA33: 34.51 | BB33: 1 | BC33: 1 | BH33: 0 | BI33: 1 | BJ33: ТСН-2001.3. Доп. 1-42. Сб. 1, т. 53, поз. 1 | BM33: 16 | BN33: 0 | BO33: 3.1-53-1 | BP33: 1 | BQ33: 30 | BR33: 0 | BS33: 34.51 | BT33: 1 | BU33: 1 | BV33: 1 | BW33: 1 | BX33: 1 | BZ33: 87 | CA33: 41 | CE33: 30 | CF33: 0 | CG33: 0 | CM33: 0 | CN33: Поправка: О.П. п.3.4.30.г Наименование: В отношении объектов, реализуемых с привлечением средств бюджета города Москвы, затраты, учитывающие усложненные условия производства работ (стесненность, сложность складирования и транспортной логистики, наличие в зоне производства работ действующего технологического оборудования или движения технологического транспорта и т.п.), определяются заказчиком в задании на проектирование при составлении локальных сметных расчетов (смет): для объектов города Москвы, расположенных за пределами Московской кольцевой автомобильной дороги | CO33: 0 | CP33: =(P33+Q33+S33) -> 2156.18 | CQ33: =ROUND((ROUND((AC33*AW33*1),2)*BC33),2) -> 0 | CR33: =(ROUND((ROUND((((ET33*1.05))*AV33*1),2)*BB33),2)+ROUND((ROUND(((AE33-((EU33*1.05)))*AV33*1),2)*BS33),2)) -> 0 | CS33: =ROUND((ROUND((AE33*AV33*1),2)*BS33),2) -> 0 | CT33: =ROUND((ROUND((AF33*AV33*1),2)*BA33),2) -> 47534.07 | CU33: =AG33 -> 0 | CV33: =(AH33*AV33) -> 140.26522 | CW33: =AI33 -> 0 | CX33: =AJ33 -> 0 | CY33: =S33*(BZ33/100) -> 1875.8766 | CZ33: =S33*(CA33/100) -> 884.0338 | DB33: 2 | DE33: *1,05 | DF33: *1,05 | DG33: *1,05 | DI33: *1,05 | DJ33: *1,05 | DN33: 105 | DO33: 77 | DP33: 1.248 | DQ33: 1 | DU33: 1013 | DV33: 100 м3 грунта | DW33: 100 м3 грунта | DX33: 1 | EE33: 51696099 | EF33: 30 | EG33: Строительные работы | EH33: 0 | EJ33: 1 | EK33: 16 | EL33: ТСН-2001.3-1. 1-49...1-55 | EM33: ТСН-2001.3-1-15 | EO33: Поправка: О.П. п.3.4.30.г | EQ33: 131072 | ER33: 1051.13 | ES33: 0 | ET33: 0 | EU33: 0 | EV33: 1051.13 | EW33: 107.04 | EX33: 0 | EY33: 0 | FQ33: 0 | FR33: 0 | FS33: 0 | FX33: 105 | FY33: 77 | GD33: 0 | GF33: 1725378853 | GG33: 2 | GH33: 1 | GI33: 2 | GJ33: 0 | GK33: =ROUND(R33*(R12)/100,2) -> 0 | GL33: =ROUND(IF(AND(BH33=3,BI33=3,FS33<>0),P33,0),2) -> 0 | GM33: =ROUND(O33+X33+Y33+GK33,2)+GX33 -> 4916.09 | GN33: =IF(OR(BI33=0,BI33=1),GM33-GX33,0) -> 4916.09 | GO33: =IF(BI33=2,GM33-GX33,0) -> 0 | GP33: =IF(BI33=4,GM33-GX33,0) -> 0 | GR33: 0 | GS33: 3 | GT33: 0 | GV33: =ROUND((GT33),6) -> 0 | GW33: 1 | GX33: =ROUND(HC33*I33,2) -> 0 | HA33: 0 | HB33: 0 | HC33: =GV33*GW33 -> 0 | HS33: 0 | IK33: 0
A34: 17 | B34: 1 | C34: =ROW(SmtRes!A15) -> 15 | D34: =ROW(EtalonRes!A16) -> 16 | E34: 3 | F34: 3.4-23-3 | G34: Устройство закрытого (подземного) перехода методом горизонтально направленного бурения с поэтапным расширением скважины для полиэтиленовых труб в грунтах I-III группы установками с тяговым усилием до 500 кН для труб Dy = 400 мм длиной до 400 м | H34: 1 М | I34: =ROUND(104.1+113.4-31.3,9) -> 186.2 | J34: 0 | K34: =ROUND(104.1+113.4-31.3,9) -> 186.2 | O34: =ROUND(CP34,2) -> 3760936.4 | P34: =ROUND((ROUND((AC34*AW34*I34),2)*BC34),2) -> 26701.75 | Q34: =(ROUND((ROUND((((ET34*1.05))*AV34*I34),2)*BB34),2)+ROUND((ROUND(((AE34-((EU34*1.05)))*AV34*I34),2)*BS34),2)) -> 3529091.3 | R34: =ROUND((ROUND((AE34*AV34*I34),2)*BS34),2) -> 404776.42 | S34: =ROUND((ROUND((AF34*AV34*I34),2)*BA34),2) -> 205143.31 | T34: =ROUND(CU34*I34,2) -> 0 | U34: =CV34*I34 -> 425.77386 | V34: =CW34*I34 -> 0 | W34: =ROUND(CX34*I34,2) -> 0 | X34: =ROUND(CY34,2) -> 244120.54 | Y34: =ROUND(CZ34,2) -> 114880.25 | AA34: 57737055 | AB34: =ROUND((AC34+AD34+AF34),6) -> 1917.2485 | AC34: =ROUND((ES34),6) -> 22.45 | AD34: =ROUND(((((ET34*1.05))-((EU34*1.05)))+AE34),6) -> 1864.3065 | AE34: =ROUND(((EU34*1.05)),6) -> 60.165 | AF34: =ROUND(((EV34*1.05)),6) -> 30.492 | AG34: =ROUND((AP34),6) -> 0 | AH34: =((EW34*1.05)) -> 2.184 | AI34: =((EX34*1.05)) -> 0 | AJ34: =(AS34) -> 0 | AK34: 1827.02 | AL34: 22.45 | AM34: 1775.53 | AN34: 57.3 | AO34: 29.04 | AP34: 0 | AQ34: 2.08 | AR34: 0 | AS34: 0 | AT34: 119 | AU34: 56 | AV34: 1.047 | AW34: 1.079 | AZ34: 1 | BA34: 34.51 | BB34: 9.71 | BC34: 5.92 | BH34: 0 | BI34: 1 | BJ34: ТСН-2001.3 Доп. 69, Сб. 4, т. 23, поз. 3 | BM34: 1989 | BN34: 0 | BO34: 3.4-23-3 | BP34: 1 | BQ34: 30 | BR34: 0 | BS34: 34.51 | BT34: 1 | BU34: 1 | BV34: 1 | BW34: 1 | BX34: 1 | BZ34: 119 | CA34: 56 | CE34: 30 | CF34: 0 | CG34: 0 | CM34: 0 | CN34: Поправка: О.П. п.3.4.30.г Наименование: В отношении объектов, реализуемых с привлечением средств бюджета города Москвы, затраты, учитывающие усложненные условия производства работ (стесненность, сложность складирования и транспортной логистики, наличие в зоне производства работ действующего технологического оборудования или движения технологического транспорта и т.п.), определяются заказчиком в задании на проектирование при составлении локальных сметных расчетов (смет): для объектов города Москвы, расположенных за пределами Московской кольцевой автомобильной дороги | CO34: 0 | CP34: =(P34+Q34+S34) -> 3760936.4 | CQ34: =ROUND((ROUND((AC34*AW34*1),2)*BC34),2) -> 143.38 | CR34: =(ROUND((ROUND((((ET34*1.05))*AV34*1),2)*BB34),2)+ROUND((ROUND(((AE34-((EU34*1.05)))*AV34*1),2)*BS34),2)) -> 18953.24 | CS34: =ROUND((ROUND((AE34*AV34*1),2)*BS34),2) -> 2173.78 | CT34: =ROUND((ROUND((AF34*AV34*1),2)*BA34),2) -> 1101.9 | CU34: =AG34 -> 0 | CV34: =(AH34*AV34) -> 2.286648 | CW34: =AI34 -> 0 | CX34: =AJ34 -> 0 | CY34: =S34*(BZ34/100) -> 244120.54 | CZ34: =S34*(CA34/100) -> 114880.25 | DB34: 3 | DE34: *1,05 | DF34: *1,05 | DG34: *1,05 | DI34: *1,05 | DJ34: *1,05 | DN34: 149 | DO34: 158 | DP34: 1.047 | DQ34: 1.079 | DU34: 1013 | DV34: 1 М | DW34: 1 М | DX34: 1 | EE34: 51698030 | EF34: 30 | EG34: Строительные работы | EH34: 0 | EJ34: 1 | EK34: 1989 | EL34: ТСН-2001.3-4. 4-23-1...4-23-5 (доп. 47) | EM34: ТСН-2001.3-4-4 | EO34: Поправка: О.П. п.3.4.30.г | EQ34: 131072 | ER34: 1827.02 | ES34: 22.45 | ET34: 1775.53 | EU34: 57.3 | EV34: 29.04 | EW34: 2.08 | EX34: 0 | EY34: 0 | FQ34: 0 | FR34: 0 | FS34: 0 | FX34: 149 | FY34: 158 | GD34: 0 | GF34: 925277583 | GG34: 2 | GH34: 1 | GI34: 2 | GJ34: 0 | GK34: =ROUND(R34*(R12)/100,2) -> 647642.27 | GL34: =ROUND(IF(AND(BH34=3,BI34=3,FS34<>0),P34,0),2) -> 0 | GM34: =ROUND(O34+X34+Y34+GK34,2)+GX34 -> 4767579.5 | GN34: =IF(OR(BI34=0,BI34=1),GM34-GX34,0) -> 4767579.5 | GO34: =IF(BI34=2,GM34-GX34,0) -> 0 | GP34: =IF(BI34=4,GM34-GX34,0) -> 0 | GR34: 0 | GS34: 3 | GT34: 0 | GV34: =ROUND((GT34),6) -> 0 | GW34: 1 | GX34: =ROUND(HC34*I34,2) -> 0 | HA34: 0 | HB34: 0 | HC34: =GV34*GW34 -> 0 | HS34: 0 | IK34: 0
A35: 18 | B35: 1 | C35: 13 | E35: 3,1 | F35: 1.1-1-1835 | G35: Бентонит натриевый тонкого помола с содержанием органических полимеров, для сгущения, увеличения объема и придания гелеобразующих свойств буровым растворам, укрепления, снижения просачивания воды в стенках каналов | H35: кг | I35: =I34*J35 -> 21748.16 | J35: 116.8 | K35: 116.8 | O35: =ROUND(CP35,2) -> 1211821.4 | P35: =ROUND((ROUND((AC35*AW35*I35),2)*BC35),2) -> 1211821.4 | Q35: =(ROUND((ROUND(((ET35)*AV35*I35),2)*BB35),2)+ROUND((ROUND(((AE35-(EU35))*AV35*I35),2)*BS35),2)) -> 0 | R35: =ROUND((ROUND((AE35*AV35*I35),2)*BS35),2) -> 0 | S35: =ROUND((ROUND((AF35*AV35*I35),2)*BA35),2) -> 0 | T35: =ROUND(CU35*I35,2) -> 0 | U35: =CV35*I35 -> 0 | V35: =CW35*I35 -> 0 | W35: =ROUND(CX35*I35,2) -> 0 | X35: =ROUND(CY35,2) -> 0 | Y35: =ROUND(CZ35,2) -> 0 | AA35: 57737055 | AB35: =ROUND((AC35+AD35+AF35),6) -> 11.3 | AC35: =ROUND((ES35),6) -> 11.3 | AD35: =ROUND((((ET35)-(EU35))+AE35),6) -> 0 | AE35: =ROUND((EU35),6) -> 0 | AF35: =ROUND((EV35),6) -> 0 | AG35: =ROUND((AP35),6) -> 0 | AH35: =(EW35) -> 0 | AI35: =(EX35) -> 0 | AJ35: =(AS35) -> 0 | AK35: 11.3 | AL35: 11.3 | AM35: 0 | AN35: 0 | AO35: 0 | AP35: 0 | AQ35: 0 | AR35: 0 | AS35: 0 | AT35: 0 | AU35: 0 | AV35: 1 | AW35: 1.079 | AZ35: 1 | BA35: 1 | BB35: 1 | BC35: 4.57 | BH35: 3 | BI35: 1 | BJ35: ТСН-2001.1 Доп. 49, Р. 1, о. 1, поз. 1835 | BM35: 1989 | BN35: 0 | BO35: 1.1-1-1835 | BP35: 1 | BQ35: 30 | BR35: 0 | BS35: 1 | BT35: 1 | BU35: 1 | BV35: 1 | BW35: 1 | BX35: 1 | BZ35: 0 | CA35: 0 | CE35: 30 | CF35: 0 | CG35: 0 | CM35: 0 | CO35: 0 | CP35: =(P35+Q35+S35) -> 1211821.4 | CQ35: =ROUND((ROUND((AC35*AW35*1),2)*BC35),2) -> 55.71 | CR35: =(ROUND((ROUND(((ET35)*AV35*1),2)*BB35),2)+ROUND((ROUND(((AE35-(EU35))*AV35*1),2)*BS35),2)) -> 0 | CS35: =ROUND((ROUND((AE35*AV35*1),2)*BS35),2) -> 0 | CT35: =ROUND((ROUND((AF35*AV35*1),2)*BA35),2) -> 0 | CU35: =AG35 -> 0 | CV35: =(AH35*AV35) -> 0 | CW35: =AI35 -> 0 | CX35: =AJ35 -> 0 | CY35: =S35*(BZ35/100) -> 0 | CZ35: =S35*(CA35/100) -> 0 | DN35: 149 | DO35: 158 | DP35: 1.047 | DQ35: 1.079 | DU35: 1009 | DV35: кг | DW35: кг | DX35: 1 | EE35: 51698030 | EF35: 30 | EG35: Строительные работы | EH35: 0 | EJ35: 1 | EK35: 1989 | EL35: ТСН-2001.3-4. 4-23-1...4-23-5 (доп. 47) | EM35: ТСН-2001.3-4-4 | EQ35: 0 | ER35: 11.3 | ES35: 11.3 | ET35: 0 | EU35: 0 | EV35: 0 | EW35: 0 | EX35: 0 | FQ35: 0 | FR35: 0 | FS35: 0 | FX35: 149 | FY35: 158 | GD35: 0 | GF35: -936542528 | GG35: 2 | GH35: 1 | GI35: 2 | GJ35: 0 | GK35: =ROUND(R35*(R12)/100,2) -> 0 | GL35: =ROUND(IF(AND(BH35=3,BI35=3,FS35<>0),P35,0),2) -> 0 | GM35: =ROUND(O35+X35+Y35+GK35,2)+GX35 -> 1211821.4 | GN35: =IF(OR(BI35=0,BI35=1),GM35-GX35,0) -> 1211821.4 | GO35: =IF(BI35=2,GM35-GX35,0) -> 0 | GP35: =IF(BI35=4,GM35-GX35,0) -> 0 | GR35: 0 | GS35: 3 | GT35: 0 | GV35: =ROUND((GT35),6) -> 0 | GW35: 1 | GX35: =ROUND(HC35*I35,2) -> 0 | HA35: 0 | HB35: 0 | HC35: =GV35*GW35 -> 0 | HS35: 0 | IK35: 0
A36: 18 | B36: 1 | C36: 15 | E36: 3,2 | F36: 1.1-1-3290 | G36: Средство полимерное, жидкое, водородный показатель рН от 8,5 до 10,5, для кондиционирования грунтов при проходке тоннелей с использованием ТПМК с грунтопригрузом, улучшения рабочих характеристик пенных реагентов в сложных грунтовых условиях, модификации бентонитового раствора для ТПМК с гидропригрузом | H36: л | I36: =I34*J36 -> 1103.7936 | J36: 5.928 | K36: 5.928 | O36: =ROUND(CP36,2) -> 963201.05 | P36: =ROUND((ROUND((AC36*AW36*I36),2)*BC36),2) -> 963201.05 | Q36: =(ROUND((ROUND(((ET36)*AV36*I36),2)*BB36),2)+ROUND((ROUND(((AE36-(EU36))*AV36*I36),2)*BS36),2)) -> 0 | R36: =ROUND((ROUND((AE36*AV36*I36),2)*BS36),2) -> 0 | S36: =ROUND((ROUND((AF36*AV36*I36),2)*BA36),2) -> 0 | T36: =ROUND(CU36*I36,2) -> 0 | U36: =CV36*I36 -> 0 | V36: =CW36*I36 -> 0 | W36: =ROUND(CX36*I36,2) -> 0 | X36: =ROUND(CY36,2) -> 0 | Y36: =ROUND(CZ36,2) -> 0 | AA36: 57737055 | AB36: =ROUND((AC36+AD36+AF36),6) -> 95.37 | AC36: =ROUND((ES36),6) -> 95.37 | AD36: =ROUND((((ET36)-(EU36))+AE36),6) -> 0 | AE36: =ROUND((EU36),6) -> 0 | AF36: =ROUND((EV36),6) -> 0 | AG36: =ROUND((AP36),6) -> 0 | AH36: =(EW36) -> 0 | AI36: =(EX36) -> 0 | AJ36: =(AS36) -> 0 | AK36: 95.37 | AL36: 95.37 | AM36: 0 | AN36: 0 | AO36: 0 | AP36: 0 | AQ36: 0 | AR36: 0 | AS36: 0 | AT36: 0 | AU36: 0 | AV36: 1 | AW36: 1.079 | AZ36: 1 | BA36: 1 | BB36: 1 | BC36: 8.48 | BH36: 3 | BI36: 1 | BJ36: ТСН-2001.1 Доп. 67, Р. 1, о. 1, поз. 3290 | BM36: 1989 | BN36: 0 | BO36: 1.1-1-3290 | BP36: 1 | BQ36: 30 | BR36: 0 | BS36: 1 | BT36: 1 | BU36: 1 | BV36: 1 | BW36: 1 | BX36: 1 | BZ36: 0 | CA36: 0 | CE36: 30 | CF36: 0 | CG36: 0 | CM36: 0 | CO36: 0 | CP36: =(P36+Q36+S36) -> 963201.05 | CQ36: =ROUND((ROUND((AC36*AW36*1),2)*BC36),2) -> 872.59 | CR36: =(ROUND((ROUND(((ET36)*AV36*1),2)*BB36),2)+ROUND((ROUND(((AE36-(EU36))*AV36*1),2)*BS36),2)) -> 0 | CS36: =ROUND((ROUND((AE36*AV36*1),2)*BS36),2) -> 0 | CT36: =ROUND((ROUND((AF36*AV36*1),2)*BA36),2) -> 0 | CU36: =AG36 -> 0 | CV36: =(AH36*AV36) -> 0 | CW36: =AI36 -> 0 | CX36: =AJ36 -> 0 | CY36: =S36*(BZ36/100) -> 0 | CZ36: =S36*(CA36/100) -> 0 | DN36: 149 | DO36: 158 | DP36: 1.047 | DQ36: 1.079 | DU36: 1013 | DV36: л | DW36: л | DX36: 1 | EE36: 51698030 | EF36: 30 | EG36: Строительные работы | EH36: 0 | EJ36: 1 | EK36: 1989 | EL36: ТСН-2001.3-4. 4-23-1...4-23-5 (доп. 47) | EM36: ТСН-2001.3-4-4 | EQ36: 0 | ER36: 95.37 | ES36: 95.37 | ET36: 0 | EU36: 0 | EV36: 0 | EW36: 0 | EX36: 0 | FQ36: 0 | FR36: 0 | FS36: 0 | FX36: 149 | FY36: 158 | GD36: 0 | GF36: 1548396739 | GG36: 2 | GH36: 1 | GI36: 2 | GJ36: 0 | GK36: =ROUND(R36*(R12)/100,2) -> 0 | GL36: =ROUND(IF(AND(BH36=3,BI36=3,FS36<>0),P36,0),2) -> 0 | GM36: =ROUND(O36+X36+Y36+GK36,2)+GX36 -> 963201.05 | GN36: =IF(OR(BI36=0,BI36=1),GM36-GX36,0) -> 963201.05 | GO36: =IF(BI36=2,GM36-GX36,0) -> 0 | GP36: =IF(BI36=4,GM36-GX36,0) -> 0 | GR36: 0 | GS36: 3 | GT36: 0 | GV36: =ROUND((GT36),6) -> 0 | GW36: 1 | GX36: =ROUND(HC36*I36,2) -> 0 | HA36: 0 | HB36: 0 | HC36: =GV36*GW36 -> 0 | HS36: 0 | IK36: 0
A37: 17 | B37: 1 | E37: 4 | F37: Цена поставщика | G37: Трубы из полиэтилена ТЗК Энергопласт ТСЗ 160*8,9 Sn 16 F3 | H37: м | I37: =ROUND(I34*3+9,9) -> 567.6 | J37: 0 | K37: =ROUND(I34*3+9,9) -> 567.6 | O37: =ROUND(CP37,2) -> 533271.82 | P37: =ROUND((ROUND((AC37*AW37*I37),2)*BC37),2) -> 533271.82 | Q37: =(ROUND((ROUND((((ET37*1.05))*AV37*I37),2)*BB37),2)+ROUND((ROUND(((AE37-((EU37*1.05)))*AV37*I37),2)*BS37),2)) -> 0 | R37: =ROUND((ROUND((AE37*AV37*I37),2)*BS37),2) -> 0 | S37: =ROUND((ROUND((AF37*AV37*I37),2)*BA37),2) -> 0 | T37: =ROUND(CU37*I37,2) -> 0 | U37: =CV37*I37 -> 0 | V37: =CW37*I37 -> 0 | W37: =ROUND(CX37*I37,2) -> 0 | X37: =ROUND(CY37,2) -> 0 | Y37: =ROUND(CZ37,2) -> 0 | AA37: 57737055 | AB37: =ROUND((AC37+AD37+AF37),6) -> 96.46 | AC37: =ROUND((ES37),6) -> 96.46 | AD37: =ROUND(((((ET37*1.05))-((EU37*1.05)))+AE37),6) -> 0 | AE37: =ROUND(((EU37*1.05)),6) -> 0 | AF37: =ROUND(((EV37*1.05)),6) -> 0 | AG37: =ROUND((AP37),6) -> 0 | AH37: =((EW37*1.05)) -> 0 | AI37: =((EX37*1.05)) -> 0 | AJ37: =(AS37) -> 0 | AK37: 96.46 | AL37: 96.46 | AM37: 0 | AN37: 0 | AO37: 0 | AP37: 0 | AQ37: 0 | AR37: 0 | AS37: 0 | AT37: 0 | AU37: 0 | AV37: 1 | AW37: 1 | AZ37: 1 | BA37: 1 | BB37: 1 | BC37: 9.74 | BH37: 3 | BI37: 1 | BM37: 400002 | BN37: 0 | BP37: 0 | BQ37: 202 | BR37: 0 | BS37: 1 | BT37: 1 | BU37: 1 | BV37: 1 | BW37: 1 | BX37: 1 | BZ37: 0 | CA37: 0 | CE37: 30 | CF37: 0 | CG37: 0 | CM37: 0 | CN37: Поправка: О.П. п.3.4.30.г Наименование: В отношении объектов, реализуемых с привлечением средств бюджета города Москвы, затраты, учитывающие усложненные условия производства работ (стесненность, сложность складирования и транспортной логистики, наличие в зоне производства работ действующего технологического оборудования или движения технологического транспорта и т.п.), определяются заказчиком в задании на проектирование при составлении локальных сметных расчетов (смет): для объектов города Москвы, расположенных за пределами Московской кольцевой автомобильной дороги | CO37: 0 | CP37: =(P37+Q37+S37) -> 533271.82 | CQ37: =ROUND((ROUND((AC37*AW37*1),2)*BC37),2) -> 939.52 | CR37: =(ROUND((ROUND((((ET37*1.05))*AV37*1),2)*BB37),2)+ROUND((ROUND(((AE37-((EU37*1.05)))*AV37*1),2)*BS37),2)) -> 0 | CS37: =ROUND((ROUND((AE37*AV37*1),2)*BS37),2) -> 0 | CT37: =ROUND((ROUND((AF37*AV37*1),2)*BA37),2) -> 0 | CU37: =AG37 -> 0 | CV37: =(AH37*AV37) -> 0 | CW37: =AI37 -> 0 | CX37: =AJ37 -> 0 | CY37: =S37*(BZ37/100) -> 0 | CZ37: =S37*(CA37/100) -> 0 | DB37: 4 | DE37: *1,05 | DF37: *1,05 | DG37: *1,05 | DI37: *1,05 | DJ37: *1,05 | DN37: 0 | DO37: 0 | DP37: 1 | DQ37: 1 | DU37: 1003 | DV37: м | DW37: м | DX37: 1 | EE37: 51698006 | EF37: 202 | EG37: Материалы | EH37: 0 | EJ37: 1 | EK37: 400002 | EL37: Материалы, изделия и конструкции | EM37: Материалы | EO37: Поправка: О.П. п.3.4.30.г | EQ37: 131072 | ER37: 96.46 | ES37: 96.46 | ET37: 0 | EU37: 0 | EV37: 0 | EW37: 0 | EX37: 0 | EY37: 0 | EZ37: 5 | FC37: 0 | FD37: 18 | FF37: 939.56 | FQ37: 0 | FR37: 0 | FS37: 0 | FX37: 0 | FY37: 0 | GA37: [939,56 / 9,74] | GD37: 0 | GF37: -2093484384 | GG37: 2 | GH37: 3 | GI37: 3 | GJ37: 0 | GK37: =ROUND(R37*(R12)/100,2) -> 0 | GL37: =ROUND(IF(AND(BH37=3,BI37=3,FS37<>0),P37,0),2) -> 0 | GM37: =ROUND(O37+X37+Y37+GK37,2)+GX37 -> 533271.82 | GN37: =IF(OR(BI37=0,BI37=1),GM37-GX37,0) -> 533271.82 | GO37: =IF(BI37=2,GM37-GX37,0) -> 0 | GP37: =IF(BI37=4,GM37-GX37,0) -> 0 | GR37: 1 | GS37: 1 | GT37: 0 | GV37: =ROUND((GT37),6) -> 0 | GW37: 1 | GX37: =ROUND(HC37*I37,2) -> 0 | HA37: 0 | HB37: 0 | HC37: =GV37*GW37 -> 0 | HE37: 0 | HF37: 0 | HS37: 0 | IK37: 0
A38: 17 | B38: 1 | C38: =ROW(SmtRes!A18) -> 18 | D38: =ROW(EtalonRes!A19) -> 19 | E38: 5 | F38: 3.4-21-2 | G38: Монтаж установки горизонтально направленного бурения с тяговым усилием до 500 кН | H38: 1 ШТ. | I38: =ROUND(2*0+1,9) -> 1 | J38: 0 | K38: =ROUND(2*0+1,9) -> 1 | O38: =ROUND(CP38,2) -> 12926.59 | P38: =ROUND((ROUND((AC38*AW38*I38),2)*BC38),2) -> 0 | Q38: =(ROUND((ROUND((((ET38*1.05))*AV38*I38),2)*BB38),2)+ROUND((ROUND(((AE38-((EU38*1.05)))*AV38*I38),2)*BS38),2)) -> 12639.47 | R38: =ROUND((ROUND((AE38*AV38*I38),2)*BS38),2) -> 1206.47 | S38: =ROUND((ROUND((AF38*AV38*I38),2)*BA38),2) -> 287.12 | T38: =ROUND(CU38*I38,2) -> 0 | U38: =CV38*I38 -> 0.65961 | V38: =CW38*I38 -> 0 | W38: =ROUND(CX38*I38,2) -> 0 | X38: =ROUND(CY38,2) -> 341.67 | Y38: =ROUND(CZ38,2) -> 160.79 | AA38: 57737055 | AB38: =ROUND((AC38+AD38+AF38),6) -> 1270.7205 | AC38: =ROUND((ES38),6) -> 0 | AD38: =ROUND(((((ET38*1.05))-((EU38*1.05)))+AE38),6) -> 1262.772 | AE38: =ROUND(((EU38*1.05)),6) -> 33.39 | AF38: =ROUND(((EV38*1.05)),6) -> 7.9485 | AG38: =ROUND((AP38),6) -> 0 | AH38: =((EW38*1.05)) -> 0.63 | AI38: =((EX38*1.05)) -> 0 | AJ38: =(AS38) -> 0 | AK38: 1210.21 | AL38: 0 | AM38: 1202.64 | AN38: 31.8 | AO38: 7.57 | AP38: 0 | AQ38: 0.6 | AR38: 0 | AS38: 0 | AT38: 119 | AU38: 56 | AV38: 1.047 | AW38: 1.079 | AZ38: 1 | BA38: 34.51 | BB38: 9.56 | BC38: 1 | BH38: 0 | BI38: 1 | BJ38: ТСН-2001.3 Доп. 68, Сб. 4, т. 21, поз. 2 | BM38: 1987 | BN38: 0 | BO38: 3.4-21-2 | BP38: 1 | BQ38: 30 | BR38: 0 | BS38: 34.51 | BT38: 1 | BU38: 1 | BV38: 1 | BW38: 1 | BX38: 1 | BZ38: 119 | CA38: 56 | CE38: 30 | CF38: 0 | CG38: 0 | CM38: 0 | CN38: Поправка: О.П. п.3.4.30.г Наименование: В отношении объектов, реализуемых с привлечением средств бюджета города Москвы, затраты, учитывающие усложненные условия производства работ (стесненность, сложность складирования и транспортной логистики, наличие в зоне производства работ действующего технологического оборудования или движения технологического транспорта и т.п.), определяются заказчиком в задании на проектирование при составлении локальных сметных расчетов (смет): для объектов города Москвы, расположенных за пределами Московской кольцевой автомобильной дороги | CO38: 0 | CP38: =(P38+Q38+S38) -> 12926.59 | CQ38: =ROUND((ROUND((AC38*AW38*1),2)*BC38),2) -> 0 | CR38: =(ROUND((ROUND((((ET38*1.05))*AV38*1),2)*BB38),2)+ROUND((ROUND(((AE38-((EU38*1.05)))*AV38*1),2)*BS38),2)) -> 12639.47 | CS38: =ROUND((ROUND((AE38*AV38*1),2)*BS38),2) -> 1206.47 | CT38: =ROUND((ROUND((AF38*AV38*1),2)*BA38),2) -> 287.12 | CU38: =AG38 -> 0 | CV38: =(AH38*AV38) -> 0.65961 | CW38: =AI38 -> 0 | CX38: =AJ38 -> 0 | CY38: =S38*(BZ38/100) -> 341.6728 | CZ38: =S38*(CA38/100) -> 160.7872 | DB38: 5 | DE38: *1,05 | DF38: *1,05 | DG38: *1,05 | DI38: *1,05 | DJ38: *1,05 | DN38: 149 | DO38: 158 | DP38: 1.047 | DQ38: 1.079 | DU38: 1013 | DV38: 1 ШТ. | DW38: 1 ШТ. | DX38: 1 | EE38: 51698028 | EF38: 30 | EG38: Строительные работы | EH38: 0 | EJ38: 1 | EK38: 1987 | EL38: ТСН-2001.3-4. 4-21-1...4-21-4 (доп. 47) | EM38: ТСН-2001.3-4-2 | EO38: Поправка: О.П. п.3.4.30.г | EQ38: 131072 | ER38: 1210.21 | ES38: 0 | ET38: 1202.64 | EU38: 31.8 | EV38: 7.57 | EW38: 0.6 | EX38: 0 | EY38: 0 | FQ38: 0 | FR38: 0 | FS38: 0 | FX38: 149 | FY38: 158 | GD38: 0 | GF38: 1434979114 | GG38: 2 | GH38: 1 | GI38: 2 | GJ38: 0 | GK38: =ROUND(R38*(R12)/100,2) -> 1930.35 | GL38: =ROUND(IF(AND(BH38=3,BI38=3,FS38<>0),P38,0),2) -> 0 | GM38: =ROUND(O38+X38+Y38+GK38,2)+GX38 -> 15359.4 | GN38: =IF(OR(BI38=0,BI38=1),GM38-GX38,0) -> 15359.4 | GO38: =IF(BI38=2,GM38-GX38,0) -> 0 | GP38: =IF(BI38=4,GM38-GX38,0) -> 0 | GR38: 0 | GS38: 3 | GT38: 0 | GV38: =ROUND((GT38),6) -> 0 | GW38: 1 | GX38: =ROUND(HC38*I38,2) -> 0 | HA38: 0 | HB38: 0 | HC38: =GV38*GW38 -> 0 | HS38: 0 | IK38: 0
A39: 17 | B39: 1 | C39: =ROW(SmtRes!A20) -> 20 | D39: =ROW(EtalonRes!A21) -> 21 | E39: 6 | F39: 3.4-21-4 | G39: Демонтаж установки горизонтального направленного бурения с тяговым усилием до 500 кН | H39: 1 ШТ. | I39: 2 | J39: 0 | K39: 2 | O39: =ROUND(CP39,2) -> 10111.92 | P39: =ROUND((ROUND((AC39*AW39*I39),2)*BC39),2) -> 0 | Q39: =(ROUND((ROUND((((ET39*1.05))*AV39*I39),2)*BB39),2)+ROUND((ROUND(((AE39-((EU39*1.05)))*AV39*I39),2)*BS39),2)) -> 9863.1 | R39: =ROUND((ROUND((AE39*AV39*I39),2)*BS39),2) -> 767.85 | S39: =ROUND((ROUND((AF39*AV39*I39),2)*BA39),2) -> 248.82 | T39: =ROUND(CU39*I39,2) -> 0 | U39: =CV39*I39 -> 0.571662 | V39: =CW39*I39 -> 0 | W39: =ROUND(CX39*I39,2) -> 0 | X39: =ROUND(CY39,2) -> 296.1 | Y39: =ROUND(CZ39,2) -> 139.34 | AA39: 57737055 | AB39: =ROUND((AC39+AD39+AF39),6) -> 506.667 | AC39: =ROUND((ES39),6) -> 0 | AD39: =ROUND(((((ET39*1.05))-((EU39*1.05)))+AE39),6) -> 503.223 | AE39: =ROUND(((EU39*1.05)),6) -> 10.626 | AF39: =ROUND(((EV39*1.05)),6) -> 3.444 | AG39: =ROUND((AP39),6) -> 0 | AH39: =((EW39*1.05)) -> 0.273 | AI39: =((EX39*1.05)) -> 0 | AJ39: =(AS39) -> 0 | AK39: 482.54 | AL39: 0 | AM39: 479.26 | AN39: 10.12 | AO39: 3.28 | AP39: 0 | AQ39: 0.26 | AR39: 0 | AS39: 0 | AT39: 119 | AU39: 56 | AV39: 1.047 | AW39: 1.079 | AZ39: 1 | BA39: 34.51 | BB39: 9.36 | BC39: 1 | BH39: 0 | BI39: 1 | BJ39: ТСН-2001.3 Доп. 68, Сб. 4, т. 21, поз. 4 | BM39: 1987 | BN39: 0 | BO39: 3.4-21-4 | BP39: 1 | BQ39: 30 | BR39: 0 | BS39: 34.51 | BT39: 1 | BU39: 1 | BV39: 1 | BW39: 1 | BX39: 1 | BZ39: 119 | CA39: 56 | CE39: 30 | CF39: 0 | CG39: 0 | CM39: 0 | CN39: Поправка: О.П. п.3.4.30.г Наименование: В отношении объектов, реализуемых с привлечением средств бюджета города Москвы, затраты, учитывающие усложненные условия производства работ (стесненность, сложность складирования и транспортной логистики, наличие в зоне производства работ действующего технологического оборудования или движения технологического транспорта и т.п.), определяются заказчиком в задании на проектирование при составлении локальных сметных расчетов (смет): для объектов города Москвы, расположенных за пределами Московской кольцевой автомобильной дороги | CO39: 0 | CP39: =(P39+Q39+S39) -> 10111.92 | CQ39: =ROUND((ROUND((AC39*AW39*1),2)*BC39),2) -> 0 | CR39: =(ROUND((ROUND((((ET39*1.05))*AV39*1),2)*BB39),2)+ROUND((ROUND(((AE39-((EU39*1.05)))*AV39*1),2)*BS39),2)) -> 4931.5 | CS39: =ROUND((ROUND((AE39*AV39*1),2)*BS39),2) -> 384.1 | CT39: =ROUND((ROUND((AF39*AV39*1),2)*BA39),2) -> 124.58 | CU39: =AG39 -> 0 | CV39: =(AH39*AV39) -> 0.285831 | CW39: =AI39 -> 0 | CX39: =AJ39 -> 0 | CY39: =S39*(BZ39/100) -> 296.0958 | CZ39: =S39*(CA39/100) -> 139.3392 | DB39: 6 | DE39: *1,05 | DF39: *1,05 | DG39: *1,05 | DI39: *1,05 | DJ39: *1,05 | DN39: 149 | DO39: 158 | DP39: 1.047 | DQ39: 1.079 | DU39: 1013 | DV39: 1 ШТ. | DW39: 1 ШТ. | DX39: 1 | EE39: 51698028 | EF39: 30 | EG39: Строительные работы | EH39: 0 | EJ39: 1 | EK39: 1987 | EL39: ТСН-2001.3-4. 4-21-1...4-21-4 (доп. 47) | EM39: ТСН-2001.3-4-2 | EO39: Поправка: О.П. п.3.4.30.г | EQ39: 131072 | ER39: 482.54 | ES39: 0 | ET39: 479.26 | EU39: 10.12 | EV39: 3.28 | EW39: 0.26 | EX39: 0 | EY39: 0 | FQ39: 0 | FR39: 0 | FS39: 0 | FX39: 149 | FY39: 158 | GD39: 0 | GF39: 2045322088 | GG39: 2 | GH39: 1 | GI39: 2 | GJ39: 0 | GK39: =ROUND(R39*(R12)/100,2) -> 1228.56 | GL39: =ROUND(IF(AND(BH39=3,BI39=3,FS39<>0),P39,0),2) -> 0 | GM39: =ROUND(O39+X39+Y39+GK39,2)+GX39 -> 11775.92 | GN39: =IF(OR(BI39=0,BI39=1),GM39-GX39,0) -> 11775.92 | GO39: =IF(BI39=2,GM39-GX39,0) -> 0 | GP39: =IF(BI39=4,GM39-GX39,0) -> 0 | GR39: 0 | GS39: 3 | GT39: 0 | GV39: =ROUND((GT39),6) -> 0 | GW39: 1 | GX39: =ROUND(HC39*I39,2) -> 0 | HA39: 0 | HB39: 0 | HC39: =GV39*GW39 -> 0 | HS39: 0 | IK39: 0
A40: 17 | B40: 1 | C40: =ROW(SmtRes!A24) -> 24 | D40: =ROW(EtalonRes!A25) -> 25 | E40: 7 | F40: 3.22-73-2 | G40: Сварка полиэтиленовых труб номинальным наружным диаметром 140 мм - 160 мм | H40: 1 стык | I40: =ROUND(55-6,9) -> 49 | J40: 0 | K40: =ROUND(55-6,9) -> 49 | O40: =ROUND(CP40,2) -> 33894.76 | P40: =ROUND((ROUND((AC40*AW40*I40),2)*BC40),2) -> 4706.33 | Q40: =(ROUND((ROUND((((ET40*1.05))*AV40*I40),2)*BB40),2)+ROUND((ROUND(((AE40-((EU40*1.05)))*AV40*I40),2)*BS40),2)) -> 1093.15 | R40: =ROUND((ROUND((AE40*AV40*I40),2)*BS40),2) -> 0 | S40: =ROUND((ROUND((AF40*AV40*I40),2)*BA40),2) -> 28095.28 | T40: =ROUND(CU40*I40,2) -> 0 | U40: =CV40*I40 -> 63.131722 | V40: =CW40*I40 -> 0 | W40: =ROUND(CX40*I40,2) -> 0 | X40: =ROUND(CY40,2) -> 30623.86 | Y40: =ROUND(CZ40,2) -> 15171.45 | AA40: 57737055 | AB40: =ROUND((AC40+AD40+AF40),6) -> 18.844 | AC40: =ROUND((ES40),6) -> 0.91 | AD40: =ROUND(((((ET40*1.05))-((EU40*1.05)))+AE40),6) -> 2.3625 | AE40: =ROUND(((EU40*1.05)),6) -> 0 | AF40: =ROUND(((EV40*1.05)),6) -> 15.5715 | AG40: =ROUND((AP40),6) -> 0 | AH40: =((EW40*1.05)) -> 1.2075 | AI40: =((EX40*1.05)) -> 0 | AJ40: =(AS40) -> 0 | AK40: 17.99 | AL40: 0.91 | AM40: 2.25 | AN40: 0 | AO40: 14.83 | AP40: 0 | AQ40: 1.15 | AR40: 0 | AS40: 0 | AT40: 109 | AU40: 54 | AV40: 1.067 | AW40: 1.003 | AZ40: 1 | BA40: 34.51 | BB40: 8.85 | BC40: 105.24 | BH40: 0 | BI40: 1 | BJ40: ТСН-2001.3 Доп. 68, Сб. 22, т. 73, поз. 2 | BM40: 2167 | BN40: 0 | BO40: 3.22-73-2 | BP40: 1 | BQ40: 30 | BR40: 0 | BS40: 34.51 | BT40: 1 | BU40: 1 | BV40: 1 | BW40: 1 | BX40: 1 | BZ40: 109 | CA40: 54 | CE40: 30 | CF40: 0 | CG40: 0 | CM40: 0 | CN40: Поправка: О.П. п.3.4.30.г Наименование: В отношении объектов, реализуемых с привлечением средств бюджета города Москвы, затраты, учитывающие усложненные условия производства работ (стесненность, сложность складирования и транспортной логистики, наличие в зоне производства работ действующего технологического оборудования или движения технологического транспорта и т.п.), определяются заказчиком в задании на проектирование при составлении локальных сметных расчетов (смет): для объектов города Москвы, расположенных за пределами Московской кольцевой автомобильной дороги | CO40: 0 | CP40: =(P40+Q40+S40) -> 33894.76 | CQ40: =ROUND((ROUND((AC40*AW40*1),2)*BC40),2) -> 95.77 | CR40: =(ROUND((ROUND((((ET40*1.05))*AV40*1),2)*BB40),2)+ROUND((ROUND(((AE40-((EU40*1.05)))*AV40*1),2)*BS40),2)) -> 22.3 | CS40: =ROUND((ROUND((AE40*AV40*1),2)*BS40),2) -> 0 | CT40: =ROUND((ROUND((AF40*AV40*1),2)*BA40),2) -> 573.21 | CU40: =AG40 -> 0 | CV40: =(AH40*AV40) -> 1.2884025 | CW40: =AI40 -> 0 | CX40: =AJ40 -> 0 | CY40: =S40*(BZ40/100) -> 30623.855 | CZ40: =S40*(CA40/100) -> 15171.451 | DB40: 7 | DE40: *1,05 | DF40: *1,05 | DG40: *1,05 | DI40: *1,05 | DJ40: *1,05 | DN40: 133 | DO40: 113 | DP40: 1.067 | DQ40: 1.003 | DU40: 1013 | DV40: 1 стык | DW40: 1 стык | DX40: 1 | EE40: 51698212 | EF40: 30 | EG40: Строительные работы | EH40: 0 | EJ40: 1 | EK40: 2167 | EL40: ТСН-2001.3-22. 22-73-1...22-73-16 (доп. 60) | EM40: ТСН-2001.3-22-9 | EO40: Поправка: О.П. п.3.4.30.г | EQ40: 131072 | ER40: 17.99 | ES40: 0.91 | ET40: 2.25 | EU40: 0 | EV40: 14.83 | EW40: 1.15 | EX40: 0 | EY40: 0 | FQ40: 0 | FR40: 0 | FS40: 0 | FX40: 133 | FY40: 113 | GD40: 0 | GF40: -503870478 | GG40: 2 | GH40: 1 | GI40: 2 | GJ40: 0 | GK40: =ROUND(R40*(R12)/100,2) -> 0 | GL40: =ROUND(IF(AND(BH40=3,BI40=3,FS40<>0),P40,0),2) -> 0 | GM40: =ROUND(O40+X40+Y40+GK40,2)+GX40 -> 79690.07 | GN40: =IF(OR(BI40=0,BI40=1),GM40-GX40,0) -> 79690.07 | GO40: =IF(BI40=2,GM40-GX40,0) -> 0 | GP40: =IF(BI40=4,GM40-GX40,0) -> 0 | GR40: 0 | GS40: 3 | GT40: 0 | GV40: =ROUND((GT40),6) -> 0 | GW40: 1 | GX40: =ROUND(HC40*I40,2) -> 0 | HA40: 0 | HB40: 0 | HC40: =GV40*GW40 -> 0 | HS40: 0 | IK40: 0
A41: 17 | B41: 1 | C41: =ROW(SmtRes!A25) -> 25 | D41: =ROW(EtalonRes!A26) -> 26 | E41: 8 | F41: 4.10-115-29 | G41: Разные работы, герметизация свободного канала кабельной канализации | H41: канал | I41: =ROUND(4,9) -> 4 | J41: 0 | K41: =ROUND(4,9) -> 4 | O41: =ROUND(CP41,2) -> 631.44 | P41: =ROUND((ROUND((AC41*AW41*I41),2)*BC41),2) -> 440.25 | Q41: =(ROUND((ROUND((((ET41*1.05))*AV41*I41),2)*BB41),2)+ROUND((ROUND(((AE41-((EU41*1.05)))*AV41*I41),2)*BS41),2)) -> 0 | R41: =ROUND((ROUND((AE41*AV41*I41),2)*BS41),2) -> 0 | S41: =ROUND((ROUND((AF41*AV41*I41),2)*BA41),2) -> 191.19 | T41: =ROUND(CU41*I41,2) -> 0 | U41: =CV41*I41 -> 0.43974 | V41: =CW41*I41 -> 0 | W41: =ROUND(CX41*I41,2) -> 0 | X41: =ROUND(CY41,2) -> 175.89 | Y41: =ROUND(CZ41,2) -> 82.21 | AA41: 57737055 | AB41: =ROUND((AC41+AD41+AF41),6) -> 12.623 | AC41: =ROUND((ES41),6) -> 11.3 | AD41: =ROUND(((((ET41*1.05))-((EU41*1.05)))+AE41),6) -> 0 | AE41: =ROUND(((EU41*1.05)),6) -> 0 | AF41: =ROUND(((EV41*1.05)),6) -> 1.323 | AG41: =ROUND((AP41),6) -> 0 | AH41: =((EW41*1.05)) -> 0.105 | AI41: =((EX41*1.05)) -> 0 | AJ41: =(AS41) -> 0 | AK41: 12.56 | AL41: 11.3 | AM41: 0 | AN41: 0 | AO41: 1.26 | AP41: 0 | AQ41: 0.1 | AR41: 0 | AS41: 0 | AT41: 92 | AU41: 43 | AV41: 1.047 | AW41: 1 | AZ41: 1 | BA41: 34.51 | BB41: 1 | BC41: 9.74 | BH41: 0 | BI41: 2 | BJ41: ТСН-2001.4. Доп. 1-42. Сб. 10, т. 115, поз. 29 | BM41: 338 | BN41: 0 | BO41: 4.10-115-29 | BP41: 1 | BQ41: 40 | BR41: 0 | BS41: 34.51 | BT41: 1 | BU41: 1 | BV41: 1 | BW41: 1 | BX41: 1 | BZ41: 92 | CA41: 43 | CE41: 30 | CF41: 0 | CG41: 0 | CM41: 0 | CN41: Поправка: О.П. п.3.4.30.г Наименование: В отношении объектов, реализуемых с привлечением средств бюджета города Москвы, затраты, учитывающие усложненные условия производства работ (стесненность, сложность складирования и транспортной логистики, наличие в зоне производства работ действующего технологического оборудования или движения технологического транспорта и т.п.), определяются заказчиком в задании на проектирование при составлении локальных сметных расчетов (смет): для объектов города Москвы, расположенных за пределами Московской кольцевой автомобильной дороги | CO41: 0 | CP41: =(P41+Q41+S41) -> 631.44 | CQ41: =ROUND((ROUND((AC41*AW41*1),2)*BC41),2) -> 110.06 | CR41: =(ROUND((ROUND((((ET41*1.05))*AV41*1),2)*BB41),2)+ROUND((ROUND(((AE41-((EU41*1.05)))*AV41*1),2)*BS41),2)) -> 0 | CS41: =ROUND((ROUND((AE41*AV41*1),2)*BS41),2) -> 0 | CT41: =ROUND((ROUND((AF41*AV41*1),2)*BA41),2) -> 47.97 | CU41: =AG41 -> 0 | CV41: =(AH41*AV41) -> 0.109935 | CW41: =AI41 -> 0 | CX41: =AJ41 -> 0 | CY41: =S41*(BZ41/100) -> 175.8948 | CZ41: =S41*(CA41/100) -> 82.2117 | DB41: 8 | DE41: *1,05 | DF41: *1,05 | DG41: *1,05 | DI41: *1,05 | DJ41: *1,05 | DN41: 112 | DO41: 70 | DP41: 1.047 | DQ41: 1 | DU41: 1013 | DV41: канал | DW41: канал | DX41: 1 | EE41: 51696377 | EF41: 40 | EG41: Монтаж оборудования | EH41: 0 | EJ41: 2 | EK41: 338 | EL41: ТСН-2001.4-10. 10-115-26...10-115-33 | EM41: ТСН-2001.4-10-3 | EO41: Поправка: О.П. п.3.4.30.г | EQ41: 131072 | ER41: 12.56 | ES41: 11.3 | ET41: 0 | EU41: 0 | EV41: 1.26 | EW41: 0.1 | EX41: 0 | EY41: 0 | FQ41: 0 | FR41: 0 | FS41: 0 | FX41: 112 | FY41: 70 | GD41: 0 | GF41: -253925426 | GG41: 2 | GH41: 1 | GI41: 2 | GJ41: 0 | GK41: =ROUND(R41*(R12)/100,2) -> 0 | GL41: =ROUND(IF(AND(BH41=3,BI41=3,FS41<>0),P41,0),2) -> 0 | GM41: =ROUND(O41+X41+Y41+GK41,2)+GX41 -> 889.54 | GN41: =IF(OR(BI41=0,BI41=1),GM41-GX41,0) -> 0 | GO41: =IF(BI41=2,GM41-GX41,0) -> 889.54 | GP41: =IF(BI41=4,GM41-GX41,0) -> 0 | GR41: 0 | GS41: 3 | GT41: 0 | GV41: =ROUND((GT41),6) -> 0 | GW41: 1 | GX41: =ROUND(HC41*I41,2) -> 0 | HA41: 0 | HB41: 0 | HC41: =GV41*GW41 -> 0 | HS41: 0 | IK41: 0
A42: 17 | B42: 1 | E42: 9 | F42: 1.12-3-62 | G42: Заглушки (пробки) полиэтиленовые для каналов кабельной канализации из хризотилцементных труб внутренним диаметром 150 мм | H42: шт. | I42: =ROUND(4,9) -> 4 | J42: 0 | K42: =ROUND(4,9) -> 4 | O42: =ROUND(CP42,2) -> 217.31 | P42: =ROUND((ROUND((AC42*AW42*I42),2)*BC42),2) -> 217.31 | Q42: =(ROUND((ROUND((((ET42*1.05))*AV42*I42),2)*BB42),2)+ROUND((ROUND(((AE42-((EU42*1.05)))*AV42*I42),2)*BS42),2)) -> 0 | R42: =ROUND((ROUND((AE42*AV42*I42),2)*BS42),2) -> 0 | S42: =ROUND((ROUND((AF42*AV42*I42),2)*BA42),2) -> 0 | T42: =ROUND(CU42*I42,2) -> 0 | U42: =CV42*I42 -> 0 | V42: =CW42*I42 -> 0 | W42: =ROUND(CX42*I42,2) -> 0 | X42: =ROUND(CY42,2) -> 0 | Y42: =ROUND(CZ42,2) -> 0 | AA42: 57737055 | AB42: =ROUND((AC42+AD42+AF42),6) -> 3.9 | AC42: =ROUND((ES42),6) -> 3.9 | AD42: =ROUND(((((ET42*1.05))-((EU42*1.05)))+AE42),6) -> 0 | AE42: =ROUND(((EU42*1.05)),6) -> 0 | AF42: =ROUND(((EV42*1.05)),6) -> 0 | AG42: =ROUND((AP42),6) -> 0 | AH42: =((EW42*1.05)) -> 0 | AI42: =((EX42*1.05)) -> 0 | AJ42: =(AS42) -> 0 | AK42: 3.9 | AL42: 3.9 | AM42: 0 | AN42: 0 | AO42: 0 | AP42: 0 | AQ42: 0 | AR42: 0 | AS42: 0 | AT42: 0 | AU42: 0 | AV42: 1 | AW42: 1 | AZ42: 1 | BA42: 1 | BB42: 1 | BC42: 13.93 | BH42: 3 | BI42: 1 | BJ42: ТСН-2001.1 Доп. 70, Р. 12, о. 3, поз. 62 | BM42: 1617 | BN42: 0 | BO42: 1.12-3-62 | BP42: 1 | BQ42: 200 | BR42: 0 | BS42: 1 | BT42: 1 | BU42: 1 | BV42: 1 | BW42: 1 | BX42: 1 | BZ42: 0 | CA42: 0 | CE42: 30 | CF42: 0 | CG42: 0 | CM42: 0 | CN42: Поправка: О.П. п.3.4.30.г Наименование: В отношении объектов, реализуемых с привлечением средств бюджета города Москвы, затраты, учитывающие усложненные условия производства работ (стесненность, сложность складирования и транспортной логистики, наличие в зоне производства работ действующего технологического оборудования или движения технологического транспорта и т.п.), определяются заказчиком в задании на проектирование при составлении локальных сметных расчетов (смет): для объектов города Москвы, расположенных за пределами Московской кольцевой автомобильной дороги | CO42: 0 | CP42: =(P42+Q42+S42) -> 217.31 | CQ42: =ROUND((ROUND((AC42*AW42*1),2)*BC42),2) -> 54.33 | CR42: =(ROUND((ROUND((((ET42*1.05))*AV42*1),2)*BB42),2)+ROUND((ROUND(((AE42-((EU42*1.05)))*AV42*1),2)*BS42),2)) -> 0 | CS42: =ROUND((ROUND((AE42*AV42*1),2)*BS42),2) -> 0 | CT42: =ROUND((ROUND((AF42*AV42*1),2)*BA42),2) -> 0 | CU42: =AG42 -> 0 | CV42: =(AH42*AV42) -> 0 | CW42: =AI42 -> 0 | CX42: =AJ42 -> 0 | CY42: =S42*(BZ42/100) -> 0 | CZ42: =S42*(CA42/100) -> 0 | DB42: 9 | DE42: *1,05 | DF42: *1,05 | DG42: *1,05 | DI42: *1,05 | DJ42: *1,05 | DN42: 0 | DO42: 0 | DP42: 1 | DQ42: 1 | DU42: 1010 | DV42: шт. | DW42: шт. | DX42: 1 | EE42: 51697656 | EF42: 200 | EG42: Материалы строительные | EH42: 0 | EJ42: 1 | EK42: 1617 | EL42: ТСН-2001.1 Материалы строительные | EM42: ТСН-2001.1-1 | EO42: Поправка: О.П. п.3.4.30.г | EQ42: 131072 | ER42: 3.9 | ES42: 3.9 | ET42: 0 | EU42: 0 | EV42: 0 | EW42: 0 | EX42: 0 | EY42: 0 | FQ42: 0 | FR42: 0 | FS42: 0 | FX42: 0 | FY42: 0 | GD42: 0 | GF42: 1553567620 | GG42: 2 | GH42: 1 | GI42: 2 | GJ42: 0 | GK42: =ROUND(R42*(R12)/100,2) -> 0 | GL42: =ROUND(IF(AND(BH42=3,BI42=3,FS42<>0),P42,0),2) -> 0 | GM42: =ROUND(O42+X42+Y42+GK42,2)+GX42 -> 217.31 | GN42: =IF(OR(BI42=0,BI42=1),GM42-GX42,0) -> 217.31 | GO42: =IF(BI42=2,GM42-GX42,0) -> 0 | GP42: =IF(BI42=4,GM42-GX42,0) -> 0 | GR42: 0 | GS42: 3 | GT42: 0 | GV42: =ROUND((GT42),6) -> 0 | GW42: 1 | GX42: =ROUND(HC42*I42,2) -> 0 | HA42: 0 | HB42: 0 | HC42: =GV42*GW42 -> 0 | HS42: 0 | IK42: 0
A44: 51 | B44: =B28 -> 1 | C44: =A28 -> 5 | D44: =ROW(A28) -> 28 | F44: =IF(F28<>"",F28,"") -> Новый подраздел | G44: =IF(G28<>"",G28,"") -> Строительные работы | H44: 0 | O44: =ROUND(AB44,2) -> 6530938.2 | P44: =ROUND(AC44,2) -> 2740359.9 | Q44: =ROUND(AD44,2) -> 3552687.1 | R44: =ROUND(AE44,2) -> 406750.74 | S44: =ROUND(AF44,2) -> 237891.23 | T44: =ROUND(AG44,2) -> 0 | U44: =AH44 -> 501.77593 | V44: =AI44 -> 0 | W44: =ROUND(AJ44,2) -> 0 | X44: =ROUND(AK44,2) -> 278973.26 | Y44: =ROUND(AL44,2) -> 132043.5 | AB44: =ROUND(SUMIF(AA32:AA42,"=57737055",O32:O42),2) -> 6530938.2 | AC44: =ROUND(SUMIF(AA32:AA42,"=57737055",P32:P42),2) -> 2740359.9 | AD44: =ROUND(SUMIF(AA32:AA42,"=57737055",Q32:Q42),2) -> 3552687.1 | AE44: =ROUND(SUMIF(AA32:AA42,"=57737055",R32:R42),2) -> 406750.74 | AF44: =ROUND(SUMIF(AA32:AA42,"=57737055",S32:S42),2) -> 237891.23 | AG44: =ROUND(SUMIF(AA32:AA42,"=57737055",T32:T42),2) -> 0 | AH44: =SUMIF(AA32:AA42,"=57737055",U32:U42) -> 501.77593 | AI44: =SUMIF(AA32:AA42,"=57737055",V32:V42) -> 0 | AJ44: =ROUND(SUMIF(AA32:AA42,"=57737055",W32:W42),2) -> 0 | AK44: =ROUND(SUMIF(AA32:AA42,"=57737055",X32:X42),2) -> 278973.26 | AL44: =ROUND(SUMIF(AA32:AA42,"=57737055",Y32:Y42),2) -> 132043.5 | AO44: =ROUND(BX44,2) -> 0 | AP44: =ROUND(BY44,2) -> 0 | AQ44: =ROUND(BZ44,2) -> 0 | AR44: =ROUND(CA44,2) -> 7592756.1 | AS44: =ROUND(CB44,2) -> 7591866.6 | AT44: =ROUND(CC44,2) -> 889.54 | AU44: =ROUND(CD44,2) -> 0 | AV44: =ROUND(CE44,2) -> 2740359.9 | ... BD44: =ROUND(CM44,2) -> 0 | BX44: =ROUND(SUMIF(AA32:AA42,"=57737055",FQ32:FQ42),2) -> 0 | BY44: =ROUND(SUMIF(AA32:AA42,"=57737055",FR32:FR42),2) -> 0 | BZ44: =ROUND(SUMIF(AA32:AA42,"=57737055",GL32:GL42),2) -> 0 | CA44: =ROUND(SUMIF(AA32:AA42,"=57737055",GM32:GM42),2) -> 7592756.1 | CB44: =ROUND(SUMIF(AA32:AA42,"=57737055",GN32:GN42),2) -> 7591866.6 | CC44: =ROUND(SUMIF(AA32:AA42,"=57737055",GO32:GO42),2) -> 889.54 | CD44: =ROUND(SUMIF(AA32:AA42,"=57737055",GP32:GP42),2) -> 0 | CE44: =AC44-BX44 -> 2740359.9 | CF44: =AC44-BY44 -> 2740359.9 | CG44: =BX44-BZ44 -> 0 | CH44: =AC44-BX44-BY44+BZ44 -> 2740359.9 | CI44: =BY44-BZ44 -> 0 | CJ44: =ROUND(SUMIF(AA32:AA42,"=57737055",GX32:GX42),2) -> 0 | CK44: =ROUND(SUMIF(AA32:AA42,"=57737055",GY32:GY42),2) -> 0 | CL44: =ROUND(SUMIF(AA32:AA42,"=57737055",GZ32:GZ42),2) -> 0 | CM44: =ROUND(SUMIF(AA32:AA42,"=57737055",HD32:HD42),2) -> 0 | GX44: 0
A46: 50 | B46: 0 | C46: 0 | D46: 1 | E46: 201 | F46: =ROUND(Source!O44,O46) -> 6530938.2 | G46: ПЗ | H46: Прямые затраты | K46: 201 | L46: 1 | M46: 3 | O46: 2 | W46: 6530938.2 | X46: 1 | Y46: 6530938.2
A47: 50 | B47: 0 | C47: 0 | D47: 1 | E47: 202 | F47: =ROUND(Source!P44,O47) -> 2740359.9 | G47: СтМатОб | H47: Стоимость материальных ресурсов (всего) | K47: 202 | L47: 2 | M47: 3 | O47: 2 | W47: 2740359.9 | X47: 1 | Y47: 2740359.9
A48: 50 | B48: 0 | C48: 0 | D48: 1 | E48: 222 | F48: =ROUND(Source!AO44,O48) -> 0 | G48: СтМатОбЗак | H48: Стоимость материалов и оборудования заказчика | K48: 222 | L48: 3 | M48: 3 | O48: 2 | W48: 0 | X48: 1 | Y48: 0
A49: 50 | B49: 0 | C49: 0 | D49: 1 | E49: 225 | F49: =ROUND(Source!AV44,O49) -> 2740359.9 | G49: СтМатОбПод | H49: Стоимость материалов и оборудования подрядчика | K49: 225 | L49: 4 | M49: 3 | O49: 2 | W49: 2740359.9 | X49: 1 | Y49: 2740359.9
A50: 50 | B50: 0 | C50: 0 | D50: 1 | E50: 226 | F50: =ROUND(Source!AW44,O50) -> 2740359.9 | G50: СтМат | H50: Стоимость материалов (всего) | K50: 226 | L50: 5 | M50: 3 | O50: 2 | W50: 2740359.9 | X50: 1 | Y50: 2740359.9
A51: 50 | B51: 0 | C51: 0 | D51: 1 | E51: 227 | F51: =ROUND(Source!AX44,O51) -> 0 | G51: СтМатЗак | H51: Стоимость материалов заказчика | K51: 227 | L51: 6 | M51: 3 | O51: 2 | W51: 0 | X51: 1 | Y51: 0
A52: 50 | B52: 0 | C52: 0 | D52: 1 | E52: 228 | F52: =ROUND(Source!AY44,O52) -> 2740359.9 | G52: СтМатПод | H52: Стоимость материалов подрядчика | K52: 228 | L52: 7 | M52: 3 | O52: 2 | W52: 2740359.9 | X52: 1 | Y52: 2740359.9
A53: 50 | B53: 0 | C53: 0 | D53: 1 | E53: 216 | F53: =ROUND(Source!AP44,O53) -> 0 | G53: Оборуд | H53: Стоимость оборудования (всего) | K53: 216 | L53: 8 | M53: 3 | O53: 2 | W53: 0 | X53: 1 | Y53: 0
A54: 50 | B54: 0 | C54: 0 | D54: 1 | E54: 223 | F54: =ROUND(Source!AQ44,O54) -> 0 | G54: ОборудЗак | H54: Стоимость оборудования заказчика | K54: 223 | L54: 9 | M54: 3 | O54: 2 | W54: 0 | X54: 1 | Y54: 0
A55: 50 | B55: 0 | C55: 0 | D55: 1 | E55: 229 | F55: =ROUND(Source!AZ44,O55) -> 0 | G55: ОборудПод | H55: Стоимость оборудования подрядчика | K55: 229 | L55: 10 | M55: 3 | O55: 2 | W55: 0 | X55: 1 | Y55: 0
A56: 50 | B56: 0 | C56: 0 | D56: 1 | E56: 203 | F56: =ROUND(Source!Q44,O56) -> 3552687.1 | G56: ЭММ | H56: Эксплуатация машин | K56: 203 | L56: 11 | M56: 3 | O56: 2 | W56: 3552687.1 | X56: 1 | Y56: 3552687.1
A57: 50 | B57: 0 | C57: 0 | D57: 1 | E57: 231 | F57: =ROUND(Source!BB44,O57) -> 0 | G57: ЭММсНРиСП | H57: Эксплуатация машин по ТСН-2001.16 | K57: 231 | L57: 12 | M57: 3 | O57: 2 | W57: 0 | X57: 1 | Y57: 0
A58: 50 | B58: 0 | C58: 0 | D58: 1 | E58: 204 | F58: =ROUND(Source!R44,O58) -> 406750.74 | G58: ЗПМ | H58: ЗП машинистов | K58: 204 | L58: 13 | M58: 3 | O58: 2 | W58: 406750.74 | X58: 1 | Y58: 406750.74
A59: 50 | B59: 0 | C59: 0 | D59: 1 | E59: 205 | F59: =ROUND(Source!S44,O59) -> 237891.23 | G59: ОЗП | H59: Основная ЗП рабочих | K59: 205 | L59: 14 | M59: 3 | O59: 2 | W59: 237891.23 | X59: 1 | Y59: 237891.23
A60: 50 | B60: 0 | C60: 0 | D60: 1 | E60: 232 | F60: =ROUND(Source!BC44,O60) -> 0 | G60: ОЗПсНРиСП | H60: Основная ЗП рабочих по ТСН-2001.16 | K60: 232 | L60: 15 | M60: 3 | O60: 2 | W60: 0 | X60: 1 | Y60: 0
A61: 50 | B61: 0 | C61: 0 | D61: 1 | E61: 214 | F61: =ROUND(Source!AS44,O61) -> 7591866.6 | G61: Строит | H61: Строительные работы с НР и СП | K61: 214 | L61: 16 | M61: 3 | O61: 2 | W61: 7591866.6 | X61: 1 | Y61: 7591866.6
A62: 50 | B62: 0 | C62: 0 | D62: 1 | E62: 215 | F62: =ROUND(Source!AT44,O62) -> 889.54 | G62: Монтаж | H62: Монтажные работы с НР и СП | K62: 215 | L62: 17 | M62: 3 | O62: 2 | W62: 889.54 | X62: 1 | Y62: 889.54
A63: 50 | B63: 0 | C63: 0 | D63: 1 | E63: 217 | F63: =ROUND(Source!AU44,O63) -> 0 | G63: Прочие | H63: Прочие работы с НР и СП | K63: 217 | L63: 18 | M63: 3 | O63: 2 | W63: 0 | X63: 1 | Y63: 0
...

Sheet SourceObSm
A1: 0 | B1: Smeta.RU (495) 974-1589 | D1: _OBSM_ | F1: 0 | G1: 0 | H1: 0 | I1: Smeta.RU | K1: 1 | L1: 75112 | M1: 10 | N1: 11 | O1: 15 | P1: 0 | Q1: 1
A12: 1 | B12: 52 | C12: 1 | E12: 0 | F12: 02-01-08 Закрытый переход_(2 этап) | G12: 02-01-08 Закрытый переход | I12: 0 | K12: 0 | L12: 0 | M12: 4098 | O12: 0 | P12: 0 | Q12: 0 | R12: 160 | T12: 1 | V12: 0 | BB12: 0 | BH12: Сметные нормы списания | BI12: Коды ОКП для ТСН-2001 МГЭ (История развития) | BJ12: 1 | BK12: 1 | BL12: 0 | BM12: 0 | BN12: 1 | BO12: 0 | BP12: 6 | BQ12: 2 | BR12: 1 | BS12: 1 | BT12: 0 | BU12: 0 | BV12: 0 | BW12: 0 | BX12: 0 | BZ12: Типовой расчет для ТСН-2001 МГЭ, Новая методика с выпуска доп. 43 (Строительство), Доп 73 | CA12: История развития для ТСН-2001 (МГЭ) 73 доп от 17.07.2024 | CB12: История развития для ТСН-2001 (МГЭ) 73 доп от 17.07.2024 | CC12: История развития для ТСН-2001 (МГЭ) 73 доп от 17.07.2024 | CD12: История развития для ТСН-2001 (МГЭ) 73 доп от 17.07.2024 | CE12: Поправки для ТСН-2001 от 16.04.2024 г. доп.72 | CF12: 0 | CG12: 0 | CH12: 8 | CK12: 79 | CQ12: Территориальные сметные нормативы для Москвы (ТСН-2001) | CR12: ТЕР | CS12: 41660 | CT12: 1 | CU12: 73 | CY12: 0 | EC12: 0
A14: 22 | B14: 1 | C14: 0 | D14: 57737055 | E14: 0 | F14: 2 | G14: 1
A16: 3 | B16: 1 | C16: Новая локальная смета | D16: Закрытые переходы | E16: =ROUND((Source!F161)/1000,2) -> 7591.87 | F16: =ROUND((Source!F162)/1000,2) -> 1151.07 | G16: =ROUND((Source!F153)/1000,2) -> 0 | H16: =ROUND((Source!F163)/1000+(Source!F164)/1000,2) -> 0 | I16: =E16+F16+G16+H16 -> 8742.94 | J16: =ROUND((Source!F159+Source!F158)/1000,2) -> 753.82 | K16: 11159.58 | L16: 0 | M16: 0 | N16: =I16+L16+M16 -> 8742.94 | AI16: 0 | AJ16: -1 | AN16: 0 | AT16: 7532850.3 | AU16: 3626729 | AV16: 0 | AW16: 0 | AX16: 0 | AY16: 3562517 | AZ16: 410220.03 | BA16: 343604.34 | BB16: 7591866.6 | BC16: 1151065.2 | BD16: 0 | BE16: 0 | BF16: 748.80028 | BG16: 0 | BH16: 0 | BI16: 376229.32 | BJ16: 177500.14 | BK16: 8742931.8
A18: 51 | E18: 7591.87 | F18: 1151.07 | G18: 0 | H18: 0 | I18: 8742.94 | J18: 753.82 | K18: 11159.58 | L18: 0 | M18: 0 | N18: 8742.94
A20: 50 | B20: 0 | C20: 0 | D20: 1 | E20: 201 | F20: 7532850.3 | G20: ПЗ | H20: Прямые затраты | K20: 201 | L20: 1 | M20: 3 | O20: 2
A21: 50 | B21: 0 | C21: 0 | D21: 1 | E21: 202 | F21: 3626729 | G21: СтМатОб | H21: Стоимость материальных ресурсов (всего) | K21: 202 | L21: 2 | M21: 3 | O21: 2
A22: 50 | B22: 0 | C22: 0 | D22: 1 | E22: 222 | F22: 0 | G22: СтМатОбЗак | H22: Стоимость материалов и оборудования заказчика | K22: 222 | L22: 3 | M22: 3 | O22: 2
A23: 50 | B23: 0 | C23: 0 | D23: 1 | E23: 225 | F23: 3626729 | G23: СтМатОбПод | H23: Стоимость материалов и оборудования подрядчика | K23: 225 | L23: 4 | M23: 3 | O23: 2
A24: 50 | B24: 0 | C24: 0 | D24: 1 | E24: 226 | F24: 3626729 | G24: СтМат | H24: Стоимость материалов (всего) | K24: 226 | L24: 5 | M24: 3 | O24: 2
A25: 50 | B25: 0 | C25: 0 | D25: 1 | E25: 227 | F25: 0 | G25: СтМатЗак | H25: Стоимость материалов заказчика | K25: 227 | L25: 6 | M25: 3 | O25: 2
A26: 50 | B26: 0 | C26: 0 | D26: 1 | E26: 228 | F26: 3626729 | G26: СтМатПод | H26: Стоимость материалов подрядчика | K26: 228 | L26: 7 | M26: 3 | O26: 2
A27: 50 | B27: 0 | C27: 0 | D27: 1 | E27: 216 | F27: 0 | G27: Оборуд | H27: Стоимость оборудования (всего) | K27: 216 | L27: 8 | M27: 3 | O27: 2
A28: 50 | B28: 0 | C28: 0 | D28: 1 | E28: 223 | F28: 0 | G28: ОборудЗак | H28: Стоимость оборудования заказчика | K28: 223 | L28: 9 | M28: 3 | O28: 2
A29: 50 | B29: 0 | C29: 0 | D29: 1 | E29: 229 | F29: 0 | G29: ОборудПод | H29: Стоимость оборудования подрядчика | K29: 229 | L29: 10 | M29: 3 | O29: 2
