Workbook

Sheet 02-01-09
A1: =Source!B1 -> Smeta.RU (495) 974-1589
J2: Форма № 4б
A3: Строительство ТП-10/0,4кВ с тр-ми 2х400кВА, 4КЛ-10кВ от ТП-10/0,4кВ луч А,Б до КЛ-10кВ направлением ТП-10/0,4кВ № № 21782 - ТП-10/0,4кВ № 24478 луч А,Б, 8КЛ-0,4кВ от ТП-10/0,4кВ до ВРЩ-0,4кВ №1-3, в т.ч. ПИР: г.Москва, ул.Феодосийская, з/у 7
A4: (наименование стройки и/или объекта)
A6: ЛОКАЛЬНАЯ СМЕТА № 02-01-09
A8: =IF(Source!G20<>"Новая локальная смета", Source!G20, "") -> Система телемеханики с включением в АИИС КУЭ в ТП
A9: (наименование работ и затрат)
A11: Основание: чертежи №290729/ПС-22-ТП-ТМ
I13: В базисном уровне цен | J13: В текущем уровне цен
E14: Сметная стоимость | I14: =I15+I16+I17+I18 -> 20.19 | J14: =J15+J16+J17+J18 -> 144.24 | K14: тыс.руб.
E15: Строительные работы | I15: =ROUND(SUM(X28:X56)/1000, 2) -> 0 | J15: =ROUND((Source!F113)/1000, 2) -> 0 | K15: тыс.руб.
E16: Работы по монтажу оборудования | I16: =ROUND(SUM(Y28:Y56)/1000, 2) -> 0.04 | J16: =ROUND((Source!F114)/1000, 2) -> 0.98 | K16: тыс.руб.
E17: Оборудование | I17: =ROUND(SUM(Z28:Z56)/1000, 2) -> 20.15 | J17: =ROUND((Source!F105)/1000, 2) -> 143.26 | K17: тыс.руб.
E18: Прочие работы и затраты | I18: =ROUND(SUM(AA28:AA56)/1000, 2) -> 0 | J18: =ROUND((Source!F115+Source!F116)/1000, 2) -> 0 | K18: тыс.руб.
E19: Средства на оплату труда | I19: =ROUND(SUM(W28:W56)/1000, 2) -> 0.01 | J19: =(Source!F111+ Source!F110)/1000 -> 0.41863 | K19: тыс.руб.
E20: Затраты труда | I20: =SUM(AB28:AB56) -> 1.07841 | K20: чел.-ч.
E21: Кроме того:
E22: Возврат материалов | I22: =ROUND(SUM(AE28:AE56)/1000, 2) -> 0 | J22: =SUM(AF28:AF56)/1000 -> 0 | K22: тыс.руб.
A24: Составлен(а) по ТСН-2001 с учетом Дополнения №: 73
A25: № и период сборника коэффициентов (индексов) пересчета: ТСН-2001-МГЭ №212 июль 2024 года
A26: № п/п | B26: Шифр расценки и коды ресурсов | C26: Наименование работ и затрат | D26: Ед. изм. | E26: Кол-во единиц | F26: Цена на ед. изм., руб. | G26: Попра- вочные коэффи- циенты | H26: Коэффи- циенты зимних удорожа- ний | I26: Всего затрат в базисном уровне цен, руб. | J26: Коэффи- циенты (индек- сы) пере- счета, нормы НР и СП | K26: ВСЕГО затрат в текущем уровне цен, руб.
A27: 1 | B27: 2 | C27: 3 | D27: 4 | E27: 5 | F27: 6 | G27: 7 | H27: 8 | I27: 9 | J27: 10 | K27: 11
A29: =CONCATENATE("Раздел: ",IF(Source!G24<>"Новый раздел", Source!G24, "")) -> Раздел: Монтажные работы
A30: 1 | B30: =Source!F28 -> 4.11-12-1 | C30: Установка съемных и выдвижных блоков (модулей, ячеек, ТЭЗ) массой до 5 кг (Оборудование ИБ) | D30: =Source!H28 -> 1 ШТ. | E30: =Source!I28 -> 1 | Q30: =ROUND((Source!DN28/100)*ROUND((ROUND((Source!AF28*Source!AV28*Source!I28),2)),2), 2) -> 13.66 | R30: =Source!X28 -> 382.63 | S30: =ROUND((Source!DO28/100)*ROUND((ROUND((Source!AF28*Source!AV28*Source!I28),2)),2), 2) -> 8.54 | T30: =Source!Y28 -> 170.52 | U30: =ROUND((175/100)*ROUND((ROUND((Source!AE28*Source!AV28*Source!I28),2)),2), 2) -> 0.14 | V30: =ROUND((160/100)*ROUND(ROUND((ROUND((Source!AE28*Source!AV28*Source!I28),2)*Source!BS28),2), 2), 2) -> 4.37 | AI30: 0
C31: ЗП | F31: =Source!AO28 -> 11.65 | G31: =Source!DG28 | H31: =Source!AV28 -> 1.047 | I31: =ROUND((ROUND((Source!AF28*Source!AV28*Source!I28),2)),2) -> 12.2 | J31: =IF(Source!BA28<> 0, Source!BA28, 1) -> 34.09 | K31: =Source!S28 -> 415.9 | W31: =I31 -> 12.2
C32: ЭМ | F32: =Source!AM28 -> 0.5 | G32: =Source!DE28 | H32: =Source!AV28 -> 1.047 | I32: =(ROUND((ROUND(((Source!ET28)*Source!AV28*Source!I28),2)),2)+ROUND((ROUND(((Source!AE28-(Source!EU28))*Source!AV28*Source!I28),2)),2)) -> 0.52 | J32: =IF(Source!BB28<> 0, Source!BB28, 1) -> 12.68 | K32: =Source!Q28 -> 6.59
C33: в т.ч. ЗПМ | F33: =Source!AN28 -> 0.08 | G33: =Source!DF28 | H33: =Source!AV28 -> 1.047 | I33: =ROUND((ROUND((Source!AE28*Source!AV28*Source!I28),2)),2) -> 0.08 | J33: =IF(Source!BS28<> 0, Source!BS28, 1) -> 34.09 | K33: =Source!R28 -> 2.73 | W33: =I33 -> 0.08
C34: НР от ЗП | D34: % | E34: =Source!DN28 -> 112 | I34: =SUM(Q30:Q33) -> 13.66 | J34: =Source!BZ28 -> 92 | K34: =SUM(R30:R33) -> 382.63
C35: СП от ЗП | D35: % | E35: =Source!DO28 -> 70 | I35: =SUM(S30:S34) -> 8.54 | J35: =Source!CA28 -> 41 | K35: =SUM(T30:T34) -> 170.52
C36: НР и СП от ЗПМ | D36: % | E36: =175 -> 175 | I36: =SUM(U30:U35) -> 0.14 | J36: =160 -> 160 | K36: =SUM(V30:V35) -> 4.37
C37: ЗТР | D37: чел-ч | E37: =Source!AQ28 -> 1.03 | G37: =Source!DI28 | H37: =Source!AV28 -> 1.047 | I37: =Source!U28 -> 1.07841 | AB37: =I37 -> 1.07841
C38: Всего по позиции: | H38: =I31+I32+I34+I35+I36+0 -> 35.06 | J38: =K31+K32+K34+K35+K36+0 -> 980.01 | O38: =I31+I32+I34+I35+I36+0 -> 35.06 | P38: =K31+K32+K34+K35+K36+0 -> 980.01 | X38: =IF(Source!BI28<=1,I31+I32+I34+I35+I36-0, 0) -> 0 | Y38: =IF(Source!BI28=2,I31+I32+I34+I35+I36-0, 0) -> 35.06 | Z38: =IF(Source!BI28=3,I31+I32+I34+I35+I36-0, 0) -> 0 | AA38: =IF(Source!BI28=4,I31+I32+I34+I35+I36,0) -> 0
A41: =CONCATENATE("Итого по разделу: ",IF(Source!G30<>"Новый раздел", Source!G30, "")) -> Итого по разделу: Монтажные работы | H41: =SUM(O29:O40) -> 35.06 | J41: =SUM(P29:P40) -> 980.01
A42: Итого по ТСН-2001.16 | H42: =SUM(AC29:AC41) -> 0 | J42: =SUM(AD29:AD41) -> 0
A43: Итого возвратных сумм | H43: =SUM(AE29:AE42) -> 0 | J43: =SUM(AF29:AF42) -> 0
A45: =CONCATENATE("Раздел: ",IF(Source!G60<>"Новый раздел", Source!G60, "")) -> Раздел: Оборудование
A46: 2 | B46: =Source!F64 -> КП № 08-5439 от 05.08.2025г. ООО "ИТ Компания Д-Системс" | C46: Программно-технический комплекс телемеханики, автоматики, АСУ ТП диспетчеризации и телекоммуникаций TOPAZ "ПТК информационной безопасности TOPAZ Gateway* 20 149,40 = [137 440,22 / 7,11] + 3% Трансп + 1,2% Заг.скл | D46: =Source!H64 -> шт. | E46: =Source!I64 -> 1 | F46: =Source!AL64 -> 20149.4 | G46: =Source!DD64 | H46: =Source!AW64 -> 1 | I46: =ROUND((ROUND((Source!AC64*Source!AW64*Source!I64),2)),2) -> 20149.4 | J46: =IF(Source!BC64<> 0, Source!BC64, 1) -> 7.11 | K46: =Source!P64 -> 143262.23 | Q46: =ROUND((Source!DN64/100)*ROUND((ROUND((Source!AF64*Source!AV64*Source!I64),2)),2), 2) -> 0 | R46: =Source!X64 -> 0 | S46: =ROUND((Source!DO64/100)*ROUND((ROUND((Source!AF64*Source!AV64*Source!I64),2)),2), 2) -> 0 | T46: =Source!Y64 -> 0 | U46: =ROUND((175/100)*ROUND((ROUND((Source!AE64*Source!AV64*Source!I64),2)),2), 2) -> 0 | V46: =ROUND((160/100)*ROUND(ROUND((ROUND((Source!AE64*Source!AV64*Source!I64),2)*Source!BS64),2), 2), 2) -> 0 | AI46: 5
C47: Всего по позиции: | H47: =I46+0 -> 20149.4 | J47: =K46+0 -> 143262.23 | O47: =I46+0 -> 20149.4 | P47: =K46+0 -> 143262.23 | X47: =IF(Source!BI64<=1,I46-0, 0) -> 0 | Y47: =IF(Source!BI64=2,I46-0, 0) -> 0 | Z47: =IF(Source!BI64=3,I46-0, 0) -> 20149.4 | AA47: =IF(Source!BI64=4,I46,0) -> 0
A50: =CONCATENATE("Итого по разделу: ",IF(Source!G66<>"Новый раздел", Source!G66, "")) -> Итого по разделу: Оборудование | H50: =SUM(O45:O49) -> 20149.4 | J50: =SUM(P45:P49) -> 143262.23
A51: Итого по ТСН-2001.16 | H51: =SUM(AC45:AC50) -> 0 | J51: =SUM(AD45:AD50) -> 0
...

Sheet Source
A1: 0 | B1: Smeta.RU (495) 974-1589 | D1: _PS_ | F1: 0 | G1: 0 | H1: 0 | I1: Smeta.RU | K1: 1 | L1: 73582 | M1: 10 | N1: 11 | O1: 13 | P1: 0 | Q1: 1
A12: 1 | B12: 240 | C12: 0 | D12: =ROW(A202) -> 202 | E12: 0 | F12: 319703/ПС-24-ТП-ТМ | G12: ПНР ТП с ИБ г.Москва, Феодосийская ул., зу 7_3кв24 | I12: 0 | K12: 0 | L12: 0 | M12: 4098 | O12: 0 | P12: 0 | Q12: 0 | R12: 160 | T12: 1 | V12: 0 | BB12: 0 | BH12: Сметные нормы списания | BI12: Коды ОКП для ТСН-2001 МГЭ Дополнение 77 | BJ12: 1 | BK12: 1 | BL12: 0 | BM12: 0 | BN12: 1 | BO12: 0 | BP12: 6 | BQ12: 2 | BR12: 1 | BS12: 1 | BT12: 0 | BU12: 0 | BV12: 0 | BW12: 0 | BX12: 0 | BY12: ТСН-2001 (МГЭ) Доп 77 - Новое строительство | BZ12: Типовой расчет для ТСН-2001 МГЭ, Новая методика с выпуска доп. 43 (Строительство), Доп 77 | CA12: Территориальные сметные нормативы для Москвы ТСН-2001 (МГЭ), дополнение 77 | CB12: Территориальные сметные нормативы для Москвы ТСН-2001 (МГЭ), дополнение 77 | CC12: Территориальные сметные нормативы для Москвы ТСН-2001 (МГЭ), дополнение 77 | CD12: Территориальные сметные нормативы для Москвы ТСН-2001 (МГЭ), дополнение 77 | CE12: Поправки для ТСН-2001 от 30.06.2025 г. доп.77 | CF12: 0 | CG12: 0 | CH12: 8200 | CK12: 77 | CQ12: Территориальные сметные нормативы для Москвы (ТСН-2001) | CR12: ТЕР | CS12: 41660 | CT12: 1 | CU12: 77 | CY12: 0 | EC12: 0
A15: 15 | B15: 1
A18: 52 | B18: =B202 -> 240 | C18: =C202 -> 1 | D18: =D202 -> 12 | E18: =E202 -> 0 | F18: =F202 -> 319703/ПС-24-ТП-ТМ | G18: =G202 -> ПНР ТП с ИБ г.Москва, Феодосийская ул., зу 7_3кв24 | O18: =O202 -> 349935.36 | P18: =P202 -> 143262.23 | Q18: =Q202 -> 6.59 | R18: =R202 -> 2.73 | S18: =S202 -> 206666.54 | T18: =T202 -> 0 | U18: =U202 -> 326.11841 | V18: =V202 -> 0 | ... GX18: =GX202 -> 0
A20: 3 | B20: 1 | D20: =ROW(A96) -> 96 | F20: 02-01-01 | G20: Система телемеханики с включением в АИИС КУЭ в ТП | I20: 0 | J20: 322640-2024-ТМ | K20: -1 | L20: 02-01-01 | S20: 0 | V20: 0 | BX20: 0 | CF20: 0 | CG20: 0
A22: 52 | B22: =B96 -> 1 | C22: =C96 -> 3 | D22: =D96 -> 20 | E22: =E96 -> 0 | F22: =F96 -> 02-01-01 | G22: =G96 -> Система телемеханики с включением в АИИС КУЭ в ТП | O22: =O96 -> 143684.72 | P22: =P96 -> 143262.23 | Q22: =Q96 -> 6.59 | R22: =R96 -> 2.73 | S22: =S96 -> 415.9 | T22: =T96 -> 0 | U22: =U96 -> 1.07841 | V22: =V96 -> 0 | ... GX22: =GX96 -> 0
A24: 4 | B24: 1 | D24: =ROW(A30) -> 30 | F24: Новый раздел | G24: Монтажные работы | I24: 0 | K24: 0 | S24: 0 | V24: 0 | BX24: 0 | CJ24: 0
A26: 52 | B26: =B30 -> 1 | C26: =C30 -> 4 | D26: =D30 -> 24 | E26: =E30 -> 0 | F26: =F30 -> Новый раздел | G26: =G30 -> Монтажные работы | O26: =O30 -> 422.49 | P26: =P30 -> 0 | Q26: =Q30 -> 6.59 | R26: =R30 -> 2.73 | S26: =S30 -> 415.9 | T26: =T30 -> 0 | U26: =U30 -> 1.07841 | V26: =V30 -> 0 | ... GX26: =GX30 -> 0
A28: 17 | B28: 1 | D28: =ROW(EtalonRes!A3) -> 3 | E28: 1 | F28: 4.11-12-1 | G28: Установка съемных и выдвижных блоков (модулей, ячеек, ТЭЗ) массой до 5 кг (Оборудование ИБ) | H28: 1 ШТ. | I28: 1 | J28: 0 | K28: 1 | O28: =ROUND(CP28,2) -> 422.49 | P28: =ROUND((ROUND((AC28*AW28*I28),2)*BC28),2) -> 0 | Q28: =(ROUND((ROUND(((ET28)*AV28*I28),2)*BB28),2)+ROUND((ROUND(((AE28-(EU28))*AV28*I28),2)*BS28),2)) -> 6.59 | R28: =ROUND((ROUND((AE28*AV28*I28),2)*BS28),2) -> 2.73 | S28: =ROUND((ROUND((AF28*AV28*I28),2)*BA28),2) -> 415.9 | T28: =ROUND(CU28*I28,2) -> 0 | U28: =CV28*I28 -> 1.07841 | V28: =CW28*I28 -> 0 | W28: =ROUND(CX28*I28,2) -> 0 | X28: =ROUND(CY28,2) -> 382.63 | Y28: =ROUND(CZ28,2) -> 170.52 | AA28: 51975038 | AB28: =ROUND((AC28+AD28+AF28),6) -> 12.15 | AC28: =ROUND((ES28),6) -> 0 | AD28: =ROUND((((ET28)-(EU28))+AE28),6) -> 0.5 | AE28: =ROUND((EU28),6) -> 0.08 | AF28: =ROUND((EV28),6) -> 11.65 | AG28: =ROUND((AP28),6) -> 0 | AH28: =(EW28) -> 1.03 | AI28: =(EX28) -> 0 | AJ28: =(AS28) -> 0 | AK28: 12.15 | AL28: 0 | AM28: 0.5 | AN28: 0.08 | AO28: 11.65 | AP28: 0 | AQ28: 1.03 | AR28: 0 | AS28: 0 | AT28: 92 | AU28: 41 | AV28: 1.047 | AW28: 1 | AZ28: 1 | BA28: 34.09 | BB28: 12.68 | BC28: 1 | BH28: 0 | BI28: 2 | BJ28: ТСН-2001.4 Доп. 68, Сб. 11, т. 12, поз. 1 | BM28: 355 | BN28: 0 | BO28: 4.11-12-1 | BP28: 1 | BQ28: 40 | BR28: 0 | BS28: 34.09 | BT28: 1 | BU28: 1 | BV28: 1 | BW28: 1 | BX28: 1 | BZ28: 92 | CA28: 41 | CE28: 30 | CF28: 0 | CG28: 0 | CM28: 0 | CO28: 0 | CP28: =(P28+Q28+S28) -> 422.49 | CQ28: =ROUND((ROUND((AC28*AW28*1),2)*BC28),2) -> 0 | CR28: =(ROUND((ROUND(((ET28)*AV28*1),2)*BB28),2)+ROUND((ROUND(((AE28-(EU28))*AV28*1),2)*BS28),2)) -> 6.59 | CS28: =ROUND((ROUND((AE28*AV28*1),2)*BS28),2) -> 2.73 | CT28: =ROUND((ROUND((AF28*AV28*1),2)*BA28),2) -> 415.9 | CU28: =AG28 -> 0 | CV28: =(AH28*AV28) -> 1.07841 | CW28: =AI28 -> 0 | CX28: =AJ28 -> 0 | CY28: =S28*(BZ28/100) -> 382.628 | CZ28: =S28*(CA28/100) -> 170.519 | DN28: 112 | DO28: 70 | DP28: 1.047 | DQ28: 1 | DU28: 1013 | DV28: 1 ШТ. | DW28: 1 ШТ. | DX28: 1 | EE28: 51354996 | EF28: 40 | EG28: Монтаж оборудования | EH28: 0 | EJ28: 2 | EK28: 355 | EL28: ТСН-2001.4-11. 11-1...11-30 | EM28: ТСН-2001.4-11-1 | EQ28: 131072 | ER28: 12.15 | ES28: 0 | ET28: 0.5 | EU28: 0.08 | EV28: 11.65 | EW28: 1.03 | EX28: 0 | EY28: 0 | FQ28: 0 | FR28: =ROUND(IF(BI28=3,GM28,0),2) -> 0 | FS28: 0 | FX28: 112 | FY28: 70 | GD28: 0 | GF28: -2032365157 | GG28: 2 | GH28: 1 | GI28: 2 | GJ28: 0 | GK28: =ROUND(R28*(R12)/100,2) -> 4.37 | GL28: =ROUND(IF(AND(BH28=3,BI28=3,FS28<>0),P28,0),2) -> 0 | GM28: =ROUND(O28+X28+Y28+GK28,2)+GX28 -> 980.01 | GN28: =IF(OR(BI28=0,BI28=1),GM28-GX28,0) -> 0 | GO28: =IF(BI28=2,GM28-GX28,0) -> 980.01 | GP28: =IF(BI28=4,GM28-GX28,0) -> 0 | GR28: 0 | GS28: 3 | GT28: 0 | GV28: =ROUND((GT28),6) -> 0 | GW28: 1 | GX28: =ROUND(HC28*I28,2) -> 0 | HA28: 0 | HB28: 0 | HC28: =GV28*GW28 -> 0 | IK28: 0
A30: 51 | B30: =B24 -> 1 | C30: =A24 -> 4 | D30: =ROW(A24) -> 24 | F30: =IF(F24<>"",F24,"") -> Новый раздел | G30: =IF(G24<>"",G24,"") -> Монтажные работы | H30: 0 | O30: =ROUND(AB30,2) -> 422.49 | P30: =ROUND(AC30,2) -> 0 | Q30: =ROUND(AD30,2) -> 6.59 | R30: =ROUND(AE30,2) -> 2.73 | S30: =ROUND(AF30,2) -> 415.9 | T30: =ROUND(AG30,2) -> 0 | U30: =AH30 -> 1.07841 | V30: =AI30 -> 0 | W30: =ROUND(AJ30,2) -> 0 | X30: =ROUND(AK30,2) -> 382.63 | Y30: =ROUND(AL30,2) -> 170.52 | AB30: =ROUND(SUMIF(AA28:AA28,"=51975038",O28:O28),2) -> 422.49 | AC30: =ROUND(SUMIF(AA28:AA28,"=51975038",P28:P28),2) -> 0 | AD30: =ROUND(SUMIF(AA28:AA28,"=51975038",Q28:Q28),2) -> 6.59 | AE30: =ROUND(SUMIF(AA28:AA28,"=51975038",R28:R28),2) -> 2.73 | AF30: =ROUND(SUMIF(AA28:AA28,"=51975038",S28:S28),2) -> 415.9 | AG30: =ROUND(SUMIF(AA28:AA28,"=51975038",T28:T28),2) -> 0 | AH30: =SUMIF(AA28:AA28,"=51975038",U28:U28) -> 1.07841 | AI30: =SUMIF(AA28:AA28,"=51975038",V28:V28) -> 0 | AJ30: =ROUND(SUMIF(AA28:AA28,"=51975038",W28:W28),2) -> 0 | AK30: =ROUND(SUMIF(AA28:AA28,"=51975038",X28:X28),2) -> 382.63 | AL30: =ROUND(SUMIF(AA28:AA28,"=51975038",Y28:Y28),2) -> 170.52 | AO30: =ROUND(BX30,2) -> 0 | AP30: =ROUND(BY30,2) -> 0 | AQ30: =ROUND(BZ30,2) -> 0 | AR30: =ROUND(CA30,2) -> 980.01 | AS30: =ROUND(CB30,2) -> 0 | AT30: =ROUND(CC30,2) -> 980.01 | AU30: =ROUND(CD30,2) -> 0 | AV30: =ROUND(CE30,2) -> 0 | ... BD30: =ROUND(CM30,2) -> 0 | BX30: =ROUND(SUMIF(AA28:AA28,"=51975038",FQ28:FQ28),2) -> 0 | BY30: =ROUND(SUMIF(AA28:AA28,"=51975038",FR28:FR28),2) -> 0 | BZ30: =ROUND(SUMIF(AA28:AA28,"=51975038",GL28:GL28),2) -> 0 | CA30: =ROUND(SUMIF(AA28:AA28,"=51975038",GM28:GM28),2) -> 980.01 | CB30: =ROUND(SUMIF(AA28:AA28,"=51975038",GN28:GN28),2) -> 0 | CC30: =ROUND(SUMIF(AA28:AA28,"=51975038",GO28:GO28),2) -> 980.01 | CD30: =ROUND(SUMIF(AA28:AA28,"=51975038",GP28:GP28),2) -> 0 | CE30: =AC30-BX30 -> 0 | CF30: =AC30-BY30 -> 0 | CG30: =BX30-BZ30 -> 0 | CH30: =AC30-BX30-BY30+BZ30 -> 0 | CI30: =BY30-BZ30 -> 0 | CJ30: =ROUND(SUMIF(AA28:AA28,"=51975038",GX28:GX28),2) -> 0 | CK30: =ROUND(SUMIF(AA28:AA28,"=51975038",GY28:GY28),2) -> 0 | CL30: =ROUND(SUMIF(AA28:AA28,"=51975038",GZ28:GZ28),2) -> 0 | CM30: =ROUND(SUMIF(AA28:AA28,"=51975038",HD28:HD28),2) -> 0 | GX30: 0
A32: 50 | B32: 0 | C32: 0 | D32: 1 | E32: 201 | F32: =ROUND(Source!O30,O32) -> 422.49 | G32: ПЗ | H32: Прямые затраты | K32: 201 | L32: 1 | M32: 3 | O32: 2 | W32: 422.49 | X32: 1 | Y32: 422.49
A33: 50 | B33: 0 | C33: 0 | D33: 1 | E33: 202 | F33: =ROUND(Source!P30,O33) -> 0 | G33: СтМатОб | H33: Стоимость материальных ресурсов (всего) | K33: 202 | L33: 2 | M33: 3 | O33: 2 | W33: 0 | X33: 1 | Y33: 0
A34: 50 | B34: 0 | C34: 0 | D34: 1 | E34: 222 | F34: =ROUND(Source!AO30,O34) -> 0 | G34: СтМатОбЗак | H34: Стоимость материалов и оборудования заказчика | K34: 222 | L34: 3 | M34: 3 | O34: 2 | W34: 0 | X34: 1 | Y34: 0
A35: 50 | B35: 0 | C35: 0 | D35: 1 | E35: 225 | F35: =ROUND(Source!AV30,O35) -> 0 | G35: СтМатОбПод | H35: Стоимость материалов и оборудования подрядчика | K35: 225 | L35: 4 | M35: 3 | O35: 2 | W35: 0 | X35: 1 | Y35: 0
A36: 50 | B36: 0 | C36: 0 | D36: 1 | E36: 226 | F36: =ROUND(Source!AW30,O36) -> 0 | G36: СтМат | H36: Стоимость материалов (всего) | K36: 226 | L36: 5 | M36: 3 | O36: 2 | W36: 0 | X36: 1 | Y36: 0
A37: 50 | B37: 0 | C37: 0 | D37: 1 | E37: 227 | F37: =ROUND(Source!AX30,O37) -> 0 | G37: СтМатЗак | H37: Стоимость материалов заказчика | K37: 227 | L37: 6 | M37: 3 | O37: 2 | W37: 0 | X37: 1 | Y37: 0
A38: 50 | B38: 0 | C38: 0 | D38: 1 | E38: 228 | F38: =ROUND(Source!AY30,O38) -> 0 | G38: СтМатПод | H38: Стоимость материалов подрядчика | K38: 228 | L38: 7 | M38: 3 | O38: 2 | W38: 0 | X38: 1 | Y38: 0
A39: 50 | B39: 0 | C39: 0 | D39: 1 | E39: 216 | F39: =ROUND(Source!AP30,O39) -> 0 | G39: Оборуд | H39: Стоимость оборудования (всего) | K39: 216 | L39: 8 | M39: 3 | O39: 2 | W39: 0 | X39: 1 | Y39: 0
A40: 50 | B40: 0 | C40: 0 | D40: 1 | E40: 223 | F40: =ROUND(Source!AQ30,O40) -> 0 | G40: ОборудЗак | H40: Стоимость оборудования заказчика | K40: 223 | L40: 9 | M40: 3 | O40: 2 | W40: 0 | X40: 1 | Y40: 0
A41: 50 | B41: 0 | C41: 0 | D41: 1 | E41: 229 | F41: =ROUND(Source!AZ30,O41) -> 0 | G41: ОборудПод | H41: Стоимость оборудования подрядчика | K41: 229 | L41: 10 | M41: 3 | O41: 2 | W41: 0 | X41: 1 | Y41: 0
A42: 50 | B42: 0 | C42: 0 | D42: 1 | E42: 203 | F42: =ROUND(Source!Q30,O42) -> 6.59 | G42: ЭММ | H42: Эксплуатация машин | K42: 203 | L42: 11 | M42: 3 | O42: 2 | W42: 6.59 | X42: 1 | Y42: 6.59
A43: 50 | B43: 0 | C43: 0 | D43: 1 | E43: 231 | F43: =ROUND(Source!BB30,O43) -> 0 | G43: ЭММсНРиСП | H43: Эксплуатация машин по ТСН-2001.16 | K43: 231 | L43: 12 | M43: 3 | O43: 2 | W43: 0 | X43: 1 | Y43: 0
A44: 50 | B44: 0 | C44: 0 | D44: 1 | E44: 204 | F44: =ROUND(Source!R30,O44) -> 2.73 | G44: ЗПМ | H44: ЗП машинистов | K44: 204 | L44: 13 | M44: 3 | O44: 2 | W44: 2.73 | X44: 1 | Y44: 2.73
A45: 50 | B45: 0 | C45: 0 | D45: 1 | E45: 205 | F45: =ROUND(Source!S30,O45) -> 415.9 | G45: ОЗП | H45: Основная ЗП рабочих | K45: 205 | L45: 14 | M45: 3 | O45: 2 | W45: 415.9 | X45: 1 | Y45: 415.9
A46: 50 | B46: 0 | C46: 0 | D46: 1 | E46: 232 | F46: =ROUND(Source!BC30,O46) -> 0 | G46: ОЗПсНРиСП | H46: Основная ЗП рабочих по ТСН-2001.16 | K46: 232 | L46: 15 | M46: 3 | O46: 2 | W46: 0 | X46: 1 | Y46: 0
A47: 50 | B47: 0 | C47: 0 | D47: 1 | E47: 214 | F47: =ROUND(Source!AS30,O47) -> 0 | G47: Строит | H47: Строительные работы с НР и СП | K47: 214 | L47: 16 | M47: 3 | O47: 2 | W47: 0 | X47: 1 | Y47: 0
A48: 50 | B48: 0 | C48: 0 | D48: 1 | E48: 215 | F48: =ROUND(Source!AT30,O48) -> 980.01 | G48: Монтаж | H48: Монтажные работы с НР и СП | K48: 215 | L48: 17 | M48: 3 | O48: 2 | W48: 980.01 | X48: 1 | Y48: 980.01
A49: 50 | B49: 0 | C49: 0 | D49: 1 | E49: 217 | F49: =ROUND(Source!AU30,O49) -> 0 | G49: Прочие | H49: Прочие работы с НР и СП | K49: 217 | L49: 18 | M49: 3 | O49: 2 | W49: 0 | X49: 1 | Y49: 0
A50: 50 | B50: 0 | C50: 0 | D50: 1 | E50: 230 | F50: =ROUND(Source!BA30,O50) -> 0 | G50: ПрочиеЗатр | H50: Прочие затраты по ТСН-2001.16 | K50: 230 | L50: 19 | M50: 3 | O50: 2 | W50: 0 | X50: 1 | Y50: 0
A51: 50 | B51: 0 | C51: 0 | D51: 1 | E51: 206 | F51: =ROUND(Source!T30,O51) -> 0 | G51: ВозврМат | H51: Возврат материалов | K51: 206 | L51: 20 | M51: 3 | O51: 2 | W51: 0 | X51: 1 | Y51: 0
A52: 50 | B52: 0 | C52: 0 | D52: 1 | E52: 207 | F52: =Source!U30 -> 1.07841 | G52: ТрудСтр | H52: Трудозатраты строителей | K52: 207 | L52: 21 | M52: 3 | O52: -1 | W52: 1.07841 | X52: 1 | Y52: 1.07841
A53: 50 | B53: 0 | C53: 0 | D53: 1 | E53: 208 | F53: =Source!V30 -> 0 | G53: ТрудМаш | H53: Трудозатраты машинистов | K53: 208 | L53: 22 | M53: 3 | O53: -1 | W53: 0 | X53: 1 | Y53: 0
A54: 50 | B54: 0 | C54: 0 | D54: 1 | E54: 209 | F54: =ROUND(Source!W30,O54) -> 0 | G54: ТранспМат | H54: Транспорт материалов | K54: 209 | L54: 23 | M54: 3 | O54: 2 | W54: 0 | X54: 1 | Y54: 0
A55: 50 | B55: 0 | C55: 0 | D55: 1 | E55: 233 | F55: =ROUND(Source!BD30,O55) -> 0 | G55: Перевозка | H55: Перевозка грузов | K55: 233 | L55: 24 | M55: 3 | O55: 2 | W55: 0 | X55: 1 | Y55: 0
A56: 50 | B56: 0 | C56: 0 | D56: 1 | E56: 210 | F56: =ROUND(Source!X30,O56) -> 382.63 | G56: НР | H56: Накладные расходы | K56: 210 | L56: 25 | M56: 3 | O56: 2 | W56: 382.63 | X56: 1 | Y56: 382.63
A57: 50 | B57: 0 | C57: 0 | D57: 1 | E57: 211 | F57: =ROUND(Source!Y30,O57) -> 170.52 | G57: СмПриб | H57: Сметная прибыль | K57: 211 | L57: 26 | M57: 3 | O57: 2 | W57: 170.52 | X57: 1 | Y57: 170.52
A58: 50 | B58: 0 | C58: 0 | D58: 1 | E58: 224 | F58: =ROUND(Source!AR30,O58) -> 980.01 | G58: Всего | H58: Всего с НР и СП | K58: 224 | L58: 27 | M58: 3 | O58: 2 | W58: 980.01 | X58: 1 | Y58: 980.01
A60: 4 | B60: 1 | D60: =ROW(A66) -> 66 | F60: Новый раздел | G60: Оборудование | I60: 0 | K60: 0 | S60: 0 | V60: 0 | BX60: 0 | CJ60: 0
A62: 52 | B62: =B66 -> 1 | C62: =C66 -> 4 | D62: =D66 -> 60 | E62: =E66 -> 0 | F62: =F66 -> Новый раздел | G62: =G66 -> Оборудование | O62: =O66 -> 143262.23 | P62: =P66 -> 143262.23 | Q62: =Q66 -> 0 | R62: =R66 -> 0 | S62: =S66 -> 0 | T62: =T66 -> 0 | U62: =U66 -> 0 | V62: =V66 -> 0 | ... GX62: =GX66 -> 0
A64: 17 | B64: 1 | E64: 2 | F64: КП № 08-5439 от 05.08.2025г. ООО "ИТ Компания Д-Системс" | G64: Программно-технический комплекс телемеханики, автоматики, АСУ ТП диспетчеризации и телекоммуникаций TOPAZ "ПТК информационной безопасности TOPAZ Gateway* | H64: шт. | I64: 1 | J64: 0 | K64: 1 | O64: =ROUND(CP64,2) -> 143262.23 | P64: =ROUND((ROUND((AC64*AW64*I64),2)*BC64),2) -> 143262.23 | Q64: =(ROUND((ROUND(((ET64)*AV64*I64),2)*BB64),2)+ROUND((ROUND(((AE64-(EU64))*AV64*I64),2)*BS64),2)) -> 0 | R64: =ROUND((ROUND((AE64*AV64*I64),2)*BS64),2) -> 0 | S64: =ROUND((ROUND((AF64*AV64*I64),2)*BA64),2) -> 0 | T64: =ROUND(CU64*I64,2) -> 0 | U64: =CV64*I64 -> 0 | V64: =CW64*I64 -> 0 | W64: =ROUND(CX64*I64,2) -> 0 | X64: =ROUND(CY64,2) -> 0 | Y64: =ROUND(CZ64,2) -> 0 | AA64: 51975038 | AB64: =ROUND((AC64+AD64+AF64),6) -> 20149.4 | AC64: =ROUND((ES64),6) -> 20149.4 | AD64: =ROUND((((ET64)-(EU64))+AE64),6) -> 0 | AE64: =ROUND((EU64),6) -> 0 | AF64: =ROUND((EV64),6) -> 0 | AG64: =ROUND((AP64),6) -> 0 | AH64: =(EW64) -> 0 | AI64: =(EX64) -> 0 | AJ64: =(AS64) -> 0 | AK64: 20149.4 | AL64: 20149.4 | AM64: 0 | AN64: 0 | AO64: 0 | AP64: 0 | AQ64: 0 | AR64: 0 | AS64: 0 | AT64: 0 | AU64: 0 | AV64: 1 | AW64: 1 | AZ64: 1 | BA64: 1 | BB64: 1 | BC64: 7.11 | BH64: 3 | BI64: 3 | BM64: 400002 | BN64: 0 | BP64: 0 | BQ64: 202 | BR64: 0 | BS64: 1 | BT64: 1 | BU64: 1 | BV64: 1 | BW64: 1 | BX64: 1 | BZ64: 0 | CA64: 0 | CE64: 30 | CF64: 0 | CG64: 0 | CM64: 0 | CO64: 0 | CP64: =(P64+Q64+S64) -> 143262.23 | CQ64: =ROUND((ROUND((AC64*AW64*1),2)*BC64),2) -> 143262.23 | CR64: =(ROUND((ROUND(((ET64)*AV64*1),2)*BB64),2)+ROUND((ROUND(((AE64-(EU64))*AV64*1),2)*BS64),2)) -> 0 | CS64: =ROUND((ROUND((AE64*AV64*1),2)*BS64),2) -> 0 | CT64: =ROUND((ROUND((AF64*AV64*1),2)*BA64),2) -> 0 | CU64: =AG64 -> 0 | CV64: =(AH64*AV64) -> 0 | CW64: =AI64 -> 0 | CX64: =AJ64 -> 0 | CY64: =S64*(BZ64/100) -> 0 | CZ64: =S64*(CA64/100) -> 0 | DN64: 0 | DO64: 0 | DP64: 1 | DQ64: 1 | DU64: 1010 | DV64: шт. | DW64: шт. | DX64: 1 | EE64: 51356608 | EF64: 202 | EG64: Материалы | EH64: 0 | EJ64: 1 | EK64: 400002 | EL64: Материалы, изделия и конструкции | EM64: Материалы | EQ64: 131072 | ER64: 20149.4 | ES64: 20149.4 | ET64: 0 | EU64: 0 | EV64: 0 | EW64: 0 | EX64: 0 | EY64: 0 | EZ64: 5 | FC64: 0 | FD64: 18 | FF64: 137440.22 | FQ64: 0 | FR64: =ROUND(IF(BI64=3,GM64,0),2) -> 143262.23 | FS64: 0 | FX64: 0 | FY64: 0 | GA64: [137 440,22 / 7,11] + 3% Трансп + 1,2% Заг.скл | GD64: 0 | GF64: 813622911 | GG64: 2 | GH64: 3 | GI64: 3 | GJ64: 0 | GK64: =ROUND(R64*(R12)/100,2) -> 0 | GL64: =ROUND(IF(AND(BH64=3,BI64=3,FS64<>0),P64,0),2) -> 0 | GM64: =ROUND(O64+X64+Y64+GK64,2)+GX64 -> 143262.23 | GN64: =IF(OR(BI64=0,BI64=1),GM64-GX64,0) -> 0 | GO64: =IF(BI64=2,GM64-GX64,0) -> 0 | GP64: =IF(BI64=4,GM64-GX64,0) -> 0 | GR64: 1 | GS64: 1 | GT64: 0 | GV64: =ROUND((GT64),6) -> 0 | GW64: 1 | GX64: =ROUND(HC64*I64,2) -> 0 | HA64: 0 | HB64: 0 | HC64: =GV64*GW64 -> 0 | HE64: 3 | HF64: 1,2 | IK64: 0
...

Sheet SourceObSm
A1: 0 | B1: Smeta.RU (495) 974-1589 | D1: _OBSM_ | F1: 0 | G1: 0 | H1: 0 | I1: Smeta.RU | K1: 1 | L1: 73582 | M1: 10 | N1: 11 | O1: 13 | P1: 0 | Q1: 1
A12: 1 | B12: 52 | C12: 0 | E12: 0 | F12: 319703/ПС-24-ТП-ТМ | G12: ПНР ТП с ИБ г.Москва, Феодосийская ул., зу 7_3кв24 | I12: 0 | K12: 0 | L12: 0 | M12: 4098 | O12: 0 | P12: 0 | Q12: 0 | R12: 160 | T12: 1 | V12: 0 | BB12: 0 | BH12: Сметные нормы списания | BI12: Коды ОКП для ТСН-2001 МГЭ Дополнение 77 | BJ12: 1 | BK12: 1 | BL12: 0 | BM12: 0 | BN12: 1 | BO12: 0 | BP12: 6 | BQ12: 2 | BR12: 1 | BS12: 1 | BT12: 0 | BU12: 0 | BV12: 0 | BW12: 0 | BX12: 0 | BY12: ТСН-2001 (МГЭ) Доп 77 - Новое строительство | BZ12: Типовой расчет для ТСН-2001 МГЭ, Новая методика с выпуска доп. 43 (Строительство), Доп 77 | CA12: Территориальные сметные нормативы для Москвы ТСН-2001 (МГЭ), дополнение 77 | CB12: Территориальные сметные нормативы для Москвы ТСН-2001 (МГЭ), дополнение 77 | CC12: Территориальные сметные нормативы для Москвы ТСН-2001 (МГЭ), дополнение 77 | CD12: Территориальные сметные нормативы для Москвы ТСН-2001 (МГЭ), дополнение 77 | CE12: Поправки для ТСН-2001 от 30.06.2025 г. доп.77 | CF12: 0 | CG12: 0 | CH12: 8200 | CK12: 77 | CQ12: Территориальные сметные нормативы для Москвы (ТСН-2001) | CR12: ТЕР | CS12: 41660 | CT12: 1 | CU12: 77 | CY12: 0 | EC12: 0
A14: 22 | B14: 1 | C14: 0 | D14: 51975038 | E14: 0 | F14: 2 | G14: 1
A16: 3 | B16: 1 | C16: 02-01-01 | D16: Система телемеханики с включением в АИИС КУЭ в ТП | E16: =ROUND((Source!F113)/1000,2) -> 0 | F16: =ROUND((Source!F114)/1000,2) -> 0.98 | G16: =ROUND((Source!F105)/1000,2) -> 143.26 | H16: =ROUND((Source!F115)/1000+(Source!F116)/1000,2) -> 0 | I16: =E16+F16+G16+H16 -> 144.24 | J16: =ROUND((Source!F111+Source!F110)/1000,2) -> 0.42 | AI16: 0 | AJ16: -1 | AN16: 0 | AT16: 143684.72 | AU16: 143262.23 | AV16: 0 | AW16: 143262.23 | AX16: 0 | AY16: 6.59 | AZ16: 2.73 | BA16: 415.9 | BB16: 0 | BC16: 980.01 | BD16: 0 | BE16: 0 | BF16: 1.07841 | BG16: 0 | BH16: 0 | BI16: 382.63 | BJ16: 170.52 | BK16: 144242.24
A17: 3 | B17: 2 | C17: 09-01-01 | D17: Система телемеханики с включением в АИИС КУЭ в ТП. ПНР | E17: =ROUND((Source!F189)/1000,2) -> 0 | F17: =ROUND((Source!F190)/1000,2) -> 0 | G17: =ROUND((Source!F181)/1000,2) -> 0 | H17: =ROUND((Source!F191)/1000+(Source!F192)/1000,2) -> 435.19 | I17: =E17+F17+G17+H17 -> 435.19 | J17: =ROUND((Source!F187+Source!F186)/1000,2) -> 206.25 | AI17: 0 | AJ17: -1 | AN17: 0 | AT17: 206250.64 | AU17: 0 | AV17: 0 | AW17: 0 | AX17: 0 | AY17: 0 | AZ17: 0 | BA17: 206250.64 | BB17: 0 | BC17: 0 | BD17: 435188.85 | BE17: 0 | BF17: 325.04 | BG17: 0 | BH17: 0 | BI17: 144375.45 | BJ17: 84562.76 | BK17: 435188.85
A19: 51 | E19: 0 | F19: 0.98 | G19: 143.26 | H19: 435.19 | I19: 579.43 | J19: 206.67
A21: 50 | B21: 0 | C21: 0 | D21: 1 | E21: 201 | F21: 349935.36 | G21: ПЗ | H21: Прямые затраты | K21: 201 | L21: 1 | M21: 3 | O21: 2
A22: 50 | B22: 0 | C22: 0 | D22: 1 | E22: 202 | F22: 143262.23 | G22: СтМатОб | H22: Стоимость материальных ресурсов (всего) | K22: 202 | L22: 2 | M22: 3 | O22: 2
A23: 50 | B23: 0 | C23: 0 | D23: 1 | E23: 222 | F23: 0 | G23: СтМатОбЗак | H23: Стоимость материалов и оборудования заказчика | K23: 222 | L23: 3 | M23: 3 | O23: 2
A24: 50 | B24: 0 | C24: 0 | D24: 1 | E24: 225 | F24: 143262.23 | G24: СтМатОбПод | H24: Стоимость материалов и оборудования подрядчика | K24: 225 | L24: 4 | M24: 3 | O24: 2
A25: 50 | B25: 0 | C25: 0 | D25: 1 | E25: 226 | F25: 0 | G25: СтМат | H25: Стоимость материалов (всего) | K25: 226 | L25: 5 | M25: 3 | O25: 2
A26: 50 | B26: 0 | C26: 0 | D26: 1 | E26: 227 | F26: 0 | G26: СтМатЗак | H26: Стоимость материалов заказчика | K26: 227 | L26: 6 | M26: 3 | O26: 2
A27: 50 | B27: 0 | C27: 0 | D27: 1 | E27: 228 | F27: 0 | G27: СтМатПод | H27: Стоимость материалов подрядчика | K27: 228 | L27: 7 | M27: 3 | O27: 2
A28: 50 | B28: 0 | C28: 0 | D28: 1 | E28: 216 | F28: 143262.23 | G28: Оборуд | H28: Стоимость оборудования (всего) | K28: 216 | L28: 8 | M28: 3 | O28: 2
A29: 50 | B29: 0 | C29: 0 | D29: 1 | E29: 223 | F29: 0 | G29: ОборудЗак | H29: Стоимость оборудования заказчика | K29: 223 | L29: 9 | M29: 3 | O29: 2
A30: 50 | B30: 0 | C30: 0 | D30: 1 | E30: 229 | F30: 143262.23 | G30: ОборудПод | H30: Стоимость оборудования подрядчика | K30: 229 | L30: 10 | M30: 3 | O30: 2
A31: 50 | B31: 0 | C31: 0 | D31: 1 | E31: 203 | F31: 6.59 | G31: ЭММ | H31: Эксплуатация машин | K31: 203 | L31: 11 | M31: 3 | O31: 2
A32: 50 | B32: 0 | C32: 0 | D32: 1 | E32: 231 | F32: 0 | G32: ЭММсНРиСП | H32: Эксплуатация машин по ТСН-2001.16 | K32: 231 | L32: 12 | M32: 3 | O32: 2
... A47: 50 | B47: 0 | C47: 0 | D47: 1 | E47: 224 | F47: 579431.09 | G47: Всего | H47: Всего с НР и СП | K47: 224 | L47: 27 | M47: 3 | O47: 2
A49: -1
A52: 75 | B52: Текущий уровень цен | C52: 2024 | D52: 0 | E52: 4 | G52: 0 | H52: 2 | I52: 1 | J52: 1 | K52: 95 | L52: 65 | M52: 0 | N52: 51975038 | O52: 1
A53: 1 | B53: Сборник индексов | D53: 0 | E53: 0 | F53: 1 | G53: 1 | H53: 0 | I53: 2 | J53: 1 | K53: 9.74 | L53: 7.11 | M53: 1 | N53: 1 | O53: 9.74 | P53: 7.11 | Q53: 1 | AN53: 51975039

Sheet SmtRes
I232: 0

Sheet EtalonRes
A1: =ROW(Source!A28) -> 28 | B1: 51975334 | C1: 51975333 | D1: 51377563 | E1: 1077 | F1: 1 | G1: 1077 | H1: 1 | I1: 9999990008 | K1: Трудозатраты рабочих | L1: 1191 | N1: 1013 | O1: чел.-ч. | P1: чел.-ч. | Q1: 1 | X1: 1.03 | Y1: 0 | Z1: 0 | AA1: 0 | AB1: 0 | AC1: 0 | AD1: 1 | AE1: 1 | AG1: 1.03 | AH1: 3 | AI1: -1 | AK1: 0 | AL1: 0 | AM1: 0 | AN1: 0 | AO1: 0 | AP1: 0 | AQ1: 0 | AR1: 0
A2: =ROW(Source!A28) -> 28 | B2: 51975335 | C2: 51975333 | D2: 51455066 | E2: 1 | F2: 1 | G2: 1077 | H2: 2 | I2: 2.1-18-7 | J2: ТСН-2001.2. Доп. 68. п.1-18-7 (183001) | K2: Автомобили грузовые бортовые, грузоподъемность до 5 т | L2: 1368 | N2: 1011 | O2: маш.-ч | P2: маш.-ч | Q2: 1 | X2: 0.006 | Y2: 0 | Z2: 83.1 | AA2: 12.62 | AB2: 0 | AC2: 0 | AD2: 1 | AE2: 0 | AG2: 0.006 | AH2: 3 | AI2: -1 | AK2: 0 | AL2: 0 | AM2: 0 | AN2: 0 | AO2: 0 | AP2: 0 | AQ2: 0 | AR2: 0
A3: =ROW(Source!A28) -> 28 | B3: 51975336 | C3: 51975333 | D3: 51405942 | E3: 1077 | F3: 1 | G3: 1077 | H3: 3 | I3: 4200000000 | K3: Съемные и выдвижные блоки, ячейки, модули, типовые элементы замены (4300000000) | L3: 1354 | N3: 1010 | O3: шт. | P3: шт. | Q3: 1 | X3: 1 | Y3: 0 | Z3: 0 | AA3: 0 | AB3: 0 | AC3: 0 | AD3: 0 | AE3: 0 | AG3: 1 | AH3: 3 | AI3: -1 | AK3: 0 | AL3: 0 | AM3: 0 | AN3: 0 | AO3: 0 | AP3: 0 | AQ3: 0 | AR3: 0
A4: =ROW(Source!A134) -> 134 | B4: 51975339 | C4: 51975338 | D4: 51377563 | E4: 1077 | F4: 1 | G4: 1077 | H4: 1 | I4: 9999990008 | K4: Трудозатраты рабочих | L4: 1191 | N4: 1013 | O4: чел.-ч. | P4: чел.-ч. | Q4: 1 | X4: 74 | Y4: 0 | Z4: 0 | AA4: 0 | AB4: 0 | AC4: 0 | AD4: 1 | AE4: 1 | AF4: )*0,8 | AG4: 59.2 | AH4: 3 | AI4: -1 | AK4: 0 | AL4: 0 | AM4: 0 | AN4: 0 | AO4: 0 | AP4: 0 | AQ4: 0 | AR4: 0
A5: =ROW(Source!A135) -> 135 | B5: 51975341 | C5: 51975340 | D5: 51377563 | E5: 1077 | F5: 1 | G5: 1077 | H5: 1 | I5: 9999990008 | K5: Трудозатраты рабочих | L5: 1191 | N5: 1013 | O5: чел.-ч. | P5: чел.-ч. | Q5: 1 | X5: 72 | Y5: 0 | Z5: 0 | AA5: 0 | AB5: 0 | AC5: 0 | AD5: 1 | AE5: 1 | AF5: )*0,8 | AG5: 57.6 | AH5: 3 | AI5: -1 | AK5: 0 | AL5: 0 | AM5: 0 | AN5: 0 | AO5: 0 | AP5: 0 | AQ5: 0 | AR5: 0
A6: =ROW(Source!A136) -> 136 | B6: 51975343 | C6: 51975342 | D6: 51377563 | E6: 1077 | F6: 1 | G6: 1077 | H6: 1 | I6: 9999990008 | K6: Трудозатраты рабочих | L6: 1191 | N6: 1013 | O6: чел.-ч. | P6: чел.-ч. | Q6: 1 | X6: 29 | Y6: 0 | Z6: 0 | AA6: 0 | AB6: 0 | AC6: 0 | AD6: 1 | AE6: 1 | AF6: )*0,8 | AG6: 23.2 | AH6: 3 | AI6: -1 | AK6: 0 | AL6: 0 | AM6: 0 | AN6: 0 | AO6: 0 | AP6: 0 | AQ6: 0 | AR6: 0
A7: =ROW(Source!A137) -> 137 | B7: 51975345 | C7: 51975344 | D7: 51377563 | E7: 1077 | F7: 1 | G7: 1077 | H7: 1 | I7: 9999990008 | K7: Трудозатраты рабочих | L7: 1191 | N7: 1013 | O7: чел.-ч. | P7: чел.-ч. | Q7: 1 | X7: 3.4 | Y7: 0 | Z7: 0 | AA7: 0 | AB7: 0 | AC7: 0 | AD7: 1 | AE7: 1 | AF7: )*0,8 | AG7: 2.72 | AH7: 3 | AI7: -1 | AK7: 0 | AL7: 0 | AM7: 0 | AN7: 0 | AO7: 0 | AP7: 0 | AQ7: 0 | AR7: 0
A8: =ROW(Source!A138) -> 138 | B8: 51975347 | C8: 51975346 | D8: 51377563 | E8: 1077 | F8: 1 | G8: 1077 | H8: 1 | I8: 9999990008 | K8: Трудозатраты рабочих | L8: 1191 | N8: 1013 | O8: чел.-ч. | P8: чел.-ч. | Q8: 1 | X8: 4.9 | Y8: 0 | Z8: 0 | AA8: 0 | AB8: 0 | AC8: 0 | AD8: 1 | AE8: 1 | AF8: )*0,8 | AG8: 3.92 | AH8: 3 | AI8: -1 | AK8: 0 | AL8: 0 | AM8: 0 | AN8: 0 | AO8: 0 | AP8: 0 | AQ8: 0 | AR8: 0
A9: =ROW(Source!A139) -> 139 | B9: 51975349 | C9: 51975348 | D9: 51377563 | E9: 1077 | F9: 1 | G9: 1077 | H9: 1 | I9: 9999990008 | K9: Трудозатраты рабочих | L9: 1191 | N9: 1013 | O9: чел.-ч. | P9: чел.-ч. | Q9: 1 | X9: 1.6 | Y9: 0 | Z9: 0 | AA9: 0 | AB9: 0 | AC9: 0 | AD9: 1 | AE9: 1 | AF9: )*0,8 | AG9: 1.28 | AH9: 3 | AI9: -1 | AK9: 0 | AL9: 0 | AM9: 0 | AN9: 0 | AO9: 0 | AP9: 0 | AQ9: 0 | AR9: 0
A10: =ROW(Source!A140) -> 140 | B10: 51975351 | C10: 51975350 | D10: 51377563 | E10: 1077 | F10: 1 | G10: 1077 | H10: 1 | I10: 9999990008 | K10: Трудозатраты рабочих | L10: 1191 | N10: 1013 | O10: чел.-ч. | P10: чел.-ч. | Q10: 1 | X10: 56 | Y10: 0 | Z10: 0 | AA10: 0 | AB10: 0 | AC10: 0 | AD10: 1 | AE10: 1 | AF10: )*0,8 | AG10: 44.8 | AH10: 3 | AI10: -1 | AK10: 0 | AL10: 0 | AM10: 0 | AN10: 0 | AO10: 0 | AP10: 0 | AQ10: 0 | AR10: 0

Sheet SrcPoprs

Sheet SrcKA
A1: 0 | B1: Smeta.RU (495) 974-1589 | D1: _PS_ | F1: 0 | G1: 0 | H1: 0 | I1: Smeta.RU | K1: 1 | L1: 73582 | M1: 10 | N1: 11 | O1: 13 | P1: 0 | Q1: 1
F12: =Source!F12 -> 319703/ПС-24-ТП-ТМ | G12: =Source!G12 -> ПНР ТП с ИБ г.Москва, Феодосийская ул., зу 7_3кв24 | CY12: =Source!CY12 -> 0
