Workbook

Sheet Смета по ТСН-2001(с доп.67
A1: =[1]Source!B1 -> Smeta.RU (495) 974-1589
J2: Форма № 4б
A3: ПИР, СМР, ПНР, материалы, оборудование (за исключением замков, предоставляемых Заказчиком) по титулу: Строительство ТП-10/0,4кВ с тр-ми 2х400кВА, 4КЛ-10кВ от ТП-10/0,4кВ луч А,Б до КЛ-10кВ направлением ТП-10/0,4кВ № № 21782 - ТП-10/0,4кВ № 24478 луч А,Б, 8КЛ-0,4кВ от ТП-10/0,4кВ до ВРЩ-0,4кВ №1-3, в т.ч. ПИР: г.Москва, ул.Феодосийская, з/у 7 для нужд МКС – филиала ПАО «Россети Московский регион»
A4: (наименование стройки и/или объекта)
A6: ЛОКАЛЬНАЯ СМЕТА № 09-01-02 | AP6: =CONCATENATE( "ЛОКАЛЬНАЯ СМЕТА № ",IF([1]Source!F12<>"Новый объект", [1]Source!F12, "")) -> ЛОКАЛЬНАЯ СМЕТА № (ТСН-2001 (Мосгосэкспертиза)) (ТСН-2001 (Мосгосэкспертиза)) (ТСН-2001 (Мосгосэкспертиза))
A8: ПНР КЛ 10 кВ
A9: (наименование работ и затрат)
A11: =CONCATENATE( "Основание: чертежи № ", [1]Source!J12) -> Основание: чертежи №
I13: В базисном уровне цен | J13: В текущем уровне цен
E14: Сметная стоимость | I14: =I15+I16+I17+I18 -> 13.33 | J14: =J15+J16+J17+J18 -> 357.17 | K14: тыс.руб.
E15: Строительные работы | I15: =ROUND(SUM(X1:X67)/1000, 2) -> 2.16 | J15: =ROUND((Source!F113)/1000, 2) -> 25.15 | K15: тыс.руб.
E16: Работы по монтажу оборудования | I16: =ROUND(SUM(Y1:Y67)/1000, 2) -> 0 | J16: =ROUND((Source!F114)/1000, 2) -> 0 | K16: тыс.руб.
E17: Оборудование | I17: =ROUND(SUM(Z1:Z67)/1000, 2) -> 0 | J17: =ROUND((Source!F105)/1000, 2) -> 0 | K17: тыс.руб.
E18: Прочие работы и затраты | I18: =ROUND(SUM(AA1:AA67)/1000, 2) -> 11.17 | J18: =ROUND((Source!F115+Source!F116)/1000, 2) -> 332.02 | K18: тыс.руб.
E19: Средства на оплату труда | I19: =ROUND(SUM(W1:W67)/1000, 2) -> 4.66 | J19: =(Source!F111+ Source!F110)/1000 -> 160.83765 | K19: тыс.руб.
E20: Затраты труда | I20: =SUM(AB1:AB67) -> 296.416 | K20: чел.-ч.
E21: Кроме того:
E22: Возврат материалов | I22: =ROUND(SUM(AE1:AE67)/1000, 2) -> 0 | J22: =SUM(AF1:AF67)/1000 -> 0 | K22: тыс.руб.
A24: Составлен(а) по ТСН-2001 с учетом Дополнения №: 73
A25: № и период сборника коэффициентов (индексов) пересчета: Коэффициенты к ТСН-2001 МГЭ №212 III квартал 2024 года | AP25: № и период сборника коэффициентов (индексов) пересчета: Коэффициенты к ТСН-2001 МГЭ №212 III квартал 2024 года
A26: № п/п | B26: Шифр расценки и коды ресурсов | C26: Наименование работ и затрат | D26: Ед. изм. | E26: Кол-во единиц | F26: Цена на ед. изм., руб. | G26: Попра- вочные коэффи- циенты | H26: Коэффи- циенты зимних удорожа- ний | I26: Всего затрат в базисном уровне цен, руб. | J26: Коэффи- циенты (индек- сы) пере- счета, нормы НР и СП | K26: ВСЕГО затрат в текущем уровне цен, руб.
A27: 1 | B27: 2 | C27: 3 | D27: 4 | E27: 5 | F27: 6 | G27: 7 | H27: 8 | I27: 9 | J27: 10 | K27: 11
A29: =CONCATENATE("Локальная смета: ",IF(Source!G20<>"Новая локальная смета", Source!G20, "")) -> Локальная смета:
A31: =CONCATENATE("Раздел: ",IF(Source!G24<>"Новый раздел", Source!G24, "")) -> Раздел: Пусконаладочные работы
A32: 1 | B32: 5.10-35-1 Поправка: Гл.5.Прил.2.2.п.2.2.23_05.00.01.37.001 | C32: Кабельные линии высокого или низкого напряжения | D32: =Source!H28 -> кабельная линия | E32: =Source!I28 -> 4 | Q32: =ROUND((Source!DN28/100)*ROUND((ROUND((Source!AF28*Source!AV28*Source!I28),2)),2), 2) -> 2485.46 | R32: =Source!X28 -> 80055.09 | S32: =ROUND((Source!DO28/100)*ROUND((ROUND((Source!AF28*Source!AV28*Source!I28),2)),2), 2) -> 2319.77 | T32: =Source!Y28 -> 46889.41 | U32: =ROUND((175/100)*ROUND((ROUND((Source!AE28*Source!AV28*Source!I28),2)),2), 2) -> 0 | V32: =ROUND((160/100)*ROUND(ROUND((ROUND((Source!AE28*Source!AV28*Source!I28),2)*Source!BS28),2), 2), 2) -> 0 | AI32: 0
C33: ЗП | F33: =Source!AO28 -> 1035.61 | G33: =Source!DG28 -> *0,8 | H33: =Source!AV28 -> 1 | I33: =ROUND((ROUND((Source!AF28*Source!AV28*Source!I28),2)),2) -> 3313.95 | J33: =IF(Source!BA28<> 0, Source!BA28, 1) -> 34.51 | K33: =Source!S28 -> 114364.41 | W33: =I33 -> 3313.95
C34: НР от ЗП | D34: % | E34: =Source!DN28 -> 75 | I34: =SUM(Q32:Q33) -> 2485.46 | J34: =Source!BZ28 -> 70 | K34: =SUM(R32:R33) -> 80055.09
C35: СП от ЗП | D35: % | E35: =Source!DO28 -> 70 | I35: =SUM(S32:S34) -> 2319.77 | J35: =Source!CA28 -> 41 | K35: =SUM(T32:T34) -> 46889.41
C36: ЗТР | D36: чел-ч | E36: =Source!AQ28 -> 65 | G36: =Source!DI28 -> *0,8 | H36: =Source!AV28 -> 1 | I36: =Source!U28 -> 208 | AB36: =I36 -> 208
C37: ВСЕГО работ по позиции: | H37: =I33+I34+I35+0-0-0 -> 8119.18 | J37: =K33+K34+K35+0-0-0 -> 241308.91
C38: ВСЕГО оборудование по позиции: | H38: =0+0 -> 0 | J38: =0+0 -> 0
O39: =I33+I34+I35+0 -> 8119.18 | P39: =K33+K34+K35+0 -> 241308.91 | X39: =IF(Source!BI28<=1,I33+I34+I35-0, 0) -> 0 | Y39: =IF(Source!BI28=2,I33+I34+I35-0, 0) -> 0 | Z39: =IF(Source!BI28=3,I33+I34+I35-0, 0) -> 0 | AA39: =IF(Source!BI28=4,I33+I34+I35,0) -> 8119.18
A41: 2 | B41: 5.10-44-1 Поправка: Гл.5.Прил.2.2.п.2.2.23_05.00.01.37.001 | C41: Кабельные линии, испытание оболочек из сшитого полиэтилена каждой строительной длины силовых кабелей на напряжение 10 кВ | D41: =Source!H29 -> 1 испытание | E41: =Source!I29 -> 12 | Q41: =ROUND((Source!DN29/100)*ROUND((ROUND((Source!AF29*Source!AV29*Source!I29),2)),2), 2) -> 934.28 | R41: =Source!X29 -> 30092.38 | S41: =ROUND((Source!DO29/100)*ROUND((ROUND((Source!AF29*Source!AV29*Source!I29),2)),2), 2) -> 871.99 | T41: =Source!Y29 -> 17625.54 | U41: =ROUND((175/100)*ROUND((ROUND((Source!AE29*Source!AV29*Source!I29),2)),2), 2) -> 0 | V41: =ROUND((160/100)*ROUND(ROUND((ROUND((Source!AE29*Source!AV29*Source!I29),2)*Source!BS29),2), 2), 2) -> 0 | AI41: 0
C42: ЗП | F42: =Source!AO29 -> 129.76 | G42: =Source!DG29 -> *0,8 | H42: =Source!AV29 -> 1 | I42: =ROUND((ROUND((Source!AF29*Source!AV29*Source!I29),2)),2) -> 1245.7 | J42: =IF(Source!BA29<> 0, Source!BA29, 1) -> 34.51 | K42: =Source!S29 -> 42989.11 | W42: =I42 -> 1245.7
C43: НР от ЗП | D43: % | E43: =Source!DN29 -> 75 | I43: =SUM(Q41:Q42) -> 934.28 | J43: =Source!BZ29 -> 70 | K43: =SUM(R41:R42) -> 30092.38
C44: СП от ЗП | D44: % | E44: =Source!DO29 -> 70 | I44: =SUM(S41:S43) -> 871.99 | J44: =Source!CA29 -> 41 | K44: =SUM(T41:T43) -> 17625.54
C45: ЗТР | D45: чел-ч | E45: =Source!AQ29 -> 9.21 | G45: =Source!DI29 -> *0,8 | H45: =Source!AV29 -> 1 | I45: =Source!U29 -> 88.416 | AB45: =I45 -> 88.416
C46: ВСЕГО работ по позиции: | H46: =I42+I43+I44+0-0-0 -> 3051.97 | J46: =K42+K43+K44+0-0-0 -> 90707.03
C47: ВСЕГО оборудование по позиции: | H47: =0+0 -> 0 | J47: =0+0 -> 0
O48: =I42+I43+I44+0 -> 3051.97 | P48: =K42+K43+K44+0 -> 90707.03 | X48: =IF(Source!BI29<=1,I42+I43+I44-0, 0) -> 0 | Y48: =IF(Source!BI29=2,I42+I43+I44-0, 0) -> 0 | Z48: =IF(Source!BI29=3,I42+I43+I44-0, 0) -> 0 | AA48: =IF(Source!BI29=4,I42+I43+I44,0) -> 3051.97
...

Sheet Source
A1: 0 | B1: Smeta.RU (495) 974-1589 | D1: _PS_ | F1: 0 | G1: 0 | H1: 0 | I1: Smeta.RU | K1: 1 | L1: 47858 | M1: 10 | N1: 11 | O1: 14 | P1: 0 | Q1: 1
A12: 1 | B12: 134 | C12: 0 | D12: =ROW(A96) -> 96 | E12: 0 | F12: (ТСН-2001 (Мосгосэкспертиза)) (ТСН-2001 (Мосгосэкспертиза)) (ТСН-2001 (Мосгосэкспертиза)) | G12: 09-01-02 ПНР КЛ 10 кВ (ТСН-2001 (Мосгосэкспертиза)) (ТСН-2001 (Мосгосэкспертиза)) | I12: 0 | K12: 0 | L12: 0 | M12: 4098 | O12: 0 | P12: 0 | Q12: 0 | R12: 160 | T12: 1 | V12: 0 | BB12: 0 | BH12: Сметные нормы списания | BI12: Коды ОКП для ТСН-2001 МГЭ (История развития) | BJ12: 1 | BK12: 1 | BL12: 0 | BM12: 0 | BN12: 1 | BO12: 0 | BP12: 6 | BQ12: 2 | BR12: 1 | BS12: 1 | BT12: 0 | BU12: 0 | BV12: 0 | BW12: 0 | BX12: 0 | BZ12: Типовой расчет для ТСН-2001 МГЭ, Новая методика с выпуска доп. 43 (Строительство), Доп 73 | CA12: История развития для ТСН-2001 (МГЭ) 73 доп от 17.07.2024 | CB12: История развития для ТСН-2001 (МГЭ) 73 доп от 17.07.2024 | CC12: История развития для ТСН-2001 (МГЭ) 73 доп от 17.07.2024 | CD12: История развития для ТСН-2001 (МГЭ) 73 доп от 17.07.2024 | CE12: Поправки для ТСН-2001 от 16.04.2024 г. доп.72 | CF12: 0 | CG12: 0 | CH12: 8 | CK12: 77 | CQ12: Территориальные сметные нормативы для Москвы (ТСН-2001) | CR12: ТЕР | CS12: 41660 | CT12: 1 | CU12: 73 | CY12: 0 | EC12: 0
A15: 15 | B15: 1
A18: 52 | B18: =B96 -> 134 | C18: =C96 -> 1 | D18: =D96 -> 12 | E18: =E96 -> 0 | F18: =F96 -> (ТСН-2001 (Мосгосэкспертиза)) (ТСН-2001 (Мосгосэкспертиза)) (ТСН-2001 (Мосгосэкспертиза)) | G18: =G96 -> 09-01-02 ПНР КЛ 10 кВ (ТСН-2001 (Мосгосэкспертиза)) (ТСН-2001 (Мосгосэкспертиза)) | O18: =O96 -> 176926.23 | P18: =P96 -> 0 | Q18: =Q96 -> 19572.71 | R18: =R96 -> 3484.13 | S18: =S96 -> 157353.52 | T18: =T96 -> 0 | U18: =U96 -> 296.416 | V18: =V96 -> 0 | ... GX18: =GX96 -> 0
A20: 3 | B20: 1 | D20: =ROW(A66) -> 66 | F20: Новая локальная смета | G20: Новая локальная смета | I20: 0 | K20: 0 | L20: Новая локальная смета | S20: 0 | V20: 0 | BX20: 0 | CF20: 0 | CG20: 0
A22: 52 | B22: =B66 -> 1 | C22: =C66 -> 3 | D22: =D66 -> 20 | E22: =E66 -> 0 | F22: =F66 -> Новая локальная смета | G22: =G66 -> Новая локальная смета | O22: =O66 -> 176926.23 | P22: =P66 -> 0 | Q22: =Q66 -> 19572.71 | R22: =R66 -> 3484.13 | S22: =S66 -> 157353.52 | T22: =T66 -> 0 | U22: =U66 -> 296.416 | V22: =V66 -> 0 | ... GX22: =GX66 -> 0
A24: 4 | B24: 1 | D24: =ROW(A36) -> 36 | F24: Новый раздел | G24: Пусконаладочные работы | I24: 0 | K24: 0 | S24: 0 | V24: 0 | BX24: 0 | CJ24: 0
A26: 52 | B26: =B36 -> 1 | C26: =C36 -> 4 | D26: =D36 -> 24 | E26: =E36 -> 0 | F26: =F36 -> Новый раздел | G26: =G36 -> Пусконаладочные работы | O26: =O36 -> 176926.23 | P26: =P36 -> 0 | Q26: =Q36 -> 19572.71 | R26: =R36 -> 3484.13 | S26: =S36 -> 157353.52 | T26: =T36 -> 0 | U26: =U36 -> 296.416 | V26: =V36 -> 0 | ... GX26: =GX36 -> 0
A28: 17 | B28: 1 | D28: =ROW(EtalonRes!A1) -> 1 | E28: 1 | F28: 5.10-35-1 | G28: Кабельные линии высокого или низкого напряжения | H28: кабельная линия | I28: 4 | J28: 0 | K28: 4 | O28: =ROUND(CP28,2) -> 114364.41 | P28: =ROUND((ROUND((AC28*AW28*I28),2)*BC28),2) -> 0 | Q28: =(ROUND((ROUND(((ET28)*AV28*I28),2)*BB28),2)+ROUND((ROUND(((AE28-(EU28))*AV28*I28),2)*BS28),2)) -> 0 | R28: =ROUND((ROUND((AE28*AV28*I28),2)*BS28),2) -> 0 | S28: =ROUND((ROUND((AF28*AV28*I28),2)*BA28),2) -> 114364.41 | T28: =ROUND(CU28*I28,2) -> 0 | U28: =CV28*I28 -> 208 | V28: =CW28*I28 -> 0 | W28: =ROUND(CX28*I28,2) -> 0 | X28: =ROUND(CY28,2) -> 80055.09 | Y28: =ROUND(CZ28,2) -> 46889.41 | AA28: 55810748 | AB28: =ROUND((AC28+AD28+AF28),6) -> 828.488 | AC28: =ROUND((ES28),6) -> 0 | AD28: =ROUND((((ET28)-(EU28))+AE28),6) -> 0 | AE28: =ROUND((EU28),6) -> 0 | AF28: =ROUND(((EV28*0.8)),6) -> 828.488 | AG28: =ROUND((AP28),6) -> 0 | AH28: =((EW28*0.8)) -> 52 | AI28: =(EX28) -> 0 | AJ28: =(AS28) -> 0 | AK28: 1035.61 | AL28: 0 | AM28: 0 | AN28: 0 | AO28: 1035.61 | AP28: 0 | AQ28: 65 | AR28: 0 | AS28: 0 | AT28: 70 | AU28: 41 | AV28: 1 | AW28: 1 | AZ28: 1 | BA28: 34.51 | BB28: 1 | BC28: 1 | BH28: 0 | BI28: 4 | BJ28: ТСН-2001.5 Доп. 57, Сб. 10, т. 35, поз. 1 | BM28: 388 | BN28: 51696011 | BP28: 0 | BQ28: 50 | BR28: 0 | BS28: 34.51 | BT28: 1 | BU28: 1 | BV28: 1 | BW28: 1 | BX28: 1 | BZ28: 70 | CA28: 41 | CE28: 30 | CF28: 0 | CG28: 0 | CM28: 0 | CN28: Поправка: Гл.5.Прил.2.2.п.2.2.23_05.00.01.37.001 Наименование: При выполнении монтажных и пусконаладочных работ по какому-либо оборудованию одним и тем же звеном (бригадой) | CO28: 0 | CP28: =(P28+Q28+S28) -> 114364.41 | CQ28: =ROUND((ROUND((AC28*AW28*1),2)*BC28),2) -> 0 | CR28: =(ROUND((ROUND(((ET28)*AV28*1),2)*BB28),2)+ROUND((ROUND(((AE28-(EU28))*AV28*1),2)*BS28),2)) -> 0 | CS28: =ROUND((ROUND((AE28*AV28*1),2)*BS28),2) -> 0 | CT28: =ROUND((ROUND((AF28*AV28*1),2)*BA28),2) -> 28591.19 | CU28: =AG28 -> 0 | CV28: =(AH28*AV28) -> 52 | CW28: =AI28 -> 0 | CX28: =AJ28 -> 0 | CY28: =S28*(BZ28/100) -> 80055.087 | CZ28: =S28*(CA28/100) -> 46889.408 | DB28: 1 | DG28: *0,8 | DI28: *0,8 | DN28: 75 | DO28: 70 | DP28: 1 | DQ28: 1 | DU28: 27733102 | DV28: кабельная линия | DW28: кабельная линия | DX28: 0 | EE28: 51696427 | EF28: 50 | EG28: Пусконаладочные работы | EH28: 0 | EJ28: 4 | EK28: 388 | EL28: ТСН-2001.5-10. 10-4...10-44 | EM28: ТСН-2001.5-10-1 | EO28: Поправка: Гл.5.Прил.2.2.п.2.2.23_05.00.01.37.001 | EQ28: 131072 | ER28: 1035.61 | ES28: 0 | ET28: 0 | EU28: 0 | EV28: 1035.61 | EW28: 65 | EX28: 0 | EY28: 0 | FQ28: 0 | FR28: 0 | FS28: 0 | FX28: 75 | FY28: 70 | GD28: 0 | GF28: 1021334093 | GG28: 2 | GH28: 1 | GI28: 2 | GJ28: 0 | GK28: =ROUND(R28*(R12)/100,2) -> 0 | GL28: =ROUND(IF(AND(BH28=3,BI28=3,FS28<>0),P28,0),2) -> 0 | GM28: =ROUND(O28+X28+Y28+GK28,2)+GX28 -> 241308.91 | GN28: =IF(OR(BI28=0,BI28=1),GM28-GX28,0) -> 0 | GO28: =IF(BI28=2,GM28-GX28,0) -> 0 | GP28: =IF(BI28=4,GM28-GX28,0) -> 241308.91 | GR28: 0 | GS28: 3 | GT28: 0 | GV28: =ROUND((GT28),6) -> 0 | GW28: 1 | GX28: =ROUND(HC28*I28,2) -> 0 | HA28: 0 | HB28: 0 | HC28: =GV28*GW28 -> 0 | HS28: 0 | IK28: 0
A29: 17 | B29: 1 | D29: =ROW(EtalonRes!A2) -> 2 | E29: 2 | F29: 5.10-44-1 | G29: Кабельные линии, испытание оболочек из сшитого полиэтилена каждой строительной длины силовых кабелей на напряжение 10 кВ | H29: 1 испытание | I29: 12 | J29: 0 | K29: 12 | O29: =ROUND(CP29,2) -> 42989.11 | P29: =ROUND((ROUND((AC29*AW29*I29),2)*BC29),2) -> 0 | Q29: =(ROUND((ROUND(((ET29)*AV29*I29),2)*BB29),2)+ROUND((ROUND(((AE29-(EU29))*AV29*I29),2)*BS29),2)) -> 0 | R29: =ROUND((ROUND((AE29*AV29*I29),2)*BS29),2) -> 0 | S29: =ROUND((ROUND((AF29*AV29*I29),2)*BA29),2) -> 42989.11 | T29: =ROUND(CU29*I29,2) -> 0 | U29: =CV29*I29 -> 88.416 | V29: =CW29*I29 -> 0 | W29: =ROUND(CX29*I29,2) -> 0 | X29: =ROUND(CY29,2) -> 30092.38 | Y29: =ROUND(CZ29,2) -> 17625.54 | AA29: 55810748 | AB29: =ROUND((AC29+AD29+AF29),6) -> 103.808 | AC29: =ROUND((ES29),6) -> 0 | AD29: =ROUND((((ET29)-(EU29))+AE29),6) -> 0 | AE29: =ROUND((EU29),6) -> 0 | AF29: =ROUND(((EV29*0.8)),6) -> 103.808 | AG29: =ROUND((AP29),6) -> 0 | AH29: =((EW29*0.8)) -> 7.368 | AI29: =(EX29) -> 0 | AJ29: =(AS29) -> 0 | AK29: 129.76 | AL29: 0 | AM29: 0 | AN29: 0 | AO29: 129.76 | AP29: 0 | AQ29: 9.21 | AR29: 0 | AS29: 0 | AT29: 70 | AU29: 41 | AV29: 1 | AW29: 1 | AZ29: 1 | BA29: 34.51 | BB29: 1 | BC29: 1 | BH29: 0 | BI29: 4 | BJ29: ТСН-2001.5. Доп. 1-42. Сб. 10, т. 44, поз. 1 | BM29: 388 | BN29: 51696011 | BP29: 0 | BQ29: 50 | BR29: 0 | BS29: 34.51 | BT29: 1 | BU29: 1 | BV29: 1 | BW29: 1 | BX29: 1 | BZ29: 70 | CA29: 41 | CE29: 30 | CF29: 0 | CG29: 0 | CM29: 0 | CN29: Поправка: Гл.5.Прил.2.2.п.2.2.23_05.00.01.37.001 Наименование: При выполнении монтажных и пусконаладочных работ по какому-либо оборудованию одним и тем же звеном (бригадой) | CO29: 0 | CP29: =(P29+Q29+S29) -> 42989.11 | CQ29: =ROUND((ROUND((AC29*AW29*1),2)*BC29),2) -> 0 | CR29: =(ROUND((ROUND(((ET29)*AV29*1),2)*BB29),2)+ROUND((ROUND(((AE29-(EU29))*AV29*1),2)*BS29),2)) -> 0 | CS29: =ROUND((ROUND((AE29*AV29*1),2)*BS29),2) -> 0 | CT29: =ROUND((ROUND((AF29*AV29*1),2)*BA29),2) -> 3582.48 | CU29: =AG29 -> 0 | CV29: =(AH29*AV29) -> 7.368 | CW29: =AI29 -> 0 | CX29: =AJ29 -> 0 | CY29: =S29*(BZ29/100) -> 30092.377 | CZ29: =S29*(CA29/100) -> 17625.535 | DB29: 2 | DG29: *0,8 | DI29: *0,8 | DN29: 75 | DO29: 70 | DP29: 1 | DQ29: 1 | DU29: 1013 | DV29: 1 испытание | DW29: 1 испытание | DX29: 1 | EE29: 51696427 | EF29: 50 | EG29: Пусконаладочные работы | EH29: 0 | EJ29: 4 | EK29: 388 | EL29: ТСН-2001.5-10. 10-4...10-44 | EM29: ТСН-2001.5-10-1 | EO29: Поправка: Гл.5.Прил.2.2.п.2.2.23_05.00.01.37.001 | EQ29: 131072 | ER29: 129.76 | ES29: 0 | ET29: 0 | EU29: 0 | EV29: 129.76 | EW29: 9.21 | EX29: 0 | EY29: 0 | FQ29: 0 | FR29: 0 | FS29: 0 | FX29: 75 | FY29: 70 | GD29: 0 | GF29: 1017172134 | GG29: 2 | GH29: 1 | GI29: 2 | GJ29: 0 | GK29: =ROUND(R29*(R12)/100,2) -> 0 | GL29: =ROUND(IF(AND(BH29=3,BI29=3,FS29<>0),P29,0),2) -> 0 | GM29: =ROUND(O29+X29+Y29+GK29,2)+GX29 -> 90707.03 | GN29: =IF(OR(BI29=0,BI29=1),GM29-GX29,0) -> 0 | GO29: =IF(BI29=2,GM29-GX29,0) -> 0 | GP29: =IF(BI29=4,GM29-GX29,0) -> 90707.03 | GR29: 0 | GS29: 3 | GT29: 0 | GV29: =ROUND((GT29),6) -> 0 | GW29: 1 | GX29: =ROUND(HC29*I29,2) -> 0 | HA29: 0 | HB29: 0 | HC29: =GV29*GW29 -> 0 | HS29: 0 | IK29: 0
A30: 17 | B30: 1 | D30: =ROW(EtalonRes!A3) -> 3 | E30: 3 | F30: 5.1-162-1 | G30: Измерение сопротивления изоляции мегаомметром кабельных и других линий напряжением до 1 кВ, предназначенных для передачи электроэнергии к распределительным устройствам, щитам, шкафам и коммутационным аппаратам | H30: измерение | I30: 0 | J30: 0 | K30: 0 | O30: =ROUND(CP30,2) -> 0 | P30: =ROUND((ROUND((AC30*AW30*I30),2)*BC30),2) -> 0 | Q30: =(ROUND((ROUND(((ET30)*AV30*I30),2)*BB30),2)+ROUND((ROUND(((AE30-(EU30))*AV30*I30),2)*BS30),2)) -> 0 | R30: =ROUND((ROUND((AE30*AV30*I30),2)*BS30),2) -> 0 | S30: =ROUND((ROUND((AF30*AV30*I30),2)*BA30),2) -> 0 | T30: =ROUND(CU30*I30,2) -> 0 | U30: =CV30*I30 -> 0 | V30: =CW30*I30 -> 0 | W30: =ROUND(CX30*I30,2) -> 0 | X30: =ROUND(CY30,2) -> 0 | Y30: =ROUND(CZ30,2) -> 0 | AA30: 55810748 | AB30: =ROUND((AC30+AD30+AF30),6) -> 5.7 | AC30: =ROUND((ES30),6) -> 0 | AD30: =ROUND((((ET30)-(EU30))+AE30),6) -> 0 | AE30: =ROUND((EU30),6) -> 0 | AF30: =ROUND((EV30),6) -> 5.7 | AG30: =ROUND((AP30),6) -> 0 | AH30: =(EW30) -> 0.36 | AI30: =(EX30) -> 0 | AJ30: =(AS30) -> 0 | AK30: 5.7 | AL30: 0 | AM30: 0 | AN30: 0 | AO30: 5.7 | AP30: 0 | AQ30: 0.36 | AR30: 0 | AS30: 0 | AT30: 70 | AU30: 41 | AV30: 1 | AW30: 1 | AZ30: 1 | BA30: 34.51 | BB30: 1 | BC30: 1 | BH30: 0 | BI30: 4 | BJ30: ТСН-2001.5. Доп. 1-42. Сб. 1, т. 162, поз. 1 | BM30: 381 | BN30: 51696011 | BP30: 0 | BQ30: 50 | BR30: 0 | BS30: 34.51 | BT30: 1 | BU30: 1 | BV30: 1 | BW30: 1 | BX30: 1 | BZ30: 70 | CA30: 41 | CE30: 30 | CF30: 0 | CG30: 0 | CM30: 0 | CO30: 0 | CP30: =(P30+Q30+S30) -> 0 | CQ30: =ROUND((ROUND((AC30*AW30*1),2)*BC30),2) -> 0 | CR30: =(ROUND((ROUND(((ET30)*AV30*1),2)*BB30),2)+ROUND((ROUND(((AE30-(EU30))*AV30*1),2)*BS30),2)) -> 0 | CS30: =ROUND((ROUND((AE30*AV30*1),2)*BS30),2) -> 0 | CT30: =ROUND((ROUND((AF30*AV30*1),2)*BA30),2) -> 196.71 | CU30: =AG30 -> 0 | CV30: =(AH30*AV30) -> 0.36 | CW30: =AI30 -> 0 | CX30: =AJ30 -> 0 | CY30: =S30*(BZ30/100) -> 0 | CZ30: =S30*(CA30/100) -> 0 | DN30: 75 | DO30: 70 | DP30: 1 | DQ30: 1 | DU30: 1013 | DV30: измерение | DW30: измерение | DX30: 1 | EE30: 51696420 | EF30: 50 | EG30: Пусконаладочные работы | EH30: 0 | EJ30: 4 | EK30: 381 | EL30: ТСН-2001.5-1. 1-1...1-189 | EM30: ТСН-2001.5-1-1 | EQ30: 131072 | ER30: 5.7 | ES30: 0 | ET30: 0 | EU30: 0 | EV30: 5.7 | EW30: 0.36 | EX30: 0 | EY30: 0 | FQ30: 0 | FR30: 0 | FS30: 0 | FX30: 75 | FY30: 70 | GD30: 0 | GF30: -714386267 | GG30: 2 | GH30: 1 | GI30: 2 | GJ30: 0 | GK30: =ROUND(R30*(R12)/100,2) -> 0 | GL30: =ROUND(IF(AND(BH30=3,BI30=3,FS30<>0),P30,0),2) -> 0 | GM30: =ROUND(O30+X30+Y30+GK30,2)+GX30 -> 0 | GN30: =IF(OR(BI30=0,BI30=1),GM30-GX30,0) -> 0 | GO30: =IF(BI30=2,GM30-GX30,0) -> 0 | GP30: =IF(BI30=4,GM30-GX30,0) -> 0 | GR30: 0 | GS30: 3 | GT30: 0 | GV30: =ROUND((GT30),6) -> 0 | GW30: 1 | GX30: =ROUND(HC30*I30,2) -> 0 | HA30: 0 | HB30: 0 | HC30: =GV30*GW30 -> 0 | HS30: 0 | IK30: 0
A31: 17 | B31: 1 | D31: =ROW(EtalonRes!A4) -> 4 | E31: 4 | F31: 5.1-158-1 | G31: Фазировка электрической линии или трансформатора с сетью напряжением до 1 кВ | H31: фазировка | I31: 0 | J31: 0 | K31: 0 | O31: =ROUND(CP31,2) -> 0 | P31: =ROUND((ROUND((AC31*AW31*I31),2)*BC31),2) -> 0 | Q31: =(ROUND((ROUND(((ET31)*AV31*I31),2)*BB31),2)+ROUND((ROUND(((AE31-(EU31))*AV31*I31),2)*BS31),2)) -> 0 | R31: =ROUND((ROUND((AE31*AV31*I31),2)*BS31),2) -> 0 | S31: =ROUND((ROUND((AF31*AV31*I31),2)*BA31),2) -> 0 | T31: =ROUND(CU31*I31,2) -> 0 | U31: =CV31*I31 -> 0 | V31: =CW31*I31 -> 0 | W31: =ROUND(CX31*I31,2) -> 0 | X31: =ROUND(CY31,2) -> 0 | Y31: =ROUND(CZ31,2) -> 0 | AA31: 55810748 | AB31: =ROUND((AC31+AD31+AF31),6) -> 14.24 | AC31: =ROUND((ES31),6) -> 0 | AD31: =ROUND((((ET31)-(EU31))+AE31),6) -> 0 | AE31: =ROUND((EU31),6) -> 0 | AF31: =ROUND((EV31),6) -> 14.24 | AG31: =ROUND((AP31),6) -> 0 | AH31: =(EW31) -> 0.9 | AI31: =(EX31) -> 0 | AJ31: =(AS31) -> 0 | AK31: 14.24 | AL31: 0 | AM31: 0 | AN31: 0 | AO31: 14.24 | AP31: 0 | AQ31: 0.9 | AR31: 0 | AS31: 0 | AT31: 70 | AU31: 41 | AV31: 1 | AW31: 1 | AZ31: 1 | BA31: 34.51 | BB31: 1 | BC31: 1 | BH31: 0 | BI31: 4 | BJ31: ТСН-2001.5. Доп. 1-42. Сб. 1, т. 158, поз. 1 | BM31: 381 | BN31: 51696011 | BP31: 0 | BQ31: 50 | BR31: 0 | BS31: 34.51 | BT31: 1 | BU31: 1 | BV31: 1 | BW31: 1 | BX31: 1 | BZ31: 70 | CA31: 41 | CE31: 30 | CF31: 0 | CG31: 0 | CM31: 0 | CO31: 0 | CP31: =(P31+Q31+S31) -> 0 | CQ31: =ROUND((ROUND((AC31*AW31*1),2)*BC31),2) -> 0 | CR31: =(ROUND((ROUND(((ET31)*AV31*1),2)*BB31),2)+ROUND((ROUND(((AE31-(EU31))*AV31*1),2)*BS31),2)) -> 0 | CS31: =ROUND((ROUND((AE31*AV31*1),2)*BS31),2) -> 0 | CT31: =ROUND((ROUND((AF31*AV31*1),2)*BA31),2) -> 491.42 | CU31: =AG31 -> 0 | CV31: =(AH31*AV31) -> 0.9 | CW31: =AI31 -> 0 | CX31: =AJ31 -> 0 | CY31: =S31*(BZ31/100) -> 0 | CZ31: =S31*(CA31/100) -> 0 | DN31: 75 | DO31: 70 | DP31: 1 | DQ31: 1 | DU31: 1013 | DV31: фазировка | DW31: фазировка | DX31: 1 | EE31: 51696420 | EF31: 50 | EG31: Пусконаладочные работы | EH31: 0 | EJ31: 4 | EK31: 381 | EL31: ТСН-2001.5-1. 1-1...1-189 | EM31: ТСН-2001.5-1-1 | EQ31: 131072 | ER31: 14.24 | ES31: 0 | ET31: 0 | EU31: 0 | EV31: 14.24 | EW31: 0.9 | EX31: 0 | EY31: 0 | FQ31: 0 | FR31: 0 | FS31: 0 | FX31: 75 | FY31: 70 | GD31: 0 | GF31: 1878032076 | GG31: 2 | GH31: 1 | GI31: 2 | GJ31: 0 | GK31: =ROUND(R31*(R12)/100,2) -> 0 | GL31: =ROUND(IF(AND(BH31=3,BI31=3,FS31<>0),P31,0),2) -> 0 | GM31: =ROUND(O31+X31+Y31+GK31,2)+GX31 -> 0 | GN31: =IF(OR(BI31=0,BI31=1),GM31-GX31,0) -> 0 | GO31: =IF(BI31=2,GM31-GX31,0) -> 0 | GP31: =IF(BI31=4,GM31-GX31,0) -> 0 | GR31: 0 | GS31: 3 | GT31: 0 | GV31: =ROUND((GT31),6) -> 0 | GW31: 1 | GX31: =ROUND(HC31*I31,2) -> 0 | HA31: 0 | HB31: 0 | HC31: =GV31*GW31 -> 0 | HS31: 0 | IK31: 0
A32: 17 | B32: 1 | E32: 5 | F32: Калькуляция | G32: Поиск и определение кабеля в пучке 1 кабель | H32: кабель | I32: 0 | J32: 0 | K32: 0 | O32: =ROUND(CP32,2) -> 0 | P32: =ROUND((ROUND((AC32*AW32*I32),2)*BC32),2) -> 0 | Q32: =(ROUND((ROUND(((ET32)*AV32*I32),2)*BB32),2)+ROUND((ROUND(((AE32-(EU32))*AV32*I32),2)*BS32),2)) -> 0 | R32: =ROUND((ROUND((AE32*AV32*I32),2)*BS32),2) -> 0 | S32: =ROUND((ROUND((AF32*AV32*I32),2)*BA32),2) -> 0 | T32: =ROUND(CU32*I32,2) -> 0 | U32: =CV32*I32 -> 0 | V32: =CW32*I32 -> 0 | W32: =ROUND(CX32*I32,2) -> 0 | X32: =ROUND(CY32,2) -> 0 | Y32: =ROUND(CZ32,2) -> 0 | AA32: 55810748 | AB32: =ROUND((AC32+AD32+AF32),6) -> 393.19 | AC32: =ROUND(393.19,6) -> 393.19 | AD32: =ROUND((((ET32)-(EU32))+AE32),6) -> 0 | AE32: =ROUND((EU32),6) -> 0 | AF32: =ROUND((EV32),6) -> 0 | AG32: =ROUND((AP32),6) -> 0 | AH32: =(EW32) -> 0 | AI32: =(EX32) -> 0 | AJ32: =(AS32) -> 0 | AK32: 0 | AL32: 0 | AM32: 0 | AN32: 0 | AO32: 0 | AP32: 0 | AQ32: 0 | AR32: 0 | AS32: 0 | AT32: 0 | AU32: 0 | AV32: 1 | AW32: 1 | AZ32: 1 | BA32: 1 | BB32: 1 | BC32: 1 | BH32: 3 | BI32: 4 | BM32: 0 | BN32: 0 | BP32: 0 | BQ32: 0 | BR32: 0 | BS32: 1 | BT32: 1 | BU32: 1 | BV32: 1 | BW32: 1 | BX32: 1 | BZ32: 0 | CA32: 0 | CE32: 30 | CF32: 0 | CG32: 0 | CM32: 0 | CO32: 0 | CP32: =(P32+Q32+S32) -> 0 | CQ32: =ROUND((ROUND((AC32*AW32*1),2)*BC32),2) -> 393.19 | CR32: =(ROUND((ROUND(((ET32)*AV32*1),2)*BB32),2)+ROUND((ROUND(((AE32-(EU32))*AV32*1),2)*BS32),2)) -> 0 | CS32: =ROUND((ROUND((AE32*AV32*1),2)*BS32),2) -> 0 | CT32: =ROUND((ROUND((AF32*AV32*1),2)*BA32),2) -> 0 | CU32: =AG32 -> 0 | CV32: =(AH32*AV32) -> 0 | CW32: =AI32 -> 0 | CX32: =AJ32 -> 0 | CY32: =S32*(BZ32/100) -> 0 | CZ32: =S32*(CA32/100) -> 0 | DD32: =393,19 | DN32: 0 | DO32: 0 | DP32: 1 | DQ32: 1 | DU32: 1013 | DV32: кабель | DW32: кабель | DX32: 1 | EE32: 51696083 | EF32: 0 | EH32: 0 | EJ32: 4 | EK32: 0 | EL32: Прочие работы | EM32: МЦЦС | EQ32: 131072 | ER32: 0 | ES32: 0 | ET32: 0 | EU32: 0 | EV32: 0 | EW32: 0 | EX32: 0 | EY32: 0 | FQ32: 0 | FR32: 0 | FS32: 0 | FX32: 0 | FY32: 0 | GD32: 0 | GF32: -247210441 | GG32: 2 | GH32: 0 | GI32: 3 | GJ32: 0 | GK32: =ROUND(R32*(R12)/100,2) -> 0 | GL32: =ROUND(IF(AND(BH32=3,BI32=3,FS32<>0),P32,0),2) -> 0 | GM32: =ROUND(O32+X32+Y32+GK32,2)+GX32 -> 0 | GN32: =IF(OR(BI32=0,BI32=1),GM32-GX32,0) -> 0 | GO32: =IF(BI32=2,GM32-GX32,0) -> 0 | GP32: =IF(BI32=4,GM32-GX32,0) -> 0 | GR32: 0 | GS32: 0 | GT32: 0 | GV32: =ROUND((GT32),6) -> 0 | GW32: 1 | GX32: =ROUND(HC32*I32,2) -> 0 | HA32: 0 | HB32: 0 | HC32: =GV32*GW32 -> 0 | HS32: 0 | IK32: 0
A33: 17 | B33: 1 | E33: 6 | F33: Калькуляция | G33: Поиск и определение кабеля в пучке последующий | H33: кабель | I33: 0 | J33: 0 | K33: 0 | O33: =ROUND(CP33,2) -> 0 | P33: =ROUND((ROUND((AC33*AW33*I33),2)*BC33),2) -> 0 | Q33: =(ROUND((ROUND(((ET33)*AV33*I33),2)*BB33),2)+ROUND((ROUND(((AE33-(EU33))*AV33*I33),2)*BS33),2)) -> 0 | R33: =ROUND((ROUND((AE33*AV33*I33),2)*BS33),2) -> 0 | S33: =ROUND((ROUND((AF33*AV33*I33),2)*BA33),2) -> 0 | T33: =ROUND(CU33*I33,2) -> 0 | U33: =CV33*I33 -> 0 | V33: =CW33*I33 -> 0 | W33: =ROUND(CX33*I33,2) -> 0 | X33: =ROUND(CY33,2) -> 0 | Y33: =ROUND(CZ33,2) -> 0 | AA33: 55810748 | AB33: =ROUND((AC33+AD33+AF33),6) -> 322.25 | AC33: =ROUND(322.25,6) -> 322.25 | AD33: =ROUND((((ET33)-(EU33))+AE33),6) -> 0 | AE33: =ROUND((EU33),6) -> 0 | AF33: =ROUND((EV33),6) -> 0 | AG33: =ROUND((AP33),6) -> 0 | AH33: =(EW33) -> 0 | AI33: =(EX33) -> 0 | AJ33: =(AS33) -> 0 | AK33: 0 | AL33: 0 | AM33: 0 | AN33: 0 | AO33: 0 | AP33: 0 | AQ33: 0 | AR33: 0 | AS33: 0 | AT33: 0 | AU33: 0 | AV33: 1 | AW33: 1 | AZ33: 1 | BA33: 1 | BB33: 1 | BC33: 1 | BH33: 3 | BI33: 4 | BM33: 0 | BN33: 0 | BP33: 0 | BQ33: 0 | BR33: 0 | BS33: 1 | BT33: 1 | BU33: 1 | BV33: 1 | BW33: 1 | BX33: 1 | BZ33: 0 | CA33: 0 | CE33: 30 | CF33: 0 | CG33: 0 | CM33: 0 | CO33: 0 | CP33: =(P33+Q33+S33) -> 0 | CQ33: =ROUND((ROUND((AC33*AW33*1),2)*BC33),2) -> 322.25 | CR33: =(ROUND((ROUND(((ET33)*AV33*1),2)*BB33),2)+ROUND((ROUND(((AE33-(EU33))*AV33*1),2)*BS33),2)) -> 0 | CS33: =ROUND((ROUND((AE33*AV33*1),2)*BS33),2) -> 0 | CT33: =ROUND((ROUND((AF33*AV33*1),2)*BA33),2) -> 0 | CU33: =AG33 -> 0 | CV33: =(AH33*AV33) -> 0 | CW33: =AI33 -> 0 | CX33: =AJ33 -> 0 | CY33: =S33*(BZ33/100) -> 0 | CZ33: =S33*(CA33/100) -> 0 | DD33: =322,25 | DN33: 0 | DO33: 0 | DP33: 1 | DQ33: 1 | DU33: 1013 | DV33: кабель | DW33: кабель | DX33: 1 | EE33: 51696083 | EF33: 0 | EH33: 0 | EJ33: 4 | EK33: 0 | EL33: Прочие работы | EM33: МЦЦС | EQ33: 131072 | ER33: 0 | ES33: 0 | ET33: 0 | EU33: 0 | EV33: 0 | EW33: 0 | EX33: 0 | EY33: 0 | FQ33: 0 | FR33: 0 | FS33: 0 | FX33: 0 | FY33: 0 | GD33: 0 | GF33: -551642664 | GG33: 2 | GH33: 0 | GI33: 3 | GJ33: 0 | GK33: =ROUND(R33*(R12)/100,2) -> 0 | GL33: =ROUND(IF(AND(BH33=3,BI33=3,FS33<>0),P33,0),2) -> 0 | GM33: =ROUND(O33+X33+Y33+GK33,2)+GX33 -> 0 | GN33: =IF(OR(BI33=0,BI33=1),GM33-GX33,0) -> 0 | GO33: =IF(BI33=2,GM33-GX33,0) -> 0 | GP33: =IF(BI33=4,GM33-GX33,0) -> 0 | GR33: 0 | GS33: 0 | GT33: 0 | GV33: =ROUND((GT33),6) -> 0 | GW33: 1 | GX33: =ROUND(HC33*I33,2) -> 0 | HA33: 0 | HB33: 0 | HC33: =GV33*GW33 -> 0 | HS33: 0 | IK33: 0
A34: 17 | B34: 1 | E34: 7 | F34: 2.1-8-3 | G34: Автолаборатории | H34: маш.-ч | I34: 8 | J34: 0 | K34: 8 | O34: =ROUND(CP34,2) -> 19572.71 | P34: =ROUND((ROUND((AC34*AW34*I34),2)*BC34),2) -> 0 | Q34: =(ROUND((ROUND(((ET34)*AV34*I34),2)*BB34),2)+ROUND((ROUND(((AE34-(EU34))*AV34*I34),2)*BS34),2)) -> 19572.71 | R34: =ROUND((ROUND((AE34*AV34*I34),2)*BS34),2) -> 3484.13 | S34: =ROUND((ROUND((AF34*AV34*I34),2)*BA34),2) -> 0 | T34: =ROUND(CU34*I34,2) -> 0 | U34: =CV34*I34 -> 0 | V34: =CW34*I34 -> 0 | W34: =ROUND(CX34*I34,2) -> 0 | X34: =ROUND(CY34,2) -> 0 | Y34: =ROUND(CZ34,2) -> 0 | AA34: 55810748 | AB34: =ROUND((AC34+AD34+AF34),6) -> 247.38 | AC34: =ROUND((ES34),6) -> 0 | AD34: =ROUND((((ET34)-(EU34))+AE34),6) -> 247.38 | AE34: =ROUND((EU34),6) -> 12.62 | AF34: =ROUND((EV34),6) -> 0 | AG34: =ROUND((AP34),6) -> 0 | AH34: =(EW34) -> 0 | AI34: =(EX34) -> 0 | AJ34: =(AS34) -> 0 | AK34: 247.38 | AL34: 0 | AM34: 247.38 | AN34: 12.62 | AO34: 0 | AP34: 0 | AQ34: 0 | AR34: 0 | AS34: 0 | AT34: 0 | AU34: 0 | AV34: 1 | AW34: 1 | AZ34: 1 | BA34: 1 | BB34: 9.89 | BC34: 1 | BH34: 2 | BI34: 1 | BJ34: ТСН-2001.2. Доп. 68. п.1-8-3 (085001) | BM34: 400001 | BN34: 51696011 | BO34: 2.1-8-3 | BP34: 1 | BQ34: 190 | BR34: 0 | BS34: 34.51 | BT34: 1 | BU34: 1 | BV34: 1 | BW34: 1 | BX34: 1 | BZ34: 0 | CA34: 0 | CE34: 30 | CF34: 0 | CG34: 0 | CM34: 0 | CO34: 0 | CP34: =(P34+Q34+S34) -> 19572.71 | CQ34: =ROUND((ROUND((AC34*AW34*1),2)*BC34),2) -> 0 | CR34: =(ROUND((ROUND(((ET34)*AV34*1),2)*BB34),2)+ROUND((ROUND(((AE34-(EU34))*AV34*1),2)*BS34),2)) -> 2446.59 | CS34: =ROUND((ROUND((AE34*AV34*1),2)*BS34),2) -> 435.52 | CT34: =ROUND((ROUND((AF34*AV34*1),2)*BA34),2) -> 0 | CU34: =AG34 -> 0 | CV34: =(AH34*AV34) -> 0 | CW34: =AI34 -> 0 | CX34: =AJ34 -> 0 | CY34: =S34*(BZ34/100) -> 0 | CZ34: =S34*(CA34/100) -> 0 | DN34: 0 | DO34: 0 | DP34: 1 | DQ34: 1 | DU34: 1011 | DV34: маш.-ч | DW34: маш.-ч | DX34: 1 | EE34: 51697852 | EF34: 190 | EG34: Механизмы | EH34: 0 | EJ34: 1 | EK34: 400001 | EL34: ТСН-2001. Машины и механизмы | EM34: ТСН-2001.2 | EQ34: 131072 | ER34: 247.38 | ES34: 0 | ET34: 247.38 | EU34: 12.62 | EV34: 0 | EW34: 0 | EX34: 0 | EY34: 0 | FQ34: 0 | FR34: 0 | FS34: 0 | FX34: 0 | FY34: 0 | GD34: 0 | GF34: 464312783 | GG34: 2 | GH34: 1 | GI34: 2 | GJ34: 0 | GK34: =ROUND(R34*(R12)/100,2) -> 5574.61 | GL34: =ROUND(IF(AND(BH34=3,BI34=3,FS34<>0),P34,0),2) -> 0 | GM34: =ROUND(O34+X34+Y34+GK34,2)+GX34 -> 25147.32 | GN34: =IF(OR(BI34=0,BI34=1),GM34-GX34,0) -> 25147.32 | GO34: =IF(BI34=2,GM34-GX34,0) -> 0 | GP34: =IF(BI34=4,GM34-GX34,0) -> 0 | GR34: 0 | GS34: 3 | GT34: 0 | GV34: =ROUND((GT34),6) -> 0 | GW34: 1 | GX34: =ROUND(HC34*I34,2) -> 0 | HA34: 0 | HB34: 0 | HC34: =GV34*GW34 -> 0 | HS34: 0 | IK34: 0
A36: 51 | B36: =B24 -> 1 | C36: =A24 -> 4 | D36: =ROW(A24) -> 24 | F36: =IF(F24<>"",F24,"") -> Новый раздел | G36: =IF(G24<>"",G24,"") -> Пусконаладочные работы | H36: 0 | O36: =ROUND(AB36,2) -> 176926.23 | P36: =ROUND(AC36,2) -> 0 | Q36: =ROUND(AD36,2) -> 19572.71 | R36: =ROUND(AE36,2) -> 3484.13 | S36: =ROUND(AF36,2) -> 157353.52 | T36: =ROUND(AG36,2) -> 0 | U36: =AH36 -> 296.416 | V36: =AI36 -> 0 | W36: =ROUND(AJ36,2) -> 0 | X36: =ROUND(AK36,2) -> 110147.47 | Y36: =ROUND(AL36,2) -> 64514.95 | AB36: =ROUND(SUMIF(AA28:AA34,"=55810748",O28:O34),2) -> 176926.23 | AC36: =ROUND(SUMIF(AA28:AA34,"=55810748",P28:P34),2) -> 0 | AD36: =ROUND(SUMIF(AA28:AA34,"=55810748",Q28:Q34),2) -> 19572.71 | AE36: =ROUND(SUMIF(AA28:AA34,"=55810748",R28:R34),2) -> 3484.13 | AF36: =ROUND(SUMIF(AA28:AA34,"=55810748",S28:S34),2) -> 157353.52 | AG36: =ROUND(SUMIF(AA28:AA34,"=55810748",T28:T34),2) -> 0 | AH36: =SUMIF(AA28:AA34,"=55810748",U28:U34) -> 296.416 | AI36: =SUMIF(AA28:AA34,"=55810748",V28:V34) -> 0 | AJ36: =ROUND(SUMIF(AA28:AA34,"=55810748",W28:W34),2) -> 0 | AK36: =ROUND(SUMIF(AA28:AA34,"=55810748",X28:X34),2) -> 110147.47 | AL36: =ROUND(SUMIF(AA28:AA34,"=55810748",Y28:Y34),2) -> 64514.95 | AO36: =ROUND(BX36,2) -> 0 | AP36: =ROUND(BY36,2) -> 0 | AQ36: =ROUND(BZ36,2) -> 0 | AR36: =ROUND(CA36,2) -> 357163.26 | AS36: =ROUND(CB36,2) -> 25147.32 | AT36: =ROUND(CC36,2) -> 0 | AU36: =ROUND(CD36,2) -> 332015.94 | AV36: =ROUND(CE36,2) -> 0 | ... BD36: =ROUND(CM36,2) -> 0 | BX36: =ROUND(SUMIF(AA28:AA34,"=55810748",FQ28:FQ34),2) -> 0 | BY36: =ROUND(SUMIF(AA28:AA34,"=55810748",FR28:FR34),2) -> 0 | BZ36: =ROUND(SUMIF(AA28:AA34,"=55810748",GL28:GL34),2) -> 0 | CA36: =ROUND(SUMIF(AA28:AA34,"=55810748",GM28:GM34),2) -> 357163.26 | CB36: =ROUND(SUMIF(AA28:AA34,"=55810748",GN28:GN34),2) -> 25147.32 | CC36: =ROUND(SUMIF(AA28:AA34,"=55810748",GO28:GO34),2) -> 0 | CD36: =ROUND(SUMIF(AA28:AA34,"=55810748",GP28:GP34),2) -> 332015.94 | CE36: =AC36-BX36 -> 0 | CF36: =AC36-BY36 -> 0 | CG36: =BX36-BZ36 -> 0 | CH36: =AC36-BX36-BY36+BZ36 -> 0 | CI36: =BY36-BZ36 -> 0 | CJ36: =ROUND(SUMIF(AA28:AA34,"=55810748",GX28:GX34),2) -> 0 | CK36: =ROUND(SUMIF(AA28:AA34,"=55810748",GY28:GY34),2) -> 0 | CL36: =ROUND(SUMIF(AA28:AA34,"=55810748",GZ28:GZ34),2) -> 0 | CM36: =ROUND(SUMIF(AA28:AA34,"=55810748",HD28:HD34),2) -> 0 | GX36: 0
A38: 50 | B38: 0 | C38: 0 | D38: 1 | E38: 201 | F38: =ROUND(Source!O36,O38) -> 176926.23 | G38: ПЗ | H38: Прямые затраты | K38: 201 | L38: 1 | M38: 3 | O38: 2 | W38: 176926.23 | X38: 1 | Y38: 176926.23
A39: 50 | B39: 0 | C39: 0 | D39: 1 | E39: 202 | F39: =ROUND(Source!P36,O39) -> 0 | G39: СтМатОб | H39: Стоимость материальных ресурсов (всего) | K39: 202 | L39: 2 | M39: 3 | O39: 2 | W39: 0 | X39: 1 | Y39: 0
A40: 50 | B40: 0 | C40: 0 | D40: 1 | E40: 227 | F40: =ROUND(Source!AO36,O40) -> 0 | G40: СтМатОбЗак | H40: Стоимость материалов и оборудования заказчика | K40: 222 | L40: 3 | M40: 3 | O40: 2 | W40: 0 | X40: 1 | Y40: 0
A41: 50 | B41: 0 | C41: 0 | D41: 1 | E41: 225 | F41: =ROUND(Source!AV36,O41) -> 0 | G41: СтМатОбПод | H41: Стоимость материалов и оборудования подрядчика | K41: 225 | L41: 4 | M41: 3 | O41: 2 | W41: 0 | X41: 1 | Y41: 0
A42: 50 | B42: 0 | C42: 0 | D42: 1 | E42: 226 | F42: =ROUND(Source!AW36,O42) -> 0 | G42: СтМат | H42: Стоимость материалов (всего) | K42: 226 | L42: 5 | M42: 3 | O42: 2 | W42: 0 | X42: 1 | Y42: 0
A43: 50 | B43: 0 | C43: 0 | D43: 1 | E43: 0 | F43: =ROUND(Source!AX36,O43) -> 0 | G43: СтМатЗак | H43: Стоимость материалов заказчика | K43: 227 | L43: 6 | M43: 3 | O43: 2 | W43: 0 | X43: 1 | Y43: 0
A44: 50 | B44: 0 | C44: 0 | D44: 1 | E44: 228 | F44: =ROUND(Source!AY36,O44) -> 0 | G44: СтМатПод | H44: Стоимость материалов подрядчика | K44: 228 | L44: 7 | M44: 3 | O44: 2 | W44: 0 | X44: 1 | Y44: 0
A45: 50 | B45: 0 | C45: 0 | D45: 1 | E45: 216 | F45: =ROUND(Source!AP36,O45) -> 0 | G45: Оборуд | H45: Стоимость оборудования (всего) | K45: 216 | L45: 8 | M45: 3 | O45: 2 | W45: 0 | X45: 1 | Y45: 0
A46: 50 | B46: 0 | C46: 0 | D46: 1 | E46: 223 | F46: =ROUND(Source!AQ36,O46) -> 0 | G46: ОборудЗак | H46: Стоимость оборудования заказчика | K46: 223 | L46: 9 | M46: 3 | O46: 2 | W46: 0 | X46: 1 | Y46: 0
A47: 50 | B47: 0 | C47: 0 | D47: 1 | E47: 229 | F47: =ROUND(Source!AZ36,O47) -> 0 | G47: ОборудПод | H47: Стоимость оборудования подрядчика | K47: 229 | L47: 10 | M47: 3 | O47: 2 | W47: 0 | X47: 1 | Y47: 0
A48: 50 | B48: 0 | C48: 0 | D48: 1 | E48: 203 | F48: =ROUND(Source!Q36,O48) -> 19572.71 | G48: ЭММ | H48: Эксплуатация машин | K48: 203 | L48: 11 | M48: 3 | O48: 2 | W48: 19572.71 | X48: 1 | Y48: 19572.71
A49: 50 | B49: 0 | C49: 0 | D49: 1 | E49: 231 | F49: =ROUND(Source!BB36,O49) -> 0 | G49: ЭММсНРиСП | H49: Эксплуатация машин по ТСН-2001.16 | K49: 231 | L49: 12 | M49: 3 | O49: 2 | W49: 0 | X49: 1 | Y49: 0
A50: 50 | B50: 0 | C50: 0 | D50: 1 | E50: 204 | F50: =ROUND(Source!R36,O50) -> 3484.13 | G50: ЗПМ | H50: ЗП машинистов | K50: 204 | L50: 13 | M50: 3 | O50: 2 | W50: 3484.13 | X50: 1 | Y50: 3484.13
A51: 50 | B51: 0 | C51: 0 | D51: 1 | E51: 205 | F51: =ROUND(Source!S36,O51) -> 157353.52 | G51: ОЗП | H51: Основная ЗП рабочих | K51: 205 | L51: 14 | M51: 3 | O51: 2 | W51: 157353.52 | X51: 1 | Y51: 157353.52
A52: 50 | B52: 0 | C52: 0 | D52: 1 | E52: 232 | F52: =ROUND(Source!BC36,O52) -> 0 | G52: ОЗПсНРиСП | H52: Основная ЗП рабочих по ТСН-2001.16 | K52: 232 | L52: 15 | M52: 3 | O52: 2 | W52: 0 | X52: 1 | Y52: 0
A53: 50 | B53: 0 | C53: 0 | D53: 1 | E53: 214 | F53: =ROUND(Source!AS36,O53) -> 25147.32 | G53: Строит | H53: Строительные работы с НР и СП | K53: 214 | L53: 16 | M53: 3 | O53: 2 | W53: 25147.32 | X53: 1 | Y53: 25147.32
A54: 50 | B54: 0 | C54: 0 | D54: 1 | E54: 215 | F54: =ROUND(Source!AT36,O54) -> 0 | G54: Монтаж | H54: Монтажные работы с НР и СП | K54: 215 | L54: 17 | M54: 3 | O54: 2 | W54: 0 | X54: 1 | Y54: 0
A55: 50 | B55: 0 | C55: 0 | D55: 1 | E55: 217 | F55: =ROUND(Source!AU36,O55) -> 332015.94 | G55: Прочие | H55: Прочие работы с НР и СП | K55: 217 | L55: 18 | M55: 3 | O55: 2 | W55: 332015.94 | X55: 1 | Y55: 332015.94
A56: 50 | B56: 0 | C56: 0 | D56: 1 | E56: 230 | F56: =ROUND(Source!BA36,O56) -> 0 | G56: ПрочиеЗатр | H56: Прочие затраты по ТСН-2001.16 | K56: 230 | L56: 19 | M56: 3 | O56: 2 | W56: 0 | X56: 1 | Y56: 0
A57: 50 | B57: 0 | C57: 0 | D57: 1 | E57: 206 | F57: =ROUND(Source!T36,O57) -> 0 | G57: ВозврМат | H57: Возврат материалов | K57: 206 | L57: 20 | M57: 3 | O57: 2 | W57: 0 | X57: 1 | Y57: 0
A58: 50 | B58: 0 | C58: 0 | D58: 1 | E58: 207 | F58: =ROUND(Source!U36,O58) -> 296.42 | G58: ТрудСтр | H58: Трудозатраты строителей | K58: 207 | L58: 21 | M58: 3 | O58: 2 | W58: 296.42 | X58: 1 | Y58: 296.42
A59: 50 | B59: 0 | C59: 0 | D59: 1 | E59: 208 | F59: =ROUND(Source!V36,O59) -> 0 | G59: ТрудМаш | H59: Трудозатраты машинистов | K59: 208 | L59: 22 | M59: 3 | O59: 2 | W59: 0 | X59: 1 | Y59: 0
A60: 50 | B60: 0 | C60: 0 | D60: 1 | E60: 209 | F60: =ROUND(Source!W36,O60) -> 0 | G60: ТранспМат | H60: Транспорт материалов | K60: 209 | L60: 23 | M60: 3 | O60: 2 | W60: 0 | X60: 1 | Y60: 0
A61: 50 | B61: 0 | C61: 0 | D61: 1 | E61: 233 | F61: =ROUND(Source!BD36,O61) -> 0 | G61: Перевозка | H61: Перевозка грузов | K61: 233 | L61: 24 | M61: 3 | O61: 2 | W61: 0 | X61: 1 | Y61: 0
...

Sheet SourceObSm
A1: 0 | B1: Smeta.RU (495) 974-1589 | D1: _OBSM_ | F1: 0 | G1: 0 | H1: 0 | I1: Smeta.RU | K1: 1 | L1: 47858 | M1: 10 | N1: 11 | O1: 14 | P1: 0 | Q1: 1
A12: 1 | B12: 51 | C12: 0 | E12: 0 | F12: (ТСН-2001 (Мосгосэкспертиза)) (ТСН-2001 (Мосгосэкспертиза)) (ТСН-2001 (Мосгосэкспертиза)) | G12: 09-01-02 ПНР КЛ 10 кВ (ТСН-2001 (Мосгосэкспертиза)) (ТСН-2001 (Мосгосэкспертиза)) | I12: 0 | K12: 0 | L12: 0 | M12: 4098 | O12: 0 | P12: 0 | Q12: 0 | R12: 160 | T12: 1 | V12: 0 | BB12: 0 | BH12: Сметные нормы списания | BI12: Коды ОКП для ТСН-2001 МГЭ (История развития) | BJ12: 1 | BK12: 1 | BL12: 0 | BM12: 0 | BN12: 1 | BO12: 0 | BP12: 6 | BQ12: 2 | BR12: 1 | BS12: 1 | BT12: 0 | BU12: 0 | BV12: 0 | BW12: 0 | BX12: 0 | BZ12: Типовой расчет для ТСН-2001 МГЭ, Новая методика с выпуска доп. 43 (Строительство), Доп 73 | CA12: История развития для ТСН-2001 (МГЭ) 73 доп от 17.07.2024 | CB12: История развития для ТСН-2001 (МГЭ) 73 доп от 17.07.2024 | CC12: История развития для ТСН-2001 (МГЭ) 73 доп от 17.07.2024 | CD12: История развития для ТСН-2001 (МГЭ) 73 доп от 17.07.2024 | CE12: Поправки для ТСН-2001 от 16.04.2024 г. доп.72 | CF12: 0 | CG12: 0 | CH12: 8 | CK12: 77 | CQ12: Территориальные сметные нормативы для Москвы (ТСН-2001) | CR12: ТЕР | CS12: 41660 | CT12: 1 | CU12: 73 | CY12: 0 | EC12: 0
A14: 22 | B14: 1 | C14: 0 | D14: 55810748 | E14: 0 | F14: 2 | G14: 1
A16: 3 | B16: 1 | C16: Новая локальная смета | D16: Новая локальная смета | E16: =ROUND((Source!F83)/1000,2) -> 25.15 | F16: =ROUND((Source!F84)/1000,2) -> 0 | G16: =ROUND((Source!F75)/1000,2) -> 0 | H16: =ROUND((Source!F85)/1000+(Source!F86)/1000,2) -> 332.02 | I16: =E16+F16+G16+H16 -> 357.17 | J16: =ROUND((Source!F81+Source!F80)/1000,2) -> 160.84 | K16: 176.93 | L16: 0 | M16: 0 | N16: =I16+L16+M16 -> 357.17 | AI16: 0 | AJ16: 0 | AN16: 0 | AT16: 176926.23 | AU16: 0 | AW16: 0 | AX16: 0 | AY16: 19572.71 | AZ16: 3484.13 | BA16: 157353.52 | BB16: 25147.32 | BC16: 0 | BD16: 332015.94 | BE16: 0 | BF16: 296.42 | BG16: 0 | BH16: 0 | BI16: 110147.47 | BJ16: 64514.95 | BK16: 357163.26
A18: 51 | E18: 25.15 | F18: 0 | G18: 0 | H18: 332.02 | I18: 357.17 | J18: 160.84 | K18: 176.93 | L18: 0 | M18: 0 | N18: 357.17
A20: 50 | B20: 0 | C20: 0 | D20: 1 | E20: 201 | F20: 176926.23 | G20: ПЗ | H20: Прямые затраты | K20: 201 | L20: 1 | M20: 3 | O20: 2
A21: 50 | B21: 0 | C21: 0 | D21: 1 | E21: 202 | F21: 0 | G21: СтМатОб | H21: Стоимость материальных ресурсов (всего) | K21: 202 | L21: 2 | M21: 3 | O21: 2
A22: 50 | B22: 0 | C22: 0 | D22: 1 | E22: 227 | F22: 0 | G22: СтМатОбЗак | H22: Стоимость материалов и оборудования заказчика | K22: 222 | L22: 3 | M22: 3 | O22: 2
A23: 50 | B23: 0 | C23: 0 | D23: 1 | E23: 225 | F23: 0 | G23: СтМатОбПод | H23: Стоимость материалов и оборудования подрядчика | K23: 225 | L23: 4 | M23: 3 | O23: 2
A24: 50 | B24: 0 | C24: 0 | D24: 1 | E24: 226 | F24: 0 | G24: СтМат | H24: Стоимость материалов (всего) | K24: 226 | L24: 5 | M24: 3 | O24: 2
A25: 50 | B25: 0 | C25: 0 | D25: 1 | E25: 0 | F25: 0 | G25: СтМатЗак | H25: Стоимость материалов заказчика | K25: 227 | L25: 6 | M25: 3 | O25: 2
A26: 50 | B26: 0 | C26: 0 | D26: 1 | E26: 228 | F26: 0 | G26: СтМатПод | H26: Стоимость материалов подрядчика | K26: 228 | L26: 7 | M26: 3 | O26: 2
A27: 50 | B27: 0 | C27: 0 | D27: 1 | E27: 216 | F27: 0 | G27: Оборуд | H27: Стоимость оборудования (всего) | K27: 216 | L27: 8 | M27: 3 | O27: 2
A28: 50 | B28: 0 | C28: 0 | D28: 1 | E28: 223 | F28: 0 | G28: ОборудЗак | H28: Стоимость оборудования заказчика | K28: 223 | L28: 9 | M28: 3 | O28: 2
A29: 50 | B29: 0 | C29: 0 | D29: 1 | E29: 229 | F29: 0 | G29: ОборудПод | H29: Стоимость оборудования подрядчика | K29: 229 | L29: 10 | M29: 3 | O29: 2
A30: 50 | B30: 0 | C30: 0 | D30: 1 | E30: 203 | F30: 19572.71 | G30: ЭММ | H30: Эксплуатация машин | K30: 203 | L30: 11 | M30: 3 | O30: 2
A31: 50 | B31: 0 | C31: 0 | D31: 1 | E31: 231 | F31: 0 | G31: ЭММсНРиСП | H31: Эксплуатация машин по ТСН-2001.16 | K31: 231 | L31: 12 | M31: 3 | O31: 2
... A46: 50 | B46: 0 | C46: 0 | D46: 1 | E46: 224 | F46: 357163.26 | G46: Всего | H46: Всего с НР и СП | K46: 224 | L46: 27 | M46: 3 | O46: 2
A48: -1
A51: 75 | B51: Уровень цен | C51: 2024 | D51: 0 | E51: 4 | G51: 0 | H51: 2 | I51: 1 | J51: 1 | K51: 95 | L51: 65 | M51: 0 | N51: 55810748 | O51: 1
A52: 1 | B52: Сборник индексов | C52: Коэффициенты к ТСН-2001 МГЭ | D52: 2024 | E52: 7 | F52: 1 | G52: 1 | H52: 0 | I52: 2 | J52: 1 | K52: 1 | L52: 1 | M52: 1 | N52: 1 | O52: 1 | P52: 1 | Q52: 1 | AA52: 212 | AN52: 55810749

Sheet SmtRes
I126: 0
I127: 0

Sheet EtalonRes
A1: =ROW(Source!A28) -> 28 | B1: 55810873 | C1: 55810862 | D1: 39569243 | E1: 27786564 | F1: 1 | G1: 27786564 | H1: 1 | I1: 9999990008 | K1: Трудозатраты рабочих | L1: 1191 | N1: 1013 | O1: чел.-ч. | P1: чел.-ч. | Q1: 1 | X1: 65 | Y1: 0 | Z1: 0 | AA1: 0 | AB1: 0 | AC1: 0 | AD1: 1 | AE1: 1 | AF1: *0,8 | AG1: 52 | AH1: 3 | AI1: -1 | AK1: 0 | AL1: 0 | AM1: 0 | AN1: 0 | AO1: 0 | AP1: 0 | AQ1: 0 | AR1: 0
A2: =ROW(Source!A29) -> 29 | B2: 55810874 | C2: 55810864 | D2: 30359939 | E2: 27786564 | F2: 1 | G2: 27786564 | H2: 1 | I2: 9999990008 | K2: Трудозатраты рабочих | L2: 1191 | N2: 1013 | O2: чел.-ч. | P2: чел.-ч. | Q2: 1 | X2: 9.21 | Y2: 0 | Z2: 0 | AA2: 0 | AB2: 0 | AC2: 0 | AD2: 1 | AE2: 1 | AF2: *0,8 | AG2: 7.368 | AH2: 3 | AI2: -1 | AK2: 0 | AL2: 0 | AM2: 0 | AN2: 0 | AO2: 0 | AP2: 0 | AQ2: 0 | AR2: 0
A3: =ROW(Source!A30) -> 30 | B3: 55810875 | C3: 55810866 | D3: 30359939 | E3: 27786564 | F3: 1 | G3: 27786564 | H3: 1 | I3: 9999990008 | K3: Трудозатраты рабочих | L3: 1191 | N3: 1013 | O3: чел.-ч. | P3: чел.-ч. | Q3: 1 | X3: 0.36 | Y3: 0 | Z3: 0 | AA3: 0 | AB3: 0 | AC3: 0 | AD3: 1 | AE3: 1 | AG3: 0.36 | AH3: 3 | AI3: -1 | AK3: 0 | AL3: 0 | AM3: 0 | AN3: 0 | AO3: 0 | AP3: 0 | AQ3: 0 | AR3: 0
A4: =ROW(Source!A31) -> 31 | B4: 55810876 | C4: 55810868 | D4: 30359939 | E4: 27786564 | F4: 1 | G4: 27786564 | H4: 1 | I4: 9999990008 | K4: Трудозатраты рабочих | L4: 1191 | N4: 1013 | O4: чел.-ч. | P4: чел.-ч. | Q4: 1 | X4: 0.9 | Y4: 0 | Z4: 0 | AA4: 0 | AB4: 0 | AC4: 0 | AD4: 1 | AE4: 1 | AG4: 0.9 | AH4: 3 | AI4: -1 | AK4: 0 | AL4: 0 | AM4: 0 | AN4: 0 | AO4: 0 | AP4: 0 | AQ4: 0 | AR4: 0

Sheet SrcPoprs
A1: 28 | B1: 1 | G1: *0,8 | I1: *0,8 | S1: Гл.5.Прил.2.2.п.2.2.23_05.00.01.37.001 | T1: При выполнении монтажных и пусконаладочных работ по какому-либо оборудованию одним и тем же звеном (бригадой) | U1: Глава 5
A2: 29 | B2: 1 | G2: *0,8 | I2: *0,8 | S2: Гл.5.Прил.2.2.п.2.2.23_05.00.01.37.001 | T2: При выполнении монтажных и пусконаладочных работ по какому-либо оборудованию одним и тем же звеном (бригадой) | U2: Глава 5

Sheet SrcKA
A1: 0 | B1: Smeta.RU (495) 974-1589 | D1: _PS_ | F1: 0 | G1: 0 | H1: 0 | I1: Smeta.RU | K1: 1 | L1: 47858 | M1: 10 | N1: 11 | O1: 14 | P1: 0 | Q1: 1
F12: =Source!F12 -> (ТСН-2001 (Мосгосэкспертиза)) (ТСН-2001 (Мосгосэкспертиза)) (ТСН-2001 (Мосгосэкспертиза)) | G12: =Source!G12 -> 09-01-02 ПНР КЛ 10 кВ (ТСН-2001 (Мосгосэкспертиза)) (ТСН-2001 (Мосгосэкспертиза)) | CY12: =Source!CY12 -> 0
