Workbook

Sheet Смета по ТСН-2001(с доп.67
A1: =[1]Source!B1 -> Smeta.RU (495) 974-1589
J2: Форма № 4б
A3: ПИР, СМР, ПНР, материалы, оборудование (за исключением замков, предоставляемых Заказчиком) по титулу: Строительство ТП-10/0,4кВ с тр-ми 2х400кВА, 4КЛ-10кВ от ТП-10/0,4кВ луч А,Б до КЛ-10кВ направлением ТП-10/0,4кВ № № 21782 - ТП-10/0,4кВ № 24478 луч А,Б, 8КЛ-0,4кВ от ТП-10/0,4кВ до ВРЩ-0,4кВ №1-3, в т.ч. ПИР: г.Москва, ул.Феодосийская, з/у 7 для нужд МКС – филиала ПАО «Россети Московский регион»
A4: (наименование стройки и/или объекта)
A6: ЛОКАЛЬНАЯ СМЕТА № 09-01-01 | AP6: =CONCATENATE( "ЛОКАЛЬНАЯ СМЕТА № ",IF([1]Source!F12<>"Новый объект", [1]Source!F12, "")) -> ЛОКАЛЬНАЯ СМЕТА № (ТСН-2001 (Мосгосэкспертиза)) (ТСН-2001 (Мосгосэкспертиза)) (ТСН-2001 (Мосгосэкспертиза))
A8: ПНР ТП
A9: (наименование работ и затрат)
A11: =CONCATENATE( "Основание: чертежи № ", [1]Source!J12) -> Основание: чертежи №
I13: В базисном уровне цен | J13: В текущем уровне цен
E14: Сметная стоимость | I14: =I15+I16+I17+I18 -> 16.34 | J14: =J15+J16+J17+J18 -> 446.51 | K14: тыс.руб.
E15: Строительные работы | I15: =ROUND(SUM(X1:X52)/1000, 2) -> 2.16 | J15: =ROUND((Source!F74)/1000, 2) -> 25.15 | K15: тыс.руб.
E16: Работы по монтажу оборудования | I16: =ROUND(SUM(Y1:Y52)/1000, 2) -> 0 | J16: =ROUND((Source!F75)/1000, 2) -> 0 | K16: тыс.руб.
E17: Оборудование | I17: =ROUND(SUM(Z1:Z52)/1000, 2) -> 0 | J17: =ROUND((Source!F66)/1000, 2) -> 0 | K17: тыс.руб.
E18: Прочие работы и затраты | I18: =ROUND(SUM(AA1:AA52)/1000, 2) -> 14.18 | J18: =ROUND((Source!F76+Source!F77)/1000, 2) -> 421.36 | K18: тыс.руб.
E19: Средства на оплату труда | I19: =ROUND(SUM(W1:W52)/1000, 2) -> 5.89 | J19: =(Source!F72+ Source!F71)/1000 -> 203.18142 | K19: тыс.руб.
E20: Затраты труда | I20: =SUM(AB1:AB52) -> 363.2 | K20: чел.-ч.
E21: Кроме того:
E22: Возврат материалов | I22: =ROUND(SUM(AE1:AE52)/1000, 2) -> 0 | J22: =SUM(AF1:AF52)/1000 -> 0 | K22: тыс.руб.
A24: Составлен(а) по ТСН-2001 с учетом Дополнения №: 73
A25: № и период сборника коэффициентов (индексов) пересчета: Коэффициенты к ТСН-2001 МГЭ №212 III квартал 2024 года | AP25: № и период сборника коэффициентов (индексов) пересчета: Коэффициенты к ТСН-2001 МГЭ №212 III квартал 2024 года
A26: № п/п | B26: Шифр расценки и коды ресурсов | C26: Наименование работ и затрат | D26: Ед. изм. | E26: Кол-во единиц | F26: Цена на ед. изм., руб. | G26: Попра- вочные коэффи- циенты | H26: Коэффи- циенты зимних удорожа- ний | I26: Всего затрат в базисном уровне цен, руб. | J26: Коэффи- циенты (индек- сы) пере- счета, нормы НР и СП | K26: ВСЕГО затрат в текущем уровне цен, руб.
A27: 1 | B27: 2 | C27: 3 | D27: 4 | E27: 5 | F27: 6 | G27: 7 | H27: 8 | I27: 9 | J27: 10 | K27: 11
A29: =CONCATENATE("Локальная смета: ",IF(Source!G20<>"Новая локальная смета", Source!G20, "")) -> Локальная смета: Пусконаладочные работы ТП
A30: 1 | B30: 5.10-32-3 Поправка: Гл.5.Прил.2.2.п.2.2.23_05.00.01.37.001 | C30: Блочная комплектная трансформаторная подстанция (БКТПу) двухтрансформаторная мощностью 2х630 кВА | D30: =Source!H24 -> 1 объект | E30: =Source!I24 -> 1 | Q30: =ROUND((Source!DN24/100)*ROUND((ROUND((Source!AF24*Source!AV24*Source!I24),2)),2), 2) -> 4339.99 | R30: =Source!X24 -> 139788.1 | S30: =ROUND((Source!DO24/100)*ROUND((ROUND((Source!AF24*Source!AV24*Source!I24),2)),2), 2) -> 4050.66 | T30: =Source!Y24 -> 81875.89 | U30: =ROUND((175/100)*ROUND((ROUND((Source!AE24*Source!AV24*Source!I24),2)),2), 2) -> 0 | V30: =ROUND((160/100)*ROUND(ROUND((ROUND((Source!AE24*Source!AV24*Source!I24),2)*Source!BS24),2), 2), 2) -> 0 | AI30: 0
C31: ЗП | F31: =Source!AO24 -> 7233.31 | G31: =Source!DG24 -> *0,8 | H31: =Source!AV24 -> 1 | I31: =ROUND((ROUND((Source!AF24*Source!AV24*Source!I24),2)),2) -> 5786.65 | J31: =IF(Source!BA24<> 0, Source!BA24, 1) -> 34.51 | K31: =Source!S24 -> 199697.29 | W31: =I31 -> 5786.65
C32: НР от ЗП | D32: % | E32: =Source!DN24 -> 75 | I32: =SUM(Q30:Q31) -> 4339.99 | J32: =Source!BZ24 -> 70 | K32: =SUM(R30:R31) -> 139788.1
C33: СП от ЗП | D33: % | E33: =Source!DO24 -> 70 | I33: =SUM(S30:S32) -> 4050.66 | J33: =Source!CA24 -> 41 | K33: =SUM(T30:T32) -> 81875.89
C34: ЗТР | D34: чел-ч | E34: =Source!AQ24 -> 454 | G34: =Source!DI24 -> *0,8 | H34: =Source!AV24 -> 1 | I34: =Source!U24 -> 363.2 | AB34: =I34 -> 363.2
C35: ВСЕГО работ по позиции: | H35: =I31+I32+I33+0-0-0 -> 14177.3 | J35: =K31+K32+K33+0-0-0 -> 421361.28
C36: ВСЕГО оборудование по позиции: | H36: =0+0 -> 0 | J36: =0+0 -> 0
O37: =I31+I32+I33+0 -> 14177.3 | P37: =K31+K32+K33+0 -> 421361.28 | X37: =IF(Source!BI24<=1,I31+I32+I33-0, 0) -> 0 | Y37: =IF(Source!BI24=2,I31+I32+I33-0, 0) -> 0 | Z37: =IF(Source!BI24=3,I31+I32+I33-0, 0) -> 0 | AA37: =IF(Source!BI24=4,I31+I32+I33,0) -> 14177.3
A39: 2 | B39: =Source!F25 -> 2.1-8-3 | C39: Автолаборатории | D39: =Source!H25 -> маш.-ч | E39: =Source!I25 -> 8 | Q39: =ROUND((Source!DN25/100)*ROUND((ROUND((Source!AF25*Source!AV25*Source!I25),2)),2), 2) -> 0 | R39: =Source!X25 -> 0 | S39: =ROUND((Source!DO25/100)*ROUND((ROUND((Source!AF25*Source!AV25*Source!I25),2)),2), 2) -> 0 | T39: =Source!Y25 -> 0 | U39: =ROUND((175/100)*ROUND((ROUND((Source!AE25*Source!AV25*Source!I25),2)),2), 2) -> 176.68 | V39: =ROUND((160/100)*ROUND(ROUND((ROUND((Source!AE25*Source!AV25*Source!I25),2)*Source!BS25),2), 2), 2) -> 5574.61 | AI39: 2
C40: ЭМ | F40: =Source!AM25 -> 247.38 | G40: =Source!DE25 | H40: =Source!AV25 -> 1 | I40: =(ROUND((ROUND(((Source!ET25)*Source!AV25*Source!I25),2)),2)+ROUND((ROUND(((Source!AE25-(Source!EU25))*Source!AV25*Source!I25),2)),2)) -> 1979.04 | J40: =IF(Source!BB25<> 0, Source!BB25, 1) -> 9.89 | K40: =Source!Q25 -> 19572.71
C41: в т.ч. ЗПМ | F41: =Source!AN25 -> 12.62 | G41: =Source!DF25 | H41: =Source!AV25 -> 1 | I41: =ROUND((ROUND((Source!AE25*Source!AV25*Source!I25),2)),2) -> 100.96 | J41: =IF(Source!BS25<> 0, Source!BS25, 1) -> 34.51 | K41: =Source!R25 -> 3484.13 | W41: =I41 -> 100.96
C42: НР и СП от ЗПМ | D42: % | E42: =175 -> 175 | I42: =SUM(U39:U41) -> 176.68 | J42: =160 -> 160 | K42: =SUM(V39:V41) -> 5574.61
C43: ВСЕГО по позиции: | H43: =I40+I42+0 -> 2155.72 | J43: =K40+K42+0 -> 25147.32 | O43: =I40+I42+0 -> 2155.72 | P43: =K40+K42+0 -> 25147.32 | X43: =IF(Source!BI25<=1,I40+I42-0, 0) -> 2155.72 | Y43: =IF(Source!BI25=2,I40+I42-0, 0) -> 0 | Z43: =IF(Source!BI25=3,I40+I42-0, 0) -> 0 | AA43: =IF(Source!BI25=4,I40+I42,0) -> 0
A46: =CONCATENATE("Итого по локальной смете: ",IF(Source!G27<>"Новая локальная смета", Source!G27, "")) -> Итого по локальной смете: Пусконаладочные работы ТП | H46: =SUM(O29:O45) -> 16333.02 | J46: =SUM(P29:P45) -> 446508.6
A47: Итого по ТСН-2001.16 | H47: =SUM(AC29:AC46) -> 0 | J47: =SUM(AD29:AD46) -> 0
A48: Итого возвратных сумм | H48: =SUM(AE29:AE47) -> 0 | J48: =SUM(AF29:AF47) -> 0
A50: =CONCATENATE("Итого по смете: ",IF(Source!G57<>"Новый объект", Source!G57, "")) -> Итого по смете: 09-01-01. ПНР ТП (ТСН-2001 (Мосгосэкспертиза)) (ТСН-2001 (Мосгосэкспертиза)) | H50: =SUM(O1:O49) -> 16333.02 | J50: =SUM(P1:P49) -> 446508.6 | AQ50: =CONCATENATE("Итого по смете: ",IF(Source!G57<>"Новый объект", Source!G57, "")) -> Итого по смете: 09-01-01. ПНР ТП (ТСН-2001 (Мосгосэкспертиза)) (ТСН-2001 (Мосгосэкспертиза))
...

Sheet Source
A1: 0 | B1: Smeta.RU (495) 974-1589 | D1: _PS_ | F1: 0 | G1: 0 | H1: 0 | I1: Smeta.RU | K1: 1 | L1: 47858 | M1: 10 | N1: 11 | O1: 14 | P1: 0 | Q1: 1
A12: 1 | B12: 94 | C12: 0 | D12: =ROW(A57) -> 57 | E12: 0 | F12: 09-01-01._(Копия) (ТСН-2001 (Мосгосэкспертиза)) (ТСН-2001 (Мосгосэкспертиза)) (ТСН-2001 (Мосгосэкспертиза)) (ТСН-2001 (Мосгосэкспертиза)) | G12: 09-01-01. ПНР ТП (ТСН-2001 (Мосгосэкспертиза)) (ТСН-2001 (Мосгосэкспертиза)) | I12: 0 | K12: 0 | L12: 0 | M12: 4098 | O12: 0 | P12: 0 | Q12: 0 | R12: 160 | T12: 1 | V12: 0 | AB12: Ефанова В.А. | AC12: Инженер-сметчик ООО "СМК" | BB12: 0 | BH12: Сметные нормы списания | BI12: Коды ОКП для ТСН-2001 МГЭ (История развития) | BJ12: 1 | BK12: 1 | BL12: 0 | BM12: 0 | BN12: 1 | BO12: 0 | BP12: 6 | BQ12: 2 | BR12: 1 | BS12: 1 | BT12: 0 | BU12: 0 | BV12: 0 | BW12: 0 | BX12: 0 | BZ12: Типовой расчет для ТСН-2001 МГЭ, Новая методика с выпуска доп. 43 (Строительство), Доп 73 | CA12: История развития для ТСН-2001 (МГЭ) 73 доп от 17.07.2024 | CB12: История развития для ТСН-2001 (МГЭ) 73 доп от 17.07.2024 | CC12: История развития для ТСН-2001 (МГЭ) 73 доп от 17.07.2024 | CD12: История развития для ТСН-2001 (МГЭ) 73 доп от 17.07.2024 | CE12: Поправки для ТСН-2001 от 16.04.2024 г. доп.72 | CF12: 0 | CG12: 0 | CH12: 8 | CK12: 77 | CQ12: Территориальные сметные нормативы для Москвы (ТСН-2001) | CR12: ТЕР | CS12: 41660 | CT12: 1 | CU12: 73 | CY12: 0 | EC12: 0
A15: 15 | B15: 1
A18: 52 | B18: =B57 -> 94 | C18: =C57 -> 1 | D18: =D57 -> 12 | E18: =E57 -> 0 | F18: =F57 -> 09-01-01._(Копия) (ТСН-2001 (Мосгосэкспертиза)) (ТСН-2001 (Мосгосэкспертиза)) (ТСН-2001 (Мосгосэкспертиза)) (ТСН-2001 (Мосгосэкспертиза)) | G18: =G57 -> 09-01-01. ПНР ТП (ТСН-2001 (Мосгосэкспертиза)) (ТСН-2001 (Мосгосэкспертиза)) | O18: =O57 -> 219270 | P18: =P57 -> 0 | Q18: =Q57 -> 19572.71 | R18: =R57 -> 3484.13 | S18: =S57 -> 199697.29 | T18: =T57 -> 0 | U18: =U57 -> 363.2 | V18: =V57 -> 0 | ... GX18: =GX57 -> 0
A20: 3 | B20: 1 | D20: =ROW(A27) -> 27 | G20: Пусконаладочные работы ТП | I20: 0 | K20: -1 | S20: 0 | V20: 0 | BD20: )*1,2)*1,15 | BE20: )*1,2)*1,15 | BF20: )*1,2)*1,15 | BH20: )*1,2)*1,15 | BI20: )*1,2)*1,15 | BN20: )*1,2)*1,15 | BO20: Поправка: ТСН-2001.4. О.П. тб1. п.3 Наименование: При выполнении работ в охранной зоне воздушных линий электропередачи, в местах прохода коммуникаций электроснабжения в действующих электроустановках, вблизи конструкций и предметов, находящихся под напряжением (в случаях, когда полное снятие напряжения по производственным условиям невозможно), если это связано с ограничением действий рабочих специальными требованиями техники безопасности Поправка: ТСН-2001.4. О.П. тб1. п.2 Наименование: На предприятиях (в цехах на производственных площадях), остановленных для производства строительно-монтажных работ, а также в зданиях и сооружениях всех назначений при наличии в зоне производства работ загромоаждающих помещение предметов (станков, установок, аппаратов, эксплуатационного и лабораторного оборудования, оргтехники, мебели и т.п.) | BP20: Поправка: ТСН-2001.4. О.П. тб1. п.3 Поправка: ТСН-2001.4. О.П. тб1. п.2 | BX20: 0 | CF20: 0 | CG20: 0
A22: 52 | B22: =B27 -> 1 | C22: =C27 -> 3 | D22: =D27 -> 20 | E22: =E27 -> 0 | F22: =F27 | G22: =G27 -> Пусконаладочные работы ТП | O22: =O27 -> 219270 | P22: =P27 -> 0 | Q22: =Q27 -> 19572.71 | R22: =R27 -> 3484.13 | S22: =S27 -> 199697.29 | T22: =T27 -> 0 | U22: =U27 -> 363.2 | V22: =V27 -> 0 | ... GX22: =GX27 -> 0
A24: 17 | B24: 1 | D24: =ROW(EtalonRes!A1) -> 1 | E24: 1 | F24: 5.10-32-3 | G24: Блочная комплектная трансформаторная подстанция (БКТПу) двухтрансформаторная мощностью 2х630 кВА | H24: 1 объект | I24: =ROUND(1,9) -> 1 | J24: 0 | K24: =ROUND(1,9) -> 1 | O24: =ROUND(CP24,2) -> 199697.29 | P24: =ROUND((ROUND((AC24*AW24*I24),2)*BC24),2) -> 0 | Q24: =(ROUND((ROUND(((ET24)*AV24*I24),2)*BB24),2)+ROUND((ROUND(((AE24-(EU24))*AV24*I24),2)*BS24),2)) -> 0 | R24: =ROUND((ROUND((AE24*AV24*I24),2)*BS24),2) -> 0 | S24: =ROUND((ROUND((AF24*AV24*I24),2)*BA24),2) -> 199697.29 | T24: =ROUND(CU24*I24,2) -> 0 | U24: =CV24*I24 -> 363.2 | V24: =CW24*I24 -> 0 | W24: =ROUND(CX24*I24,2) -> 0 | X24: =ROUND(CY24,2) -> 139788.1 | Y24: =ROUND(CZ24,2) -> 81875.89 | AA24: 55810629 | AB24: =ROUND((AC24+AD24+AF24),6) -> 5786.648 | AC24: =ROUND((ES24),6) -> 0 | AD24: =ROUND((((ET24)-(EU24))+AE24),6) -> 0 | AE24: =ROUND((EU24),6) -> 0 | AF24: =ROUND(((EV24*0.8)),6) -> 5786.648 | AG24: =ROUND((AP24),6) -> 0 | AH24: =((EW24*0.8)) -> 363.2 | AI24: =(EX24) -> 0 | AJ24: =(AS24) -> 0 | AK24: 7233.31 | AL24: 0 | AM24: 0 | AN24: 0 | AO24: 7233.31 | AP24: 0 | AQ24: 454 | AR24: 0 | AS24: 0 | AT24: 70 | AU24: 41 | AV24: 1 | AW24: 1 | AZ24: 1 | BA24: 34.51 | BB24: 1 | BC24: 1 | BH24: 0 | BI24: 4 | BJ24: ТСН-2001.5. Доп. 1-42. Сб. 10, т. 32, поз. 3 | BM24: 388 | BN24: 51696011 | BP24: 0 | BQ24: 50 | BR24: 0 | BS24: 34.51 | BT24: 1 | BU24: 1 | BV24: 1 | BW24: 1 | BX24: 1 | BZ24: 70 | CA24: 41 | CE24: 30 | CF24: 0 | CG24: 0 | CM24: 0 | CN24: Поправка: Гл.5.Прил.2.2.п.2.2.23_05.00.01.37.001 Наименование: При выполнении монтажных и пусконаладочных работ по какому-либо оборудованию одним и тем же звеном (бригадой) | CO24: 0 | CP24: =(P24+Q24+S24) -> 199697.29 | CQ24: =ROUND((ROUND((AC24*AW24*1),2)*BC24),2) -> 0 | CR24: =(ROUND((ROUND(((ET24)*AV24*1),2)*BB24),2)+ROUND((ROUND(((AE24-(EU24))*AV24*1),2)*BS24),2)) -> 0 | CS24: =ROUND((ROUND((AE24*AV24*1),2)*BS24),2) -> 0 | CT24: =ROUND((ROUND((AF24*AV24*1),2)*BA24),2) -> 199697.29 | CU24: =AG24 -> 0 | CV24: =(AH24*AV24) -> 363.2 | CW24: =AI24 -> 0 | CX24: =AJ24 -> 0 | CY24: =S24*(BZ24/100) -> 139788.1 | CZ24: =S24*(CA24/100) -> 81875.889 | DB24: 1 | DG24: *0,8 | DI24: *0,8 | DN24: 75 | DO24: 70 | DP24: 1 | DQ24: 1 | DU24: 1013 | DV24: 1 объект | DW24: 1 объект | DX24: 1 | EE24: 51696427 | EF24: 50 | EG24: Пусконаладочные работы | EH24: 0 | EJ24: 4 | EK24: 388 | EL24: ТСН-2001.5-10. 10-4...10-44 | EM24: ТСН-2001.5-10-1 | EO24: Поправка: Гл.5.Прил.2.2.п.2.2.23_05.00.01.37.001 | EQ24: 1441792 | ER24: 7233.31 | ES24: 0 | ET24: 0 | EU24: 0 | EV24: 7233.31 | EW24: 454 | EX24: 0 | EY24: 0 | FQ24: 0 | FR24: 0 | FS24: 0 | FX24: 75 | FY24: 70 | GD24: 0 | GF24: -1121463885 | GG24: 2 | GH24: 1 | GI24: 2 | GJ24: 0 | GK24: =ROUND(R24*(R12)/100,2) -> 0 | GL24: =ROUND(IF(AND(BH24=3,BI24=3,FS24<>0),P24,0),2) -> 0 | GM24: =ROUND(O24+X24+Y24+GK24,2)+GX24 -> 421361.28 | GN24: =IF(OR(BI24=0,BI24=1),GM24-GX24,0) -> 0 | GO24: =IF(BI24=2,GM24-GX24,0) -> 0 | GP24: =IF(BI24=4,GM24-GX24,0) -> 421361.28 | GR24: 0 | GS24: 3 | GT24: 0 | GV24: =ROUND((GT24),6) -> 0 | GW24: 1 | GX24: =ROUND(HC24*I24,2) -> 0 | HA24: 0 | HB24: 0 | HC24: =GV24*GW24 -> 0 | HS24: 0 | IK24: 0
A25: 17 | B25: 1 | E25: 2 | F25: 2.1-8-3 | G25: Автолаборатории | H25: маш.-ч | I25: =ROUND(8,9) -> 8 | J25: 0 | K25: =ROUND(8,9) -> 8 | O25: =ROUND(CP25,2) -> 19572.71 | P25: =ROUND((ROUND((AC25*AW25*I25),2)*BC25),2) -> 0 | Q25: =(ROUND((ROUND(((ET25)*AV25*I25),2)*BB25),2)+ROUND((ROUND(((AE25-(EU25))*AV25*I25),2)*BS25),2)) -> 19572.71 | R25: =ROUND((ROUND((AE25*AV25*I25),2)*BS25),2) -> 3484.13 | S25: =ROUND((ROUND((AF25*AV25*I25),2)*BA25),2) -> 0 | T25: =ROUND(CU25*I25,2) -> 0 | U25: =CV25*I25 -> 0 | V25: =CW25*I25 -> 0 | W25: =ROUND(CX25*I25,2) -> 0 | X25: =ROUND(CY25,2) -> 0 | Y25: =ROUND(CZ25,2) -> 0 | AA25: 55810629 | AB25: =ROUND((AC25+AD25+AF25),6) -> 247.38 | AC25: =ROUND((ES25),6) -> 0 | AD25: =ROUND((((ET25)-(EU25))+AE25),6) -> 247.38 | AE25: =ROUND((EU25),6) -> 12.62 | AF25: =ROUND((EV25),6) -> 0 | AG25: =ROUND((AP25),6) -> 0 | AH25: =(EW25) -> 0 | AI25: =(EX25) -> 0 | AJ25: =(AS25) -> 0 | AK25: 247.38 | AL25: 0 | AM25: 247.38 | AN25: 12.62 | AO25: 0 | AP25: 0 | AQ25: 0 | AR25: 0 | AS25: 0 | AT25: 0 | AU25: 0 | AV25: 1 | AW25: 1 | AZ25: 1 | BA25: 1 | BB25: 9.89 | BC25: 1 | BH25: 2 | BI25: 1 | BJ25: ТСН-2001.2. Доп. 68. п.1-8-3 (085001) | BM25: 400001 | BN25: 51696011 | BO25: 2.1-8-3 | BP25: 1 | BQ25: 190 | BR25: 0 | BS25: 34.51 | BT25: 1 | BU25: 1 | BV25: 1 | BW25: 1 | BX25: 1 | BZ25: 0 | CA25: 0 | CE25: 30 | CF25: 0 | CG25: 0 | CM25: 0 | CO25: 0 | CP25: =(P25+Q25+S25) -> 19572.71 | CQ25: =ROUND((ROUND((AC25*AW25*1),2)*BC25),2) -> 0 | CR25: =(ROUND((ROUND(((ET25)*AV25*1),2)*BB25),2)+ROUND((ROUND(((AE25-(EU25))*AV25*1),2)*BS25),2)) -> 2446.59 | CS25: =ROUND((ROUND((AE25*AV25*1),2)*BS25),2) -> 435.52 | CT25: =ROUND((ROUND((AF25*AV25*1),2)*BA25),2) -> 0 | CU25: =AG25 -> 0 | CV25: =(AH25*AV25) -> 0 | CW25: =AI25 -> 0 | CX25: =AJ25 -> 0 | CY25: =S25*(BZ25/100) -> 0 | CZ25: =S25*(CA25/100) -> 0 | DN25: 0 | DO25: 0 | DP25: 1 | DQ25: 1 | DU25: 1011 | DV25: маш.-ч | DW25: маш.-ч | DX25: 1 | EE25: 51697852 | EF25: 190 | EG25: Механизмы | EH25: 0 | EJ25: 1 | EK25: 400001 | EL25: ТСН-2001. Машины и механизмы | EM25: ТСН-2001.2 | EQ25: 1179648 | ER25: 247.38 | ES25: 0 | ET25: 247.38 | EU25: 12.62 | EV25: 0 | EW25: 0 | EX25: 0 | EY25: 0 | FQ25: 0 | FR25: 0 | FS25: 0 | FX25: 0 | FY25: 0 | GD25: 0 | GF25: 464312783 | GG25: 2 | GH25: 1 | GI25: 2 | GJ25: 0 | GK25: =ROUND(R25*(R12)/100,2) -> 5574.61 | GL25: =ROUND(IF(AND(BH25=3,BI25=3,FS25<>0),P25,0),2) -> 0 | GM25: =ROUND(O25+X25+Y25+GK25,2)+GX25 -> 25147.32 | GN25: =IF(OR(BI25=0,BI25=1),GM25-GX25,0) -> 25147.32 | GO25: =IF(BI25=2,GM25-GX25,0) -> 0 | GP25: =IF(BI25=4,GM25-GX25,0) -> 0 | GR25: 0 | GS25: 3 | GT25: 0 | GV25: =ROUND((GT25),6) -> 0 | GW25: 1 | GX25: =ROUND(HC25*I25,2) -> 0 | HA25: 0 | HB25: 0 | HC25: =GV25*GW25 -> 0 | HS25: 0 | IK25: 0
A27: 51 | B27: =B20 -> 1 | C27: =A20 -> 3 | D27: =ROW(A20) -> 20 | F27: =IF(F20<>"",F20,"") | G27: =IF(G20<>"",G20,"") -> Пусконаладочные работы ТП | H27: 0 | O27: =ROUND(AB27,2) -> 219270 | P27: =ROUND(AC27,2) -> 0 | Q27: =ROUND(AD27,2) -> 19572.71 | R27: =ROUND(AE27,2) -> 3484.13 | S27: =ROUND(AF27,2) -> 199697.29 | T27: =ROUND(AG27,2) -> 0 | U27: =AH27 -> 363.2 | V27: =AI27 -> 0 | W27: =ROUND(AJ27,2) -> 0 | X27: =ROUND(AK27,2) -> 139788.1 | Y27: =ROUND(AL27,2) -> 81875.89 | AB27: =ROUND(SUMIF(AA24:AA25,"=55810629",O24:O25),2) -> 219270 | AC27: =ROUND(SUMIF(AA24:AA25,"=55810629",P24:P25),2) -> 0 | AD27: =ROUND(SUMIF(AA24:AA25,"=55810629",Q24:Q25),2) -> 19572.71 | AE27: =ROUND(SUMIF(AA24:AA25,"=55810629",R24:R25),2) -> 3484.13 | AF27: =ROUND(SUMIF(AA24:AA25,"=55810629",S24:S25),2) -> 199697.29 | AG27: =ROUND(SUMIF(AA24:AA25,"=55810629",T24:T25),2) -> 0 | AH27: =SUMIF(AA24:AA25,"=55810629",U24:U25) -> 363.2 | AI27: =SUMIF(AA24:AA25,"=55810629",V24:V25) -> 0 | AJ27: =ROUND(SUMIF(AA24:AA25,"=55810629",W24:W25),2) -> 0 | AK27: =ROUND(SUMIF(AA24:AA25,"=55810629",X24:X25),2) -> 139788.1 | AL27: =ROUND(SUMIF(AA24:AA25,"=55810629",Y24:Y25),2) -> 81875.89 | AO27: =ROUND(BX27,2) -> 0 | AP27: =ROUND(BY27,2) -> 0 | AQ27: =ROUND(BZ27,2) -> 0 | AR27: =ROUND(CA27,2) -> 446508.6 | AS27: =ROUND(CB27,2) -> 25147.32 | AT27: =ROUND(CC27,2) -> 0 | AU27: =ROUND(CD27,2) -> 421361.28 | AV27: =ROUND(CE27,2) -> 0 | ... BD27: =ROUND(CM27,2) -> 0 | BX27: =ROUND(SUMIF(AA24:AA25,"=55810629",FQ24:FQ25),2) -> 0 | BY27: =ROUND(SUMIF(AA24:AA25,"=55810629",FR24:FR25),2) -> 0 | BZ27: =ROUND(SUMIF(AA24:AA25,"=55810629",GL24:GL25),2) -> 0 | CA27: =ROUND(SUMIF(AA24:AA25,"=55810629",GM24:GM25),2) -> 446508.6 | CB27: =ROUND(SUMIF(AA24:AA25,"=55810629",GN24:GN25),2) -> 25147.32 | CC27: =ROUND(SUMIF(AA24:AA25,"=55810629",GO24:GO25),2) -> 0 | CD27: =ROUND(SUMIF(AA24:AA25,"=55810629",GP24:GP25),2) -> 421361.28 | CE27: =AC27-BX27 -> 0 | CF27: =AC27-BY27 -> 0 | CG27: =BX27-BZ27 -> 0 | CH27: =AC27-BX27-BY27+BZ27 -> 0 | CI27: =BY27-BZ27 -> 0 | CJ27: =ROUND(SUMIF(AA24:AA25,"=55810629",GX24:GX25),2) -> 0 | CK27: =ROUND(SUMIF(AA24:AA25,"=55810629",GY24:GY25),2) -> 0 | CL27: =ROUND(SUMIF(AA24:AA25,"=55810629",GZ24:GZ25),2) -> 0 | CM27: =ROUND(SUMIF(AA24:AA25,"=55810629",HD24:HD25),2) -> 0 | GX27: 0
A29: 50 | B29: 0 | C29: 0 | D29: 1 | E29: 201 | F29: =ROUND(Source!O27,O29) -> 219270 | G29: ПЗ | H29: Прямые затраты | K29: 201 | L29: 1 | M29: 3 | O29: 2 | W29: 219270 | X29: 1 | Y29: 219270
A30: 50 | B30: 0 | C30: 0 | D30: 1 | E30: 202 | F30: =ROUND(Source!P27,O30) -> 0 | G30: СтМатОб | H30: Стоимость материальных ресурсов (всего) | K30: 202 | L30: 2 | M30: 3 | O30: 2 | W30: 0 | X30: 1 | Y30: 0
A31: 50 | B31: 0 | C31: 0 | D31: 1 | E31: 222 | F31: =ROUND(Source!AO27,O31) -> 0 | G31: СтМатОбЗак | H31: Стоимость материалов и оборудования заказчика | K31: 222 | L31: 3 | M31: 3 | O31: 2 | W31: 0 | X31: 1 | Y31: 0
A32: 50 | B32: 0 | C32: 0 | D32: 1 | E32: 225 | F32: =ROUND(Source!AV27,O32) -> 0 | G32: СтМатОбПод | H32: Стоимость материалов и оборудования подрядчика | K32: 225 | L32: 4 | M32: 3 | O32: 2 | W32: 0 | X32: 1 | Y32: 0
A33: 50 | B33: 0 | C33: 0 | D33: 1 | E33: 226 | F33: =ROUND(Source!AW27,O33) -> 0 | G33: СтМат | H33: Стоимость материалов (всего) | K33: 226 | L33: 5 | M33: 3 | O33: 2 | W33: 0 | X33: 1 | Y33: 0
A34: 50 | B34: 0 | C34: 0 | D34: 1 | E34: 227 | F34: =ROUND(Source!AX27,O34) -> 0 | G34: СтМатЗак | H34: Стоимость материалов заказчика | K34: 227 | L34: 6 | M34: 3 | O34: 2 | W34: 0 | X34: 1 | Y34: 0
A35: 50 | B35: 0 | C35: 0 | D35: 1 | E35: 228 | F35: =ROUND(Source!AY27,O35) -> 0 | G35: СтМатПод | H35: Стоимость материалов подрядчика | K35: 228 | L35: 7 | M35: 3 | O35: 2 | W35: 0 | X35: 1 | Y35: 0
A36: 50 | B36: 0 | C36: 0 | D36: 1 | E36: 216 | F36: =ROUND(Source!AP27,O36) -> 0 | G36: Оборуд | H36: Стоимость оборудования (всего) | K36: 216 | L36: 8 | M36: 3 | O36: 2 | W36: 0 | X36: 1 | Y36: 0
A37: 50 | B37: 0 | C37: 0 | D37: 1 | E37: 223 | F37: =ROUND(Source!AQ27,O37) -> 0 | G37: ОборудЗак | H37: Стоимость оборудования заказчика | K37: 223 | L37: 9 | M37: 3 | O37: 2 | W37: 0 | X37: 1 | Y37: 0
A38: 50 | B38: 0 | C38: 0 | D38: 1 | E38: 229 | F38: =ROUND(Source!AZ27,O38) -> 0 | G38: ОборудПод | H38: Стоимость оборудования подрядчика | K38: 229 | L38: 10 | M38: 3 | O38: 2 | W38: 0 | X38: 1 | Y38: 0
A39: 50 | B39: 0 | C39: 0 | D39: 1 | E39: 203 | F39: =ROUND(Source!Q27,O39) -> 19572.71 | G39: ЭММ | H39: Эксплуатация машин | K39: 203 | L39: 11 | M39: 3 | O39: 2 | W39: 19572.71 | X39: 1 | Y39: 19572.71
A40: 50 | B40: 0 | C40: 0 | D40: 1 | E40: 231 | F40: =ROUND(Source!BB27,O40) -> 0 | G40: ЭММсНРиСП | H40: Эксплуатация машин по ТСН-2001.16 | K40: 231 | L40: 12 | M40: 3 | O40: 2 | W40: 0 | X40: 1 | Y40: 0
A41: 50 | B41: 0 | C41: 0 | D41: 1 | E41: 204 | F41: =ROUND(Source!R27,O41) -> 3484.13 | G41: ЗПМ | H41: ЗП машинистов | K41: 204 | L41: 13 | M41: 3 | O41: 2 | W41: 3484.13 | X41: 1 | Y41: 3484.13
A42: 50 | B42: 0 | C42: 0 | D42: 1 | E42: 205 | F42: =ROUND(Source!S27,O42) -> 199697.29 | G42: ОЗП | H42: Основная ЗП рабочих | K42: 205 | L42: 14 | M42: 3 | O42: 2 | W42: 199697.29 | X42: 1 | Y42: 199697.29
A43: 50 | B43: 0 | C43: 0 | D43: 1 | E43: 232 | F43: =ROUND(Source!BC27,O43) -> 0 | G43: ОЗПсНРиСП | H43: Основная ЗП рабочих по ТСН-2001.16 | K43: 232 | L43: 15 | M43: 3 | O43: 2 | W43: 0 | X43: 1 | Y43: 0
A44: 50 | B44: 0 | C44: 0 | D44: 1 | E44: 214 | F44: =ROUND(Source!AS27,O44) -> 25147.32 | G44: Строит | H44: Строительные работы с НР и СП | K44: 214 | L44: 16 | M44: 3 | O44: 2 | W44: 25147.32 | X44: 1 | Y44: 25147.32
A45: 50 | B45: 0 | C45: 0 | D45: 1 | E45: 215 | F45: =ROUND(Source!AT27,O45) -> 0 | G45: Монтаж | H45: Монтажные работы с НР и СП | K45: 215 | L45: 17 | M45: 3 | O45: 2 | W45: 0 | X45: 1 | Y45: 0
A46: 50 | B46: 0 | C46: 0 | D46: 1 | E46: 217 | F46: =ROUND(Source!AU27,O46) -> 421361.28 | G46: Прочие | H46: Прочие работы с НР и СП | K46: 217 | L46: 18 | M46: 3 | O46: 2 | W46: 421361.28 | X46: 1 | Y46: 421361.28
A47: 50 | B47: 0 | C47: 0 | D47: 1 | E47: 230 | F47: =ROUND(Source!BA27,O47) -> 0 | G47: ПрочиеЗатр | H47: Прочие затраты по ТСН-2001.16 | K47: 230 | L47: 19 | M47: 3 | O47: 2 | W47: 0 | X47: 1 | Y47: 0
A48: 50 | B48: 0 | C48: 0 | D48: 1 | E48: 206 | F48: =ROUND(Source!T27,O48) -> 0 | G48: ВозврМат | H48: Возврат материалов | K48: 206 | L48: 20 | M48: 3 | O48: 2 | W48: 0 | X48: 1 | Y48: 0
A49: 50 | B49: 0 | C49: 0 | D49: 1 | E49: 207 | F49: =Source!U27 -> 363.2 | G49: ТрудСтр | H49: Трудозатраты строителей | K49: 207 | L49: 21 | M49: 3 | O49: -1 | W49: 363.2 | X49: 1 | Y49: 363.2
A50: 50 | B50: 0 | C50: 0 | D50: 1 | E50: 208 | F50: =Source!V27 -> 0 | G50: ТрудМаш | H50: Трудозатраты машинистов | K50: 208 | L50: 22 | M50: 3 | O50: -1 | W50: 0 | X50: 1 | Y50: 0
A51: 50 | B51: 0 | C51: 0 | D51: 1 | E51: 209 | F51: =ROUND(Source!W27,O51) -> 0 | G51: ТранспМат | H51: Транспорт материалов | K51: 209 | L51: 23 | M51: 3 | O51: 2 | W51: 0 | X51: 1 | Y51: 0
A52: 50 | B52: 0 | C52: 0 | D52: 1 | E52: 233 | F52: =ROUND(Source!BD27,O52) -> 0 | G52: Перевозка | H52: Перевозка грузов | K52: 233 | L52: 24 | M52: 3 | O52: 2 | W52: 0 | X52: 1 | Y52: 0
A53: 50 | B53: 0 | C53: 0 | D53: 1 | E53: 210 | F53: =ROUND(Source!X27,O53) -> 139788.1 | G53: НР | H53: Накладные расходы | K53: 210 | L53: 25 | M53: 3 | O53: 2 | W53: 139788.1 | X53: 1 | Y53: 139788.1
A54: 50 | B54: 0 | C54: 0 | D54: 1 | E54: 211 | F54: =ROUND(Source!Y27,O54) -> 81875.89 | G54: СмПриб | H54: Сметная прибыль | K54: 211 | L54: 26 | M54: 3 | O54: 2 | W54: 81875.89 | X54: 1 | Y54: 81875.89
A55: 50 | B55: 0 | C55: 0 | D55: 1 | E55: 224 | F55: =ROUND(Source!AR27,O55) -> 446508.6 | G55: Всего | H55: Всего с НР и СП | K55: 224 | L55: 27 | M55: 3 | O55: 2 | W55: 446508.6 | X55: 1 | Y55: 446508.6
A57: 51 | B57: =B12 -> 94 | C57: =A12 -> 1 | D57: =ROW(A12) -> 12 | F57: =IF(F12<>"",F12,"") -> 09-01-01._(Копия) (ТСН-2001 (Мосгосэкспертиза)) (ТСН-2001 (Мосгосэкспертиза)) (ТСН-2001 (Мосгосэкспертиза)) (ТСН-2001 (Мосгосэкспертиза)) | G57: =IF(G12<>"",G12,"") -> 09-01-01. ПНР ТП (ТСН-2001 (Мосгосэкспертиза)) (ТСН-2001 (Мосгосэкспертиза)) | H57: 0 | O57: =ROUND(O27,2) -> 219270 | P57: =ROUND(P27,2) -> 0 | Q57: =ROUND(Q27,2) -> 19572.71 | R57: =ROUND(R27,2) -> 3484.13 | S57: =ROUND(S27,2) -> 199697.29 | T57: =ROUND(T27,2) -> 0 | U57: =U27 -> 363.2 | V57: =V27 -> 0 | W57: =ROUND(W27,2) -> 0 | X57: =ROUND(X27,2) -> 139788.1 | Y57: =ROUND(Y27,2) -> 81875.89 | AO57: =ROUND(AO27,2) -> 0 | AP57: =ROUND(AP27,2) -> 0 | AQ57: =ROUND(AQ27,2) -> 0 | AR57: =ROUND(AR27,2) -> 446508.6 | AS57: =ROUND(AS27,2) -> 25147.32 | AT57: =ROUND(AT27,2) -> 0 | AU57: =ROUND(AU27,2) -> 421361.28 | AV57: =ROUND(AV27,2) -> 0 | ... BD57: =ROUND(BD27,2) -> 0 | GX57: 0
A59: 50 | B59: 0 | C59: 0 | D59: 1 | E59: 201 | F59: =ROUND(Source!O57,O59) -> 219270 | G59: ПЗ | H59: Прямые затраты | K59: 201 | L59: 1 | M59: 3 | O59: 2 | W59: 219270 | X59: 1 | Y59: 219270
A60: 50 | B60: 0 | C60: 0 | D60: 1 | E60: 202 | F60: =ROUND(Source!P57,O60) -> 0 | G60: СтМатОб | H60: Стоимость материальных ресурсов (всего) | K60: 202 | L60: 2 | M60: 3 | O60: 2 | W60: 0 | X60: 1 | Y60: 0
A61: 50 | B61: 0 | C61: 0 | D61: 1 | E61: 222 | F61: =ROUND(Source!AO57,O61) -> 0 | G61: СтМатОбЗак | H61: Стоимость материалов и оборудования заказчика | K61: 222 | L61: 3 | M61: 3 | O61: 2 | W61: 0 | X61: 1 | Y61: 0
...

Sheet SourceObSm
A1: 0 | B1: Smeta.RU (495) 974-1589 | D1: _OBSM_ | F1: 0 | G1: 0 | H1: 0 | I1: Smeta.RU | K1: 1 | L1: 47858 | M1: 10 | N1: 11 | O1: 14 | P1: 0 | Q1: 1
A12: 1 | B12: 51 | C12: 0 | E12: 0 | F12: 09-01-01._(Копия) (ТСН-2001 (Мосгосэкспертиза)) (ТСН-2001 (Мосгосэкспертиза)) (ТСН-2001 (Мосгосэкспертиза)) (ТСН-2001 (Мосгосэкспертиза)) | G12: 09-01-01. ПНР ТП (ТСН-2001 (Мосгосэкспертиза)) (ТСН-2001 (Мосгосэкспертиза)) | I12: 0 | K12: 0 | L12: 0 | M12: 4098 | O12: 0 | P12: 0 | Q12: 0 | R12: 160 | T12: 1 | V12: 0 | AB12: Ефанова В.А. | AC12: Инженер-сметчик ООО "СМК" | BB12: 0 | BH12: Сметные нормы списания | BI12: Коды ОКП для ТСН-2001 МГЭ (История развития) | BJ12: 1 | BK12: 1 | BL12: 0 | BM12: 0 | BN12: 1 | BO12: 0 | BP12: 6 | BQ12: 2 | BR12: 1 | BS12: 1 | BT12: 0 | BU12: 0 | BV12: 0 | BW12: 0 | BX12: 0 | BZ12: Типовой расчет для ТСН-2001 МГЭ, Новая методика с выпуска доп. 43 (Строительство), Доп 73 | CA12: История развития для ТСН-2001 (МГЭ) 73 доп от 17.07.2024 | CB12: История развития для ТСН-2001 (МГЭ) 73 доп от 17.07.2024 | CC12: История развития для ТСН-2001 (МГЭ) 73 доп от 17.07.2024 | CD12: История развития для ТСН-2001 (МГЭ) 73 доп от 17.07.2024 | CE12: Поправки для ТСН-2001 от 16.04.2024 г. доп.72 | CF12: 0 | CG12: 0 | CH12: 8 | CK12: 77 | CQ12: Территориальные сметные нормативы для Москвы (ТСН-2001) | CR12: ТЕР | CS12: 41660 | CT12: 1 | CU12: 73 | CY12: 0 | EC12: 0
A14: 22 | B14: 1 | C14: 0 | D14: 55810629 | E14: 0 | F14: 2 | G14: 1
A16: 3 | B16: 1 | D16: Пусконаладочные работы ТП | E16: =ROUND((Source!F44)/1000,2) -> 25.15 | F16: =ROUND((Source!F45)/1000,2) -> 0 | G16: =ROUND((Source!F36)/1000,2) -> 0 | H16: =ROUND((Source!F46)/1000+(Source!F47)/1000,2) -> 421.36 | I16: =E16+F16+G16+H16 -> 446.51 | J16: =ROUND((Source!F42+Source!F41)/1000,2) -> 203.18 | K16: 219.27 | L16: 0 | M16: 0 | N16: =I16+L16+M16 -> 446.51 | AI16: 0 | AJ16: -1 | AL16: Поправка: ТСН-2001.4. О.П. тб1. п.3 Наименование: При выполнении работ в охранной зоне воздушных линий электропередачи, в местах прохода коммуникаций электроснабжения в действующих электроустановках, вблизи конструкций и предметов, находящихся под напряжением (в случаях, когда полное снятие напряжения по производственным условиям невозможно), если это связано с ограничением действий рабочих специальными требованиями техники безопасности Поправка: ТСН-2001.4. О.П. тб1. п.2 Наименование: На предприятиях (в цехах на производственных площадях), остановленных для производства строительно-монтажных работ, а также в зданиях и сооружениях всех назначений при наличии в зоне производства работ загромоаждающих помещение предметов (станков, установок, аппаратов, эксплуатационного и лабораторного оборудования, оргтехники, мебели и т.п.) | AM16: Поправка: ТСН-2001.4. О.П. тб1. п.3 Поправка: ТСН-2001.4. О.П. тб1. п.2 | AN16: 0 | AT16: 219270 | AU16: 0 | AV16: 0 | AW16: 0 | AX16: 0 | AY16: 19572.71 | AZ16: 3484.13 | BA16: 199697.29 | BB16: 25147.32 | BC16: 0 | BD16: 421361.28 | BE16: 0 | BF16: 363.2 | BG16: 0 | BH16: 0 | BI16: 139788.1 | BJ16: 81875.89 | BK16: 446508.6
A18: 51 | E18: 25.15 | F18: 0 | G18: 0 | H18: 421.36 | I18: 446.51 | J18: 203.18 | K18: 219.27 | L18: 0 | M18: 0 | N18: 446.51
A20: 50 | B20: 0 | C20: 0 | D20: 1 | E20: 201 | F20: 219270 | G20: ПЗ | H20: Прямые затраты | K20: 201 | L20: 1 | M20: 3 | O20: 2
A21: 50 | B21: 0 | C21: 0 | D21: 1 | E21: 202 | F21: 0 | G21: СтМатОб | H21: Стоимость материальных ресурсов (всего) | K21: 202 | L21: 2 | M21: 3 | O21: 2
A22: 50 | B22: 0 | C22: 0 | D22: 1 | E22: 222 | F22: 0 | G22: СтМатОбЗак | H22: Стоимость материалов и оборудования заказчика | K22: 222 | L22: 3 | M22: 3 | O22: 2
A23: 50 | B23: 0 | C23: 0 | D23: 1 | E23: 225 | F23: 0 | G23: СтМатОбПод | H23: Стоимость материалов и оборудования подрядчика | K23: 225 | L23: 4 | M23: 3 | O23: 2
A24: 50 | B24: 0 | C24: 0 | D24: 1 | E24: 226 | F24: 0 | G24: СтМат | H24: Стоимость материалов (всего) | K24: 226 | L24: 5 | M24: 3 | O24: 2
A25: 50 | B25: 0 | C25: 0 | D25: 1 | E25: 227 | F25: 0 | G25: СтМатЗак | H25: Стоимость материалов заказчика | K25: 227 | L25: 6 | M25: 3 | O25: 2
A26: 50 | B26: 0 | C26: 0 | D26: 1 | E26: 228 | F26: 0 | G26: СтМатПод | H26: Стоимость материалов подрядчика | K26: 228 | L26: 7 | M26: 3 | O26: 2
A27: 50 | B27: 0 | C27: 0 | D27: 1 | E27: 216 | F27: 0 | G27: Оборуд | H27: Стоимость оборудования (всего) | K27: 216 | L27: 8 | M27: 3 | O27: 2
A28: 50 | B28: 0 | C28: 0 | D28: 1 | E28: 223 | F28: 0 | G28: ОборудЗак | H28: Стоимость оборудования заказчика | K28: 223 | L28: 9 | M28: 3 | O28: 2
A29: 50 | B29: 0 | C29: 0 | D29: 1 | E29: 229 | F29: 0 | G29: ОборудПод | H29: Стоимость оборудования подрядчика | K29: 229 | L29: 10 | M29: 3 | O29: 2
A30: 50 | B30: 0 | C30: 0 | D30: 1 | E30: 203 | F30: 19572.71 | G30: ЭММ | H30: Эксплуатация машин | K30: 203 | L30: 11 | M30: 3 | O30: 2
A31: 50 | B31: 0 | C31: 0 | D31: 1 | E31: 231 | F31: 0 | G31: ЭММсНРиСП | H31: Эксплуатация машин по ТСН-2001.16 | K31: 231 | L31: 12 | M31: 3 | O31: 2
... A46: 50 | B46: 0 | C46: 0 | D46: 1 | E46: 224 | F46: 446508.6 | G46: Всего | H46: Всего с НР и СП | K46: 224 | L46: 27 | M46: 3 | O46: 2
A48: -1
A51: 75 | B51: Уровень цен | C51: 2024 | D51: 0 | E51: 4 | G51: 0 | H51: 2 | I51: 1 | J51: 1 | K51: 95 | L51: 65 | M51: 0 | N51: 55810629 | O51: 1
A52: 1 | B52: Сборник индексов | C52: Коэффициенты к ТСН-2001 МГЭ | D52: 2024 | E52: 7 | F52: 1 | G52: 1 | H52: 0 | I52: 2 | J52: 1 | K52: 1 | L52: 1 | M52: 1 | N52: 1 | O52: 1 | P52: 1 | Q52: 1 | AA52: 212 | AN52: 55810630

Sheet SmtRes
I87: 0

Sheet EtalonRes
A1: =ROW(Source!A24) -> 24 | B1: 55810690 | C1: 55810687 | D1: 30359939 | E1: 27786564 | F1: 1 | G1: 27786564 | H1: 1 | I1: 9999990008 | K1: Трудозатраты рабочих | L1: 1191 | N1: 1013 | O1: чел.-ч. | P1: чел.-ч. | Q1: 1 | X1: 454 | Y1: 0 | Z1: 0 | AA1: 0 | AB1: 0 | AC1: 0 | AD1: 1 | AE1: 1 | AF1: *0,8 | AG1: 363.2 | AH1: 3 | AI1: -1 | AK1: 0 | AL1: 0 | AM1: 0 | AN1: 0 | AO1: 0 | AP1: 0 | AQ1: 0 | AR1: 0

Sheet SrcPoprs
A1: 24 | B1: 1 | G1: *0,8 | I1: *0,8 | S1: Гл.5.Прил.2.2.п.2.2.23_05.00.01.37.001 | T1: При выполнении монтажных и пусконаладочных работ по какому-либо оборудованию одним и тем же звеном (бригадой) | U1: Глава 5

Sheet SrcKA
A1: 0 | B1: Smeta.RU (495) 974-1589 | D1: _PS_ | F1: 0 | G1: 0 | H1: 0 | I1: Smeta.RU | K1: 1 | L1: 47858 | M1: 10 | N1: 11 | O1: 14 | P1: 0 | Q1: 1
F12: =Source!F12 -> 09-01-01._(Копия) (ТСН-2001 (Мосгосэкспертиза)) (ТСН-2001 (Мосгосэкспертиза)) (ТСН-2001 (Мосгосэкспертиза)) (ТСН-2001 (Мосгосэкспертиза)) | G12: =Source!G12 -> 09-01-01. ПНР ТП (ТСН-2001 (Мосгосэкспертиза)) (ТСН-2001 (Мосгосэкспертиза)) | CY12: =Source!CY12 -> 0
