Workbook

Sheet Смета по ТСН-2001(с доп.43
A1: =Source!B1 -> Smeta.RU (495) 974-1589
J2: Форма № 4б
A3: ПИР, СМР, ПНР, материалы, оборудование (за исключением замков, предоставляемых Заказчиком) по титулу: Строительство ТП-10/0,4кВ с тр-ми 2х400кВА, 4КЛ-10кВ от ТП-10/0,4кВ луч А,Б до КЛ-10кВ направлением ТП-10/0,4кВ № № 21782 - ТП-10/0,4кВ № 24478 луч А,Б, 8КЛ-0,4кВ от ТП-10/0,4кВ до ВРЩ-0,4кВ №1-3, в т.ч. ПИР: г.Москва, ул.Феодосийская, з/у 7 для нужд МКС – филиала ПАО «Россети Московский регион»
A4: (наименование стройки и/или объекта)
A6: ЛОКАЛЬНАЯ СМЕТА № 09-01-04
A8: Транспортировка грунта и мусора (2 этап)
A9: (наименование работ и затрат)
A11: =CONCATENATE( "Основание: чертежи № ", Source!J12) -> Основание: чертежи №
I13: В базисном уровне цен | J13: В текущем уровне цен
E14: Сметная стоимость | I14: =I15+I16+I17+I18 -> 4.87 | J14: =J15+J16+J17+J18 -> 71.22 | K14: тыс.руб.
E15: Строительные работы | I15: =ROUND(SUM(X1:X68)/1000, 2) -> 0 | J15: =ROUND((Source!P231)/1000, 2) -> 0 | K15: тыс.руб.
E16: Работы по монтажу оборудования | I16: =ROUND(SUM(Y1:Y68)/1000, 2) -> 0 | J16: =ROUND((Source!P232)/1000, 2) -> 0 | K16: тыс.руб.
E17: Оборудование | I17: =ROUND(SUM(Z1:Z68)/1000, 2) -> 0 | J17: =ROUND((Source!P223)/1000, 2) -> 0 | K17: тыс.руб.
E18: Прочие работы и затраты | I18: =ROUND(SUM(AA1:AA68)/1000, 2) -> 4.87 | J18: =ROUND((Source!P233+Source!P234)/1000, 2) -> 71.22 | K18: тыс.руб.
E19: Средства на оплату труда | I19: =ROUND(SUM(W1:W68)/1000, 2) -> 0 | J19: =((Source!P229 + Source!P228)/1000) -> 0 | K19: тыс.руб.
E20: Затраты труда | I20: =SUM(AB1:AB68) -> 0 | K20: чел.-ч.
E21: Кроме того:
E22: Возврат материалов | I22: =ROUND(SUM(AE1:AE68)/1000, 2) -> 0 | J22: =SUM(AF1:AF68)/1000 -> 0 | K22: тыс.руб.
A24: Составлен(а) по ТСН-2001 с учетом Дополнения №: 73
A25: № и период сборника коэффициентов (индексов) пересчета: Коэффициенты к ТСН-2001 МГЭ №212 III квартал 2024 года | AP25: № и период сборника коэффициентов (индексов) пересчета: Коэффициенты к ТСН-2001 МГЭ №212 III квартал 2024 года
A26: № п/п | B26: Шифр расценки и коды ресурсов | C26: Наименование работ и затрат | D26: Ед. изм. | E26: Кол-во единиц | F26: Цена на ед. изм., руб. | G26: Попра- вочные коэффи- циенты | H26: Коэффи- циенты зимних удорожа- ний | I26: Всего затрат в базисном уровне цен, руб. | J26: Коэффи- циенты (индек- сы) пере- счета, нормы НР и СП | K26: ВСЕГО затрат в текущем уровне цен, руб.
A27: 1 | B27: 2 | C27: 3 | D27: 4 | E27: 5 | F27: 6 | G27: 7 | H27: 8 | I27: 9 | J27: 10 | K27: 11
A30: =CONCATENATE("Раздел: ",IF(Source!G24<>"Новый раздел", Source!G24, "")) -> Раздел: Благоустройство
A31: 1 | B31: =Source!F29 -> 15.2-50-10 | C31: Перевозка строительного мусора на расстояние до 50 км автосамосвалами грузоподъемностью до 10 т | D31: =Source!DW29 -> т | E31: =Source!I29 -> 10.55 | Q31: =ROUND((Source!DN29/100)*ROUND((ROUND((Source!AF29*Source!AV29*Source!I29),2)),2), 2) -> 0 | R31: =Source!X29 -> 0 | S31: =ROUND((Source!DO29/100)*ROUND((ROUND((Source!AF29*Source!AV29*Source!I29),2)),2), 2) -> 0 | T31: =Source!Y29 -> 0 | U31: =ROUND((175/100)*ROUND((ROUND((Source!AE29*Source!AV29*Source!I29),2)),2), 2) -> 0 | V31: =ROUND((160/100)*ROUND(ROUND((ROUND((Source!AE29*Source!AV29*Source!I29),2)*Source!BS29),2), 2), 2) -> 0 | AI31: 0
C32: ЭМ | F32: =Source!AM29 -> 42.72 | G32: =Source!DE29 | H32: =Source!AV29 -> 1 | I32: =(ROUND((ROUND(((Source!ET29)*Source!AV29*Source!I29),2)),2)+ROUND((ROUND(((Source!AE29-(Source!EU29))*Source!AV29*Source!I29),2)),2)) -> 450.7 | J32: =IF(Source!BB29<> 0, Source!BB29, 1) -> 15.67 | K32: =Source!Q29 -> 7062.47
C33: Всего по позиции: | H33: =I32+0 -> 450.7 | J33: =K32+0 -> 7062.47 | O33: =I32+0 -> 450.7 | P33: =K32+0 -> 7062.47 | X33: =IF(Source!BI29<=1,I32-0, 0) -> 0 | Y33: =IF(Source!BI29=2,I32-0, 0) -> 0 | Z33: =IF(Source!BI29=3,I32-0, 0) -> 0 | AA33: =IF(Source!BI29=4,I32,0) -> 450.7
A35: 2 | B35: =Source!F31 -> 15.1-1300-02 | C35: Лом асфальтовых и асфальтобетонных покрытий малоопасный | D35: =Source!DW31 -> 1 Т | E35: =Source!I31 -> 10.55 | Q35: =ROUND((Source!DN31/100)*ROUND((ROUND((Source!AF31*Source!AV31*Source!I31),2)),2), 2) -> 0 | R35: =Source!X31 -> 0 | S35: =ROUND((Source!DO31/100)*ROUND((ROUND((Source!AF31*Source!AV31*Source!I31),2)),2), 2) -> 0 | T35: =Source!Y31 -> 0 | U35: =ROUND((175/100)*ROUND((ROUND((Source!AE31*Source!AV31*Source!I31),2)),2), 2) -> 0 | V35: =ROUND((160/100)*ROUND(ROUND((ROUND((Source!AE31*Source!AV31*Source!I31),2)*Source!BS31),2), 2), 2) -> 0 | AI35: 0
C36: ЭМ | F36: =Source!AM31 -> 36.59 | G36: =Source!DE31 | H36: =Source!AV31 -> 1 | I36: =(ROUND((ROUND(((Source!ET31)*Source!AV31*Source!I31),2)),2)+ROUND((ROUND(((Source!AE31-(Source!EU31))*Source!AV31*Source!I31),2)),2)) -> 386.02 | J36: =IF(Source!BB31<> 0, Source!BB31, 1) -> 8.2 | K36: =Source!Q31 -> 3165.36
C37: Всего по позиции: | H37: =I36+0 -> 386.02 | J37: =K36+0 -> 3165.36 | O37: =I36+0 -> 386.02 | P37: =K36+0 -> 3165.36 | X37: =IF(Source!BI31<=1,I36-0, 0) -> 0 | Y37: =IF(Source!BI31=2,I36-0, 0) -> 0 | Z37: =IF(Source!BI31=3,I36-0, 0) -> 0 | AA37: =IF(Source!BI31=4,I36,0) -> 386.02
A40: =CONCATENATE("Итого по разделу: ",IF(Source!G39<>"Новый раздел", Source!G39, "")) -> Итого по разделу: Благоустройство | H40: =SUM(O30:O39) -> 836.72 | J40: =SUM(P30:P39) -> 10227.83
A41: Итого по ТСН-2001.16 | H41: =SUM(AC30:AC40) -> 0 | J41: =SUM(AD30:AD40) -> 0
A42: Итого возвратных сумм | H42: =SUM(AE30:AE41) -> 0 | J42: =SUM(AF30:AF41) -> 0
A44: =CONCATENATE("Раздел: ",IF(Source!G69<>"Новый раздел", Source!G69, "")) -> Раздел: 10 кВ и 0,4 кВ
A45: 6 | B45: =Source!F74 -> 15.2-53-4 | C45: Перевозка грунтов скальных и дисперсных несвязных на расстояние до 53 км автосамосвалами грузоподъемностью до 10 т | D45: =Source!DW74 -> т | E45: =Source!I74 -> 69.86 | Q45: =ROUND((Source!DN74/100)*ROUND((ROUND((Source!AF74*Source!AV74*Source!I74),2)),2), 2) -> 0 | R45: =Source!X74 -> 0 | S45: =ROUND((Source!DO74/100)*ROUND((ROUND((Source!AF74*Source!AV74*Source!I74),2)),2), 2) -> 0 | T45: =Source!Y74 -> 0 | U45: =ROUND((175/100)*ROUND((ROUND((Source!AE74*Source!AV74*Source!I74),2)),2), 2) -> 0 | V45: =ROUND((160/100)*ROUND(ROUND((ROUND((Source!AE74*Source!AV74*Source!I74),2)*Source!BS74),2), 2), 2) -> 0 | AI45: 0
C46: ="Объем: "&Source!I74&"=(39,92)*"&"1,75" -> Объем: 69,86=(39,92)*1,75
C47: ЭМ | F47: =Source!AM74 -> 45.1 | G47: =Source!DE74 | H47: =Source!AV74 -> 1 | I47: =(ROUND((ROUND(((Source!ET74)*Source!AV74*Source!I74),2)),2)+ROUND((ROUND(((Source!AE74-(Source!EU74))*Source!AV74*Source!I74),2)),2)) -> 3150.69 | J47: =IF(Source!BB74<> 0, Source!BB74, 1) -> 15.65 | K47: =Source!Q74 -> 49308.3
C48: Всего по позиции: | H48: =I47+0 -> 3150.69 | J48: =K47+0 -> 49308.3 | O48: =I47+0 -> 3150.69 | P48: =K47+0 -> 49308.3 | X48: =IF(Source!BI74<=1,I47-0, 0) -> 0 | Y48: =IF(Source!BI74=2,I47-0, 0) -> 0 | Z48: =IF(Source!BI74=3,I47-0, 0) -> 0 | AA48: =IF(Source!BI74=4,I47,0) -> 3150.69
A50: 7 | B50: =Source!F76 -> 15.1-1102-01 | C50: Отходы грунта при проведении открытых земляных работ практически неопасные | D50: =Source!DW76 -> 1 Т | E50: =Source!I76 -> 69.86 | Q50: =ROUND((Source!DN76/100)*ROUND((ROUND((Source!AF76*Source!AV76*Source!I76),2)),2), 2) -> 0 | R50: =Source!X76 -> 0 | S50: =ROUND((Source!DO76/100)*ROUND((ROUND((Source!AF76*Source!AV76*Source!I76),2)),2), 2) -> 0 | T50: =Source!Y76 -> 0 | U50: =ROUND((175/100)*ROUND((ROUND((Source!AE76*Source!AV76*Source!I76),2)),2), 2) -> 0 | V50: =ROUND((160/100)*ROUND(ROUND((ROUND((Source!AE76*Source!AV76*Source!I76),2)*Source!BS76),2), 2), 2) -> 0 | AI50: 0
C51: ЭМ | F51: =Source!AM76 -> 12.61 | G51: =Source!DE76 | H51: =Source!AV76 -> 1 | I51: =(ROUND((ROUND(((Source!ET76)*Source!AV76*Source!I76),2)),2)+ROUND((ROUND(((Source!AE76-(Source!EU76))*Source!AV76*Source!I76),2)),2)) -> 880.93 | J51: =IF(Source!BB76<> 0, Source!BB76, 1) -> 13.26 | K51: =Source!Q76 -> 11681.13
C52: Всего по позиции: | H52: =I51+0 -> 880.93 | J52: =K51+0 -> 11681.13 | O52: =I51+0 -> 880.93 | P52: =K51+0 -> 11681.13 | X52: =IF(Source!BI76<=1,I51-0, 0) -> 0 | Y52: =IF(Source!BI76=2,I51-0, 0) -> 0 | Z52: =IF(Source!BI76=3,I51-0, 0) -> 0 | AA52: =IF(Source!BI76=4,I51,0) -> 880.93
...

Sheet Source
A1: 0 | B1: Smeta.RU (495) 974-1589 | D1: _PS_ | F1: 0 | G1: 0 | H1: 0 | I1: Smeta.RU | K1: 1 | L1: 75112 | M1: 10 | N1: 11 | O1: 15 | P1: 0 | Q1: 1
A12: 1 | B12: 249 | C12: 1 | D12: =ROW(A214) -> 214 | E12: 0 | F12: 09-01-04 Транспортировка_(2 этап) | G12: 09-01-04 Транспортировка | I12: 0 | K12: 0 | L12: 0 | M12: 4098 | O12: 0 | P12: 0 | Q12: 0 | R12: 175 | S12: 160 | T12: 1 | V12: 0 | BB12: 0 | BH12: Сметные нормы списания | BI12: Коды ОКП для ТСН-2001 МГЭ (История развития) | BJ12: 1 | BK12: 1 | BL12: 0 | BM12: 0 | BN12: 1 | BO12: 0 | BP12: 6 | BQ12: 2 | BR12: 1 | BS12: 1 | BT12: 0 | BU12: 0 | BV12: 0 | BW12: 0 | BX12: 0 | BZ12: Типовой расчет для ТСН-2001 МГЭ, Новая методика с выпуска доп. 43 (Строительство), Доп 73 | CA12: История развития для ТСН-2001 (МГЭ) 73 доп от 17.07.2024 | CB12: История развития для ТСН-2001 (МГЭ) 73 доп от 17.07.2024 | CC12: История развития для ТСН-2001 (МГЭ) 73 доп от 17.07.2024 | CD12: История развития для ТСН-2001 (МГЭ) 73 доп от 17.07.2024 | CE12: Поправки для ТСН-2001 от 16.04.2024 г. доп.72 | CF12: 0 | CG12: 0 | CH12: 8 | CK12: 79 | CQ12: Территориальные сметные нормативы для Москвы (ТСН-2001) | CR12: ТЕР | CS12: 41660 | CT12: 1 | CU12: 73 | CY12: 0 | EC12: 0
A15: 15 | B15: 1
A18: 52 | B18: =B214 -> 249 | C18: =C214 -> 1 | D18: =D214 -> 12 | E18: =E214 -> 0 | F18: =F214 -> 09-01-04 Транспортировка_(2 этап) | G18: =G214 -> 09-01-04 Транспортировка | O18: =O214 -> 4868.34 | P18: =P214 -> 0 | Q18: =Q214 -> 4868.34 | R18: =R214 -> 0 | S18: =S214 -> 0 | T18: =T214 -> 0 | U18: =U214 -> 0 | V18: =V214 -> 0 | ... GX18: =GX214 -> 0
A20: 3 | B20: 1 | D20: =ROW(A184) -> 184 | F20: Новая локальная смета | G20: Новая локальная смета | I20: 0 | K20: 0 | L20: Новая локальная смета | S20: 0 | T20: 0 | V20: 0 | BX20: 0 | CF20: 0 | CG20: 0
A22: 52 | B22: =B184 -> 1 | C22: =C184 -> 3 | D22: =D184 -> 20 | E22: =E184 -> 0 | F22: =F184 -> Новая локальная смета | G22: =G184 -> Новая локальная смета | O22: =O184 -> 4868.34 | P22: =P184 -> 0 | Q22: =Q184 -> 4868.34 | R22: =R184 -> 0 | S22: =S184 -> 0 | T22: =T184 -> 0 | U22: =U184 -> 0 | V22: =V184 -> 0 | ... GX22: =GX184 -> 0
A24: 4 | B24: 1 | D24: =ROW(A39) -> 39 | F24: Новый раздел | G24: Благоустройство | I24: 0 | K24: 0 | S24: 0 | T24: 0 | V24: 0 | BX24: 0 | CJ24: 0
A26: 52 | B26: =B39 -> 1 | C26: =C39 -> 4 | D26: =D39 -> 24 | E26: =E39 -> 0 | F26: =F39 -> Новый раздел | G26: =G39 -> Благоустройство | O26: =O39 -> 836.72 | P26: =P39 -> 0 | Q26: =Q39 -> 836.72 | R26: =R39 -> 0 | S26: =S39 -> 0 | T26: =T39 -> 0 | U26: =U39 -> 0 | V26: =V39 -> 0 | ... GX26: =GX39 -> 0
A28: 17 | B28: 1 | C28: =ROW(SmtRes!A1) -> 1 | D28: =ROW(EtalonRes!A1) -> 1 | E28: 1 | F28: 15.2-50-10 | G28: Перевозка строительного мусора на расстояние до 50 км автосамосвалами грузоподъемностью до 10 т | H28: т | I28: 10.55 | J28: 0 | K28: 10.55 | O28: =ROUND(CP28,2) -> 450.7 | P28: =ROUND((ROUND((AC28*AW28*I28),2)*BC28),2) -> 0 | Q28: =(ROUND((ROUND(((ET28)*AV28*I28),2)*BB28),2)+ROUND((ROUND(((AE28-(EU28))*AV28*I28),2)*BS28),2)) -> 450.7 | R28: =ROUND((ROUND((AE28*AV28*I28),2)*BS28),2) -> 0 | S28: =ROUND((ROUND((AF28*AV28*I28),2)*BA28),2) -> 0 | T28: =ROUND(CU28*I28,2) -> 0 | U28: =CV28*I28 -> 0 | V28: =CW28*I28 -> 0 | W28: =ROUND(CX28*I28,2) -> 0 | X28: =ROUND(CY28,2) -> 0 | Y28: =ROUND(CZ28,2) -> 0 | AA28: 57734472 | AB28: =ROUND((AC28+AD28+AF28),6) -> 42.72 | AC28: =ROUND((ES28),6) -> 0 | AD28: =ROUND((((ET28)-(EU28))+AE28),6) -> 42.72 | AE28: =ROUND((EU28),6) -> 0 | AF28: =ROUND((EV28),6) -> 0 | AG28: =ROUND((AP28),6) -> 0 | AH28: =(EW28) -> 0 | AI28: =(EX28) -> 0 | AJ28: =(AS28) -> 0 | AK28: 42.72 | AL28: 0 | AM28: 42.72 | AN28: 0 | AO28: 0 | AP28: 0 | AQ28: 0 | AR28: 0 | AS28: 0 | AT28: 0 | AU28: 0 | AV28: 1 | AW28: 1 | AZ28: 1 | BA28: 1 | BB28: 1 | BC28: 1 | BH28: 0 | BI28: 4 | BJ28: ТСН-2001.15 Доп. 68, Сб. 2, т. 50, поз. 10 | BM28: 1113 | BN28: 0 | BP28: 0 | BQ28: 150 | BR28: 0 | BS28: 1 | BT28: 1 | BU28: 1 | BV28: 1 | BW28: 1 | BX28: 1 | BZ28: 0 | CA28: 0 | CE28: 30 | CF28: 0 | CG28: 0 | CM28: 0 | CO28: 0 | CP28: =(P28+Q28+S28) -> 450.7 | CQ28: =ROUND((ROUND((AC28*AW28*1),2)*BC28),2) -> 0 | CR28: =(ROUND((ROUND(((ET28)*AV28*1),2)*BB28),2)+ROUND((ROUND(((AE28-(EU28))*AV28*1),2)*BS28),2)) -> 42.72 | CS28: =ROUND((ROUND((AE28*AV28*1),2)*BS28),2) -> 0 | CT28: =ROUND((ROUND((AF28*AV28*1),2)*BA28),2) -> 0 | CU28: =AG28 -> 0 | CV28: =(AH28*AV28) -> 0 | CW28: =AI28 -> 0 | CX28: =AJ28 -> 0 | CY28: =((S28*BZ28)/100) -> 0 | CZ28: =((S28*CA28)/100) -> 0 | DN28: 0 | DO28: 0 | DP28: 1 | DQ28: 1 | DU28: 1009 | DV28: т | DW28: т | DX28: 1000 | EE28: 51697152 | EF28: 150 | EG28: Транспортные затраты | EH28: 0 | EJ28: 4 | EK28: 1113 | EL28: ТСН-2001.15-1. Перевозка строительного мусора | EM28: ТСН-2001.15-1-5 | EQ28: 131072 | ER28: 42.72 | ES28: 0 | ET28: 42.72 | EU28: 0 | EV28: 0 | EW28: 0 | EX28: 0 | EY28: 0 | FQ28: 0 | FR28: 0 | FS28: 0 | FX28: 0 | FY28: 0 | GD28: 1 | GF28: -444714868 | GG28: 2 | GH28: 1 | GI28: -2 | GJ28: 0 | GK28: 0 | GL28: =ROUND(IF(AND(BH28=3,BI28=3,FS28<>0),P28,0),2) -> 0 | GM28: =ROUND(O28+X28+Y28,2)+GX28 -> 450.7 | GN28: =IF(OR(BI28=0,BI28=1),GM28-GX28,0) -> 0 | GO28: =IF(BI28=2,GM28-GX28,0) -> 0 | GP28: =IF(BI28=4,GM28-GX28,0) -> 450.7 | GR28: 0 | GS28: 0 | GT28: 0 | GV28: =ROUND((GT28),6) -> 0 | GW28: 1 | GX28: =ROUND(HC28*I28,2) -> 0 | HA28: 0 | HB28: 0 | HC28: =GV28*GW28 -> 0 | HS28: 0 | IK28: 0
A29: 17 | B29: 1 | C29: =ROW(SmtRes!A2) -> 2 | D29: =ROW(EtalonRes!A2) -> 2 | E29: 1 | F29: 15.2-50-10 | G29: Перевозка строительного мусора на расстояние до 50 км автосамосвалами грузоподъемностью до 10 т | H29: т | I29: 10.55 | J29: 0 | K29: 10.55 | O29: =ROUND(CP29,2) -> 7062.47 | P29: =ROUND((ROUND((AC29*AW29*I29),2)*BC29),2) -> 0 | Q29: =(ROUND((ROUND(((ET29)*AV29*I29),2)*BB29),2)+ROUND((ROUND(((AE29-(EU29))*AV29*I29),2)*BS29),2)) -> 7062.47 | R29: =ROUND((ROUND((AE29*AV29*I29),2)*BS29),2) -> 0 | S29: =ROUND((ROUND((AF29*AV29*I29),2)*BA29),2) -> 0 | T29: =ROUND(CU29*I29,2) -> 0 | U29: =CV29*I29 -> 0 | V29: =CW29*I29 -> 0 | W29: =ROUND(CX29*I29,2) -> 0 | X29: =ROUND(CY29,2) -> 0 | Y29: =ROUND(CZ29,2) -> 0 | AA29: 57734470 | AB29: =ROUND((AC29+AD29+AF29),6) -> 42.72 | AC29: =ROUND((ES29),6) -> 0 | AD29: =ROUND((((ET29)-(EU29))+AE29),6) -> 42.72 | AE29: =ROUND((EU29),6) -> 0 | AF29: =ROUND((EV29),6) -> 0 | AG29: =ROUND((AP29),6) -> 0 | AH29: =(EW29) -> 0 | AI29: =(EX29) -> 0 | AJ29: =(AS29) -> 0 | AK29: 42.72 | AL29: 0 | AM29: 42.72 | AN29: 0 | AO29: 0 | AP29: 0 | AQ29: 0 | AR29: 0 | AS29: 0 | AT29: 95 | AU29: 65 | AV29: 1 | AW29: 1 | AZ29: 1 | BA29: 1 | BB29: 15.67 | BC29: 1 | BH29: 0 | BI29: 4 | BJ29: ТСН-2001.15 Доп. 68, Сб. 2, т. 50, поз. 10 | BM29: 1113 | BN29: 0 | BO29: 15.2-50-10 | BP29: 1 | BQ29: 150 | BR29: 0 | BS29: 1 | BT29: 1 | BU29: 1 | BV29: 1 | BW29: 1 | BX29: 1 | BZ29: 95 | CA29: 65 | CE29: 30 | CF29: 0 | CG29: 0 | CM29: 0 | CO29: 0 | CP29: =(P29+Q29+S29) -> 7062.47 | CQ29: =ROUND((ROUND((AC29*AW29*1),2)*BC29),2) -> 0 | CR29: =(ROUND((ROUND(((ET29)*AV29*1),2)*BB29),2)+ROUND((ROUND(((AE29-(EU29))*AV29*1),2)*BS29),2)) -> 669.42 | CS29: =ROUND((ROUND((AE29*AV29*1),2)*BS29),2) -> 0 | CT29: =ROUND((ROUND((AF29*AV29*1),2)*BA29),2) -> 0 | CU29: =AG29 -> 0 | CV29: =(AH29*AV29) -> 0 | CW29: =AI29 -> 0 | CX29: =AJ29 -> 0 | CY29: =S29*(BZ29/100) -> 0 | CZ29: =S29*(CA29/100) -> 0 | DN29: 0 | DO29: 0 | DP29: 1 | DQ29: 1 | DU29: 1009 | DV29: т | DW29: т | DX29: 1000 | EE29: 51697152 | EF29: 150 | EG29: Транспортные затраты | EH29: 0 | EJ29: 4 | EK29: 1113 | EL29: ТСН-2001.15-1. Перевозка строительного мусора | EM29: ТСН-2001.15-1-5 | EQ29: 131072 | ER29: 42.72 | ES29: 0 | ET29: 42.72 | EU29: 0 | EV29: 0 | EW29: 0 | EX29: 0 | EY29: 0 | FQ29: 0 | FR29: 0 | FS29: 0 | FX29: 0 | FY29: 0 | GD29: 0 | GF29: -444714868 | GG29: 2 | GH29: 1 | GI29: 2 | GJ29: 0 | GK29: =ROUND(R29*(S12)/100,2) -> 0 | GL29: =ROUND(IF(AND(BH29=3,BI29=3,FS29<>0),P29,0),2) -> 0 | GM29: =ROUND(O29+X29+Y29+GK29,2)+GX29 -> 7062.47 | GN29: =IF(OR(BI29=0,BI29=1),GM29-GX29,0) -> 0 | GO29: =IF(BI29=2,GM29-GX29,0) -> 0 | GP29: =IF(BI29=4,GM29-GX29,0) -> 7062.47 | GR29: 0 | GS29: 3 | GT29: 0 | GV29: =ROUND((GT29),6) -> 0 | GW29: 1 | GX29: =ROUND(HC29*I29,2) -> 0 | HA29: 0 | HB29: 0 | HC29: =GV29*GW29 -> 0 | HS29: 0 | IK29: 0
A30: 17 | B30: 1 | D30: =ROW(EtalonRes!A3) -> 3 | E30: 2 | F30: 15.1-1300-02 | G30: Лом асфальтовых и асфальтобетонных покрытий малоопасный | H30: 1 Т | I30: 10.55 | J30: 0 | K30: 10.55 | O30: =ROUND(CP30,2) -> 386.02 | P30: =ROUND((ROUND((AC30*AW30*I30),2)*BC30),2) -> 0 | Q30: =(ROUND((ROUND(((ET30)*AV30*I30),2)*BB30),2)+ROUND((ROUND(((AE30-(EU30))*AV30*I30),2)*BS30),2)) -> 386.02 | R30: =ROUND((ROUND((AE30*AV30*I30),2)*BS30),2) -> 0 | S30: =ROUND((ROUND((AF30*AV30*I30),2)*BA30),2) -> 0 | T30: =ROUND(CU30*I30,2) -> 0 | U30: =CV30*I30 -> 0 | V30: =CW30*I30 -> 0 | W30: =ROUND(CX30*I30,2) -> 0 | X30: =ROUND(CY30,2) -> 0 | Y30: =ROUND(CZ30,2) -> 0 | AA30: 57734472 | AB30: =ROUND((AC30+AD30+AF30),6) -> 36.59 | AC30: =ROUND((ES30),6) -> 0 | AD30: =ROUND((((ET30)-(EU30))+AE30),6) -> 36.59 | AE30: =ROUND((EU30),6) -> 0 | AF30: =ROUND((EV30),6) -> 0 | AG30: =ROUND((AP30),6) -> 0 | AH30: =(EW30) -> 0 | AI30: =(EX30) -> 0 | AJ30: =(AS30) -> 0 | AK30: 36.59 | AL30: 0 | AM30: 36.59 | AN30: 0 | AO30: 0 | AP30: 0 | AQ30: 0 | AR30: 0 | AS30: 0 | AT30: 0 | AU30: 0 | AV30: 1 | AW30: 1 | AZ30: 1 | BA30: 1 | BB30: 1 | BC30: 1 | BH30: 0 | BI30: 4 | BJ30: ТСН-2001.15 Доп. 56, Сб. 1, т. 1300, поз. 2 | BM30: 1113 | BN30: 0 | BP30: 0 | BQ30: 150 | BR30: 0 | BS30: 1 | BT30: 1 | BU30: 1 | BV30: 1 | BW30: 1 | BX30: 1 | BZ30: 0 | CA30: 0 | CE30: 30 | CF30: 0 | CG30: 0 | CM30: 0 | CO30: 0 | CP30: =(P30+Q30+S30) -> 386.02 | CQ30: =ROUND((ROUND((AC30*AW30*1),2)*BC30),2) -> 0 | CR30: =(ROUND((ROUND(((ET30)*AV30*1),2)*BB30),2)+ROUND((ROUND(((AE30-(EU30))*AV30*1),2)*BS30),2)) -> 36.59 | CS30: =ROUND((ROUND((AE30*AV30*1),2)*BS30),2) -> 0 | CT30: =ROUND((ROUND((AF30*AV30*1),2)*BA30),2) -> 0 | CU30: =AG30 -> 0 | CV30: =(AH30*AV30) -> 0 | CW30: =AI30 -> 0 | CX30: =AJ30 -> 0 | CY30: =((S30*BZ30)/100) -> 0 | CZ30: =((S30*CA30)/100) -> 0 | DN30: 0 | DO30: 0 | DP30: 1 | DQ30: 1 | DU30: 1013 | DV30: 1 Т | DW30: 1 Т | DX30: 1 | EE30: 51697152 | EF30: 150 | EG30: Транспортные затраты | EH30: 0 | EJ30: 4 | EK30: 1113 | EL30: ТСН-2001.15-1. Перевозка строительного мусора | EM30: ТСН-2001.15-1-5 | EQ30: 131072 | ER30: 36.59 | ES30: 0 | ET30: 36.59 | EU30: 0 | EV30: 0 | EW30: 0 | EX30: 0 | EY30: 0 | FQ30: 0 | FR30: 0 | FS30: 0 | FX30: 0 | FY30: 0 | GD30: 1 | GF30: 1137320751 | GG30: 2 | GH30: 1 | GI30: -2 | GJ30: 0 | GK30: 0 | GL30: =ROUND(IF(AND(BH30=3,BI30=3,FS30<>0),P30,0),2) -> 0 | GM30: =ROUND(O30+X30+Y30,2)+GX30 -> 386.02 | GN30: =IF(OR(BI30=0,BI30=1),GM30-GX30,0) -> 0 | GO30: =IF(BI30=2,GM30-GX30,0) -> 0 | GP30: =IF(BI30=4,GM30-GX30,0) -> 386.02 | GR30: 0 | GS30: 0 | GT30: 0 | GV30: =ROUND((GT30),6) -> 0 | GW30: 1 | GX30: =ROUND(HC30*I30,2) -> 0 | HA30: 0 | HB30: 0 | HC30: =GV30*GW30 -> 0 | HS30: 0 | IK30: 0
A31: 17 | B31: 1 | D31: =ROW(EtalonRes!A4) -> 4 | E31: 2 | F31: 15.1-1300-02 | G31: Лом асфальтовых и асфальтобетонных покрытий малоопасный | H31: 1 Т | I31: 10.55 | J31: 0 | K31: 10.55 | O31: =ROUND(CP31,2) -> 3165.36 | P31: =ROUND((ROUND((AC31*AW31*I31),2)*BC31),2) -> 0 | Q31: =(ROUND((ROUND(((ET31)*AV31*I31),2)*BB31),2)+ROUND((ROUND(((AE31-(EU31))*AV31*I31),2)*BS31),2)) -> 3165.36 | R31: =ROUND((ROUND((AE31*AV31*I31),2)*BS31),2) -> 0 | S31: =ROUND((ROUND((AF31*AV31*I31),2)*BA31),2) -> 0 | T31: =ROUND(CU31*I31,2) -> 0 | U31: =CV31*I31 -> 0 | V31: =CW31*I31 -> 0 | W31: =ROUND(CX31*I31,2) -> 0 | X31: =ROUND(CY31,2) -> 0 | Y31: =ROUND(CZ31,2) -> 0 | AA31: 57734470 | AB31: =ROUND((AC31+AD31+AF31),6) -> 36.59 | AC31: =ROUND((ES31),6) -> 0 | AD31: =ROUND((((ET31)-(EU31))+AE31),6) -> 36.59 | AE31: =ROUND((EU31),6) -> 0 | AF31: =ROUND((EV31),6) -> 0 | AG31: =ROUND((AP31),6) -> 0 | AH31: =(EW31) -> 0 | AI31: =(EX31) -> 0 | AJ31: =(AS31) -> 0 | AK31: 36.59 | AL31: 0 | AM31: 36.59 | AN31: 0 | AO31: 0 | AP31: 0 | AQ31: 0 | AR31: 0 | AS31: 0 | AT31: 95 | AU31: 65 | AV31: 1 | AW31: 1 | AZ31: 1 | BA31: 1 | BB31: 8.2 | BC31: 1 | BH31: 0 | BI31: 4 | BJ31: ТСН-2001.15 Доп. 56, Сб. 1, т. 1300, поз. 2 | BM31: 1113 | BN31: 0 | BO31: 15.1-1300-02 | BP31: 1 | BQ31: 150 | BR31: 0 | BS31: 1 | BT31: 1 | BU31: 1 | BV31: 1 | BW31: 1 | BX31: 1 | BZ31: 95 | CA31: 65 | CE31: 30 | CF31: 0 | CG31: 0 | CM31: 0 | CO31: 0 | CP31: =(P31+Q31+S31) -> 3165.36 | CQ31: =ROUND((ROUND((AC31*AW31*1),2)*BC31),2) -> 0 | CR31: =(ROUND((ROUND(((ET31)*AV31*1),2)*BB31),2)+ROUND((ROUND(((AE31-(EU31))*AV31*1),2)*BS31),2)) -> 300.04 | CS31: =ROUND((ROUND((AE31*AV31*1),2)*BS31),2) -> 0 | CT31: =ROUND((ROUND((AF31*AV31*1),2)*BA31),2) -> 0 | CU31: =AG31 -> 0 | CV31: =(AH31*AV31) -> 0 | CW31: =AI31 -> 0 | CX31: =AJ31 -> 0 | CY31: =S31*(BZ31/100) -> 0 | CZ31: =S31*(CA31/100) -> 0 | DN31: 0 | DO31: 0 | DP31: 1 | DQ31: 1 | DU31: 1013 | DV31: 1 Т | DW31: 1 Т | DX31: 1 | EE31: 51697152 | EF31: 150 | EG31: Транспортные затраты | EH31: 0 | EJ31: 4 | EK31: 1113 | EL31: ТСН-2001.15-1. Перевозка строительного мусора | EM31: ТСН-2001.15-1-5 | EQ31: 131072 | ER31: 36.59 | ES31: 0 | ET31: 36.59 | EU31: 0 | EV31: 0 | EW31: 0 | EX31: 0 | EY31: 0 | FQ31: 0 | FR31: 0 | FS31: 0 | FX31: 0 | FY31: 0 | GD31: 0 | GF31: 1137320751 | GG31: 2 | GH31: 1 | GI31: 2 | GJ31: 0 | GK31: =ROUND(R31*(S12)/100,2) -> 0 | GL31: =ROUND(IF(AND(BH31=3,BI31=3,FS31<>0),P31,0),2) -> 0 | GM31: =ROUND(O31+X31+Y31+GK31,2)+GX31 -> 3165.36 | GN31: =IF(OR(BI31=0,BI31=1),GM31-GX31,0) -> 0 | GO31: =IF(BI31=2,GM31-GX31,0) -> 0 | GP31: =IF(BI31=4,GM31-GX31,0) -> 3165.36 | GR31: 0 | GS31: 3 | GT31: 0 | GV31: =ROUND((GT31),6) -> 0 | GW31: 1 | GX31: =ROUND(HC31*I31,2) -> 0 | HA31: 0 | HB31: 0 | HC31: =GV31*GW31 -> 0 | HS31: 0 | IK31: 0
A32: 17 | B32: 1 | D32: =ROW(EtalonRes!A5) -> 5 | E32: 3 | F32: 15.1-1201-03 | G32: Лом бетонных изделий, отходы бетона в кусковой форме, практически неопасные | H32: 1 Т | I32: 0 | J32: 0 | K32: 0 | O32: =ROUND(CP32,2) -> 0 | P32: =ROUND((ROUND((AC32*AW32*I32),2)*BC32),2) -> 0 | Q32: =(ROUND((ROUND(((ET32)*AV32*I32),2)*BB32),2)+ROUND((ROUND(((AE32-(EU32))*AV32*I32),2)*BS32),2)) -> 0 | R32: =ROUND((ROUND((AE32*AV32*I32),2)*BS32),2) -> 0 | S32: =ROUND((ROUND((AF32*AV32*I32),2)*BA32),2) -> 0 | T32: =ROUND(CU32*I32,2) -> 0 | U32: =CV32*I32 -> 0 | V32: =CW32*I32 -> 0 | W32: =ROUND(CX32*I32,2) -> 0 | X32: =ROUND(CY32,2) -> 0 | Y32: =ROUND(CZ32,2) -> 0 | AA32: 57734472 | AB32: =ROUND((AC32+AD32+AF32),6) -> 22.57 | AC32: =ROUND((ES32),6) -> 0 | AD32: =ROUND((((ET32)-(EU32))+AE32),6) -> 22.57 | AE32: =ROUND((EU32),6) -> 0 | AF32: =ROUND((EV32),6) -> 0 | AG32: =ROUND((AP32),6) -> 0 | AH32: =(EW32) -> 0 | AI32: =(EX32) -> 0 | AJ32: =(AS32) -> 0 | AK32: 22.57 | AL32: 0 | AM32: 22.57 | AN32: 0 | AO32: 0 | AP32: 0 | AQ32: 0 | AR32: 0 | AS32: 0 | AT32: 0 | AU32: 0 | AV32: 1 | AW32: 1 | AZ32: 1 | BA32: 1 | BB32: 1 | BC32: 1 | BH32: 0 | BI32: 4 | BJ32: ТСН-2001.15 Доп. 56, Сб. 1, т. 1201, поз. 3 | BM32: 1113 | BN32: 0 | BP32: 0 | BQ32: 150 | BR32: 0 | BS32: 1 | BT32: 1 | BU32: 1 | BV32: 1 | BW32: 1 | BX32: 1 | BZ32: 0 | CA32: 0 | CE32: 30 | CF32: 0 | CG32: 0 | CM32: 0 | CO32: 0 | CP32: =(P32+Q32+S32) -> 0 | CQ32: =ROUND((ROUND((AC32*AW32*1),2)*BC32),2) -> 0 | CR32: =(ROUND((ROUND(((ET32)*AV32*1),2)*BB32),2)+ROUND((ROUND(((AE32-(EU32))*AV32*1),2)*BS32),2)) -> 22.57 | CS32: =ROUND((ROUND((AE32*AV32*1),2)*BS32),2) -> 0 | CT32: =ROUND((ROUND((AF32*AV32*1),2)*BA32),2) -> 0 | CU32: =AG32 -> 0 | CV32: =(AH32*AV32) -> 0 | CW32: =AI32 -> 0 | CX32: =AJ32 -> 0 | CY32: =((S32*BZ32)/100) -> 0 | CZ32: =((S32*CA32)/100) -> 0 | DN32: 0 | DO32: 0 | DP32: 1 | DQ32: 1 | DU32: 1013 | DV32: 1 Т | DW32: 1 Т | DX32: 1 | EE32: 51697152 | EF32: 150 | EG32: Транспортные затраты | EH32: 0 | EJ32: 4 | EK32: 1113 | EL32: ТСН-2001.15-1. Перевозка строительного мусора | EM32: ТСН-2001.15-1-5 | EQ32: 131072 | ER32: 22.57 | ES32: 0 | ET32: 22.57 | EU32: 0 | EV32: 0 | EW32: 0 | EX32: 0 | EY32: 0 | FQ32: 0 | FR32: 0 | FS32: 0 | FX32: 0 | FY32: 0 | GD32: 1 | GF32: -1150173431 | GG32: 2 | GH32: 1 | GI32: -2 | GJ32: 0 | GK32: 0 | GL32: =ROUND(IF(AND(BH32=3,BI32=3,FS32<>0),P32,0),2) -> 0 | GM32: =ROUND(O32+X32+Y32,2)+GX32 -> 0 | GN32: =IF(OR(BI32=0,BI32=1),GM32-GX32,0) -> 0 | GO32: =IF(BI32=2,GM32-GX32,0) -> 0 | GP32: =IF(BI32=4,GM32-GX32,0) -> 0 | GR32: 0 | GS32: 0 | GT32: 0 | GV32: =ROUND((GT32),6) -> 0 | GW32: 1 | GX32: =ROUND(HC32*I32,2) -> 0 | HA32: 0 | HB32: 0 | HC32: =GV32*GW32 -> 0 | HS32: 0 | IK32: 0
A33: 17 | B33: 1 | D33: =ROW(EtalonRes!A6) -> 6 | E33: 3 | F33: 15.1-1201-03 | G33: Лом бетонных изделий, отходы бетона в кусковой форме, практически неопасные | H33: 1 Т | I33: 0 | J33: 0 | K33: 0 | O33: =ROUND(CP33,2) -> 0 | P33: =ROUND((ROUND((AC33*AW33*I33),2)*BC33),2) -> 0 | Q33: =(ROUND((ROUND(((ET33)*AV33*I33),2)*BB33),2)+ROUND((ROUND(((AE33-(EU33))*AV33*I33),2)*BS33),2)) -> 0 | R33: =ROUND((ROUND((AE33*AV33*I33),2)*BS33),2) -> 0 | S33: =ROUND((ROUND((AF33*AV33*I33),2)*BA33),2) -> 0 | T33: =ROUND(CU33*I33,2) -> 0 | U33: =CV33*I33 -> 0 | V33: =CW33*I33 -> 0 | W33: =ROUND(CX33*I33,2) -> 0 | X33: =ROUND(CY33,2) -> 0 | Y33: =ROUND(CZ33,2) -> 0 | AA33: 57734470 | AB33: =ROUND((AC33+AD33+AF33),6) -> 22.57 | AC33: =ROUND((ES33),6) -> 0 | AD33: =ROUND((((ET33)-(EU33))+AE33),6) -> 22.57 | AE33: =ROUND((EU33),6) -> 0 | AF33: =ROUND((EV33),6) -> 0 | AG33: =ROUND((AP33),6) -> 0 | AH33: =(EW33) -> 0 | AI33: =(EX33) -> 0 | AJ33: =(AS33) -> 0 | AK33: 22.57 | AL33: 0 | AM33: 22.57 | AN33: 0 | AO33: 0 | AP33: 0 | AQ33: 0 | AR33: 0 | AS33: 0 | AT33: 95 | AU33: 65 | AV33: 1 | AW33: 1 | AZ33: 1 | BA33: 1 | BB33: 6.48 | BC33: 1 | BH33: 0 | BI33: 4 | BJ33: ТСН-2001.15 Доп. 56, Сб. 1, т. 1201, поз. 3 | BM33: 1113 | BN33: 0 | BO33: 15.1-1201-03 | BP33: 1 | BQ33: 150 | BR33: 0 | BS33: 1 | BT33: 1 | BU33: 1 | BV33: 1 | BW33: 1 | BX33: 1 | BZ33: 95 | CA33: 65 | CE33: 30 | CF33: 0 | CG33: 0 | CM33: 0 | CO33: 0 | CP33: =(P33+Q33+S33) -> 0 | CQ33: =ROUND((ROUND((AC33*AW33*1),2)*BC33),2) -> 0 | CR33: =(ROUND((ROUND(((ET33)*AV33*1),2)*BB33),2)+ROUND((ROUND(((AE33-(EU33))*AV33*1),2)*BS33),2)) -> 146.25 | CS33: =ROUND((ROUND((AE33*AV33*1),2)*BS33),2) -> 0 | CT33: =ROUND((ROUND((AF33*AV33*1),2)*BA33),2) -> 0 | CU33: =AG33 -> 0 | CV33: =(AH33*AV33) -> 0 | CW33: =AI33 -> 0 | CX33: =AJ33 -> 0 | CY33: =S33*(BZ33/100) -> 0 | CZ33: =S33*(CA33/100) -> 0 | DN33: 0 | DO33: 0 | DP33: 1 | DQ33: 1 | DU33: 1013 | DV33: 1 Т | DW33: 1 Т | DX33: 1 | EE33: 51697152 | EF33: 150 | EG33: Транспортные затраты | EH33: 0 | EJ33: 4 | EK33: 1113 | EL33: ТСН-2001.15-1. Перевозка строительного мусора | EM33: ТСН-2001.15-1-5 | EQ33: 131072 | ER33: 22.57 | ES33: 0 | ET33: 22.57 | EU33: 0 | EV33: 0 | EW33: 0 | EX33: 0 | EY33: 0 | FQ33: 0 | FR33: 0 | FS33: 0 | FX33: 0 | FY33: 0 | GD33: 0 | GF33: -1150173431 | GG33: 2 | GH33: 1 | GI33: 2 | GJ33: 0 | GK33: =ROUND(R33*(S12)/100,2) -> 0 | GL33: =ROUND(IF(AND(BH33=3,BI33=3,FS33<>0),P33,0),2) -> 0 | GM33: =ROUND(O33+X33+Y33+GK33,2)+GX33 -> 0 | GN33: =IF(OR(BI33=0,BI33=1),GM33-GX33,0) -> 0 | GO33: =IF(BI33=2,GM33-GX33,0) -> 0 | GP33: =IF(BI33=4,GM33-GX33,0) -> 0 | GR33: 0 | GS33: 3 | GT33: 0 | GV33: =ROUND((GT33),6) -> 0 | GW33: 1 | GX33: =ROUND(HC33*I33,2) -> 0 | HA33: 0 | HB33: 0 | HC33: =GV33*GW33 -> 0 | HS33: 0 | IK33: 0
A34: 17 | B34: 1 | D34: =ROW(EtalonRes!A7) -> 7 | E34: 4 | F34: 15.1-1106-02 | G34: Отходы строительного щебня незагрязненные практически неопасные | H34: 1 Т | I34: 0 | J34: 0 | K34: 0 | O34: =ROUND(CP34,2) -> 0 | P34: =ROUND((ROUND((AC34*AW34*I34),2)*BC34),2) -> 0 | Q34: =(ROUND((ROUND(((ET34)*AV34*I34),2)*BB34),2)+ROUND((ROUND(((AE34-(EU34))*AV34*I34),2)*BS34),2)) -> 0 | R34: =ROUND((ROUND((AE34*AV34*I34),2)*BS34),2) -> 0 | S34: =ROUND((ROUND((AF34*AV34*I34),2)*BA34),2) -> 0 | T34: =ROUND(CU34*I34,2) -> 0 | U34: =CV34*I34 -> 0 | V34: =CW34*I34 -> 0 | W34: =ROUND(CX34*I34,2) -> 0 | X34: =ROUND(CY34,2) -> 0 | Y34: =ROUND(CZ34,2) -> 0 | AA34: 57734472 | AB34: =ROUND((AC34+AD34+AF34),6) -> 17.84 | AC34: =ROUND((ES34),6) -> 0 | AD34: =ROUND((((ET34)-(EU34))+AE34),6) -> 17.84 | AE34: =ROUND((EU34),6) -> 0 | AF34: =ROUND((EV34),6) -> 0 | AG34: =ROUND((AP34),6) -> 0 | AH34: =(EW34) -> 0 | AI34: =(EX34) -> 0 | AJ34: =(AS34) -> 0 | AK34: 17.84 | AL34: 0 | AM34: 17.84 | AN34: 0 | AO34: 0 | AP34: 0 | AQ34: 0 | AR34: 0 | AS34: 0 | AT34: 0 | AU34: 0 | AV34: 1 | AW34: 1 | AZ34: 1 | BA34: 1 | BB34: 1 | BC34: 1 | BH34: 0 | BI34: 4 | BJ34: ТСН-2001.15 Доп. 68, Сб. 1, т. 1106, поз. 2 | BM34: 1113 | BN34: 0 | BP34: 0 | BQ34: 150 | BR34: 0 | BS34: 1 | BT34: 1 | BU34: 1 | BV34: 1 | BW34: 1 | BX34: 1 | BZ34: 0 | CA34: 0 | CE34: 30 | CF34: 0 | CG34: 0 | CM34: 0 | CO34: 0 | CP34: =(P34+Q34+S34) -> 0 | CQ34: =ROUND((ROUND((AC34*AW34*1),2)*BC34),2) -> 0 | CR34: =(ROUND((ROUND(((ET34)*AV34*1),2)*BB34),2)+ROUND((ROUND(((AE34-(EU34))*AV34*1),2)*BS34),2)) -> 17.84 | CS34: =ROUND((ROUND((AE34*AV34*1),2)*BS34),2) -> 0 | CT34: =ROUND((ROUND((AF34*AV34*1),2)*BA34),2) -> 0 | CU34: =AG34 -> 0 | CV34: =(AH34*AV34) -> 0 | CW34: =AI34 -> 0 | CX34: =AJ34 -> 0 | CY34: =((S34*BZ34)/100) -> 0 | CZ34: =((S34*CA34)/100) -> 0 | DN34: 0 | DO34: 0 | DP34: 1 | DQ34: 1 | DU34: 1013 | DV34: 1 Т | DW34: 1 Т | DX34: 1 | EE34: 51697152 | EF34: 150 | EG34: Транспортные затраты | EH34: 0 | EJ34: 4 | EK34: 1113 | EL34: ТСН-2001.15-1. Перевозка строительного мусора | EM34: ТСН-2001.15-1-5 | EQ34: 131072 | ER34: 17.84 | ES34: 0 | ET34: 17.84 | EU34: 0 | EV34: 0 | EW34: 0 | EX34: 0 | EY34: 0 | FQ34: 0 | FR34: 0 | FS34: 0 | FX34: 0 | FY34: 0 | GD34: 1 | GF34: 821670597 | GG34: 2 | GH34: 1 | GI34: -2 | GJ34: 0 | GK34: 0 | GL34: =ROUND(IF(AND(BH34=3,BI34=3,FS34<>0),P34,0),2) -> 0 | GM34: =ROUND(O34+X34+Y34,2)+GX34 -> 0 | GN34: =IF(OR(BI34=0,BI34=1),GM34-GX34,0) -> 0 | GO34: =IF(BI34=2,GM34-GX34,0) -> 0 | GP34: =IF(BI34=4,GM34-GX34,0) -> 0 | GR34: 0 | GS34: 0 | GT34: 0 | GV34: =ROUND((GT34),6) -> 0 | GW34: 1 | GX34: =ROUND(HC34*I34,2) -> 0 | HA34: 0 | HB34: 0 | HC34: =GV34*GW34 -> 0 | HS34: 0 | IK34: 0
A35: 17 | B35: 1 | D35: =ROW(EtalonRes!A8) -> 8 | E35: 4 | F35: 15.1-1106-02 | G35: Отходы строительного щебня незагрязненные практически неопасные | H35: 1 Т | I35: 0 | J35: 0 | K35: 0 | O35: =ROUND(CP35,2) -> 0 | P35: =ROUND((ROUND((AC35*AW35*I35),2)*BC35),2) -> 0 | Q35: =(ROUND((ROUND(((ET35)*AV35*I35),2)*BB35),2)+ROUND((ROUND(((AE35-(EU35))*AV35*I35),2)*BS35),2)) -> 0 | R35: =ROUND((ROUND((AE35*AV35*I35),2)*BS35),2) -> 0 | S35: =ROUND((ROUND((AF35*AV35*I35),2)*BA35),2) -> 0 | T35: =ROUND(CU35*I35,2) -> 0 | U35: =CV35*I35 -> 0 | V35: =CW35*I35 -> 0 | W35: =ROUND(CX35*I35,2) -> 0 | X35: =ROUND(CY35,2) -> 0 | Y35: =ROUND(CZ35,2) -> 0 | AA35: 57734470 | AB35: =ROUND((AC35+AD35+AF35),6) -> 17.84 | AC35: =ROUND((ES35),6) -> 0 | AD35: =ROUND((((ET35)-(EU35))+AE35),6) -> 17.84 | AE35: =ROUND((EU35),6) -> 0 | AF35: =ROUND((EV35),6) -> 0 | AG35: =ROUND((AP35),6) -> 0 | AH35: =(EW35) -> 0 | AI35: =(EX35) -> 0 | AJ35: =(AS35) -> 0 | AK35: 17.84 | AL35: 0 | AM35: 17.84 | AN35: 0 | AO35: 0 | AP35: 0 | AQ35: 0 | AR35: 0 | AS35: 0 | AT35: 95 | AU35: 65 | AV35: 1 | AW35: 1 | AZ35: 1 | BA35: 1 | BB35: 12.3 | BC35: 1 | BH35: 0 | BI35: 4 | BJ35: ТСН-2001.15 Доп. 68, Сб. 1, т. 1106, поз. 2 | BM35: 1113 | BN35: 0 | BO35: 15.1-1106-02 | BP35: 1 | BQ35: 150 | BR35: 0 | BS35: 1 | BT35: 1 | BU35: 1 | BV35: 1 | BW35: 1 | BX35: 1 | BZ35: 95 | CA35: 65 | CE35: 30 | CF35: 0 | CG35: 0 | CM35: 0 | CO35: 0 | CP35: =(P35+Q35+S35) -> 0 | CQ35: =ROUND((ROUND((AC35*AW35*1),2)*BC35),2) -> 0 | CR35: =(ROUND((ROUND(((ET35)*AV35*1),2)*BB35),2)+ROUND((ROUND(((AE35-(EU35))*AV35*1),2)*BS35),2)) -> 219.43 | CS35: =ROUND((ROUND((AE35*AV35*1),2)*BS35),2) -> 0 | CT35: =ROUND((ROUND((AF35*AV35*1),2)*BA35),2) -> 0 | CU35: =AG35 -> 0 | CV35: =(AH35*AV35) -> 0 | CW35: =AI35 -> 0 | CX35: =AJ35 -> 0 | CY35: =S35*(BZ35/100) -> 0 | CZ35: =S35*(CA35/100) -> 0 | DN35: 0 | DO35: 0 | DP35: 1 | DQ35: 1 | DU35: 1013 | DV35: 1 Т | DW35: 1 Т | DX35: 1 | EE35: 51697152 | EF35: 150 | EG35: Транспортные затраты | EH35: 0 | EJ35: 4 | EK35: 1113 | EL35: ТСН-2001.15-1. Перевозка строительного мусора | EM35: ТСН-2001.15-1-5 | EQ35: 131072 | ER35: 17.84 | ES35: 0 | ET35: 17.84 | EU35: 0 | EV35: 0 | EW35: 0 | EX35: 0 | EY35: 0 | FQ35: 0 | FR35: 0 | FS35: 0 | FX35: 0 | FY35: 0 | GD35: 0 | GF35: 821670597 | GG35: 2 | GH35: 1 | GI35: 2 | GJ35: 0 | GK35: =ROUND(R35*(S12)/100,2) -> 0 | GL35: =ROUND(IF(AND(BH35=3,BI35=3,FS35<>0),P35,0),2) -> 0 | GM35: =ROUND(O35+X35+Y35+GK35,2)+GX35 -> 0 | GN35: =IF(OR(BI35=0,BI35=1),GM35-GX35,0) -> 0 | GO35: =IF(BI35=2,GM35-GX35,0) -> 0 | GP35: =IF(BI35=4,GM35-GX35,0) -> 0 | GR35: 0 | GS35: 3 | GT35: 0 | GV35: =ROUND((GT35),6) -> 0 | GW35: 1 | GX35: =ROUND(HC35*I35,2) -> 0 | HA35: 0 | HB35: 0 | HC35: =GV35*GW35 -> 0 | HS35: 0 | IK35: 0
A36: 17 | B36: 1 | D36: =ROW(EtalonRes!A9) -> 9 | E36: 5 | F36: 15.1-1200-01 | G36: Лом бортовых камней, брусчатки, булыжных камней и прочие отходы изделий из природного камня, практически неопасный | H36: 1 Т | I36: 0 | J36: 0 | K36: 0 | O36: =ROUND(CP36,2) -> 0 | P36: =ROUND((ROUND((AC36*AW36*I36),2)*BC36),2) -> 0 | Q36: =(ROUND((ROUND(((ET36)*AV36*I36),2)*BB36),2)+ROUND((ROUND(((AE36-(EU36))*AV36*I36),2)*BS36),2)) -> 0 | R36: =ROUND((ROUND((AE36*AV36*I36),2)*BS36),2) -> 0 | S36: =ROUND((ROUND((AF36*AV36*I36),2)*BA36),2) -> 0 | T36: =ROUND(CU36*I36,2) -> 0 | U36: =CV36*I36 -> 0 | V36: =CW36*I36 -> 0 | W36: =ROUND(CX36*I36,2) -> 0 | X36: =ROUND(CY36,2) -> 0 | Y36: =ROUND(CZ36,2) -> 0 | AA36: 57734472 | AB36: =ROUND((AC36+AD36+AF36),6) -> 21.71 | AC36: =ROUND((ES36),6) -> 0 | AD36: =ROUND((((ET36)-(EU36))+AE36),6) -> 21.71 | AE36: =ROUND((EU36),6) -> 0 | AF36: =ROUND((EV36),6) -> 0 | AG36: =ROUND((AP36),6) -> 0 | AH36: =(EW36) -> 0 | AI36: =(EX36) -> 0 | AJ36: =(AS36) -> 0 | AK36: 21.71 | AL36: 0 | AM36: 21.71 | AN36: 0 | AO36: 0 | AP36: 0 | AQ36: 0 | AR36: 0 | AS36: 0 | AT36: 0 | AU36: 0 | AV36: 1 | AW36: 1 | AZ36: 1 | BA36: 1 | BB36: 1 | BC36: 1 | BH36: 0 | BI36: 4 | BJ36: ТСН-2001.15 Доп. 56, Сб. 1, т. 1200, поз. 1 | BM36: 1113 | BN36: 0 | BP36: 0 | BQ36: 150 | BR36: 0 | BS36: 1 | BT36: 1 | BU36: 1 | BV36: 1 | BW36: 1 | BX36: 1 | BZ36: 0 | CA36: 0 | CE36: 30 | CF36: 0 | CG36: 0 | CM36: 0 | CO36: 0 | CP36: =(P36+Q36+S36) -> 0 | CQ36: =ROUND((ROUND((AC36*AW36*1),2)*BC36),2) -> 0 | CR36: =(ROUND((ROUND(((ET36)*AV36*1),2)*BB36),2)+ROUND((ROUND(((AE36-(EU36))*AV36*1),2)*BS36),2)) -> 21.71 | CS36: =ROUND((ROUND((AE36*AV36*1),2)*BS36),2) -> 0 | CT36: =ROUND((ROUND((AF36*AV36*1),2)*BA36),2) -> 0 | CU36: =AG36 -> 0 | CV36: =(AH36*AV36) -> 0 | CW36: =AI36 -> 0 | CX36: =AJ36 -> 0 | CY36: =((S36*BZ36)/100) -> 0 | CZ36: =((S36*CA36)/100) -> 0 | DN36: 0 | DO36: 0 | DP36: 1 | DQ36: 1 | DU36: 1013 | DV36: 1 Т | DW36: 1 Т | DX36: 1 | EE36: 51697152 | EF36: 150 | EG36: Транспортные затраты | EH36: 0 | EJ36: 4 | EK36: 1113 | EL36: ТСН-2001.15-1. Перевозка строительного мусора | EM36: ТСН-2001.15-1-5 | EQ36: 131072 | ER36: 21.71 | ES36: 0 | ET36: 21.71 | EU36: 0 | EV36: 0 | EW36: 0 | EX36: 0 | EY36: 0 | FQ36: 0 | FR36: 0 | FS36: 0 | FX36: 0 | FY36: 0 | GD36: 1 | GF36: -2025383143 | GG36: 2 | GH36: 1 | GI36: -2 | GJ36: 0 | GK36: 0 | GL36: =ROUND(IF(AND(BH36=3,BI36=3,FS36<>0),P36,0),2) -> 0 | GM36: =ROUND(O36+X36+Y36,2)+GX36 -> 0 | GN36: =IF(OR(BI36=0,BI36=1),GM36-GX36,0) -> 0 | GO36: =IF(BI36=2,GM36-GX36,0) -> 0 | GP36: =IF(BI36=4,GM36-GX36,0) -> 0 | GR36: 0 | GS36: 0 | GT36: 0 | GV36: =ROUND((GT36),6) -> 0 | GW36: 1 | GX36: =ROUND(HC36*I36,2) -> 0 | HA36: 0 | HB36: 0 | HC36: =GV36*GW36 -> 0 | HS36: 0 | IK36: 0
A37: 17 | B37: 1 | D37: =ROW(EtalonRes!A10) -> 10 | E37: 5 | F37: 15.1-1200-01 | G37: Лом бортовых камней, брусчатки, булыжных камней и прочие отходы изделий из природного камня, практически неопасный | H37: 1 Т | I37: 0 | J37: 0 | K37: 0 | O37: =ROUND(CP37,2) -> 0 | P37: =ROUND((ROUND((AC37*AW37*I37),2)*BC37),2) -> 0 | Q37: =(ROUND((ROUND(((ET37)*AV37*I37),2)*BB37),2)+ROUND((ROUND(((AE37-(EU37))*AV37*I37),2)*BS37),2)) -> 0 | R37: =ROUND((ROUND((AE37*AV37*I37),2)*BS37),2) -> 0 | S37: =ROUND((ROUND((AF37*AV37*I37),2)*BA37),2) -> 0 | T37: =ROUND(CU37*I37,2) -> 0 | U37: =CV37*I37 -> 0 | V37: =CW37*I37 -> 0 | W37: =ROUND(CX37*I37,2) -> 0 | X37: =ROUND(CY37,2) -> 0 | Y37: =ROUND(CZ37,2) -> 0 | AA37: 57734470 | AB37: =ROUND((AC37+AD37+AF37),6) -> 21.71 | AC37: =ROUND((ES37),6) -> 0 | AD37: =ROUND((((ET37)-(EU37))+AE37),6) -> 21.71 | AE37: =ROUND((EU37),6) -> 0 | AF37: =ROUND((EV37),6) -> 0 | AG37: =ROUND((AP37),6) -> 0 | AH37: =(EW37) -> 0 | AI37: =(EX37) -> 0 | AJ37: =(AS37) -> 0 | AK37: 21.71 | AL37: 0 | AM37: 21.71 | AN37: 0 | AO37: 0 | AP37: 0 | AQ37: 0 | AR37: 0 | AS37: 0 | AT37: 95 | AU37: 65 | AV37: 1 | AW37: 1 | AZ37: 1 | BA37: 1 | BB37: 9 | BC37: 1 | BH37: 0 | BI37: 4 | BJ37: ТСН-2001.15 Доп. 56, Сб. 1, т. 1200, поз. 1 | BM37: 1113 | BN37: 0 | BO37: 15.1-1200-01 | BP37: 1 | BQ37: 150 | BR37: 0 | BS37: 1 | BT37: 1 | BU37: 1 | BV37: 1 | BW37: 1 | BX37: 1 | BZ37: 95 | CA37: 65 | CE37: 30 | CF37: 0 | CG37: 0 | CM37: 0 | CO37: 0 | CP37: =(P37+Q37+S37) -> 0 | CQ37: =ROUND((ROUND((AC37*AW37*1),2)*BC37),2) -> 0 | CR37: =(ROUND((ROUND(((ET37)*AV37*1),2)*BB37),2)+ROUND((ROUND(((AE37-(EU37))*AV37*1),2)*BS37),2)) -> 195.39 | CS37: =ROUND((ROUND((AE37*AV37*1),2)*BS37),2) -> 0 | CT37: =ROUND((ROUND((AF37*AV37*1),2)*BA37),2) -> 0 | CU37: =AG37 -> 0 | CV37: =(AH37*AV37) -> 0 | CW37: =AI37 -> 0 | CX37: =AJ37 -> 0 | CY37: =S37*(BZ37/100) -> 0 | CZ37: =S37*(CA37/100) -> 0 | DN37: 0 | DO37: 0 | DP37: 1 | DQ37: 1 | DU37: 1013 | DV37: 1 Т | DW37: 1 Т | DX37: 1 | EE37: 51697152 | EF37: 150 | EG37: Транспортные затраты | EH37: 0 | EJ37: 4 | EK37: 1113 | EL37: ТСН-2001.15-1. Перевозка строительного мусора | EM37: ТСН-2001.15-1-5 | EQ37: 131072 | ER37: 21.71 | ES37: 0 | ET37: 21.71 | EU37: 0 | EV37: 0 | EW37: 0 | EX37: 0 | EY37: 0 | FQ37: 0 | FR37: 0 | FS37: 0 | FX37: 0 | FY37: 0 | GD37: 0 | GF37: -2025383143 | GG37: 2 | GH37: 1 | GI37: 2 | GJ37: 0 | GK37: =ROUND(R37*(S12)/100,2) -> 0 | GL37: =ROUND(IF(AND(BH37=3,BI37=3,FS37<>0),P37,0),2) -> 0 | GM37: =ROUND(O37+X37+Y37+GK37,2)+GX37 -> 0 | GN37: =IF(OR(BI37=0,BI37=1),GM37-GX37,0) -> 0 | GO37: =IF(BI37=2,GM37-GX37,0) -> 0 | GP37: =IF(BI37=4,GM37-GX37,0) -> 0 | GR37: 0 | GS37: 3 | GT37: 0 | GV37: =ROUND((GT37),6) -> 0 | GW37: 1 | GX37: =ROUND(HC37*I37,2) -> 0 | HA37: 0 | HB37: 0 | HC37: =GV37*GW37 -> 0 | HS37: 0 | IK37: 0
A39: 51 | B39: =B24 -> 1 | C39: =A24 -> 4 | D39: =ROW(A24) -> 24 | F39: =IF(F24<>"",F24,"") -> Новый раздел | G39: =IF(G24<>"",G24,"") -> Благоустройство | H39: 0 | O39: =ROUND(AB39,2) -> 836.72 | P39: =ROUND(AC39,2) -> 0 | Q39: =ROUND(AD39,2) -> 836.72 | R39: =ROUND(AE39,2) -> 0 | S39: =ROUND(AF39,2) -> 0 | T39: =ROUND(AG39,2) -> 0 | U39: =AH39 -> 0 | V39: =AI39 -> 0 | W39: =ROUND(AJ39,2) -> 0 | X39: =ROUND(AK39,2) -> 0 | Y39: =ROUND(AL39,2) -> 0 | AB39: =ROUND(SUMIF(AA28:AA37,"=57734472",O28:O37),2) -> 836.72 | AC39: =ROUND(SUMIF(AA28:AA37,"=57734472",P28:P37),2) -> 0 | AD39: =ROUND(SUMIF(AA28:AA37,"=57734472",Q28:Q37),2) -> 836.72 | AE39: =ROUND(SUMIF(AA28:AA37,"=57734472",R28:R37),2) -> 0 | AF39: =ROUND(SUMIF(AA28:AA37,"=57734472",S28:S37),2) -> 0 | AG39: =ROUND(SUMIF(AA28:AA37,"=57734472",T28:T37),2) -> 0 | AH39: =SUMIF(AA28:AA37,"=57734472",U28:U37) -> 0 | AI39: =SUMIF(AA28:AA37,"=57734472",V28:V37) -> 0 | AJ39: =ROUND(SUMIF(AA28:AA37,"=57734472",W28:W37),2) -> 0 | AK39: =ROUND(SUMIF(AA28:AA37,"=57734472",X28:X37),2) -> 0 | AL39: =ROUND(SUMIF(AA28:AA37,"=57734472",Y28:Y37),2) -> 0 | AO39: =ROUND(BX39,2) -> 0 | AP39: =ROUND(BY39,2) -> 0 | AQ39: =ROUND(BZ39,2) -> 0 | AR39: =ROUND(CA39,2) -> 836.72 | AS39: =ROUND(CB39,2) -> 0 | AT39: =ROUND(CC39,2) -> 0 | AU39: =ROUND(CD39,2) -> 836.72 | AV39: =ROUND(CE39,2) -> 0 | ... BD39: =ROUND(CM39,2) -> 0 | BX39: =ROUND(SUMIF(AA28:AA37,"=57734472",FQ28:FQ37),2) -> 0 | BY39: =ROUND(SUMIF(AA28:AA37,"=57734472",FR28:FR37),2) -> 0 | BZ39: =ROUND(SUMIF(AA28:AA37,"=57734472",GL28:GL37),2) -> 0 | CA39: =ROUND(SUMIF(AA28:AA37,"=57734472",GM28:GM37),2) -> 836.72 | CB39: =ROUND(SUMIF(AA28:AA37,"=57734472",GN28:GN37),2) -> 0 | CC39: =ROUND(SUMIF(AA28:AA37,"=57734472",GO28:GO37),2) -> 0 | CD39: =ROUND(SUMIF(AA28:AA37,"=57734472",GP28:GP37),2) -> 836.72 | CE39: =AC39-BX39 -> 0 | CF39: =AC39-BY39 -> 0 | CG39: =BX39-BZ39 -> 0 | CH39: =AC39-BX39-BY39+BZ39 -> 0 | CI39: =BY39-BZ39 -> 0 | CJ39: =ROUND(SUMIF(AA28:AA37,"=57734472",GX28:GX37),2) -> 0 | CK39: =ROUND(SUMIF(AA28:AA37,"=57734472",GY28:GY37),2) -> 0 | CL39: =ROUND(SUMIF(AA28:AA37,"=57734472",GZ28:GZ37),2) -> 0 | CM39: =ROUND(SUMIF(AA28:AA37,"=57734472",HD28:HD37),2) -> 0 | DG39: =ROUND(DT39,2) -> 10227.83 | DH39: =ROUND(DU39,2) -> 0 | DI39: =ROUND(DV39,2) -> 10227.83 | DJ39: =ROUND(DW39,2) -> 0 | DK39: =ROUND(DX39,2) -> 0 | DL39: =ROUND(DY39,2) -> 0 | DM39: =DZ39 -> 0 | DN39: =EA39 -> 0 | DO39: =ROUND(EB39,2) -> 0 | DP39: =ROUND(EC39,2) -> 0 | DQ39: =ROUND(ED39,2) -> 0 | DT39: =ROUND(SUMIF(AA28:AA37,"=57734470",O28:O37),2) -> 10227.83 | DU39: =ROUND(SUMIF(AA28:AA37,"=57734470",P28:P37),2) -> 0 | DV39: =ROUND(SUMIF(AA28:AA37,"=57734470",Q28:Q37),2) -> 10227.83 | DW39: =ROUND(SUMIF(AA28:AA37,"=57734470",R28:R37),2) -> 0 | DX39: =ROUND(SUMIF(AA28:AA37,"=57734470",S28:S37),2) -> 0 | DY39: =ROUND(SUMIF(AA28:AA37,"=57734470",T28:T37),2) -> 0 | DZ39: =SUMIF(AA28:AA37,"=57734470",U28:U37) -> 0 | EA39: =SUMIF(AA28:AA37,"=57734470",V28:V37) -> 0 | EB39: =ROUND(SUMIF(AA28:AA37,"=57734470",W28:W37),2) -> 0 | EC39: =ROUND(SUMIF(AA28:AA37,"=57734470",X28:X37),2) -> 0 | ED39: =ROUND(SUMIF(AA28:AA37,"=57734470",Y28:Y37),2) -> 0 | EG39: =ROUND(FP39,2) -> 0 | EH39: =ROUND(FQ39,2) -> 0 | EI39: =ROUND(FR39,2) -> 0 | EJ39: =ROUND(FS39,2) -> 10227.83 | EK39: =ROUND(FT39,2) -> 0 | EL39: =ROUND(FU39,2) -> 0 | EM39: =ROUND(FV39,2) -> 10227.83 | EN39: =ROUND(FW39,2) -> 0 | ... EV39: =ROUND(GE39,2) -> 0 | FP39: =ROUND(SUMIF(AA28:AA37,"=57734470",FQ28:FQ37),2) -> 0 | FQ39: =ROUND(SUMIF(AA28:AA37,"=57734470",FR28:FR37),2) -> 0 | FR39: =ROUND(SUMIF(AA28:AA37,"=57734470",GL28:GL37),2) -> 0 | FS39: =ROUND(SUMIF(AA28:AA37,"=57734470",GM28:GM37),2) -> 10227.83 | FT39: =ROUND(SUMIF(AA28:AA37,"=57734470",GN28:GN37),2) -> 0 | FU39: =ROUND(SUMIF(AA28:AA37,"=57734470",GO28:GO37),2) -> 0 | FV39: =ROUND(SUMIF(AA28:AA37,"=57734470",GP28:GP37),2) -> 10227.83 | FW39: =DU39-FP39 -> 0 | FX39: =DU39-FQ39 -> 0 | FY39: =FP39-FR39 -> 0 | FZ39: =DU39-FP39-FQ39+FR39 -> 0 | GA39: =FQ39-FR39 -> 0 | GB39: =ROUND(SUMIF(AA28:AA37,"=57734470",GX28:GX37),2) -> 0 | GC39: =ROUND(SUMIF(AA28:AA37,"=57734470",GY28:GY37),2) -> 0 | GD39: =ROUND(SUMIF(AA28:AA37,"=57734470",GZ28:GZ37),2) -> 0 | GE39: =ROUND(SUMIF(AA28:AA37,"=57734470",HD28:HD37),2) -> 0 | GX39: 0
A41: 50 | B41: 0 | C41: 0 | D41: 1 | E41: 201 | F41: =ROUND(Source!O39,O41) -> 836.72 | G41: ПЗ | H41: Прямые затраты | K41: 201 | L41: 1 | M41: 3 | O41: 2 | P41: =ROUND(Source!DG39,O41) -> 10227.83 | W41: 836.72 | X41: 1 | Y41: 836.72 | Z41: 10227.83 | AA41: 1 | AB41: 10227.83
A42: 50 | B42: 0 | C42: 0 | D42: 1 | E42: 202 | F42: =ROUND(Source!P39,O42) -> 0 | G42: СтМатОб | H42: Стоимость материальных ресурсов (всего) | K42: 202 | L42: 2 | M42: 3 | O42: 2 | P42: =ROUND(Source!DH39,O42) -> 0 | W42: 0 | X42: 1 | Y42: 0 | Z42: 0 | AA42: 1 | AB42: 0
A43: 50 | B43: 0 | C43: 0 | D43: 1 | E43: 222 | F43: =ROUND(Source!AO39,O43) -> 0 | G43: СтМатОбЗак | H43: Стоимость материалов и оборудования заказчика | K43: 222 | L43: 3 | M43: 3 | O43: 2 | P43: =ROUND(Source!EG39,O43) -> 0 | W43: 0 | X43: 1 | Y43: 0 | Z43: 0 | AA43: 1 | AB43: 0
A44: 50 | B44: 0 | C44: 0 | D44: 1 | E44: 225 | F44: =ROUND(Source!AV39,O44) -> 0 | G44: СтМатОбПод | H44: Стоимость материалов и оборудования подрядчика | K44: 225 | L44: 4 | M44: 3 | O44: 2 | P44: =ROUND(Source!EN39,O44) -> 0 | W44: 0 | X44: 1 | Y44: 0 | Z44: 0 | AA44: 1 | AB44: 0
A45: 50 | B45: 0 | C45: 0 | D45: 1 | E45: 226 | F45: =ROUND(Source!AW39,O45) -> 0 | G45: СтМат | H45: Стоимость материалов (всего) | K45: 226 | L45: 5 | M45: 3 | O45: 2 | P45: =ROUND(Source!EO39,O45) -> 0 | W45: 0 | X45: 1 | Y45: 0 | Z45: 0 | AA45: 1 | AB45: 0
A46: 50 | B46: 0 | C46: 0 | D46: 1 | E46: 227 | F46: =ROUND(Source!AX39,O46) -> 0 | G46: СтМатЗак | H46: Стоимость материалов заказчика | K46: 227 | L46: 6 | M46: 3 | O46: 2 | P46: =ROUND(Source!EP39,O46) -> 0 | W46: 0 | X46: 1 | Y46: 0 | Z46: 0 | AA46: 1 | AB46: 0
A47: 50 | B47: 0 | C47: 0 | D47: 1 | E47: 228 | F47: =ROUND(Source!AY39,O47) -> 0 | G47: СтМатПод | H47: Стоимость материалов подрядчика | K47: 228 | L47: 7 | M47: 3 | O47: 2 | P47: =ROUND(Source!EQ39,O47) -> 0 | W47: 0 | X47: 1 | Y47: 0 | Z47: 0 | AA47: 1 | AB47: 0
A48: 50 | B48: 0 | C48: 0 | D48: 1 | E48: 216 | F48: =ROUND(Source!AP39,O48) -> 0 | G48: Оборуд | H48: Стоимость оборудования (всего) | K48: 216 | L48: 8 | M48: 3 | O48: 2 | P48: =ROUND(Source!EH39,O48) -> 0 | W48: 0 | X48: 1 | Y48: 0 | Z48: 0 | AA48: 1 | AB48: 0
A49: 50 | B49: 0 | C49: 0 | D49: 1 | E49: 223 | F49: =ROUND(Source!AQ39,O49) -> 0 | G49: ОборудЗак | H49: Стоимость оборудования заказчика | K49: 223 | L49: 9 | M49: 3 | O49: 2 | P49: =ROUND(Source!EI39,O49) -> 0 | W49: 0 | X49: 1 | Y49: 0 | Z49: 0 | AA49: 1 | AB49: 0
A50: 50 | B50: 0 | C50: 0 | D50: 1 | E50: 229 | F50: =ROUND(Source!AZ39,O50) -> 0 | G50: ОборудПод | H50: Стоимость оборудования подрядчика | K50: 229 | L50: 10 | M50: 3 | O50: 2 | P50: =ROUND(Source!ER39,O50) -> 0 | W50: 0 | X50: 1 | Y50: 0 | Z50: 0 | AA50: 1 | AB50: 0
A51: 50 | B51: 0 | C51: 0 | D51: 1 | E51: 203 | F51: =ROUND(Source!Q39,O51) -> 836.72 | G51: ЭММ | H51: Эксплуатация машин | K51: 203 | L51: 11 | M51: 3 | O51: 2 | P51: =ROUND(Source!DI39,O51) -> 10227.83 | W51: 836.72 | X51: 1 | Y51: 836.72 | Z51: 10227.83 | AA51: 1 | AB51: 10227.83
A52: 50 | B52: 0 | C52: 0 | D52: 1 | E52: 231 | F52: =ROUND(Source!BB39,O52) -> 0 | G52: ЭММсНРиСП | H52: Эксплуатация машин по ТСН-2001.16 | K52: 231 | L52: 12 | M52: 3 | O52: 2 | P52: =ROUND(Source!ET39,O52) -> 0 | W52: 0 | X52: 1 | Y52: 0 | Z52: 0 | AA52: 1 | AB52: 0
A53: 50 | B53: 0 | C53: 0 | D53: 1 | E53: 204 | F53: =ROUND(Source!R39,O53) -> 0 | G53: ЗПМ | H53: ЗП машинистов | K53: 204 | L53: 13 | M53: 3 | O53: 2 | P53: =ROUND(Source!DJ39,O53) -> 0 | W53: 0 | X53: 1 | Y53: 0 | Z53: 0 | AA53: 1 | AB53: 0
A54: 50 | B54: 0 | C54: 0 | D54: 1 | E54: 205 | F54: =ROUND(Source!S39,O54) -> 0 | G54: ОЗП | H54: Основная ЗП рабочих | K54: 205 | L54: 14 | M54: 3 | O54: 2 | P54: =ROUND(Source!DK39,O54) -> 0 | W54: 0 | X54: 1 | Y54: 0 | Z54: 0 | AA54: 1 | AB54: 0
A55: 50 | B55: 0 | C55: 0 | D55: 1 | E55: 232 | F55: =ROUND(Source!BC39,O55) -> 0 | G55: ОЗПсНРиСП | H55: Основная ЗП рабочих по ТСН-2001.16 | K55: 232 | L55: 15 | M55: 3 | O55: 2 | P55: =ROUND(Source!EU39,O55) -> 0 | W55: 0 | X55: 1 | Y55: 0 | Z55: 0 | AA55: 1 | AB55: 0
A56: 50 | B56: 0 | C56: 0 | D56: 1 | E56: 214 | F56: =ROUND(Source!AS39,O56) -> 0 | G56: Строит | H56: Строительные работы с НР и СП | K56: 214 | L56: 16 | M56: 3 | O56: 2 | P56: =ROUND(Source!EK39,O56) -> 0 | W56: 0 | X56: 1 | Y56: 0 | Z56: 0 | AA56: 1 | AB56: 0
A57: 50 | B57: 0 | C57: 0 | D57: 1 | E57: 215 | F57: =ROUND(Source!AT39,O57) -> 0 | G57: Монтаж | H57: Монтажные работы с НР и СП | K57: 215 | L57: 17 | M57: 3 | O57: 2 | P57: =ROUND(Source!EL39,O57) -> 0 | W57: 0 | X57: 1 | Y57: 0 | Z57: 0 | AA57: 1 | AB57: 0
A58: 50 | B58: 0 | C58: 0 | D58: 1 | E58: 217 | F58: =ROUND(Source!AU39,O58) -> 836.72 | G58: Прочие | H58: Прочие работы с НР и СП | K58: 217 | L58: 18 | M58: 3 | O58: 2 | P58: =ROUND(Source!EM39,O58) -> 10227.83 | W58: 836.72 | X58: 1 | Y58: 836.72 | Z58: 10227.83 | AA58: 1 | AB58: 10227.83
A59: 50 | B59: 0 | C59: 0 | D59: 1 | E59: 230 | F59: =ROUND(Source!BA39,O59) -> 0 | G59: ПрочиеЗатр | H59: Прочие затраты по ТСН-2001.16 | K59: 230 | L59: 19 | M59: 3 | O59: 2 | P59: =ROUND(Source!ES39,O59) -> 0 | W59: 0 | X59: 1 | Y59: 0 | Z59: 0 | AA59: 1 | AB59: 0
A60: 50 | B60: 0 | C60: 0 | D60: 1 | E60: 206 | F60: =ROUND(Source!T39,O60) -> 0 | G60: ВозврМат | H60: Возврат материалов | K60: 206 | L60: 20 | M60: 3 | O60: 2 | P60: =ROUND(Source!DL39,O60) -> 0 | W60: 0 | X60: 1 | Y60: 0 | Z60: 0 | AA60: 1 | AB60: 0
A61: 50 | B61: 0 | C61: 0 | D61: 1 | E61: 207 | F61: =Source!U39 -> 0 | G61: ТрудСтр | H61: Трудозатраты строителей | K61: 207 | L61: 21 | M61: 3 | O61: -1 | P61: =Source!DM39 -> 0 | W61: 0 | X61: 1 | Y61: 0 | Z61: 0 | AA61: 1 | AB61: 0
...

Sheet SourceObSm
A1: 0 | B1: Smeta.RU (495) 974-1589 | D1: _OBSM_ | F1: 0 | G1: 0 | H1: 0 | I1: Smeta.RU | K1: 1 | L1: 75112 | M1: 10 | N1: 11 | O1: 15 | P1: 0 | Q1: 1
A12: 1 | B12: 51 | C12: 1 | E12: 0 | F12: 09-01-04 Транспортировка_(2 этап) | G12: 09-01-04 Транспортировка | I12: 0 | K12: 0 | L12: 0 | M12: 4098 | O12: 0 | P12: 0 | Q12: 0 | R12: 175 | S12: 160 | T12: 1 | V12: 0 | BB12: 0 | BH12: Сметные нормы списания | BI12: Коды ОКП для ТСН-2001 МГЭ (История развития) | BJ12: 1 | BK12: 1 | BL12: 0 | BM12: 0 | BN12: 1 | BO12: 0 | BP12: 6 | BQ12: 2 | BR12: 1 | BS12: 1 | BT12: 0 | BU12: 0 | BV12: 0 | BW12: 0 | BX12: 0 | BZ12: Типовой расчет для ТСН-2001 МГЭ, Новая методика с выпуска доп. 43 (Строительство), Доп 73 | CA12: История развития для ТСН-2001 (МГЭ) 73 доп от 17.07.2024 | CB12: История развития для ТСН-2001 (МГЭ) 73 доп от 17.07.2024 | CC12: История развития для ТСН-2001 (МГЭ) 73 доп от 17.07.2024 | CD12: История развития для ТСН-2001 (МГЭ) 73 доп от 17.07.2024 | CE12: Поправки для ТСН-2001 от 16.04.2024 г. доп.72 | CF12: 0 | CG12: 0 | CH12: 8 | CK12: 79 | CQ12: Территориальные сметные нормативы для Москвы (ТСН-2001) | CR12: ТЕР | CS12: 41660 | CT12: 1 | CU12: 73 | CY12: 0 | EC12: 0
A14: 22 | B14: 1 | C14: 0 | D14: 57734472 | E14: 57734470 | F14: 2 | G14: 1
A16: 3 | B16: 1 | C16: Новая локальная смета | D16: Новая локальная смета | E16: =ROUND((Source!F201)/1000,2) -> 0 | F16: =ROUND((Source!F202)/1000,2) -> 0 | G16: =ROUND((Source!F193)/1000,2) -> 0 | H16: =ROUND((Source!F203)/1000+(Source!F204)/1000,2) -> 4.87 | I16: =E16+F16+G16+H16 -> 4.87 | J16: =ROUND((Source!F199+Source!F198)/1000,2) -> 0 | K16: 4.87 | L16: 0 | M16: 0 | N16: =I16+L16+M16 -> 4.87 | T16: =ROUND((Source!P201)/1000,2) -> 0 | U16: =ROUND((Source!P202)/1000,2) -> 0 | V16: =ROUND((Source!P193)/1000,2) -> 0 | W16: =ROUND((Source!P203)/1000+(Source!P204)/1000,2) -> 71.22 | X16: =T16+U16+V16+W16 -> 71.22 | Y16: =ROUND((Source!P199+Source!P198)/1000,2) -> 0 | Z16: 71.22 | AA16: 0 | AB16: 0 | AC16: =X16+AA16+AB16 -> 71.22 | AI16: 0 | AJ16: 0 | AN16: 0 | AT16: 4868.34 | AU16: 0 | AV16: 0 | AW16: 0 | AX16: 0 | AY16: 4868.34 | AZ16: 0 | BA16: 0 | BB16: 0 | BC16: 0 | BD16: 4868.34 | BE16: 0 | BF16: 0 | BG16: 0 | BH16: 0 | BI16: 0 | BJ16: 0 | BK16: 4868.34 | BR16: 71217.26 | BS16: 0 | BT16: 0 | BU16: 0 | BV16: 0 | BW16: 71217.26 | BX16: 0 | BY16: 0 | BZ16: 0 | CA16: 0 | CB16: 71217.26 | CC16: 0 | CD16: 0 | CE16: 0 | CF16: 0 | CG16: 0 | CH16: 0 | CI16: 71217.26
A18: 51 | E18: 0 | F18: 0 | G18: 0 | H18: 4.87 | I18: 4.87 | J18: 0 | K18: 4.87 | L18: 0 | M18: 0 | N18: 4.87 | T18: 0 | U18: 0 | V18: 0 | W18: 71.22 | X18: 71.22 | Y18: 0 | Z18: 71.22 | AA18: 0 | AB18: 0 | AC18: 71.22
A20: 50 | B20: 0 | C20: 0 | D20: 1 | E20: 201 | F20: 4868.34 | G20: ПЗ | H20: Прямые затраты | K20: 201 | L20: 1 | M20: 3 | O20: 2 | P20: 71217.26
A21: 50 | B21: 0 | C21: 0 | D21: 1 | E21: 202 | F21: 0 | G21: СтМатОб | H21: Стоимость материальных ресурсов (всего) | K21: 202 | L21: 2 | M21: 3 | O21: 2 | P21: 0
A22: 50 | B22: 0 | C22: 0 | D22: 1 | E22: 222 | F22: 0 | G22: СтМатОбЗак | H22: Стоимость материалов и оборудования заказчика | K22: 222 | L22: 3 | M22: 3 | O22: 2 | P22: 0
A23: 50 | B23: 0 | C23: 0 | D23: 1 | E23: 225 | F23: 0 | G23: СтМатОбПод | H23: Стоимость материалов и оборудования подрядчика | K23: 225 | L23: 4 | M23: 3 | O23: 2 | P23: 0
A24: 50 | B24: 0 | C24: 0 | D24: 1 | E24: 226 | F24: 0 | G24: СтМат | H24: Стоимость материалов (всего) | K24: 226 | L24: 5 | M24: 3 | O24: 2 | P24: 0
A25: 50 | B25: 0 | C25: 0 | D25: 1 | E25: 227 | F25: 0 | G25: СтМатЗак | H25: Стоимость материалов заказчика | K25: 227 | L25: 6 | M25: 3 | O25: 2 | P25: 0
A26: 50 | B26: 0 | C26: 0 | D26: 1 | E26: 228 | F26: 0 | G26: СтМатПод | H26: Стоимость материалов подрядчика | K26: 228 | L26: 7 | M26: 3 | O26: 2 | P26: 0
A27: 50 | B27: 0 | C27: 0 | D27: 1 | E27: 216 | F27: 0 | G27: Оборуд | H27: Стоимость оборудования (всего) | K27: 216 | L27: 8 | M27: 3 | O27: 2 | P27: 0
A28: 50 | B28: 0 | C28: 0 | D28: 1 | E28: 223 | F28: 0 | G28: ОборудЗак | H28: Стоимость оборудования заказчика | K28: 223 | L28: 9 | M28: 3 | O28: 2 | P28: 0
A29: 50 | B29: 0 | C29: 0 | D29: 1 | E29: 229 | F29: 0 | G29: ОборудПод | H29: Стоимость оборудования подрядчика | K29: 229 | L29: 10 | M29: 3 | O29: 2 | P29: 0
A30: 50 | B30: 0 | C30: 0 | D30: 1 | E30: 203 | F30: 4868.34 | G30: ЭММ | H30: Эксплуатация машин | K30: 203 | L30: 11 | M30: 3 | O30: 2 | P30: 71217.26
A31: 50 | B31: 0 | C31: 0 | D31: 1 | E31: 231 | F31: 0 | G31: ЭММсНРиСП | H31: Эксплуатация машин по ТСН-2001.16 | K31: 231 | L31: 12 | M31: 3 | O31: 2 | P31: 0
... A46: 50 | B46: 0 | C46: 0 | D46: 1 | E46: 224 | F46: 4868.34 | G46: Всего | H46: Всего с НР и СП | K46: 224 | L46: 27 | M46: 3 | O46: 2 | P46: 71217.26
A48: -1
A51: 75 | B51: Базовый уровень цен | C51: 2000 | D51: 0 | E51: 1 | G51: 0 | H51: 1 | I51: 0 | J51: 1 | K51: 98 | L51: 77 | M51: 0 | N51: 57734472 | O51: 1
A52: 75 | B52: Текущий уровень цен | C52: 2024 | D52: 0 | E52: 4 | G52: 0 | H52: 2 | I52: 1 | J52: 1 | K52: 95 | L52: 65 | M52: 1 | N52: 57734470 | O52: 2
A53: 1 | B53: Сборник индексов | C53: Коэффициенты к ТСН-2001 МГЭ | D53: 2024 | E53: 7 | F53: 1 | G53: 1 | H53: 0 | I53: 2 | J53: 1 | K53: 1 | L53: 1 | M53: 1 | N53: 1 | O53: 1 | P53: 1 | Q53: 1 | AA53: 212 | AN53: 57734471

Sheet SmtRes
A1: =ROW(Source!A28) -> 28 | B1: 57734472 | C1: 57734765 | D1: 47634960 | E1: 27786564 | F1: 1 | G1: 27786564 | H1: 2 | I1: 9999990007 | K1: Стоимость прочих машин (ЭСН) | L1: 1344 | N1: 1008 | O1: руб. | P1: руб. | Q1: 1 | W1: 0 | X1: -1180195794 | Y1: =AT1 -> 42.72 | AA1: 0 | AB1: 1 | AC1: 0 | AD1: 0 | AE1: 0 | AF1: 1 | AG1: 0 | AH1: 0 | AI1: 1 | AJ1: 1 | AK1: 1 | AL1: 1 | AM1: -2 | AN1: 0 | AO1: 1 | AP1: 1 | AQ1: 0 | AR1: 0 | AT1: 42.72 | AV1: 0 | AW1: 2 | AX1: 57734767 | AY1: 1 | AZ1: 0 | BA1: 1 | BB1: 0 | BC1: 0 | BD1: 0 | BE1: 0 | BF1: 0 | BG1: 0 | BH1: 0 | BI1: 0 | BJ1: 0 | BK1: 0 | BL1: 0 | BM1: 0 | BN1: 0 | BO1: 0 | BP1: 0 | BQ1: 0 | BR1: 0 | BS1: 0 | BT1: 0 | BU1: 0 | BV1: 0 | BW1: 0 | CV1: 0 | CW1: =ROUND(Y1*Source!I28*DO1,9) -> 0 | CX1: =ROUND(Y1*Source!I28,9) -> 450.696 | CY1: =AB1 -> 1 | CZ1: =AF1 -> 1 | DA1: =AJ1 -> 1 | DB1: =ROUND(ROUND(AT1*CZ1,2),6) -> 42.72 | DC1: =ROUND(ROUND(AT1*AG1,2),6) -> 0 | DF1: =ROUND(ROUND(AE1,2)*CX1,2) -> 0 | DG1: =ROUND(ROUND(AF1,2)*CX1,2) -> 450.7 | DH1: =ROUND(ROUND(AG1,2)*CX1,2) -> 0 | DI1: =ROUND(ROUND(AH1,2)*CX1,2) -> 0 | DJ1: =DG1 -> 450.7 | DK1: 0 | DM1: 0 | DO1: 0
A2: =ROW(Source!A29) -> 29 | B2: 57734470 | C2: 57734765 | D2: 47634960 | E2: 27786564 | F2: 1 | G2: 27786564 | H2: 2 | I2: 9999990007 | K2: Стоимость прочих машин (ЭСН) | L2: 1344 | N2: 1008 | O2: руб. | P2: руб. | Q2: 1 | W2: 0 | X2: -1180195794 | Y2: =AT2 -> 42.72 | AA2: 0 | AB2: 1 | AC2: 0 | AD2: 0 | AE2: 0 | AF2: 1 | AG2: 0 | AH2: 0 | AI2: 1 | AJ2: 1 | AK2: 1 | AL2: 1 | AM2: -2 | AN2: 0 | AO2: 1 | AP2: 1 | AQ2: 0 | AR2: 0 | AT2: 42.72 | AV2: 0 | AW2: 2 | AX2: 57734767 | AY2: 1 | AZ2: 0 | BA2: 2 | BB2: 0 | BC2: 0 | BD2: 0 | BE2: 0 | BF2: 0 | BG2: 0 | BH2: 0 | BI2: 0 | BJ2: 0 | BK2: 0 | BL2: 0 | BM2: 0 | BN2: 0 | BO2: 0 | BP2: 0 | BQ2: 0 | BR2: 0 | BS2: 0 | BT2: 0 | BU2: 0 | BV2: 0 | BW2: 0 | CV2: 0 | CW2: =ROUND(Y2*Source!I29*DO2,9) -> 0 | CX2: =ROUND(Y2*Source!I29,9) -> 450.696 | CY2: =AB2 -> 1 | CZ2: =AF2 -> 1 | DA2: =AJ2 -> 1 | DB2: =ROUND(ROUND(AT2*CZ2,2),6) -> 42.72 | DC2: =ROUND(ROUND(AT2*AG2,2),6) -> 0 | DF2: =ROUND(ROUND(AE2,2)*CX2,2) -> 0 | DG2: =ROUND(ROUND(AF2,2)*CX2,2) -> 450.7 | DH2: =ROUND(ROUND(AG2,2)*CX2,2) -> 0 | DI2: =ROUND(ROUND(AH2,2)*CX2,2) -> 0 | DJ2: =DG2 -> 450.7 | DK2: 0 | DM2: 0 | DO2: 0

Sheet EtalonRes
A1: =ROW(Source!A28) -> 28 | B1: 57734767 | C1: 57734765 | D1: 47634960 | E1: 27786564 | F1: 1 | G1: 27786564 | H1: 2 | I1: 9999990007 | K1: Стоимость прочих машин (ЭСН) | L1: 1344 | N1: 1008 | O1: руб. | P1: руб. | Q1: 1 | X1: 42.72 | Y1: 0 | Z1: 1 | AA1: 0 | AB1: 0 | AC1: 0 | AD1: 1 | AE1: 0 | AG1: 42.72 | AH1: 2 | AI1: 57734766 | AJ1: 1 | AK1: 0 | AL1: 0 | AM1: 0 | AN1: 0 | AO1: 0 | AP1: 0 | AQ1: 0 | AR1: 0
A2: =ROW(Source!A29) -> 29 | B2: 57734767 | C2: 57734765 | D2: 47634960 | E2: 27786564 | F2: 1 | G2: 27786564 | H2: 2 | I2: 9999990007 | K2: Стоимость прочих машин (ЭСН) | L2: 1344 | N2: 1008 | O2: руб. | P2: руб. | Q2: 1 | X2: 42.72 | Y2: 0 | Z2: 1 | AA2: 0 | AB2: 0 | AC2: 0 | AD2: 1 | AE2: 0 | AG2: 42.72 | AH2: 2 | AI2: 57734766 | AJ2: 2 | AK2: 0 | AL2: 0 | AM2: 0 | AN2: 0 | AO2: 0 | AP2: 0 | AQ2: 0 | AR2: 0
A3: =ROW(Source!A30) -> 30 | B3: 57734769 | C3: 57734768 | D3: 47634960 | E3: 27786564 | F3: 1 | G3: 27786564 | H3: 2 | I3: 9999990007 | K3: Стоимость прочих машин (ЭСН) | L3: 1344 | N3: 1008 | O3: руб. | P3: руб. | Q3: 1 | X3: 36.59 | Y3: 0 | Z3: 1 | AA3: 0 | AB3: 0 | AC3: 0 | AD3: 1 | AE3: 0 | AG3: 36.59 | AH3: 3 | AI3: -1 | AK3: 0 | AL3: 0 | AM3: 0 | AN3: 0 | AO3: 0 | AP3: 0 | AQ3: 0 | AR3: 0
A4: =ROW(Source!A31) -> 31 | B4: 57734769 | C4: 57734768 | D4: 47634960 | E4: 27786564 | F4: 1 | G4: 27786564 | H4: 2 | I4: 9999990007 | K4: Стоимость прочих машин (ЭСН) | L4: 1344 | N4: 1008 | O4: руб. | P4: руб. | Q4: 1 | X4: 36.59 | Y4: 0 | Z4: 1 | AA4: 0 | AB4: 0 | AC4: 0 | AD4: 1 | AE4: 0 | AG4: 36.59 | AH4: 3 | AI4: -1 | AK4: 0 | AL4: 0 | AM4: 0 | AN4: 0 | AO4: 0 | AP4: 0 | AQ4: 0 | AR4: 0
A5: =ROW(Source!A32) -> 32 | B5: 57734771 | C5: 57734770 | D5: 47634960 | E5: 27786564 | F5: 1 | G5: 27786564 | H5: 2 | I5: 9999990007 | K5: Стоимость прочих машин (ЭСН) | L5: 1344 | N5: 1008 | O5: руб. | P5: руб. | Q5: 1 | X5: 22.57 | Y5: 0 | Z5: 1 | AA5: 0 | AB5: 0 | AC5: 0 | AD5: 1 | AE5: 0 | AG5: 22.57 | AH5: 3 | AI5: -1 | AK5: 0 | AL5: 0 | AM5: 0 | AN5: 0 | AO5: 0 | AP5: 0 | AQ5: 0 | AR5: 0
A6: =ROW(Source!A33) -> 33 | B6: 57734771 | C6: 57734770 | D6: 47634960 | E6: 27786564 | F6: 1 | G6: 27786564 | H6: 2 | I6: 9999990007 | K6: Стоимость прочих машин (ЭСН) | L6: 1344 | N6: 1008 | O6: руб. | P6: руб. | Q6: 1 | X6: 22.57 | Y6: 0 | Z6: 1 | AA6: 0 | AB6: 0 | AC6: 0 | AD6: 1 | AE6: 0 | AG6: 22.57 | AH6: 3 | AI6: -1 | AK6: 0 | AL6: 0 | AM6: 0 | AN6: 0 | AO6: 0 | AP6: 0 | AQ6: 0 | AR6: 0
A7: =ROW(Source!A34) -> 34 | B7: 57734773 | C7: 57734772 | D7: 47634960 | E7: 27786564 | F7: 1 | G7: 27786564 | H7: 2 | I7: 9999990007 | K7: Стоимость прочих машин (ЭСН) | L7: 1344 | N7: 1008 | O7: руб. | P7: руб. | Q7: 1 | X7: 17.84 | Y7: 0 | Z7: 1 | AA7: 0 | AB7: 0 | AC7: 0 | AD7: 1 | AE7: 0 | AG7: 17.84 | AH7: 3 | AI7: -1 | AK7: 0 | AL7: 0 | AM7: 0 | AN7: 0 | AO7: 0 | AP7: 0 | AQ7: 0 | AR7: 0
A8: =ROW(Source!A35) -> 35 | B8: 57734773 | C8: 57734772 | D8: 47634960 | E8: 27786564 | F8: 1 | G8: 27786564 | H8: 2 | I8: 9999990007 | K8: Стоимость прочих машин (ЭСН) | L8: 1344 | N8: 1008 | O8: руб. | P8: руб. | Q8: 1 | X8: 17.84 | Y8: 0 | Z8: 1 | AA8: 0 | AB8: 0 | AC8: 0 | AD8: 1 | AE8: 0 | AG8: 17.84 | AH8: 3 | AI8: -1 | AK8: 0 | AL8: 0 | AM8: 0 | AN8: 0 | AO8: 0 | AP8: 0 | AQ8: 0 | AR8: 0
A9: =ROW(Source!A36) -> 36 | B9: 57734775 | C9: 57734774 | D9: 47634960 | E9: 27786564 | F9: 1 | G9: 27786564 | H9: 2 | I9: 9999990007 | K9: Стоимость прочих машин (ЭСН) | L9: 1344 | N9: 1008 | O9: руб. | P9: руб. | Q9: 1 | X9: 21.71 | Y9: 0 | Z9: 1 | AA9: 0 | AB9: 0 | AC9: 0 | AD9: 1 | AE9: 0 | AG9: 21.71 | AH9: 3 | AI9: -1 | AK9: 0 | AL9: 0 | AM9: 0 | AN9: 0 | AO9: 0 | AP9: 0 | AQ9: 0 | AR9: 0
A10: =ROW(Source!A37) -> 37 | B10: 57734775 | C10: 57734774 | D10: 47634960 | E10: 27786564 | F10: 1 | G10: 27786564 | H10: 2 | I10: 9999990007 | K10: Стоимость прочих машин (ЭСН) | L10: 1344 | N10: 1008 | O10: руб. | P10: руб. | Q10: 1 | X10: 21.71 | Y10: 0 | Z10: 1 | AA10: 0 | AB10: 0 | AC10: 0 | AD10: 1 | AE10: 0 | AG10: 21.71 | AH10: 3 | AI10: -1 | AK10: 0 | AL10: 0 | AM10: 0 | AN10: 0 | AO10: 0 | AP10: 0 | AQ10: 0 | AR10: 0
